Workbook
Name \A: [1]A!$D$9:$D$53
Name _11_0ELECSURE: '[5]#¡REF'!#REF!
Name _14_0ELECSURME: '[5]#¡REF'!#REF!
Name _17_0ELECT: '[5]#¡REF'!#REF!
Name _20_0ELECTROL: '[5]#¡REF'!#REF!
Name _23_0ELEORIE: '[5]#¡REF'!#REF!
Name _26_0ELNO: '[5]#¡REF'!#REF!
Name _29_0ELSURE: '[5]#¡REF'!#REF!
Name _32_0HIDRAND: '[5]#¡REF'!#REF!
Name _35_0S: '[5]#¡REF'!#REF!
Name _5_0EL: '[5]#¡REF'!#REF!
Name _8_0ELCEN: '[5]#¡REF'!#REF!
Name _gg1: '[6]#¡REF'!#REF!
Name _LM3: '[7]FORMA-LM3'!$B$1:$N$48
Name _LS1: '[7]FORMA-LS1-LS2'!$A$1:$P$83
Name _LS2: '[7]FORMA-LS1-LS2'!$A$86:$P$168
Name _LS3: '[7]FORMA-LS3'!$A$1:$M$53
Name _MET1: #REF!
Name _MET2: #REF!
Name _PPA1: #REF!
Name _PPB2: #REF!
Name _PPC3: #REF!
Name _PPD4: #REF!
Name _PPE5: #REF!
Name _PPF6: #REF!
Name _RE1: '[7]FORMA- RE1'!$A$3:$H$52
Name _RES1: #REF!
Name _RES2: #REF!
Name _RES3: #REF!
Name _RES4: #REF!
Name _REV3: [8]DATOS!$A$3:$E$22
Name _RL1: '[7]FORMA-LM3'!$B$1:$L$46
Name _SE2: '[7]FORMA-SE2'!$M$5
Name _sec01: [9]Datos!$D$26
Name _sec02: [9]Datos!$D$27
Name _sec03: [9]Datos!$D$28
Name _sec04: [9]Datos!$D$29
Name _sec05: [9]Datos!$D$30
Name _SOL1: #REF!
Name _SOL2: #REF!
Name _SOL3: #REF!
Name _SOL4: #REF!
Name _UI1577: #REF!
Name _vu111: #REF!
Name A: '[5]#¡REF'!#REF!
Name A_1: #REF!
Name A_10: #REF!
Name A_11: #REF!
Name A_12: #REF!
Name A_13: #REF!
Name A_14: #REF!
Name A_15: #REF!
Name A_16: #REF!
Name A_17: #REF!
Name A_18: #REF!
Name A_19: #REF!
Name A_2: #REF!
Name A_20: #REF!
Name A_21: #REF!
Name A_22: #REF!

Sheet ESTUIDIO + OBRA
B1: CALENDARIO VALORIZADO DE AVANCE DE OBRA
B3: PROYECTO | C3: =+LP!C3 -> : “AMPLIACIÓN DEL SERVICIO DE ENERGÍA ELÉCTRICA EN LA PROVINCIA DEL SANTA Y EN EL DISTRITO DE PAMPAROMAS – DEPARTAMENTO DE ANCASH”
B4: SECCION | C4: : RESUMEN GENERAL
B5: EJECUTOR | C5: : CONSORCIO PACIFICO
B6: PLAZO | C6: : 330 DIAS CALENDARIOS
B7: PLAZO ESTUDIO DIFINITIVO | C7: : 120 DIAS CALENDARIOS
B8: PLAZO EJECUCION DE OBRA | C8: : 210 DIAS CALENDARIOS
B9: MONTO DE CONTRATO | C9: : 3,841,290.50
C11: ESTUDIO DIFINITIVO | G11: EJECUCION DE OBRA
B12: MES | C12: INFOR 01 | D12: INFORME 02 | E12: INFORME 03 | F12: INFORME 04 | G12: LINEA PRIMARIA | H12: RED PRIMARIA | I12: RED SECUNDARIA | J12: SISTEMA FOTOVOLTAICO | K12: TOTAL (INCLUIDO IGV) | M12: ACUMULADO (INCLUIDO IGV)
B13: MES 1 | C13: 0 | K13: =SUM(C13:J13) -> 0 | M13: =+K13 -> 0
B14: MES 2 | D14: 70843.14 | K14: =SUM(C14:J14) -> 70843.14 | M14: =+M13+K14 -> 70843.14
B15: MES 3 | E15: 70843.14 | K15: =SUM(C15:J15) -> 70843.14 | M15: =+K15+M14 -> 141686.28
B16: MES 4 | F16: 94457.53 | K16: =SUM(C16:J16) -> 94457.53 | M16: =+K16+M15+0.01 -> 236143.82
B17: MES 5 | G17: {=+TRANSPOSE(LP!E67:K67)} -> 12520.9 | H17: {=+TRANSPOSE(RP!E61:K61)} -> 4311.63 | I17: {=+TRANSPOSE(RS!E54:K54)} -> 4526.67 | J17: {=+TRANSPOSE(SFD!E45:K45)} -> 0 | K17: =SUM(G17:J17) -> 21359.2 | M17: =+K17+M16 -> 257503.02
B18: MES 6 | G18: 62364.252 | H18: 14744.52 | I18: 36707.14 | J18: 0 | K18: =SUM(G18:J18)-0.01 -> 113815.9 | M18: =+K18+M17 -> 371318.92
B19: MES 7 | G19: 201641.02 | H19: 52674.9 | I19: 109168.91 | J19: 4768.92 | K19: =SUM(G19:J19) -> 368253.75 | M19: =+K19+M18 -> 739572.67
B20: MES 8 | G20: 445833.12 | H20: 125883.32 | I20: 300095.66 | J20: 18807.015 | K20: =SUM(G20:J20) -> 890619.12 | M20: =+K20+M19 -> 1630191.8
B21: MES 9 | G21: 545669.85 | H21: 190464.54 | I21: 159840.65 | J21: 54165.095 | K21: =SUM(G21:J21) -> 950140.14 | M21: =+K21+M20 -> 2580331.9
B22: MES 10 | G22: 114115.85 | H22: 14338.33 | I22: 290266.96 | J22: 262444.74 | K22: =SUM(G22:J22) -> 681165.88 | M22: =+K22+M21 -> 3261497.8
B23: MES 11 | G23: 347463.33 | H23: 34302.98 | I23: 154099.76 | J23: 43926.64 | K23: =SUM(G23:J23)-0.01 -> 579792.7 | M23: =+K23+M22 -> 3841290.5
B25: TOTAL (ONCLUYE IGV) | C25: =SUM(C13:C24) -> 0 | D25: =SUM(D13:D24) -> 70843.14 | E25: =SUM(E13:E24) -> 70843.14 | F25: =SUM(F13:F24) -> 94457.53 | G25: =SUM(G17:G24) -> 1729608.3 | H25: =SUM(H17:H24) -> 436720.22 | I25: =SUM(I17:I24)+0.01 -> 1054705.8 | J25: =SUM(J17:J24)+0.01 -> 384112.42 | K25: =SUM(C25:J25)-0.03 -> 3841290.5 | N25: 3841290.5 | O25: =+K25-N25 -> 0
H39: Firma, Nombres y Apellidos del contratista o Representante legal o común, según corresponda

Sheet RESUMEN LP
B2: METRADO BASE - LINEAS PRIMARIAS
B4: “AMPLIACIÓN DEL SERVICIO DE ENERGÍA ELÉCTRICA EN LA PROVINCIA DEL SANTA Y EN EL DISTRITO DE PAMPAROMAS – DEPARTAMENTO DE ANCASH”
B6: UBICACIÓN | D6: : | E6: ANCASH
B7: SECCIÓN I | D7: : | E7: LINEAS PRIMARIAS | T7: 16910.97
M8: =tc -> T.C. (S//US$): 3,642
B9: ITEM | C9: DESCRIPCION | F9: MES 1 | G9: MES 2 | H9: MES 3 | I9: MES 4 | J9: MES 5 | K9: MES 6 | L9: MES 7 | M9: TOTAL S/.
B11: A | D11: SUMINISTRO DE MATERIALES | F11: =+LP!E12 -> 4113.31 | G11: =+LP!F12 -> 28952.002 | H11: =+LP!G12 -> 109978.39 | I11: =+LP!H12 -> 264989.59 | J11: =+LP!I12 -> 275696.9 | K11: =+LP!J12 -> 0 | L11: =+LP!K12 -> 0 | M11: =+SUM(F11:L11) -> 683730.19
B12: B | D12: MONTAJE ELECTROMECANICO | F12: =+LP!E40 -> 2571.44 | G12: =+LP!F40 -> 11099.67 | H12: =+LP!G40 -> 27108.31 | I12: =+LP!H40 -> 42690.11 | J12: =+LP!I40 -> 123493.33 | K12: =+LP!J40 -> 85491.83 | L12: =+LP!K40 -> 260308.04 | M12: =+SUM(F12:L12) -> 552762.73
B13: C | D13: TRANSPORTE DE MATERIALES | F13: =+LP!E26 -> 2695.49 | G13: =+LP!F26 -> 6669.55 | H13: =+LP!G26 -> 13976.09 | I13: =+LP!H26 -> 26323.72 | J13: =+LP!I26 -> 9607.58 | K13: =+LP!J26 -> 0 | L13: =+LP!K26 -> 0 | M13: =+SUM(F13:L13) -> 59272.43
B14: D | D14: TOTAL COSTO DIRECTO | F14: =SUM(F11:F13) -> 9380.24 | G14: =SUM(G11:G13) -> 46721.222 | H14: =SUM(H11:H13) -> 151062.79 | I14: =SUM(I11:I13) -> 334003.42 | J14: =SUM(J11:J13) -> 408797.81 | K14: =SUM(K11:K13) -> 85491.83 | L14: =SUM(L11:L13) -> 260308.04 | M14: =SUM(M11:M13) -> 1295765.4
B16: E | E16: GASTOS GENERALES (10.12%) | F16: =ROUND(+F14*$N$16,2) -> 949.28 | G16: =ROUND(+G14*$N$16,2) -> 4728.19 | H16: =ROUND(+H14*$N$16,2) -> 15287.55 | I16: =ROUND(+I14*$N$16,2) -> 33801.15 | J16: =ROUND(+J14*$N$16,2) -> 41370.34 | K16: =ROUND(+K14*$N$16,2) -> 8651.77 | L16: =ROUND(+L14*$N$16,2) -> 26343.17 | M16: =+SUM(F16:L16)+0.01 -> 131131.46 | N16: 0.1012
B17: F | E17: UTILIDADES(3.%) | F17: =ROUND(+F14*$N$17,2) -> 281.41 | G17: =ROUND(+G14*$N$17,2) -> 1401.64 | H17: =ROUND(+H14*$N$17,2) -> 4531.88 | I17: =ROUND(+I14*$N$17,2) -> 10020.1 | J17: =ROUND(+J14*$N$17,2) -> 12263.93 | K17: =ROUND(+K14*$N$17,2) -> 2564.75 | L17: =ROUND(+L14*$N$17,2) -> 7809.24 | M17: =+SUM(F17:L17) -> 38872.95 | N17: 0.03
D19: COSTO TOTAL S/ (No incluye I.G.V.) | F19: =+F14+F16+F17 -> 10610.93 | G19: =+G14+G16+G17 -> 52851.052 | H19: =+H14+H16+H17 -> 170882.22 | I19: =+I14+I16+I17 -> 377824.67 | J19: =+J14+J16+J17 -> 462432.08 | K19: =+K14+K16+K17 -> 96708.35 | L19: =+L14+L16+L17 -> 294460.45 | M19: =+M14+M16+M17 -> 1465769.8
M22: 1300732.1

Sheet RESUMEN RP
B2: METRADO BASE - REDES PRIMARIAS
B4: “AMPLIACIÓN DEL SERVICIO DE ENERGÍA ELÉCTRICA EN LA PROVINCIA DEL SANTA Y EN EL DISTRITO DE PAMPAROMAS – DEPARTAMENTO DE ANCASH”
B6: UBICACIÓN | D6: : | E6: ANCASH
B7: SECCIÓN I | D7: : | E7: REDES PRIMARIAS | T7: 16910.97
M8: =tc -> T.C. (S//US$): 3,642
B9: ITEM | C9: DESCRIPCION | F9: MES 1 | G9: MES 2 | H9: MES 3 | I9: MES 4 | J9: MES 5 | K9: MES 6 | L9: MES 7 | M9: TOTAL S/.
B11: A | D11: SUMINISTRO DE MATERIALES | F11: =+RP!E12 -> 582.28 | G11: =+RP!F12 -> 6535.4 | H11: =+RP!G12 -> 29031.64 | I11: =+RP!H12 -> 75295.26 | J11: =+RP!I12 -> 111761.01 | K11: =+RP!J12 -> 0 | L11: =+RP!K12 -> 0 | M11: =+SUM(F11:L11) -> 223205.59
B12: B | D12: MONTAJE ELECTROMECANICO | F12: =+RP!E44 -> 1869.14 | G12: =+RP!F44 -> 2817.42 | H12: =+RP!G44 -> 6378.95 | I12: =+RP!H44 -> 11562.76 | J12: =+RP!I44 -> 25786.75 | K12: =+RP!J44 -> 10741.81 | L12: =+RP!K44 -> 25698.66 | M12: =+SUM(F12:L12) -> 84855.49
B13: C | D13: TRANSPORTE DE MATERIALES | F13: =+RP!E28 -> 778.71 | G13: =+RP!F28 -> 1693.29 | H13: =+RP!G28 -> 4051.7 | I13: =+RP!H28 -> 7449.59 | J13: =+RP!I28 -> 5141.97 | K13: =+RP!J28 -> 0 | L13: =+RP!K28 -> 0 | M13: =+SUM(F13:L13) -> 19115.26
B14: D | D14: TOTAL COSTO DIRECTO | F14: =SUM(F11:F13) -> 3230.13 | G14: =SUM(G11:G13) -> 11046.11 | H14: =SUM(H11:H13) -> 39462.29 | I14: =SUM(I11:I13) -> 94307.61 | J14: =SUM(J11:J13) -> 142689.73 | K14: =SUM(K11:K13) -> 10741.81 | L14: =SUM(L11:L13) -> 25698.66 | M14: =SUM(M11:M13) -> 327176.34
B16: E | E16: GASTOS GENERALES (10.12%) | F16: =ROUND(+F14*$N$16,2) -> 326.89 | G16: =ROUND(+G14*$N$16,2) -> 1117.87 | H16: =ROUND(+H14*$N$16,2) -> 3993.58 | I16: =ROUND(+I14*$N$16,2) -> 9543.93 | J16: =ROUND(+J14*$N$16,2) -> 14440.2 | K16: =ROUND(+K14*$N$16,2) -> 1087.07 | L16: =ROUND(+L14*$N$16,2) -> 2600.7 | M16: =+SUM(F16:L16)+0.01 -> 33110.25 | N16: 0.1012
B17: F | E17: UTILIDADES(3.%) | F17: =ROUND(+F14*$N$17,2) -> 96.9 | G17: =ROUND(+G14*$N$17,2) -> 331.38 | H17: =ROUND(+H14*$N$17,2) -> 1183.87 | I17: =ROUND(+I14*$N$17,2) -> 2829.23 | J17: =ROUND(+J14*$N$17,2) -> 4280.69 | K17: =ROUND(+K14*$N$17,2) -> 322.25 | L17: =ROUND(+L14*$N$17,2) -> 770.96 | M17: =+SUM(F17:L17)+0.01 -> 9815.29 | N17: 0.03
D19: COSTO TOTAL S/ (No incluye I.G.V.) | F19: =+F14+F16+F17 -> 3653.92 | G19: =+G14+G16+G17 -> 12495.36 | H19: =+H14+H16+H17 -> 44639.74 | I19: =+I14+I16+I17 -> 106680.77 | J19: =+J14+J16+J17 -> 161410.62 | K19: =+K14+K16+K17 -> 12151.13 | L19: =+L14+L16+L17 -> 29070.32 | M19: =+M14+M16+M17 -> 370101.88
F23: 30.52

Sheet RESUMEN RS
B2: METRADO BASE - REDES SECUNDARIAS
B4: “AMPLIACIÓN DEL SERVICIO DE ENERGÍA ELÉCTRICA EN LA PROVINCIA DEL SANTA Y EN EL DISTRITO DE PAMPAROMAS – DEPARTAMENTO DE ANCASH”
B6: UBICACIÓN | D6: : | E6: ANCASH
B7: SECCIÓN I | D7: : | E7: REDES SECUNDARIAS | M7: =Fecha -> #REF! | T7: 16910.97
M8: =tc -> T.C. (S//US$): 3,642
B9: ITEM | C9: DESCRIPCION | F9: MES 1 | G9: MES 2 | H9: MES 3 | I9: MES 4 | J9: MES 5 | K9: MES 6 | L9: MES 7 | M9: TOTAL S/.
B11: A | D11: SUMINISTRO DE MATERIALES | F11: =+RS!E12 -> 1945.27 | G11: =+RS!F12 -> 13666.07 | H11: =+RS!G12 -> 51873.23 | I11: =+RS!H12 -> 174912.29 | J11: =+RS!I12 -> 49262.5 | K11: =+RS!J12 -> 128751.25 | L11: =+RS!K12 -> 0 | M11: =+SUM(F11:L11) -> 420410.61
B12: B | D12: MONTAJE ELECTROMECANICO | F12: =+RS!E34 -> 0 | G12: =+RS!F34 -> 9255.88 | H12: =+RS!G34 -> 16050.34 | I12: =+RS!H34 -> 25513.91 | J12: =+RS!I34 -> 68832.52 | K12: =+RS!J34 -> 87917.82 | L12: =+RS!K34 -> 115446.45 | M12: =+SUM(F12:L12) -> 323016.92
B13: C | D13: TRANSPORTE DE MATERIALES | F13: =+RS!E23 -> 1445.96 | G13: =+RS!F23 -> 4577.82 | H13: =+RS!G23 -> 13862.16 | I13: =+RS!H23 -> 24395.54 | J13: =+RS!I23 -> 1652.31 | K13: =+RS!J23 -> 789.34 | L13: =+RS!K23 -> 0 | M13: =+SUM(F13:L13) -> 46723.13
B14: D | D14: TOTAL COSTO DIRECTO | F14: =SUM(F11:F13) -> 3391.23 | G14: =SUM(G11:G13) -> 27499.77 | H14: =SUM(H11:H13) -> 81785.73 | I14: =SUM(I11:I13) -> 224821.74 | J14: =SUM(J11:J13) -> 119747.33 | K14: =SUM(K11:K13) -> 217458.41 | L14: =SUM(L11:L13) -> 115446.45 | M14: =SUM(M11:M13) -> 790150.66
B16: E | E16: GASTOS GENERALES (10.12%) | F16: =ROUND(+F14*$N$16,2) -> 343.19 | G16: =ROUND(+G14*$N$16,2) -> 2782.98 | H16: =ROUND(+H14*$N$16,2) -> 8276.72 | I16: =ROUND(+I14*$N$16,2) -> 22751.96 | J16: =ROUND(+J14*$N$16,2) -> 12118.43 | K16: =ROUND(+K14*$N$16,2) -> 22006.79 | L16: =ROUND(+L14*$N$16,2) -> 11683.18 | M16: =+SUM(F16:L16)+0.01 -> 79963.26 | N16: 0.1012
B17: F | E17: UTILIDADES(3.%) | F17: =ROUND(+F14*$N$17,2) -> 101.74 | G17: =ROUND(+G14*$N$17,2) -> 824.99 | H17: =ROUND(+H14*$N$17,2) -> 2453.57 | I17: =ROUND(+I14*$N$17,2) -> 6744.65 | J17: =ROUND(+J14*$N$17,2) -> 3592.42 | K17: =ROUND(+K14*$N$17,2) -> 6523.75 | L17: =ROUND(+L14*$N$17,2) -> 3463.39 | M17: =+SUM(F17:L17) -> 23704.51 | N17: 0.03
D19: COSTO TOTAL S/ (No incluye I.G.V.) | F19: =+F14+F16+F17 -> 3836.16 | G19: =+G14+G16+G17 -> 31107.74 | H19: =+H14+H16+H17 -> 92516.02 | I19: =+I14+I16+I17 -> 254318.35 | J19: =+J14+J16+J17 -> 135458.18 | K19: =+K14+K16+K17 -> 245988.95 | L19: =+L14+L16+L17 -> 130593.02 | M19: =+M14+M16+M17 -> 893818.43
M22: 695458.08
F23: 30.52

Sheet RESUMEN SDF
B2: METRADO BASE - SISTEMA FOTOVOLTAICO DOMESTICO
B4: “AMPLIACIÓN DEL SERVICIO DE ENERGÍA ELÉCTRICA EN LA PROVINCIA DEL SANTA Y EN EL DISTRITO DE PAMPAROMAS – DEPARTAMENTO DE ANCASH”
B6: UBICACIÓN | D6: : | E6: ANCASH
B7: SECCIÓN I | D7: : | E7: SISTEMA FOTOVOLTAICO DOMESTICO | M7: =Fecha -> #REF! | T7: 16910.97
M8: =tc -> T.C. (S//US$): 3,642
B9: ITEM | C9: DESCRIPCION | F9: MES 1 | G9: MES 2 | H9: MES 3 | I9: MES 4 | J9: MES 5 | K9: MES 6 | L9: MES 7 | M9: TOTAL S/.
B11: A | D11: SUMINISTRO DE MATERIALES | F11: =+SFD!E12 -> 0 | G11: =+SFD!F12 -> 0 | H11: =+SFD!G12 -> 3572.72 | I11: =+SFD!H12 -> 13038.125 | J11: =+SFD!I12 -> 38038.125 | K11: =+SFD!J12 -> 177319.42 | L11: =+SFD!K12 -> 0 | M11: =+SUM(F11:L11) -> 231968.39
B12: B | D12: MONTAJE ELECTROMECANICO | F12: =+SFD!E32 -> 0 | G12: =+SFD!F32 -> 0 | H12: =+SFD!G32 -> 0 | I12: =+SFD!H32 -> 0 | J12: =+SFD!I32 -> 1489.12 | K12: =+SFD!J32 -> 14841.27 | L12: =+SFD!K32 -> 32908.39 | M12: =+SUM(F12:L12) -> 49238.78
B13: C | D13: TRANSPORTE DE MATERIALES | F13: =+SFD!E22 -> 0 | G13: =+SFD!F22 -> 0 | H13: =+SFD!G22 -> 0 | I13: =+SFD!H22 -> 1051.46 | J13: =+SFD!I22 -> 1051.46 | K13: =+SFD!J22 -> 4454.22 | L13: =+SFD!K22 -> 0 | M13: =+SUM(F13:L13) -> 6557.14
B14: D | D14: TOTAL COSTO DIRECTO | F14: =SUM(F11:F13) -> 0 | G14: =SUM(G11:G13) -> 0 | H14: =SUM(H11:H13) -> 3572.72 | I14: =SUM(I11:I13) -> 14089.585 | J14: =SUM(J11:J13) -> 40578.705 | K14: =SUM(K11:K13) -> 196614.91 | L14: =SUM(L11:L13) -> 32908.39 | M14: =SUM(M11:M13) -> 287764.31
B16: E | E16: GASTOS GENERALES (10.12%) | F16: =ROUND(+F14*$N$16,2) -> 0 | G16: =ROUND(+G14*$N$16,2) -> 0 | H16: =ROUND(+H14*$N$16,2) -> 361.56 | I16: =ROUND(+I14*$N$16,2) -> 1425.87 | J16: =ROUND(+J14*$N$16,2) -> 4106.56 | K16: =ROUND(+K14*$N$16,2) -> 19897.43 | L16: =ROUND(+L14*$N$16,2) -> 3330.33 | M16: =+SUM(F16:L16) -> 29121.75 | N16: 0.1012
B17: F | E17: UTILIDADES(3.%) | F17: =ROUND(+F14*$N$17,2) -> 0 | G17: =ROUND(+G14*$N$17,2) -> 0 | H17: =ROUND(+H14*$N$17,2) -> 107.18 | I17: =ROUND(+I14*$N$17,2) -> 422.69 | J17: =ROUND(+J14*$N$17,2) -> 1217.36 | K17: =ROUND(+K14*$N$17,2) -> 5898.45 | L17: =ROUND(+L14*$N$17,2) -> 987.25 | M17: =+SUM(F17:L17)+0.01 -> 8632.94 | N17: 0.03
D19: COSTO TOTAL S/ (No incluye I.G.V.) | F19: =+F14+F16+F17 -> 0 | G19: =+G14+G16+G17 -> 0 | H19: =+H14+H16+H17 -> 4041.46 | I19: =+I14+I16+I17 -> 15938.145 | J19: =+J14+J16+J17 -> 45902.625 | K19: =+K14+K16+K17 -> 222410.79 | L19: =+L14+L16+L17 -> 37225.97 | M19: =+M14+M16+M17 -> 325519
M22: 318768.1
F23: 30.52

Sheet LP
B1: CALENDARIO VALORIZADO DE AVANCE DE OBRA
B3: PROYECTO | C3: : “AMPLIACIÓN DEL SERVICIO DE ENERGÍA ELÉCTRICA EN LA PROVINCIA DEL SANTA Y EN EL DISTRITO DE PAMPAROMAS – DEPARTAMENTO DE ANCASH”
B4: SECCION | C4: : LINEAS PRIMARIAS
B5: EJECUTOR | C5: : CONSORCIO PACIFICO
B6: PLAZO | C6: : 210 DIAS CALENDARIOS
B7: MONTO | C7: : 1'729,608.32
B9: ITEM | C9: DESCRIPCION DE PARTIDAS | E9: VAL No. 01 | F9: VAL No. 02 | G9: VAL No. 03 | H9: VAL No. 04 | I9: VAL No. 05 | J9: VAL No. 06 | K9: VAL No. 07 | M9: TOTAL
E10: MES 1 | F10: MES 2 | G10: MES 3 | H10: MES 4 | I10: MES 5 | J10: MES 6 | K10: MES 7
C11: LINEAS PRIMARIAS
C12: SUMINISTRO DE MATERIALES | E12: =SUM(E13:E25) -> 4113.31 | F12: =SUM(F13:F25) -> 28952.002 | G12: =SUM(G13:G25) -> 109978.39 | H12: =SUM(H13:H25) -> 264989.59 | I12: =SUM(I13:I25) -> 275696.9 | J12: =SUM(J13:J25) -> 0 | K12: =SUM(K13:K25) -> 0 | M12: =SUM(E12:K12) -> 683730.19 | N12: 683730.19 | O12: =+M12-N12 -> 0
B13: 1 | C13: POSTES DE CONCRETO ARMADO CENTRIFUGADO | E13: 4113.31 | F13: 20266.842 | G13: 52668.428 | H13: 107654.43 | K13: 0 | M13: =SUM(E13:K13) -> 184703.01 | N13: 184703.01 | O13: =+N13-M13 -> 0
B14: =+B13+1 -> 2 | C14: POSTES DE FIBRA DE VIDRIO | E14: 0 | F14: 0 | G14: 2910.69 | H14: 34198.54 | K14: 0 | M14: =SUM(E14:K14) -> 37109.23 | N14: 37109.23 | O14: =+N14-M14 -> 0
B15: =+B14+1 -> 3 | C15: OTROS MATERIALES DE CONCRETO ARMADO | E15: 0 | F15: 1048.15 | G15: 13306.69 | H15: 21164.36 | K15: 0 | M15: =SUM(E15:K15) -> 35519.2 | N15: 35519.2 | O15: =+N15-M15 -> 0
B16: =+B15+1 -> 4 | C16: AISLADORES Y ACCESORIOS | E16: 0 | G16: 1873.58 | H16: 5762.89 | I16: 59423.92 | K16: 0 | M16: =SUM(E16:K16) -> 67060.39 | N16: 67060.39 | O16: =+N16-M16 -> 0
B17: =+B16+1 -> 5 | C17: AISLADORES DE SUSPENSION Y ACCESORIOS | E17: 0 | G17: 2439.18 | H17: 7561.47 | I17: 16720.21 | K17: 0 | M17: =SUM(E17:K17) -> 26720.86 | N17: 26720.86 | O17: =+N17-M17 -> 0
B18: =+B17+1 -> 6 | C18: CONDUCTOR DE ALEACIÓN DE ALUMINIO | E18: 0 | G18: 4396.45 | H18: 12689.86 | I18: 102935.43 | K18: 0 | M18: =SUM(E18:K18) -> 120021.74 | N18: 120021.74 | O18: =+N18-M18 -> 0
B19: =+B18+1 -> 7 | C19: ACCESORIOS PARA CONDUCTOR DE ALEACION DE ALUMINIO | E19: 0 | F19: 1760.3 | G19: 3344.57 | H19: 8566.11 | K19: 0 | M19: =SUM(E19:K19) -> 13670.98 | N19: 13670.98 | O19: =+N19-M19 -> 0
B20: =+B19+1 -> 8 | C20: CONDUCTOR DE PUESTA A TIERRA | E20: 0 | F20: 1520.79 | G20: 12527.36 | H20: 26436.97 | K20: 0 | M20: =SUM(E20:K20) -> 40485.12 | N20: 40485.12 | O20: =+N20-M20 -> 0
B21: =+B20+1 -> 9 | C21: MATERIAL DE FERRETERÍA PARA POSTES Y CRUCETAS | E21: 0 | F21: 1429.38 | G21: 4892.25 | H21: 8826.91 | K21: 0 | M21: =SUM(E21:K21) -> 15148.54 | N21: 15148.54 | O21: =+N21-M21 -> 0
B22: =+B21+1 -> 10 | C22: RETENIDAS Y ANCLAJES | E22: 0 | F22: 1070.81 | G22: 7303.7 | H22: 23210.73 | K22: 0 | M22: =SUM(E22:K22) -> 31585.24 | N22: 31585.24 | O22: =+N22-M22 -> 0
B23: =+B22+1 -> 11 | C23: MATERIAL PARA PUESTA A TIERRA | E23: 0 | F23: 1855.73 | G23: 3735.66 | H23: 5845.85 | K23: 0 | M23: =SUM(E23:K23) -> 11437.24 | N23: 11437.24 | O23: =+N23-M23 -> 0
B24: =+B23+1 -> 12 | C24: EQUIPO DE PROTECCIÓN Y MANIOBRA | E24: 0 | G24: 376.67 | H24: 1289.46 | I24: 12079.53 | K24: 0 | M24: =SUM(E24:K24) -> 13745.66 | N24: 13745.66 | O24: =+N24-M24 -> 0
B25: =+B24+1 -> 13 | C25: TRAMO SUBTERRANEO | E25: 0 | G25: 203.16 | H25: 1782.01 | I25: 84537.81 | K25: 0 | M25: =SUM(E25:K25) -> 86522.98 | N25: 86522.98 | O25: =+N25-M25 -> 0
C26: TRANSPORTE DE MATERIALES | E26: =SUM(E27:E39) -> 2695.49 | F26: =SUM(F27:F39) -> 6669.55 | G26: =SUM(G27:G39) -> 13976.09 | H26: =SUM(H27:H39) -> 26323.72 | I26: =SUM(I27:I39) -> 9607.58 | J26: =SUM(J27:J39) -> 0 | K26: =SUM(K27:K39) -> 0 | M26: =SUM(E26:K26) -> 59272.43 | N26: =SUM(N27:N39) -> 59272.43 | O26: =+M26-N26 -> 0
B27: 1 | C27: POSTES DE CONCRETO ARMADO CENTRIFUGADO | E27: 2695.49 | F27: 5132.75 | G27: 8470.5 | H27: 13728.62 | I27: 0 | J27: 0 | K27: 0 | M27: =SUM(E27:K27) -> 30027.36 | N27: 30027.36 | O27: =+M27-N27 -> 0
B28: =+B27+1 -> 2 | C28: POSTES DE FIBRA DE VIDRIO | E28: 0 | F28: 0 | G28: 587.69 | H28: 891.96 | I28: 0 | J28: 0 | K28: 0 | M28: =SUM(E28:K28) -> 1479.65 | N28: 1479.65 | O28: =+M28-N28 -> 0
B29: =+B28+1 -> 3 | C29: OTROS MATERIALES DE CONCRETO ARMADO | E29: 0 | F29: 454.51 | G29: 1115.7 | H29: 3020.19 | K29: 0 | M29: =SUM(E29:K29) -> 4590.4 | N29: 4590.4 | O29: =+M29-N29 -> 0
B30: =+B29+1 -> 4 | C30: AISLADORES Y ACCESORIOS | E30: 0 | G30: 136 | H30: 221.59 | I30: 320.37 | K30: 0 | M30: =SUM(E30:K30) -> 677.96 | N30: 677.96 | O30: =+M30-N30 -> 0
B31: =+B30+1 -> 5 | C31: AISLADORES DE SUSPENSION Y ACCESORIOS | E31: 0 | F31: 0 | G31: 141.21 | H31: 550.89 | I31: 954.96 | K31: 0 | M31: =SUM(E31:K31) -> 1647.06 | N31: 1647.06 | O31: =+M31-N31 -> 0
B32: =+B31+1 -> 6 | C32: CONDUCTOR DE ALEACIÓN DE ALUMINIO | E32: 0 | G32: 690.23 | H32: 911.12 | I32: 2865.51 | M32: =SUM(E32:K32) -> 4466.86 | N32: 4466.86 | O32: =+M32-N32 -> 0
B33: =+B32+1 -> 7 | C33: ACCESORIOS PARA CONDUCTOR DE ALEACION DE ALUMINIO | E33: 0 | G33: 325.96 | H33: 616.35 | I33: 0 | J33: 0 | K33: 0 | M33: =SUM(E33:K33) -> 942.31 | N33: 942.31 | O33: =+M33-N33 -> 0
B34: =+B33+1 -> 8 | C34: CONDUCTOR DE PUESTA A TIERRA | E34: 0 | F34: 411.05 | G34: 781 | H34: 1464.79 | K34: 0 | M34: =SUM(E34:K34) -> 2656.84 | N34: 2656.84 | O34: =+M34-N34 -> 0
B35: =+B34+1 -> 9 | C35: MATERIAL DE FERRETERÍA PARA POSTES Y CRUCETAS | E35: 0 | F35: 72.04 | G35: 203.31 | H35: 266 | I35: 0 | J35: 0 | K35: 0 | M35: =SUM(E35:K35) -> 541.35 | N35: 541.35 | O35: =+M35-N35 -> 0
B36: =+B35+1 -> 10 | C36: RETENIDAS Y ANCLAJES | E36: 0 | F36: 509.49 | G36: 968.02 | H36: 2222.63 | K36: 0 | M36: =SUM(E36:K36) -> 3700.14 | N36: 3700.14 | O36: =+M36-N36 -> 0
B37: =+B36+1 -> 11 | C37: MATERIAL PARA PUESTA A TIERRA | E37: 0 | F37: 89.71 | G37: 278.69 | H37: 754.73 | I37: 0 | J37: 0 | K37: 0 | M37: =SUM(E37:K37) -> 1123.13 | N37: 1123.13 | O37: =+M37-N37 -> 0
B38: =+B37+1 -> 12 | C38: EQUIPO DE PROTECCIÓN Y MANIOBRA | E38: 0 | G38: 29.93 | H38: 88.91 | I38: 97.77 | M38: =SUM(E38:K38) -> 216.61 | N38: 216.61 | O38: =+M38-N38 -> 0
B39: =+B38+1 -> 13 | C39: TRAMO SUBTERRANEO | E39: 0 | F39: 0 | G39: 247.85 | H39: 1585.94 | I39: 5368.97 | K39: 0 | M39: =SUM(E39:K39) -> 7202.76 | N39: 7202.76 | O39: =+M39-N39 -> 0
C40: MONTAJE ELECTROMECÁNICO | E40: =+E41+E50+E51+E55+E56+E57+E58+E59+E60 -> 2571.44 | F40: =+F41+F50+F51+F55+F56+F57+F58+F59+F60 -> 11099.67 | G40: =+G41+G50+G51+G55+G56+G57+G58+G59+G60 -> 27108.31 | H40: =+H41+H50+H51+H55+H56+H57+H58+H59+H60 -> 42690.11 | I40: =+I41+I50+I51+I55+I56+I57+I58+I59+I60 -> 123493.33 | J40: =+J41+J50+J51+J55+J56+J57+J58+J59+J60 -> 85491.83 | K40: =+K41+K50+K51+K55+K56+K57+K58+K59+K60 -> 260308.04 | M40: =SUM(E40:K40) -> 552762.73 | N40: 552762.73 | O40: =+M40-N40 -> 0
B41: 1 | C41: OBRAS PRELIMINARES | E41: =SUM(E42:E49) -> 1703.1 | F41: =SUM(F42:F49) -> 0 | G41: =SUM(G42:G49) -> 8726.37 | H41: =SUM(H42:H49) -> 5317.65 | I41: =SUM(I42:I49) -> 6197.38 | J41: =SUM(J42:J49) -> 8370.31 | K41: =SUM(K42:K49) -> 10253.67 | M41: =SUM(E41:K41) -> 40568.48 | N41: 40568.48 | O41: =+M41-N41 -> 0
B42: 1.01 | C42: Estudio de Coordinación de la Protección y Balance de Cargas | E42: 0 | G42: 5182.52 | H42: 0 | I42: 0 | J42: 0 | K42: 0 | M42: =SUM(E42:K42) -> 5182.52 | N42: 5182.52 | O42: =+M42-N42 -> 0
...

Sheet RP
B1: =+LP!B1 -> CALENDARIO VALORIZADO DE AVANCE DE OBRA
B2: =+LP!B2 -> 0
B3: =+LP!B3 -> PROYECTO | C3: =+LP!C3 -> : “AMPLIACIÓN DEL SERVICIO DE ENERGÍA ELÉCTRICA EN LA PROVINCIA DEL SANTA Y EN EL DISTRITO DE PAMPAROMAS – DEPARTAMENTO DE ANCASH”
B4: =+LP!B4 -> SECCION | C4: : REDES PRIMARIAS
B5: =+LP!B5 -> EJECUTOR | C5: =+LP!C5 -> : CONSORCIO PACIFICO
B6: =+LP!B6 -> PLAZO | C6: =+LP!C6 -> : 210 DIAS CALENDARIOS
B7: =+LP!B7 -> MONTO | C7: : 436,720.22
B8: =+LP!B8 -> 0
B9: ITEM | C9: DESCRIPCION DE PARTIDAS | E9: VAL No. 01 | F9: VAL No. 02 | G9: VAL No. 03 | H9: VAL No. 04 | I9: VAL No. 05 | J9: VAL No. 06 | K9: VAL No. 07 | M9: TOTAL
E10: MES 1 | F10: MES 2 | G10: MES 3 | H10: MES 4 | I10: MES 5 | J10: MES 6 | K10: MES 7 | Q10: 1 | R10: 2 | S10: 3 | T10: 4 | U10: 5 | V10: 6 | W10: 7
C11: REDES PRIMARIAS | M11: =SUM(E11:K11) -> 0 | O11: =+M11-N11 -> 0
C12: SUMINISTRO DE MATERIALES | E12: =SUM(E13:E27) -> 582.28 | F12: =SUM(F13:F27) -> 6535.4 | G12: =SUM(G13:G27) -> 29031.64 | H12: =SUM(H13:H27) -> 75295.26 | I12: =SUM(I13:I27) -> 111761.01 | J12: =SUM(J13:J27) -> 0 | K12: =SUM(K13:K27) -> 0 | M12: =SUM(E12:K12) -> 223205.59 | N12: 223205.59 | O12: =+M12-N12 -> 0
B13: 1 | C13: POSTES DE CONCRETO ARMADO CENTRIFUGADO | E13: 582.28 | F13: 3899.46 | G13: 12897.84 | H13: 24310.68 | K13: 0 | M13: =SUM(E13:K13) -> 41690.26 | N13: 41690.26 | O13: =+M13-N13 -> 0 | Q13: S/. 10,493.02 | R13: S/. 11,617.27 | S13: S/. 11,617.27 | T13: S/. 1,873.75
B14: 2 | C14: POSTES DE FIBRA DE VIDRIO | E14: 0 | F14: 0 | G14: 1196.2 | H14: 12506.25 | K14: 0 | M14: =SUM(E14:K14) -> 13702.45 | N14: 13702.45 | O14: =+M14-N14 -> 0 | S14: S/. 4,290.62 | T14: S/. 858.12
B15: 3 | C15: OTROS MATERIALES DE CONCRETO ARMADO | E15: 0 | G15: 1788.86 | H15: 7240.64 | K15: 0 | M15: =SUM(E15:K15) -> 9029.5 | N15: 9029.5 | O15: =+M15-N15 -> 0 | R15: S/. 3,505.86 | S15: S/. 3,747.64
B16: 4 | C16: AISLADORES Y ACCESORIOS | E16: 0 | G16: 1394.85 | H16: 2224.62 | I16: 9780.88 | K16: 0 | M16: =SUM(E16:K16) -> 13400.35 | N16: 13400.35 | O16: =+M16-N16 -> 0 | S16: S/. 4,073.82 | T16: S/. 3,802.24 | U16: S/. 2,308.50
B17: 5 | C17: AISLADORES DE SUSPENSION Y ACCESORIOS | E17: 0 | G17: 251.79 | H17: 780.48 | I17: 1139.39 | K17: 0 | M17: =SUM(E17:K17) -> 2171.66 | N17: 2171.66 | O17: =+M17-N17 -> 0 | S17: S/. 604.29 | T17: S/. 564.00 | U17: S/. 342.43
B18: 6 | C18: CONDUCTOR DE ALEACIÓN DE ALUMINIO | E18: 0 | G18: 632.96 | H18: 1763.75 | I18: 6577.43 | K18: 0 | M18: =SUM(E18:K18) -> 8974.14 | N18: 8974.14 | O18: =+M18-N18 -> 0 | S18: S/. 3,158.47 | T18: S/. 2,947.90 | U18: S/. 1,789.80
B19: 7 | C19: ACCESORIOS PARA CONDUCTOR DE ALEACION DE ALUMINIO | E19: 0 | F19: 230.25 | G19: 513.58 | H19: 973.12 | J19: 0 | K19: 0 | M19: =SUM(E19:K19) -> 1716.95 | N19: 1716.95 | O19: =+M19-N19 -> 0 | R19: S/. 322.35 | S19: S/. 713.78 | T19: S/. 345.38
B20: 8 | C20: CONDUCTOR DE PUESTA A TIERRA | E20: 0 | F20: 861.1 | G20: 1436 | H20: 3226.1 | J20: 0 | K20: 0 | M20: =SUM(E20:K20) -> 5523.2 | N20: 5523.2 | O20: =+M20-N20 -> 0 | R20: S/. 3,551.15 | S20: S/. 3,796.05 | T20: S/. 1,836.80
B21: 9 | C21: MATERIAL DE FERRETERÍA PARA POSTES Y CRUCETAS | E21: 0 | F21: 915.54 | G21: 1223.99 | H21: 1595.95 | K21: 0 | M21: =SUM(E21:K21) -> 3735.48 | N21: 3735.48 | O21: =+M21-N21 -> 0 | R21: S/. 1,396.63 | S21: S/. 1,492.95 | T21: S/. 722.39
B22: 10 | C22: RETENIDAS Y ANCLAJES | E22: 0 | F22: 362.76 | G22: 2635.26 | H22: 3002.29 | J22: 0 | K22: 0 | M22: =SUM(E22:K22) -> 6000.31 | N22: 6000.31 | O22: =+M22-N22 -> 0 | R22: S/. 1,529.76 | S22: S/. 1,635.26 | T22: S/. 791.26
B23: 11 | C23: MATERIAL PARA PUESTA A TIERRA | E23: 0 | F23: 266.29 | G23: 2652.55 | H23: 9240.2 | J23: 0 | K23: 0 | M23: =SUM(E23:K23) -> 12159.04 | N23: 12159.04 | O23: =+M23-N23 -> 0 | R23: S/. 3,417.00 | S23: S/. 3,652.66 | T23: S/. 1,767.42
B24: 12 | C24: EQUIPO DE PROTECCIÓN Y MANIOBRA | E24: 0 | G24: 736.34 | H24: 2382.2 | I24: 11177.72 | K24: 0 | M24: =SUM(E24:K24) -> 14296.26 | N24: 14296.26 | O24: =+M24-N24 -> 0 | S24: S/. 7,473.05 | T24: S/. 6,974.84 | U24: S/. 498.20
B25: 13 | C25: TRANSFORMADORES DE DISTRIBUCIÓN | E25: 0 | G25: 537.9 | H25: 2678.7 | I25: 54575.48 | K25: 0 | M25: =SUM(E25:K25) -> 57792.08 | N25: 57792.08 | O25: =+M25-N25 -> 0 | S25: S/. 27,653.69 | T25: S/. 25,810.11 | U25: S/. 1,843.58
B26: 14 | C26: TABLEROS DE DISTRIBUCIÓN | E26: 0 | G26: 552.32 | H26: 2454.5 | I26: 26739.87 | K26: 0 | M26: =SUM(E26:K26) -> 29746.69 | N26: 29746.69 | O26: =+M26-N26 -> 0 | S26: S/. 16,956.97 | T26: S/. 15,826.51 | U26: S/. 1,130.46
B27: 15 | C27: CABLES DE ENERGÍA DE BAJA TENSIÓN | E27: 0 | G27: 581.2 | H27: 915.78 | I27: 1770.24 | M27: =SUM(E27:K27) -> 3267.22 | N27: 3267.22 | O27: =+M27-N27 -> 0 | S27: S/. 1,761.75 | T27: S/. 1,644.30 | U27: S/. 117.45
C28: TRANSPORTE DE MATERIALES | E28: =SUM(E29:E43) -> 778.71 | F28: =SUM(F29:F43) -> 1693.29 | G28: =SUM(G29:G43) -> 4051.7 | H28: =SUM(H29:H43) -> 7449.59 | I28: =SUM(I29:I43) -> 5141.97 | J28: =SUM(J29:J43) -> 0 | K28: =SUM(K29:K43) -> 0 | M28: =SUM(E28:K28) -> 19115.26 | N28: 19115.26 | O28: =+M28-N28 -> 0
B29: 1 | C29: POSTES DE CONCRETO ARMADO CENTRIFUGADO | E29: 778.71 | F29: 1113.66 | G29: 1957.81 | H29: 2979.82 | K29: 0 | M29: =SUM(E29:K29) -> 6830 | N29: 6830 | O29: =+M29-N29 -> 0 | Q29: S/. 848.21 | R29: S/. 2,022.66 | S29: S/. 2,022.66 | T29: S/. 978.71
B30: 2 | C30: POSTES DE FIBRA DE VIDRIO | E30: 0 | F30: 0 | G30: 229.25 | H30: 296.42 | J30: 0 | K30: 0 | M30: =SUM(E30:K30) -> 525.67 | N30: 525.67 | O30: =+M30-N30 -> 0 | S30: S/. 214.74 | T30: S/. 214.74
B31: 3 | C31: OTROS MATERIALES DE CONCRETO ARMADO | E31: 0 | F31: 208.09 | G31: 407.38 | H31: 1145.08 | K31: 0 | M31: =SUM(E31:K31) -> 1760.55 | N31: 1760.55 | O31: =+M31-N31 -> 0 | R31: S/. 291.33 | S31: S/. 645.08 | T31: S/. 312.14
B32: 4 | C32: AISLADORES Y ACCESORIOS | E32: 0 | G32: 30.32 | H32: 87.62 | I32: 128.29 | K32: 0 | M32: =SUM(E32:K32) -> 246.23 | N32: 246.23 | O32: =+M32-N32 -> 0 | S32: S/. 45.48 | T32: S/. 84.90 | U32: S/. 51.54
B33: 5 | C33: AISLADORES DE SUSPENSION Y ACCESORIOS | E33: 0 | G33: 0 | H33: 39.95 | I33: 93.91 | K33: 0 | M33: =SUM(E33:K33) -> 133.86 | N33: 133.86 | O33: =+M33-N33 -> 0 | T33: S/. 57.94 | U33: S/. 35.18
B34: 6 | C34: CONDUCTOR DE ALEACIÓN DE ALUMINIO | E34: 0 | G34: 58.9 | H34: 92.86 | I34: 181.5 | K34: 0 | M34: =SUM(E34:K34) -> 333.26 | N34: 333.26 | O34: =+M34-N34 -> 0 | S34: S/. 73.31 | T34: S/. 136.84 | U34: S/. 83.08
B35: 7 | C35: ACCESORIOS PARA CONDUCTOR DE ALEACION DE ALUMINIO | E35: 0 | F35: 0 | G35: 58.92 | H35: 104.29 | K35: 0 | M35: =SUM(E35:K35) -> 163.21 | N35: 163.21 | O35: =+M35-N35 -> 0 | S35: S/. 85.14 | T35: S/. 42.57
B36: 8 | C36: CONDUCTOR DE PUESTA A TIERRA | E36: 0 | F36: 50.45 | G36: 100.86 | H36: 211.15 | K36: 0 | M36: =SUM(E36:K36) -> 362.46 | N36: 362.46 | O36: =+M36-N36 -> 0 | R36: S/. 140.63 | S36: S/. 311.40 | T36: S/. 150.68
B37: 9 | C37: MATERIAL DE FERRETERÍA PARA POSTES Y CRUCETAS | E37: 0 | F37: 22.07 | G37: 38 | H37: 79 | K37: 0 | M37: =SUM(E37:K37) -> 139.07 | N37: 139.07 | O37: =+M37-N37 -> 0 | R37: S/. 26.70 | S37: S/. 59.11 | T37: S/. 28.60
B38: 10 | C38: RETENIDAS Y ANCLAJES | E38: 0 | F38: 73.5 | G38: 242.04 | H38: 359.1 | K38: 0 | M38: =SUM(E38:K38) -> 674.64 | N38: 674.64 | O38: =+M38-N38 -> 0 | R38: S/. 103.92 | S38: S/. 230.10 | T38: S/. 111.34
B39: 11 | C39: MATERIAL PARA PUESTA A TIERRA | E39: 0 | F39: 225.52 | G39: 928.22 | H39: 1695.34 | K39: 0 | M39: =SUM(E39:K39) -> 2849.08 | N39: 2849.08 | O39: =+M39-N39 -> 0 | R39: S/. 315.77 | S39: S/. 699.21 | T39: S/. 338.33
B40: 12 | C40: EQUIPO DE PROTECCIÓN Y MANIOBRA | E40: 0 | H40: 100 | I40: 158.94 | K40: 0 | M40: =SUM(E40:K40) -> 258.94 | N40: 258.94 | O40: =+M40-N40 -> 0 | T40: S/. 252.66 | U40: S/. 18.05
...

Sheet RS
B1: =+RP!B1 -> CALENDARIO VALORIZADO DE AVANCE DE OBRA
B2: =+RP!B2 -> 0
B3: =+RP!B3 -> PROYECTO | C3: =+LP!C3 -> : “AMPLIACIÓN DEL SERVICIO DE ENERGÍA ELÉCTRICA EN LA PROVINCIA DEL SANTA Y EN EL DISTRITO DE PAMPAROMAS – DEPARTAMENTO DE ANCASH”
B4: =+RP!B4 -> SECCION | C4: : REDES SECUNDARIAS
B5: =+RP!B5 -> EJECUTOR | C5: =+LP!C5 -> : CONSORCIO PACIFICO
B6: =+RP!B6 -> PLAZO | C6: =+LP!C6 -> : 210 DIAS CALENDARIOS
B7: =+RP!B7 -> MONTO | C7: : 1'054,705.75
B9: ITEM | C9: DESCRIPCION DE PARTIDAS | E9: VAL No. 01 | F9: VAL No. 02 | G9: VAL No. 03 | H9: VAL No. 04 | I9: VAL No. 05 | J9: VAL No. 06 | K9: VAL No. 07 | M9: TOTAL
E10: MES 1 | F10: MES 2 | G10: MES 3 | H10: MES 4 | I10: MES 5 | J10: MES 6 | K10: MES 7 | Q10: 1 | R10: 2 | S10: 3 | T10: 4 | U10: 5 | V10: 6 | W10: 7
C11: REDES SECUNDARIAS | M11: =SUM(E11:K11) -> 0
C12: SUMINISTRO DE MATERIALES | E12: =SUM(E13:E22) -> 1945.27 | F12: =SUM(F13:F22) -> 13666.07 | G12: =SUM(G13:G22) -> 51873.23 | H12: =SUM(H13:H22) -> 174912.29 | I12: =SUM(I13:I22) -> 49262.5 | J12: =SUM(J13:J22) -> 128751.25 | K12: =SUM(K13:K22) -> 0 | M12: =SUM(E12:K12) -> 420410.61 | N12: 420410.61 | O12: =+M12-N12 -> 0
B13: 1 | C13: POSTES DE CONCRETO ARMADO | E13: 1945.27 | F13: 8662.32 | G13: 32591.75 | H13: 49581.27 | K13: 0 | M13: =SUM(E13:K13) -> 92780.61 | N13: 92780.61 | O13: =+M13-N13 -> 0 | Q13: S/. 26,168.02 | R13: S/. 28,971.73 | S13: S/. 28,971.73 | T13: S/. 4,672.86
B14: 2 | C14: POSTES DE FIBRA DE VIDRIO | E14: 0 | F14: 0 | G14: 926.78 | H14: 25442.28 | K14: 0 | M14: =SUM(E14:K14) -> 26369.06 | N14: 26369.06 | O14: =+M14-N14 -> 0 | S14: S/. 6,042.45 | T14: S/. 1,208.49
B15: 3 | C15: CABLES Y CONDUCTORES DE ALUMINIO | H15: 2899.4 | I15: 13598.2 | J15: 82405.73 | K15: 0 | M15: =SUM(E15:K15) -> 98903.33 | N15: 98903.33 | O15: =+M15-N15 -> 0 | S15: S/. 28,293.84 | T15: S/. 26,407.58 | U15: S/. 16,033.18
B16: 4 | C16: ACCESORIOS DE CABLES AUTOPORTANTES | F16: 880.03 | G16: 3890.16 | H16: 6954.85 | K16: 0 | M16: =SUM(E16:K16) -> 11725.04 | N16: 11725.04 | O16: =+M16-N16 -> 0 | R16: S/. 2,888.50 | S16: S/. 3,087.71 | T16: S/. 1,494.05
B17: 5 | C17: CABLES, CONDUCTORES DE COBRE Y ACERO RECUBIERTO CON COBRE | F17: 518.82 | G17: 2885.25 | H17: 45219.41 | K17: 0 | M17: =SUM(E17:K17) -> 48623.48 | N17: 48623.48 | O17: =+M17-N17 -> 0 | R17: S/. 12,193.51 | S17: S/. 13,034.44 | T17: S/. 6,306.99
B18: 6 | C18: RETENIDAS Y ANCLAJES | F18: 1489.51 | G18: 2849.14 | H18: 21436.87 | K18: 0 | M18: =SUM(E18:K18) -> 25775.52 | N18: 25775.52 | O18: =+M18-N18 -> 0 | R18: S/. 8,641.93 | S18: S/. 9,237.93 | T18: S/. 4,469.96
B19: 7 | C19: LUMINARIAS LÁMPARAS Y ACCESORIOS | G19: 1960.95 | H19: 5782.84 | I19: 29881.9 | K19: 0 | M19: =SUM(E19:K19) -> 37625.69 | N19: 37625.69 | O19: =+M19-N19 -> 0 | S19: S/. 6,698.81 | T19: S/. 6,252.22 | U19: S/. 3,795.99
B20: 8 | C20: ACCESORIOS DE FERRETERÍA PARA POSTES | F20: 1272.84 | G20: 2638.56 | H20: 8279.98 | K20: 0 | M20: =SUM(E20:K20) -> 12191.38 | N20: 12191.38 | O20: =+M20-N20 -> 0 | R20: S/. 4,220.67 | S20: S/. 4,511.75 | T20: S/. 2,183.11
B21: 9 | C21: PUESTA A TIERRA | F21: 842.55 | G21: 4130.64 | H21: 8062.42 | K21: 0 | M21: =SUM(E21:K21) -> 13035.61 | N21: 13035.61 | O21: =+M21-N21 -> 0 | R21: S/. 2,827.67 | S21: S/. 3,022.68 | T21: S/. 1,462.59
B22: 10 | C22: CONEXIONES DOMICILIARIAS | H22: 1252.97 | I22: 5782.4 | J22: 46345.52 | K22: 0 | M22: =SUM(E22:K22) -> 53380.89 | N22: 53380.89 | O22: =+M22-N22 -> 0 | T22: S/. 14,289.97 | U22: S/. 15,821.04 | V22: S/. 8,165.70
C23: TRANSPORTE DE MATERIALES | E23: =SUM(E24:E33) -> 1445.96 | F23: =SUM(F24:F33) -> 4577.82 | G23: =SUM(G24:G33) -> 13862.16 | H23: =SUM(H24:H33) -> 24395.54 | I23: =SUM(I24:I33) -> 1652.31 | J23: =SUM(J24:J33) -> 789.34 | K23: =SUM(K24:K33) -> 0 | M23: =SUM(E23:K23) -> 46723.13 | N23: 46723.13 | O23: =+M23-N23 -> 0
B24: 1 | C24: POSTES DE CONCRETO ARMADO | E24: 1445.96 | F24: 4577.82 | G24: 10686.66 | H24: 15587.89 | K24: 0 | M24: =SUM(E24:K24) -> 32298.33 | N24: 32298.33 | O24: =+M24-N24 -> 0 | Q24: S/. 2,756.77 | R24: S/. 10,682.47 | S24: S/. 10,682.47 | T24: S/. 6,891.91
B25: 2 | C25: POSTES DE FIBRA DE VIDRIO | E25: 0 | F25: 0 | G25: 345.01 | H25: 1891.07 | J25: 0 | K25: 0 | M25: =SUM(E25:K25) -> 2236.08 | N25: 2236.08 | O25: =+M25-N25 -> 0 | S25: S/. 279.51 | T25: S/. 559.02
B26: 3 | C26: CABLES Y CONDUCTORES DE ALUMINIO | E26: 0 | F26: 0 | H26: 598.91 | I26: 792.79 | K26: 0 | M26: =SUM(E26:K26) -> 1391.7 | N26: 1391.7 | O26: =+M26-N26 -> 0 | T26: S/. 644.98 | U26: S/. 391.59
B27: 4 | C27: ACCESORIOS DE CABLES AUTOPORTANTES | E27: 0 | F27: 0 | G27: 30.88 | H27: 62.45 | J27: 0 | K27: 0 | M27: =SUM(E27:K27) -> 93.33 | N27: 93.33 | O27: =+M27-N27 -> 0 | S27: S/. 35.63 | T27: S/. 17.81
B28: 5 | C28: CABLES, CONDUCTORES DE COBRE Y ACERO RECUBIERTO CON COBRE | E28: 0 | F28: 0 | G28: 735.8 | H28: 944.24 | J28: 0 | K28: 0 | M28: =SUM(E28:K28) -> 1680.04 | N28: 1680.04 | O28: =+M28-N28 -> 0 | S28: S/. 844.61 | T28: S/. 422.30
B29: 6 | C29: RETENIDAS Y ANCLAJES | E29: 0 | F29: 0 | G29: 1601.23 | H29: 2588.9 | K29: 0 | M29: =SUM(E29:K29) -> 4190.13 | N29: 4190.13 | O29: =+M29-N29 -> 0 | S29: S/. 2,530.27 | T29: S/. 1,265.14
B30: 7 | C30: LUMINARIAS LÁMPARAS Y ACCESORIOS | E30: 0 | F30: 0 | H30: 142.84 | I30: 306.59 | K30: 0 | M30: =SUM(E30:K30) -> 449.43 | N30: 449.43 | O30: =+M30-N30 -> 0 | T30: S/. 157.08 | U30: S/. 95.37
B31: 8 | C31: ACCESORIOS DE FERRETERÍA PARA POSTES | E31: 0 | F31: 0 | G31: 230.18 | H31: 172.96 | J31: 0 | K31: 0 | M31: =SUM(E31:K31) -> 403.14 | N31: 403.14 | O31: =+M31-N31 -> 0 | S31: S/. 274.68 | T31: S/. 137.34
B32: 9 | C32: PUESTA A TIERRA | E32: 0 | F32: 0 | G32: 232.4 | H32: 2406.28 | J32: 0 | K32: 0 | M32: =SUM(E32:K32) -> 2638.68 | N32: 2638.68 | O32: =+M32-N32 -> 0 | S32: S/. 155.72 | T32: S/. 77.86
B33: 10 | C33: CONEXIONES DOMICILIARIAS | E33: 0 | F33: 0 | I33: 552.93 | J33: 789.34 | K33: 0 | M33: =SUM(E33:K33) -> 1342.27 | N33: 1342.27 | O33: =+M33-N33 -> 0 | U33: S/. 616.73 | V33: S/. 340.26
C34: MONTAJE ELECTROMECÁNICO | E34: =+E35+E36+E40+E41+E42+E43+E44+E45+E46+E47 -> 0 | F34: =+F35+F36+F40+F41+F42+F43+F44+F45+F46+F47 -> 9255.88 | G34: =+G35+G36+G40+G41+G42+G43+G44+G45+G46+G47 -> 16050.34 | H34: =+H35+H36+H40+H41+H42+H43+H44+H45+H46+H47 -> 25513.91 | I34: =+I35+I36+I40+I41+I42+I43+I44+I45+I46+I47 -> 68832.52 | J34: =+J35+J36+J40+J41+J42+J43+J44+J45+J46+J47 -> 87917.82 | K34: =+K35+K36+K40+K41+K42+K43+K44+K45+K46+K47 -> 115446.45 | M34: =+M35+M36+M40+M41+M42+M43+M44+M45+M46+M47 -> 323016.92 | N34: 323016.92 | O34: =+M34-N34 -> 0
B35: 1 | C35: TRANSPORTE DE MATERIALES DE ALMACEN EN OBRA A PUNTO DE INSTALACION | F35: 2149 | G35: 5883.12 | H35: 5664.22 | I35: 10891.53 | J35: 31895.01 | M35: =SUM(E35:K35) -> 56482.88 | N35: 56482.88 | O35: =+M35-N35 -> 0 | R35: S/. 5,808.61 | S35: S/. 12,861.91 | T35: S/. 11,617.21 | U35: S/. 12,861.91 | V35: S/. 6,638.41
B36: 2 | C36: INSTALACION DE POSTES | E36: =SUM(E37:E39) -> 0 | F36: =SUM(F37:F39) -> 7106.88 | G36: =SUM(G37:G39) -> 10167.22 | H36: =SUM(H37:H39) -> 19286.24 | I36: =SUM(I37:I39) -> 41664.75 | J36: =SUM(J37:J39) -> 0 | K36: =SUM(K37:K39) -> 0 | M36: =SUM(E36:K36) -> 78225.09 | N36: 78225.09 | O36: =+M36-N36 -> 0
B37: 2.01 | C37: Excavación en terreno normal y rocoso | F37: 1117.44 | G37: 2064.54 | H37: 2381.04 | I37: 2701.65 | K37: 0 | M37: =SUM(E37:K37) -> 8264.67 | N37: 8264.67 | O37: =+M37-N37 -> 0 | R37: S/. 1,906.02 | S37: S/. 2,461.94 | T37: S/. 2,223.69 | U37: S/. 1,747.19
B38: 2.02 | C38: Transporte poste de almacén a punto de izaje | E38: 0 | F38: 0 | G38: 0 | H38: 0 | I38: 0 | K38: 0 | M38: =SUM(E38:K38) -> 0 | O38: =+M38-N38 -> 0
B39: 2.03 | C39: Izado de postes, relleno y compactación para cimentación | E39: 0 | F39: 5989.44 | G39: 8102.68 | H39: 16905.2 | I39: 38963.1 | M39: =SUM(E39:K39) -> 69960.42 | N39: 69960.42 | O39: =+M39-N39 -> 0 | R39: S/. 11,619.01 | S39: S/. 18,957.33 | T39: S/. 17,122.75 | U39: S/. 16,511.23
B40: 3 | C40: INSTALACIÓN DE RETENIDAS | E40: 0 | F40: 0 | H40: 428.21 | I40: 5696.29 | J40: 20977.7 | K40: 0 | M40: =SUM(E40:K40) -> 27102.2 | N40: 27102.2 | O40: =+M40-N40 -> 0 | T40: S/. 6,892.27 | U40: S/. 11,245.29 | V40: S/. 7,255.02
B41: 4 | C41: MONTAJE DE ARMADOS | E41: 0 | F41: 0 | H41: 135.24 | I41: 3697.3 | J41: 6921.3 | K41: 0 | M41: =SUM(E41:K41) -> 10753.84 | N41: 10753.84 | O41: =+M41-N41 -> 0 | T41: S/. 2,202.55 | U41: S/. 3,593.63 | V41: S/. 2,318.47
...

Sheet SFD
B1: =+LP!B1 -> CALENDARIO VALORIZADO DE AVANCE DE OBRA
B2: =+LP!B2 -> 0
B3: =+LP!B3 -> PROYECTO | C3: =+RS!C3 -> : “AMPLIACIÓN DEL SERVICIO DE ENERGÍA ELÉCTRICA EN LA PROVINCIA DEL SANTA Y EN EL DISTRITO DE PAMPAROMAS – DEPARTAMENTO DE ANCASH”
B4: =+LP!B4 -> SECCION | C4: : SISTEMA FOTOVOLTAICO DOMÉSTICO | D4: =+RS!D4 -> 0
B5: =+LP!B5 -> EJECUTOR | C5: =+RS!C5 -> : CONSORCIO PACIFICO | D5: =+RS!D5 -> 0
B6: =+LP!B6 -> PLAZO | C6: =+RS!C6 -> : 210 DIAS CALENDARIOS | D6: =+RS!D6 -> 0
B7: =+LP!B7 -> MONTO | C7: : 384,112.41 | D7: =+RS!D7 -> 0
B9: ITEM | C9: DESCRIPCION DE PARTIDAS | E9: VAL No. 01 | F9: VAL No. 02 | G9: VAL No. 03 | H9: VAL No. 04 | I9: VAL No. 05 | J9: VAL No. 06 | K9: VAL No. 07 | M9: TOTAL
E10: MES 1 | F10: MES 2 | G10: MES 3 | H10: MES 4 | I10: MES 5 | J10: MES 6 | K10: MES 7 | Q10: 1 | R10: 2 | S10: 3 | T10: 4 | U10: 5 | V10: 6 | W10: 7
C11: SISTEMA FOTOVOLTAICO DOMESTICO | M11: =SUM(E11:K11) -> 0 | O11: =+M11-N11 -> 0
C12: SUMINISTRO DE MATERIALES | E12: =SUM(E13:E21) -> 0 | F12: =SUM(F13:F21) -> 0 | G12: =SUM(G13:G21) -> 3572.72 | H12: =SUM(H13:H21) -> 13038.125 | I12: =SUM(I13:I21) -> 38038.125 | J12: =SUM(J13:J21) -> 177319.42 | K12: =SUM(K13:K21) -> 0 | M12: =SUM(E12:K12) -> 231968.39 | N12: 231968.39 | O12: =+M12-N12 -> 0
B13: 1 | C13: UNIDAD DE GENERACION | E13: 0 | F13: 0 | G13: 478.05 | H13: 2556.55 | I13: 7556.55 | J13: 33516.92 | M13: =SUM(E13:K13) -> 44108.07 | N13: 44108.07 | O13: =+M13-N13 -> 0 | S13: S/. 9,298.46 | T13: S/. 17,357.12 | U13: S/. 19,216.81 | V13: S/. 619.90
B14: 2 | C14: UNIDAD DE CONTROL | E14: 0 | F14: 0 | G14: 593.62 | H14: 1399.04 | I14: 5399.04 | J14: 31999.09 | M14: =SUM(E14:K14) -> 39390.79 | N14: 39390.79 | O14: =+M14-N14 -> 0 | S14: S/. 4,496.54 | T14: S/. 8,393.55 | U14: S/. 9,292.86 | V14: S/. 299.77
B15: 3 | C15: UNIDAD DE ALMACENAMIENTO | E15: 0 | F15: 0 | G15: 156.18 | H15: 3505.67 | I15: 11505.67 | J15: 49094.08 | M15: =SUM(E15:K15) -> 64261.6 | N15: 64261.6 | O15: =+M15-N15 -> 0 | S15: S/. 13,547.04 | T15: S/. 25,287.81 | U15: S/. 27,997.22 | V15: S/. 903.14
B16: 4 | C16: UNIDAD DE INVERSOR DC/AC | E16: 0 | F16: 0 | G16: 435.02 | H16: 1014.045 | I16: 5014.045 | J16: 28917.03 | M16: =SUM(E16:K16) -> 35380.14 | N16: 35380.14 | O16: =+M16-N16 -> 0 | S16: S/. 7,458.52 | T16: S/. 13,922.56 | U16: S/. 15,414.27 | V16: S/. 497.23
B17: 5 | C17: UNIDAD DE PROTECCION 220 VAC | E17: 0 | F17: 0 | G17: 525.27 | H17: 1260.95 | I17: 1260.95 | J17: 3950.27 | M17: =SUM(E17:K17) -> 6997.44 | N17: 6997.44 | O17: =+M17-N17 -> 0 | S17: S/. 1,475.14 | T17: S/. 2,753.59 | U17: S/. 3,048.61 | V17: S/. 98.34
B18: 6 | C18: UNIDAD DE CARGA 220 VAC | E18: 0 | F18: 0 | G18: 86.43 | H18: 1633.61 | I18: 4633.61 | J18: 20184.6 | M18: =SUM(E18:K18) -> 26538.25 | N18: 26538.25 | O18: =+M18-N18 -> 0 | S18: S/. 5,594.55 | T18: S/. 10,443.16 | U18: S/. 11,562.07 | V18: S/. 372.97
B19: 7 | C19: RED EQUIPOTENCIAL | E19: 0 | F19: 0 | G19: 605.13 | H19: 461.56 | I19: 461.56 | J19: 1113.18 | M19: =SUM(E19:K19) -> 2641.43 | N19: 2641.43 | O19: =+M19-N19 -> 0 | S19: S/. 556.84 | T19: S/. 1,039.44 | U19: S/. 1,150.81 | V19: S/. 37.12
B20: 8 | C20: PUESTA A TIERRA | E20: 0 | F20: 0 | G20: 286.26 | H20: 928.39 | I20: 1928.39 | J20: 7878.89 | M20: =SUM(E20:K20) -> 11021.93 | N20: 11021.93 | O20: =+M20-N20 -> 0 | S20: S/. 2,199.68 | T20: S/. 4,106.07 | U20: S/. 4,546.00 | V20: S/. 146.65
B21: 9 | C21: ACOMETIDA PARA SFV | E21: 0 | F21: 0 | G21: 406.76 | H21: 278.31 | I21: 278.31 | J21: 665.36 | M21: =SUM(E21:K21) -> 1628.74 | N21: 1628.74 | O21: =+M21-N21 -> 0 | S21: S/. 321.13 | T21: S/. 599.44 | U21: S/. 663.66 | V21: S/. 21.41
C22: TRANSPORTE DE MATERIALES | E22: =SUM(E23:E31) -> 0 | F22: =SUM(F23:F31) -> 0 | G22: =SUM(G23:G31) -> 0 | H22: =SUM(H23:H31) -> 1051.46 | I22: =SUM(I23:I31) -> 1051.46 | J22: =SUM(J23:J31) -> 4454.22 | K22: =SUM(K23:K31) -> 0 | M22: =SUM(E22:K22) -> 6557.14 | N22: 6557.14 | O22: =+M22-N22 -> 0
B23: 1 | C23: UNIDAD DE GENERACION | E23: 0 | F23: 0 | G23: 0 | H23: 156.53 | I23: 156.53 | J23: 627.11 | K23: 0 | M23: =SUM(E23:K23) -> 940.17 | N23: 940.17 | O23: =+M23-N23 -> 0 | U23: S/. 957.96 | V23: S/. 33.03
B24: 2 | C24: UNIDAD DE CONTROL | E24: 0 | F24: 0 | G24: 0 | H24: 55.29 | I24: 55.29 | J24: 253.5 | K24: 0 | M24: =SUM(E24:K24) -> 364.08 | N24: 364.08 | O24: =+M24-N24 -> 0 | U24: S/. 291.42 | V24: S/. 10.05
B25: 3 | C25: UNIDAD DE ALMACENAMIENTO | E25: 0 | F25: 0 | G25: 0 | H25: 156.105 | I25: 156.105 | J25: 599.1 | K25: 0 | M25: =SUM(E25:K25) -> 911.31 | N25: 911.31 | O25: =+M25-N25 -> 0 | U25: S/. 928.55 | V25: S/. 32.02
B26: 4 | C26: UNIDAD DE INVERSOR DC/AC | E26: 0 | F26: 0 | G26: 0 | H26: 103.96 | I26: 103.96 | J26: 330.06 | K26: 0 | M26: =SUM(E26:K26) -> 537.98 | N26: 537.98 | O26: =+M26-N26 -> 0 | U26: S/. 548.16 | V26: S/. 18.90
B27: 5 | C27: UNIDAD DE PROTECCION 220 VAC | E27: 0 | F27: 0 | G27: 0 | H27: 19.59 | I27: 19.59 | J27: 62.2 | K27: 0 | M27: =SUM(E27:K27) -> 101.38 | N27: 101.38 | O27: =+M27-N27 -> 0 | U27: S/. 103.30 | V27: S/. 3.56
B28: 6 | C28: UNIDAD DE CARGA 220 VAC | E28: 0 | F28: 0 | G28: 0 | H28: 126.505 | I28: 126.505 | J28: 507.71 | K28: 0 | M28: =SUM(E28:K28) -> 760.72 | N28: 760.72 | O28: =+M28-N28 -> 0 | U28: S/. 775.11 | V28: S/. 26.73
B29: 7 | C29: RED EQUIPOTENCIAL | E29: 0 | F29: 0 | G29: 0 | H29: 48.05 | I29: 48.05 | J29: 152.54 | K29: 0 | M29: =SUM(E29:K29) -> 248.64 | N29: 248.64 | O29: =+M29-N29 -> 0 | U29: S/. 253.34 | V29: S/. 8.74
B30: 8 | C30: PUESTA A TIERRA | E30: 0 | F30: 0 | G30: 0 | H30: 379.065 | I30: 379.065 | J30: 1900.32 | K30: 0 | M30: =SUM(E30:K30) -> 2658.45 | N30: 2658.45 | O30: =+M30-N30 -> 0 | U30: S/. 1,481.99 | V30: S/. 51.10
B31: 9 | C31: ACOMETIDA PARA SFV | E31: 0 | F31: 0 | G31: 0 | H31: 6.365 | I31: 6.365 | J31: 21.68 | K31: 0 | M31: =SUM(E31:K31) -> 34.41 | N31: 34.41 | O31: =+M31-N31 -> 0 | U31: S/. 33.55 | V31: S/. 1.16
C32: MONTAJE ELECTROMECÁNICO | E32: =SUM(E33:E38) -> 0 | F32: =SUM(F33:F38) -> 0 | G32: =SUM(G33:G38) -> 0 | H32: =SUM(H33:H38) -> 0 | I32: =SUM(I33:I38) -> 1489.12 | J32: =SUM(J33:J38) -> 14841.27 | K32: =SUM(K33:K38) -> 32908.39 | M32: =SUM(E32:K32) -> 49238.78 | N32: 49238.78 | O32: =+M32-N32 -> 0
B33: 1 | C33: TRANSPORTE DE MATERIALES DE ALMACEN EN OBRA A PUNTO DE INSTALACION | E33: 0 | F33: 0 | G33: 0 | I33: 553.59 | J33: 6811.08 | K33: 0 | M33: =SUM(E33:K33) -> 7364.67 | N33: 7364.67 | O33: =+M33-N33 -> 0 | U33: S/. 5,720.72 | V33: S/. 1,980.25
B34: 2 | C34: MONTAJE DE LA UNIDAD DE GENERACION Y ACOMETIDA | E34: 0 | F34: 0 | G34: 0 | I34: 585.41 | J34: 4912.88 | K34: 0 | M34: =SUM(E34:K34) -> 5498.29 | N34: 5498.29 | O34: =+M34-N34 -> 0 | U34: S/. 2,676.15 | V34: S/. 3,177.92
B35: 3 | C35: MONTAJE DE UNIDAD DE CONTROL Y UNIDAD DE ALMACENAMIENTO | E35: 0 | F35: 0 | G35: 0 | H35: 0 | I35: 350.12 | J35: 980.1 | K35: 2442.3 | M35: =SUM(E35:K35) -> 3772.52 | N35: 3772.52 | O35: =+M35-N35 -> 0 | U35: S/. 113.61 | V35: S/. 3,408.38 | W35: S/. 454.45
B36: 4 | C36: MONTAJE DE LAS UNIDADES EN CORRIENTE ALTERNA 220 AC | E36: 0 | F36: 0 | G36: 0 | H36: 0 | I36: 0 | J36: 1128.19 | K36: 9441.6 | M36: =SUM(E36:K36) -> 10569.79 | N36: 10569.79 | O36: =+M36-N36 -> 0 | V36: S/. 2,864.86 | W36: S/. 8,276.27
B37: 5 | C37: SISTEMA DE PUESTA A TIERRA | E37: 0 | F37: 0 | G37: 0 | H37: 0 | I37: 0 | J37: 1009.02 | K37: 16861.45 | M37: =SUM(E37:K37) -> 17870.47 | N37: 17870.47 | O37: =+M37-N37 -> 0 | V37: S/. 668.06 | W37: S/. 18,037.65
B38: 6 | C38: INSPECCION Y PRUEBAS | E38: 0 | F38: 0 | G38: 0 | H38: 0 | I38: 0 | J38: 0 | K38: 4163.04 | M38: =SUM(E38:K38) -> 4163.04 | N38: 4163.04 | O38: =+M38-N38 -> 0 | W38: S/. 4,119.97
O39: =+M39-N39 -> 0
C40: TOTAL GENERAL | E40: =+E12+E22+E32 -> 0 | F40: =+F12+F22+F32 -> 0 | G40: =+G12+G22+G32 -> 3572.72 | H40: =+H12+H22+H32 -> 14089.585 | I40: =+I12+I22+I32 -> 40578.705 | J40: =+J12+J22+J32 -> 196614.91 | K40: =+K12+K22+K32 -> 32908.39 | M40: =+M12+M22+M32 -> 287764.31 | N40: 287764.31 | O40: =+M40-N40 -> 0
B41: 0.1012 | C41: GASTOS GENERALES 9.70% | E41: =ROUND($B$41*E40,2) -> 0 | F41: =ROUND($B$41*F40,2) -> 0 | G41: =ROUND($B$41*G40,2) -> 361.56 | H41: =ROUND($B$41*H40,2) -> 1425.87 | I41: =ROUND($B$41*I40,2) -> 4106.56 | J41: =ROUND($B$41*J40,2) -> 19897.43 | K41: =ROUND($B$41*K40,2) -> 3330.33 | M41: =ROUND($B$41*M40,2) -> 29121.75 | N41: 29121.75 | O41: =+M41-N41 -> 0
...

Sheet RESUMEN
B1: CALENDARIO VALORIZADO DE AVANCE DE OBRA
B3: PROYECTO | C3: =+LP!C3 -> : “AMPLIACIÓN DEL SERVICIO DE ENERGÍA ELÉCTRICA EN LA PROVINCIA DEL SANTA Y EN EL DISTRITO DE PAMPAROMAS – DEPARTAMENTO DE ANCASH”
B4: SECCION | C4: : RESUMEN GENERAL
B5: EJECUTOR | C5: =+LP!C5 -> : CONSORCIO PACIFICO
B6: PLAZO | C6: =+LP!C6 -> : 210 DIAS CALENDARIOS
B7: MONTO | C7: : 3'605,146.68
B9: MES | C9: LINEA PRIMARIA | D9: RED PRIMARIA | E9: RED SECUNDARIA | F9: SISTEMA FOTOVOLTAICO | G9: TOTAL | I9: ACUMULADO
B10: MES 1 | C10: {=+TRANSPOSE(LP!E67:K67)} -> 12520.9 | D10: {=+TRANSPOSE(RP!E61:K61)} -> 4311.63 | E10: {=+TRANSPOSE(RS!E54:K54)} -> 4526.67 | F10: {=+TRANSPOSE(SFD!E45:K45)} -> 0 | G10: =SUM(C10:F10) -> 21359.2 | I10: =+G10 -> 21359.2 | J10: 31298.09
B11: MES 2 | C11: 62364.252 | D11: 14744.52 | E11: 36707.14 | F11: 0 | G11: =SUM(C11:F11)-0.01 -> 113815.9 | I11: =+G11+I10 -> 135175.1 | J11: 164212.54
B12: MES 3 | C12: 201641.02 | D12: 52674.9 | E12: 109168.91 | F12: 4768.92 | G12: =SUM(C12:F12) -> 368253.75 | I12: =+G12+I11 -> 503428.85 | J12: 486134.85
B13: MES 4 | C13: 445833.12 | D13: 125883.32 | E13: 300095.66 | F13: 18807.015 | G13: =SUM(C13:F13) -> 890619.12 | I13: =+G13+I12 -> 1394048
B14: MES 5 | C14: 545669.85 | D14: 190464.54 | E14: 159840.65 | F14: 54165.095 | G14: =SUM(C14:F14) -> 950140.14 | I14: =+G14+I13 -> 2344188.1 | J14: 1201276.4
B15: MES 6 | C15: 114115.85 | D15: 14338.33 | E15: 290266.96 | F15: 262444.74 | G15: =SUM(C15:F15) -> 681165.88 | I15: =+G15+I14 -> 3025354 | J15: 1120683.4
B16: MES 7 | C16: 347463.33 | D16: 34302.98 | E16: 154099.76 | F16: 43926.64 | G16: =SUM(C16:F16)-0.01 -> 579792.7 | I16: =+G16+I15 -> 3605146.7 | J16: 601541.38
B18: TOTAL | C18: =SUM(C10:C17) -> 1729608.3 | D18: =SUM(D10:D17) -> 436720.22 | E18: =SUM(E10:E17) -> 1054705.8 | F18: =SUM(F10:F17) -> 384112.41 | G18: =SUM(C18:F18)-0.02 -> 3605146.7
D32: Firma, Nombres y Apellidos del contratista o Representante legal o común, según corresponda

Sheet RESUMEN 04 SECCIONES
B1: CRONOGRAMA DE DESEMBOLSOS MENSUALES DE OBRA
B2: “AMPLIACIÓN DEL SERVICIO DE ENERGÍA ELÉCTRICA EN LA PROVINCIA DEL SANTA Y EN EL DISTRITO DE PAMPAROMAS – DEPARTAMENTO DE ANCASH” | C2: =+name_proy -> CREACIÓN INSTALACIÓN DEL SUBSISTEMA DE DISTRIBUCIÓN PRIMARIA 10-22,9 KV Y SUBSISTEMA DE DISTRIBUCIÓN SECUNDARIA 380/220 V E INSTALACIÓN DE ALUMBRADO PÚBLICO LUCAS CUTIVALU DEL DISTRITO DE MIGUEL CHECA - PROVINCIA DE SULLANA - DEPARTAMENTO DE PIURA | D2: =+name_proy -> CREACIÓN INSTALACIÓN DEL SUBSISTEMA DE DISTRIBUCIÓN PRIMARIA 10-22,9 KV Y SUBSISTEMA DE DISTRIBUCIÓN SECUNDARIA 380/220 V E INSTALACIÓN DE ALUMBRADO PÚBLICO LUCAS CUTIVALU DEL DISTRITO DE MIGUEL CHECA - PROVINCIA DE SULLANA - DEPARTAMENTO DE PIURA | E2: =+name_proy -> CREACIÓN INSTALACIÓN DEL SUBSISTEMA DE DISTRIBUCIÓN PRIMARIA 10-22,9 KV Y SUBSISTEMA DE DISTRIBUCIÓN SECUNDARIA 380/220 V E INSTALACIÓN DE ALUMBRADO PÚBLICO LUCAS CUTIVALU DEL DISTRITO DE MIGUEL CHECA - PROVINCIA DE SULLANA - DEPARTAMENTO DE PIURA | F2: =+name_proy -> CREACIÓN INSTALACIÓN DEL SUBSISTEMA DE DISTRIBUCIÓN PRIMARIA 10-22,9 KV Y SUBSISTEMA DE DISTRIBUCIÓN SECUNDARIA 380/220 V E INSTALACIÓN DE ALUMBRADO PÚBLICO LUCAS CUTIVALU DEL DISTRITO DE MIGUEL CHECA - PROVINCIA DE SULLANA - DEPARTAMENTO DE PIURA | G2: =+name_proy -> CREACIÓN INSTALACIÓN DEL SUBSISTEMA DE DISTRIBUCIÓN PRIMARIA 10-22,9 KV Y SUBSISTEMA DE DISTRIBUCIÓN SECUNDARIA 380/220 V E INSTALACIÓN DE ALUMBRADO PÚBLICO LUCAS CUTIVALU DEL DISTRITO DE MIGUEL CHECA - PROVINCIA DE SULLANA - DEPARTAMENTO DE PIURA | H2: =+name_proy -> CREACIÓN INSTALACIÓN DEL SUBSISTEMA DE DISTRIBUCIÓN PRIMARIA 10-22,9 KV Y SUBSISTEMA DE DISTRIBUCIÓN SECUNDARIA 380/220 V E INSTALACIÓN DE ALUMBRADO PÚBLICO LUCAS CUTIVALU DEL DISTRITO DE MIGUEL CHECA - PROVINCIA DE SULLANA - DEPARTAMENTO DE PIURA | I2: =+name_proy -> CREACIÓN INSTALACIÓN DEL SUBSISTEMA DE DISTRIBUCIÓN PRIMARIA 10-22,9 KV Y SUBSISTEMA DE DISTRIBUCIÓN SECUNDARIA 380/220 V E INSTALACIÓN DE ALUMBRADO PÚBLICO LUCAS CUTIVALU DEL DISTRITO DE MIGUEL CHECA - PROVINCIA DE SULLANA - DEPARTAMENTO DE PIURA | J2: =+name_proy -> CREACIÓN INSTALACIÓN DEL SUBSISTEMA DE DISTRIBUCIÓN PRIMARIA 10-22,9 KV Y SUBSISTEMA DE DISTRIBUCIÓN SECUNDARIA 380/220 V E INSTALACIÓN DE ALUMBRADO PÚBLICO LUCAS CUTIVALU DEL DISTRITO DE MIGUEL CHECA - PROVINCIA DE SULLANA - DEPARTAMENTO DE PIURA | K2: =+name_proy -> CREACIÓN INSTALACIÓN DEL SUBSISTEMA DE DISTRIBUCIÓN PRIMARIA 10-22,9 KV Y SUBSISTEMA DE DISTRIBUCIÓN SECUNDARIA 380/220 V E INSTALACIÓN DE ALUMBRADO PÚBLICO LUCAS CUTIVALU DEL DISTRITO DE MIGUEL CHECA - PROVINCIA DE SULLANA - DEPARTAMENTO DE PIURA | M2: =+name_proy -> CREACIÓN INSTALACIÓN DEL SUBSISTEMA DE DISTRIBUCIÓN PRIMARIA 10-22,9 KV Y SUBSISTEMA DE DISTRIBUCIÓN SECUNDARIA 380/220 V E INSTALACIÓN DE ALUMBRADO PÚBLICO LUCAS CUTIVALU DEL DISTRITO DE MIGUEL CHECA - PROVINCIA DE SULLANA - DEPARTAMENTO DE PIURA | N2: =+name_proy -> CREACIÓN INSTALACIÓN DEL SUBSISTEMA DE DISTRIBUCIÓN PRIMARIA 10-22,9 KV Y SUBSISTEMA DE DISTRIBUCIÓN SECUNDARIA 380/220 V E INSTALACIÓN DE ALUMBRADO PÚBLICO LUCAS CUTIVALU DEL DISTRITO DE MIGUEL CHECA - PROVINCIA DE SULLANA - DEPARTAMENTO DE PIURA
B3: PROYECTO | E3: : | F3: “AMPLIACIÓN DEL SERVICIO DE ENERGÍA ELÉCTRICA EN LA PROVINCIA DEL SANTA Y EN EL DISTRITO DE PAMPAROMAS – DEPARTAMENTO DE ANCASH”
B4: DEPARTAMENTO | E4: : | F4: ANCASH
D5: SUMINISTROS DE MATERIALES | G5: =SUM(H5:N5) -> 1 | H5: 0.05 | I5: 0.45 | J5: 0.5 | K5: 0 | L5: 0 | M5: 0 | N5: =100%-SUM(H5:M5) -> 0
D6: MONTAJE ELECTROMECANICO | G6: =SUM(H6:N6) -> 1 | H6: 0.05 | I6: 0.1 | J6: 0.25 | K6: 0.35 | L6: 0 | M6: 0 | N6: =100%-SUM(H6:M6) -> 0.25
D7: TRANSPORTE DE MATERIALES | G7: =SUM(H7:N7) -> 1 | I7: 0.45 | J7: 0.5 | K7: 0.05 | L7: 0 | M7: 0 | N7: =100%-SUM(H7:M7) -> 0
B9: ITEM | C9: DESCRIPCION | G9: TOTAL S/. | H9: MES 1 | I9: MES 2 | J9: MES 3 | K9: MES 4 | L9: MES 5 | M9: MES 6 | N9: MES 7
B11: A | D11: SUMINISTROS DE MATERIALES | G11: =ROUND(+SUM(H11:N11),2) -> 1559314.8 | H11: =+'RESUMEN LP'!F11+'RESUMEN RP'!F11+'RESUMEN RS'!F11+'RESUMEN SDF'!F11 -> 6640.86 | I11: =+'RESUMEN LP'!G11+'RESUMEN RP'!G11+'RESUMEN RS'!G11+'RESUMEN SDF'!G11 -> 49153.472 | J11: =+'RESUMEN LP'!H11+'RESUMEN RP'!H11+'RESUMEN RS'!H11+'RESUMEN SDF'!H11 -> 194455.98 | K11: =+'RESUMEN LP'!I11+'RESUMEN RP'!I11+'RESUMEN RS'!I11+'RESUMEN SDF'!I11 -> 528235.27 | L11: =+'RESUMEN LP'!J11+'RESUMEN RP'!J11+'RESUMEN RS'!J11+'RESUMEN SDF'!J11 -> 474758.54 | M11: =+'RESUMEN LP'!K11+'RESUMEN RP'!K11+'RESUMEN RS'!K11+'RESUMEN SDF'!K11 -> 306070.67 | N11: =+'RESUMEN LP'!L11+'RESUMEN RP'!L11+'RESUMEN RS'!L11+'RESUMEN SDF'!L11 -> 0 | O11: =+SUM(H11:N11) -> 1559314.8 | P11: 2531.39
B12: B | D12: MONTAJE ELECTROMECANICO | G12: =ROUND(+SUM(H12:N12),2) -> 1009873.9 | H12: =+'RESUMEN LP'!F12+'RESUMEN RP'!F12+'RESUMEN RS'!F12+'RESUMEN SDF'!F12 -> 4440.58 | I12: =+'RESUMEN LP'!G12+'RESUMEN RP'!G12+'RESUMEN RS'!G12+'RESUMEN SDF'!G12 -> 23172.97 | J12: =+'RESUMEN LP'!H12+'RESUMEN RP'!H12+'RESUMEN RS'!H12+'RESUMEN SDF'!H12 -> 49537.6 | K12: =+'RESUMEN LP'!I12+'RESUMEN RP'!I12+'RESUMEN RS'!I12+'RESUMEN SDF'!I12 -> 79766.78 | L12: =+'RESUMEN LP'!J12+'RESUMEN RP'!J12+'RESUMEN RS'!J12+'RESUMEN SDF'!J12 -> 219601.72 | M12: =+'RESUMEN LP'!K12+'RESUMEN RP'!K12+'RESUMEN RS'!K12+'RESUMEN SDF'!K12 -> 198992.73 | N12: =+'RESUMEN LP'!L12+'RESUMEN RP'!L12+'RESUMEN RS'!L12+'RESUMEN SDF'!L12 -> 434361.54 | O12: =+SUM(H12:N12) -> 1009873.9
B13: C | D13: TRANSPORTE DE MATERIALES | G13: =ROUND(+SUM(H13:N13),2) -> 131667.96 | H13: =+'RESUMEN LP'!F13+'RESUMEN RP'!F13+'RESUMEN RS'!F13+'RESUMEN SDF'!F13 -> 4920.16 | I13: =+'RESUMEN LP'!G13+'RESUMEN RP'!G13+'RESUMEN RS'!G13+'RESUMEN SDF'!G13 -> 12940.66 | J13: =+'RESUMEN LP'!H13+'RESUMEN RP'!H13+'RESUMEN RS'!H13+'RESUMEN SDF'!H13 -> 31889.95 | K13: =+'RESUMEN LP'!I13+'RESUMEN RP'!I13+'RESUMEN RS'!I13+'RESUMEN SDF'!I13 -> 59220.31 | L13: =+'RESUMEN LP'!J13+'RESUMEN RP'!J13+'RESUMEN RS'!J13+'RESUMEN SDF'!J13 -> 17453.32 | M13: =+'RESUMEN LP'!K13+'RESUMEN RP'!K13+'RESUMEN RS'!K13+'RESUMEN SDF'!K13 -> 5243.56 | N13: =+'RESUMEN LP'!L13+'RESUMEN RP'!L13+'RESUMEN RS'!L13+'RESUMEN SDF'!L13 -> 0 | O13: =+SUM(H13:N13) -> 131667.96
B15: D | D15: COSTO DIRECTO ( C.D. ) | G15: =ROUND(+SUM(G11:G13),2)-0.01 -> 2700856.7 | H15: =+SUM(H11:H13) -> 16001.6 | I15: =+SUM(I11:I13) -> 85267.102 | J15: =+SUM(J11:J13) -> 275883.53 | K15: =+SUM(K11:K13) -> 667222.36 | L15: =+SUM(L11:L13) -> 711813.58 | M15: =+SUM(M11:M13) -> 510306.96 | N15: =+SUM(N11:N13) -> 434361.54
B17: E | F17: GASTOS GENERALES (10.12%) | G17: =+G15*O17 -> 273326.69 | H17: =ROUND(+H15*$O$17,2) -> 1619.36 | I17: =ROUND(+I15*$O$17,2) -> 8629.03 | J17: =ROUND(+J15*$O$17,2) -> 27919.41 | K17: =ROUND(+K15*$O$17,2) -> 67522.9 | L17: =ROUND(+L15*$O$17,2) -> 72035.53 | M17: =ROUND(+M15*$O$17,2) -> 51643.06 | N17: =ROUND(+N15*$O$17,2) -> 43957.39 | O17: 0.1012
B18: F | F18: UTILIDADES (3.00%) | G18: =+G15*O18 -> 81025.7 | H18: =ROUND(+H15*$O$18,2) -> 480.05 | I18: =ROUND(+I15*$O$18,2) -> 2558.01 | J18: =ROUND(+J15*$O$18,2) -> 8276.51 | K18: =ROUND(+K15*$O$18,2) -> 20016.67 | L18: =ROUND(+L15*$O$18,2) -> 21354.41 | M18: =ROUND(+M15*$O$18,2) -> 15309.21 | N18: =ROUND(+N15*$O$18,2) -> 13030.85 | O18: 0.03
D21: SUB-TOTAL SIN I.G.V. (S/.) | G21: =ROUND(+SUM(G15:G18),2)+0.01 -> 3055209 | H21: =+SUM(H15:H18) -> 18101.01 | I21: =+SUM(I15:I18) -> 96454.142 | J21: =+SUM(J15:J18) -> 312079.45 | K21: =+SUM(K15:K18) -> 754761.93 | L21: =+SUM(L15:L18) -> 805203.52 | M21: =+SUM(M15:M18) -> 577259.23 | N21: =+SUM(N15:N18) -> 491349.78
D23: IMPUESTO GENERAL A LAS VENTAS IGV (18%) | G23: =+G21*O23 -> 549937.63 | H23: =+H21*$O$23 -> 3258.1818 | I23: =+I21*$O$23 -> 17361.746 | J23: =+J21*$O$23 -> 56174.301 | K23: =+K21*$O$23 -> 135857.15 | L23: =+L21*$O$23 -> 144936.63 | M23: =+M21*$O$23 -> 103906.66 | N23: =+N21*$O$23 -> 88442.96 | O23: 0.18
C24: COSTO TOTAL OBRA (Incluye I.G.V.) | G24: =+G23+G21 -> 3605146.7 | H24: =+H23+H21 -> 21359.192 | I24: =+I23+I21 -> 113815.89 | J24: =+J23+J21 -> 368253.75 | K24: =+K23+K21 -> 890619.07 | L24: =+L23+L21 -> 950140.15 | M24: =+M23+M21 -> 681165.89 | N24: =+N23+N21 -> 579792.74
