Workbook
Name \A: [1]A!$D$9:$D$53
Name \p: #REF!
Name _: '[2]#¡REF'!#REF!
Name __?EL: '[3]#¡REF'!#REF!
Name __?EL_1: '[3]#¡REF'!#REF!
Name __?ELCEN: '[3]#¡REF'!#REF!
Name __?ELCEN_1: '[3]#¡REF'!#REF!
Name __?ELECSURE: '[3]#¡REF'!#REF!
Name __?ELECSURE_1: '[3]#¡REF'!#REF!
Name __?ELECSURME: '[3]#¡REF'!#REF!
Name __?ELECSURME_1: '[3]#¡REF'!#REF!
Name __?ELECT: '[3]#¡REF'!#REF!
Name __?ELECT_1: '[3]#¡REF'!#REF!
Name __?ELECTROL: '[3]#¡REF'!#REF!
Name __?ELECTROL_1: '[3]#¡REF'!#REF!
Name __?ELEORIE: '[3]#¡REF'!#REF!
Name __?ELEORIE_1: '[3]#¡REF'!#REF!
Name __?ELNO: '[3]#¡REF'!#REF!
Name __?ELNO_1: '[3]#¡REF'!#REF!
Name __?ELSURE: '[3]#¡REF'!#REF!
Name __?ELSURE_1: '[3]#¡REF'!#REF!
Name __?HIDRAND: '[3]#¡REF'!#REF!
Name __?HIDRAND_1: '[3]#¡REF'!#REF!
Name __?S: '[3]#¡REF'!#REF!
Name __?S_1: '[3]#¡REF'!#REF!
Name ______________REV3: [4]DATOS!$A$3:$E$22
Name ______________SOL1: #REF!
Name _____________REV3: [4]DATOS!$A$3:$E$22
Name _____________SOL1: #REF!
Name ____________PPA1: #REF!
Name ____________REV3: [4]DATOS!$A$3:$E$22
Name ____________Rp12: [5]Datos!$G$17
Name ____________Sec13: [5]Datos!$G$12
Name ____________Sec77: [5]Datos!$G$8
Name ____________SOL1: #REF!
Name ___________Pbs1: [5]Datos!$E$6
Name ___________PPA1: #REF!
Name ___________REV3: [4]DATOS!$A$3:$E$22
Name ___________Rp12: [5]Datos!$G$17
Name ___________Sec13: [5]Datos!$G$12
Name ___________Sec77: [5]Datos!$G$8
Name ___________SOL1: #REF!
Name __________HED2: #REF!
Name __________Pbs1: [5]Datos!$E$6
Name __________PPA1: #REF!
Name __________REV3: [6]DATOS!$A$3:$E$22
Name __________Rp12: [5]Datos!$G$17
Name __________Sec01: [5]Datos!$G$4
Name __________sec02: [7]Datos!$D$27
Name __________sec03: [8]Datos!$D$28
Name __________sec04: [7]Datos!$D$29
Name __________sec05: [7]Datos!$D$30
Name __________Sec13: [5]Datos!$G$12
Name __________Sec77: [5]Datos!$G$8
Name __________SOL1: #REF!
Name _________HED2: #REF!
Name _________Pbs1: [5]Datos!$E$6
Name _________PPA1: #REF!
Name _________REV3: [6]DATOS!$A$3:$E$22
Name _________Rp12: [5]Datos!$G$17

Sheet RESUMEN TOTAL
B2: RESUMEN GENERAL DEL PRESUPUESTO (OBRA Y EXPEDIENTE TÉCNICO)
B4: PROYECTO | C4: : | D4: AMPLIACIÓN DEL SERVICIO DE ENERGÍA ELÉCTRICA EN LA PROVINCIA DEL SANTA Y EN EL DISTRITO DE PAMPAROMAS – DEPARTAMENTO DE ANCASH
B5: DEPARTAMENTO | C5: : | D5: ANCASH
J6: Fecha: 30-May-2022
J7: T.C. (S/ /US$): 3,683
E9: CONTRACTUAL | H9: ESTUDIO DEFINITIVO
B10: ITEM | D10: Descripcion | E10: Total Sin I.G.V. (S/.) | F10: I.G.V. | G10: TOTAL S/. | H10: Total Sin I.G.V. (S/.) | I10: I.G.V. | J10: TOTAL S/.
B12: A | D12: COSTO DE OBRA | E12: =+'RES-GRAL OBRA'!G15 -> 2658762.1 | F12: =+'RES-GRAL OBRA'!G16 -> 478577.18 | G12: =+SUM(E12:F12) -> 3137339.3 | H12: =+'RES-GRAL OBRA'!H15 -> 3055209.1 | I12: =+'RES-GRAL OBRA'!H16 -> 549937.63 | J12: =+SUM(H12:I12) -> 3605146.7
B14: B | D14: COSTO DE EXPEDIENTE TÉCNICO | E14: 200121.88 | F14: 36021.94 | G14: =+SUM(E14:F14) -> 236143.82 | H14: =+E14 -> 200121.88 | I14: =+F14 -> 36021.94 | J14: =+SUM(H14:I14) -> 236143.82
G15: =+SUM(E15:F15) -> 0
D16: TOTAL | E16: =E12+E14 -> 2858884 | F16: =F12+F14 -> 514599.12 | G16: =G12+G14 -> 3373483.1 | H16: =H12+H14 -> 3255330.9 | I16: =I12+I14 -> 585959.57 | J16: =J12+J14 -> 3841290.5
G18: % DE INCIDENCIA SOBRE EL CONTRACTUAL | J18: =ROUND((J16/G16),4) -> 1.1387
J21: =+J12/G12 -> 1.1491096

Sheet RES-GRAL OBRA
B2: RESUMEN GENERAL PRESUPUESTO DE OBRA
B4: PROYECTO | E4: : | F4: AMPLIACIÓN DEL SERVICIO DE ENERGÍA ELÉCTRICA EN LA PROVINCIA DEL SANTA Y EN EL DISTRITO DE PAMPAROMAS – DEPARTAMENTO DE ANCASH
B5: DEPARTAMENTO | E5: : | F5: ANCASH | H5: Fecha: 30-May-2022
H6: T.C. (S/ /US$): 3,683
B7: ITEM | C7: DESCRIPCION | G7: PRESUPUESTO CONTRATO | H7: PRESUPUESTO ESTUDIO DEFINITIVO | I7: ADICIONALES | K7: DEDUCTIVOS
I8: MAYORES METRADOS | J8: PARTIDAS NUEVAS | K8: MENOR METRADO | L8: DEDUCTIVO VINCULANTE
B9: A | D9: SUMINISTROS DE MATERIALES | G9: =+'RES-LP'!G12+'RES-RP'!G12+'RES-RS'!G12+'RES- SFV'!G12 -> 1356698.6 | H9: =+'RES-LP'!H12+'RES-RP'!H12+'RES-RS'!H12+'RES- SFV'!H12 -> 1559314.8 | I9: =+'RES-LP'!I12+'RES-RP'!I12+'RES-RS'!I12+'RES- SFV'!I12 -> 165194.76 | J9: =+'RES-LP'!J12+'RES-RP'!J12+'RES-RS'!J12+'RES- SFV'!J12 -> 387288.28 | K9: =+'RES-LP'!K12+'RES-RP'!K12+'RES-RS'!K12+'RES- SFV'!K12 -> 349866.84 | L9: =+'RES-LP'!L12+'RES-RP'!L12+'RES-RS'!L12+'RES- SFV'!L12 -> 196109.06
B10: B | D10: MONTAJE ELECTROMECANICO | G10: =+'RES-LP'!G13+'RES-RP'!G13+'RES-RS'!G13+'RES- SFV'!G13 -> 872009.12 | H10: =+'RES-LP'!H13+'RES-RP'!H13+'RES-RS'!H13+'RES- SFV'!H13 -> 1009873.9 | I10: =+'RES-LP'!I13+'RES-RP'!I13+'RES-RS'!I13+'RES- SFV'!I13 -> 124806.45 | J10: =+'RES-LP'!J13+'RES-RP'!J13+'RES-RS'!J13+'RES- SFV'!J13 -> 116126.84 | K10: =+'RES-LP'!K13+'RES-RP'!K13+'RES-RS'!K13+'RES- SFV'!K13 -> 103068.48 | L10: =+'RES-LP'!L13+'RES-RP'!L13+'RES-RS'!L13+'RES- SFV'!L13 -> 81998.26
B11: C | D11: TRANSPORTE DE MATERIALES | G11: =+'RES-LP'!G14+'RES-RP'!G14+'RES-RS'!G14+'RES- SFV'!G14 -> 121683.17 | H11: =+'RES-LP'!H14+'RES-RP'!H14+'RES-RS'!H14+'RES- SFV'!H14 -> 131667.96 | I11: =+'RES-LP'!I14+'RES-RP'!I14+'RES-RS'!I14+'RES- SFV'!I14 -> 16270.73 | J11: =+'RES-LP'!J14+'RES-RP'!J14+'RES-RS'!J14+'RES- SFV'!J14 -> 19445.26 | K11: =+'RES-LP'!K14+'RES-RP'!K14+'RES-RS'!K14+'RES- SFV'!K14 -> 25731.2 | L11: =+'RES-LP'!L14+'RES-RP'!L14+'RES-RS'!L14+'RES- SFV'!L14 -> 16682.92
B12: D | D12: COSTO DIRECTO ( C.D. ) | G12: =ROUND(SUM(G9:G11),2) -> 2350390.9 | H12: =ROUND(SUM(H9:H11),2) -> 2700856.7 | I12: =ROUND(SUM(I9:I11),2) -> 306271.94 | J12: =ROUND(SUM(J9:J11),2) -> 522860.38 | K12: =ROUND(SUM(K9:K11),2) -> 478666.52 | L12: =ROUND(SUM(L9:L11),2) -> 294790.24
B13: E | D13: GASTOS GENERALES (10.12%) | G13: =ROUND(G12*10.12%,2) -> 237859.55 | H13: =ROUND(H12*10.12%,2) -> 273326.69 | I13: =ROUND(I12*10.12%,2) -> 30994.72 | J13: =ROUND(J12*10.12%,2) -> 52913.47 | K13: =ROUND(K12*10.12%,2) -> 48441.05 | L13: =ROUND(L12*10.12%,2) -> 29832.77 | M13: =+H13-G13 -> 35467.14
B14: F | D14: UTILIDADES (3%) | G14: =ROUND(G12*3%,2) -> 70511.73 | H14: =ROUND(H12*3%,2) -> 81025.7 | I14: =ROUND(I12*3%,2) -> 9188.16 | J14: =ROUND(J12*3%,2) -> 15685.81 | K14: =ROUND(K12*3%,2) -> 14360 | L14: =ROUND(L12*3%,2) -> 8843.71 | M14: =+H14-G14 -> 10513.97
D15: SUB-TOTAL SIN I.G.V. (S/.) | G15: =G14+G13+G12 -> 2658762.1 | H15: =H14+H13+H12 -> 3055209.1 | I15: =I14+I13+I12 -> 346454.82 | J15: =J14+J13+J12 -> 591459.66 | K15: =K14+K13+K12 -> 541467.57 | L15: =L14+L13+L12 -> 333466.72 | M15: =+H15-G15 -> 396446.92
D16: IMPUESTO GENERAL A LAS VENTAS IGV (18%) | G16: =ROUND(G15*0.18,2) -> 478577.18 | H16: =ROUND(H15*0.18,2) -> 549937.63 | I16: =ROUND(I15*0.18,2) -> 62361.87 | J16: =ROUND(J15*0.18,2) -> 106462.74 | K16: =ROUND(K15*0.18,2) -> 97464.16 | L16: =ROUND(L15*0.18,2) -> 60024.01
D17: COSTO TOTAL (Incluye I.G.V.) S/. | G17: =G15+G16 -> 3137339.3 | H17: =H15+H16 -> 3605146.7 | I17: =I15+I16 -> 408816.69 | J17: =J15+J16 -> 697922.4 | K17: =K15+K16 -> 638931.73 | L17: =L15+L16 -> 393490.73
D19: INCIDENCIA RESPECTO AL CONTRACTUAL % | H19: =+ROUND(H17/$G$17,4) -> 1.1491 | I19: =+ROUND(I17/$G$17,4) -> 0.1303 | J19: =+ROUND(J17/$G$17,4) -> 0.2225 | K19: =+ROUND(K17/$G$17,4) -> 0.2037 | L19: =+ROUND(L17/$G$17,4) -> 0.1254
H23: =+G17+I17+J17-K17 -> 3605146.7 | I23: =+H17-G17 -> 467807.37 | J23: =+I17+J17-K17 -> 467807.36
H24: =+H17-H23 -> 0.0099999998 | J24: =+I23-J23 -> 0.01

Sheet RG
B2: RESUMEN DE PRESUPUESTO CONTRATCUAL REPLANTEO
B4: PROYECTO | E4: : | F4: CREACIÓN INSTALACIÓN DEL SUBSISTEMA DE DISTRIBUCIÓN PRIMARIA 10-22,9 KV Y SUBSISTEMA DE DISTRIBUCIÓN SECUNDARIA 380/220 V E INSTALACIÓN DE ALUMBRADO PÚBLICO LUCAS CUTIVALU DEL DISTRITO DE MIGUEL CHECA - PROVINCIA DE SULLANA - DEPARTAMENTO DE PIURA
B5: DEPARTAMENTOS | E5: : | F5: PIURA
B6: ITEM | C6: DESCRIPCION | G6: LINEAS PRIMARIAS | I6: REDES PRIMARIAS | K6: REDES SECUNDARIAS | M6: TOTAL
G7: PRESUPUESTO CONTRATO | H7: PRESUPUESTO REPLANTEO | I7: PRESUPUESTO CONTRATO | J7: PRESUPUESTO REPLANTEO | K7: PRESUPUESTO CONTRATO | L7: PRESUPUESTO REPLANTEO | M7: PRESUPUESTO CONTRATO | N7: PRESUPUESTO REPLANTEO
B9: A | D9: SUMINISTROS DE MATERIALES | G9: =+#REF! -> #REF! | H9: =+#REF! -> #REF! | I9: =+#REF! -> #REF! | J9: =+#REF! -> #REF! | K9: =+'RES-RS'!G12 -> 301377.1 | L9: =+'RES-RS'!H12 -> 420410.61 | M9: =+G9+I9+K9 -> #REF! | N9: =+H9+J9+L9 -> #REF!
B10: B | D10: MONTAJE ELECTROMECANICO | G10: =+#REF! -> #REF! | H10: =+#REF! -> #REF! | I10: =+#REF! -> #REF! | J10: =+#REF! -> #REF! | K10: =+'RES-RS'!G13 -> 273560.14 | L10: =+'RES-RS'!H13 -> 323016.92 | M10: =+G10+I10+K10 -> #REF! | N10: =+H10+J10+L10 -> #REF!
B11: C | D11: TRANSPORTE DE MATERIALES | G11: =+#REF! -> #REF! | H11: =+#REF! -> #REF! | I11: =+#REF! -> #REF! | J11: =+#REF! -> #REF! | K11: =+'RES-RS'!G14 -> 39859.51 | L11: =+'RES-RS'!H14 -> 46723.13 | M11: =+G11+I11+K11 -> #REF! | N11: =+H11+J11+L11 -> #REF!
B13: D | D13: COSTO DIRECTO ( C.D. ) | G13: =SUM(G9:G12) -> #REF! | H13: =SUM(H9:H12) -> #REF! | I13: =SUM(I9:I12) -> #REF! | J13: =SUM(J9:J12) -> #REF! | K13: =SUM(K9:K12) -> 614796.75 | L13: =SUM(L9:L12) -> 790150.66 | M13: =SUM(M9:M12) -> #REF! | N13: =SUM(N9:N12) -> #REF!
B15: E | D15: GASTOS GENERALES (30.52%) | G15: =ROUND(G13*30.52%,2) -> #REF! | H15: =ROUND(H13*30.52%,2) -> #REF! | I15: =ROUND(I13*30.52%,2) -> #REF! | J15: =ROUND(J13*30.52%,2) -> #REF! | K15: =ROUND(K13*30.52%,2) -> 187635.97 | L15: =ROUND(L13*30.52%,2) -> 241153.98 | M15: =ROUND(M13*30.52%,2) -> #REF! | N15: =ROUND(N13*30.52%,2) -> #REF!
B16: F | D16: UTILIDADES (4.01%) | G16: =ROUND(G13*4.01%,2) -> #REF! | H16: =ROUND(H13*4.01%,2) -> #REF! | I16: =ROUND(I13*4.01%,2) -> #REF! | J16: =ROUND(J13*4.01%,2) -> #REF! | K16: =ROUND(K13*4.01%,2) -> 24653.35 | L16: =ROUND(L13*4.01%,2) -> 31685.04 | M16: =ROUND(M13*4.01%,2) -> #REF! | N16: =ROUND(N13*4.01%,2) -> #REF!
D19: SUB-TOTAL SIN I.G.V. (S/.) | G19: =G16+G15+G13 -> #REF! | H19: =H16+H15+H13 -> #REF! | I19: =I16+I15+I13 -> #REF! | J19: =J16+J15+J13 -> #REF! | K19: =K16+K15+K13 -> 827086.07 | L19: =L16+L15+L13 -> 1062989.7 | M19: =M16+M15+M13 -> #REF! | N19: =N16+N15+N13 -> #REF!
D21: IMPUESTO GENERAL A LAS VENTAS IGV (18%) | G21: =ROUND(G19*0.18,2) -> #REF! | H21: =ROUND(H19*0.18,2) -> #REF! | I21: =ROUND(I19*0.18,2) -> #REF! | J21: =ROUND(J19*0.18,2) -> #REF! | K21: =ROUND(K19*0.18,2) -> 148875.49 | L21: =ROUND(L19*0.18,2) -> 191338.14 | M21: =ROUND(M19*0.18,2) -> #REF! | N21: =ROUND(N19*0.18,2) -> #REF!
D22: COSTO TOTAL (Incluye I.G.V.) S/. | G22: =G19+G21 -> #REF! | H22: =H19+H21 -> #REF! | I22: =I19+I21 -> #REF! | J22: =J19+J21 -> #REF! | K22: =K19+K21 -> 975961.56 | L22: =L19+L21 -> 1254327.8 | M22: =M19+M21 -> #REF! | N22: =N19+N21 -> #REF!
D23: INCIDENCIA RESPECTO AL CONTRACTUAL % | H23: =+H22/$G$22 -> #REF! | J23: =+J22/$I$22 -> #REF! | L23: =+L22/$L$22 -> 1 | N23: =+N22/$M$22 -> #REF!
D24: INCIDENCIA DEL ADICIONAL % | G24: =+(I22+J22-L22)/G22 -> #REF!
D25: INCIDENCIA DEL MAYOR METRADO % | G25: =+K22/G22 -> #REF!
D26: INCIDENCIA DEL ADICONAL + MAYOR METRADO % | G26: =+(I22+J22+K22-L22)/G22 -> #REF!
H29: =+H22-K22+M22 -> #REF! | M29: 1495463.1 | N29: 1557304.6
H30: =+H29-G22 -> #REF!

Sheet GG Contr.
B1: CREACIÓN INSTALACIÓN DEL SUBSISTEMA DE DISTRIBUCIÓN PRIMARIA 10-22,9 KV Y SUBSISTEMA DE DISTRIBUCIÓN SECUNDARIA 380/220 V E INSTALACIÓN DE ALUMBRADO PÚBLICO LUCAS CUTIVALU DEL DISTRITO DE MIGUEL CHECA - PROVINCIA DE SULLANA - DEPARTAMENTO DE PIURA
B3: CALCULO DE LOS GASTOS GENERALES DIRECTOS E INDIRECTOS
C5: Sección : | D5: LINEAS PRIMARIAS, REDES PRIMARIAS Y REDES SECUNDARIAS
C6: Departamento : | D6: PIURA | K6: =I190/E69 -> 0.30530483
C7: Plazo de Obra : | D7: 5 | E7: meses
B9: 1.0 | C9: GASTOS GENERALES VARIABLES-GG DIRECTOS | I9: 942051.3
B11: 1.1 | C11: Personal Profesional Principal
C12: Descripción | D12: Unidad | E12: Cant. | F12: Particip. | G12: Tiempo | H12: Sueldo | I12: Parcial
F13: % | G13: (meses) | H13: (S/.) | I13: (S/.)
C14: Gerente de Obra | D14: Und. | E14: 0 | F14: 0.5 | G14: 2.5 | H14: 10000 | I14: 0
C15: Ingeniero Residente de la Obra | D15: Und. | E15: 1 | F15: 1 | G15: 5 | H15: 6000 | I15: =ROUND(E15*F15*G15*H15,2) -> 30000
C16: Ingeniero Asistente de Obra | D16: Und. | E16: 0 | F16: 0.82 | G16: 4.1 | H16: 6500 | I16: 0
C17: Gestor de Servidumbre | D17: Und. | E17: 0 | F17: 0.5 | G17: 2.5 | H17: 4500 | I17: 0
C18: Ingeniero de Seguridad e Higiene Ocupacional | D18: Und. | E18: 1 | F18: 1 | G18: 5 | H18: 4500 | I18: =ROUND(E18*F18*G18*H18,2) -> 22500
C19: Ingeniero Asistente de Residente de Obra | D19: Und. | E19: 1 | F19: 1 | G19: 5 | H19: 4000 | I19: =ROUND(E19*F19*G19*H19,2) -> 20000
C21: PARCIAL 1,1 | I21: =SUM(I14:I20) -> 72500
C22: Nota: El sueldo considerado por cada profesional incluye impuestos y leyes sociales
B24: 1.2 | C24: Personal de Auxiliar y Apoyo
C25: Descripción | D25: Und. | E25: Cant. | F25: Particip. | G25: Tiempo | H25: Sueldo | I25: Parcial
F26: % | G26: (meses) | H26: (S/.) | I26: (S/.)
C27: Administrador | D27: Und. | E27: 1 | F27: 1 | G27: 5 | H27: 3500 | I27: =ROUND(E27*F27*G27*H27,2) -> 17500
C28: Asistente de administrador | D28: Und. | E28: 0 | F28: 0.8 | G28: 4 | H28: 1500 | I28: =ROUND(E28*F28*G28*H28,2) -> 0
C29: Dibujante en Autocad y otros programas | D29: Und. | E29: 1 | F29: 1 | G29: 5 | H29: 1500 | I29: =ROUND(E29*F29*G29*H29,2) -> 7500
C30: Almacenero | D30: Und. | E30: 1 | F30: 1 | G30: 5 | H30: 1800 | I30: =ROUND(E30*F30*G30*H30,2) -> 9000
C31: Asistente de almacen | D31: Und. | E31: 0 | F31: 1 | G31: 5 | H31: 1050 | I31: =ROUND(E31*F31*G31*H31,2) -> 0
C32: Técnico mecánico | D32: Und. | E32: 0 | F32: 1 | G32: 5 | H32: 1200 | I32: =ROUND(E32*F32*G32*H32,2) -> 0
C33: Chofer | D33: Und. | E33: 1 | F33: 1 | G33: 5 | H33: 1500 | I33: =ROUND(E33*F33*G33*H33,2) -> 7500
C34: Seguridad en obra (Guardian) | D34: Und. | E34: 1 | F34: 1 | G34: 5 | H34: 1047 | I34: =ROUND(E34*F34*G34*H34,2) -> 5235
C36: PARCIAL 1,2 | I36: =SUM(I27:I35) -> 46735 | K36: 46735
C37: Nota: El sueldo considerado por trabajador incluye impuestos y leyes sociales
B39: 1.3 | C39: Hospedajes, Oficina, Campamentos, alimentación y movilidad del personal principal, auxiliar y apoyo
C40: Descripción | D40: Und. | E40: Cant. | F40: Particip. | G40: Tiempo | H40: Gasto/ Und. | I40: Parcial
F41: % | G41: (meses) | H41: (S/.) | I41: (S/.)
C42: Hospedajes | D42: Glb/mes | E42: 1 | F42: 1 | G42: 5 | H42: 1500 | I42: =ROUND(E42*F42*G42*H42,2) -> 7500
C43: Alquiler de Oficina - Almacen en Obra (Incluye agua y luz) | D43: Glb/mes | E43: 1 | F43: 1 | G43: 5 | H43: 849.88 | I43: =ROUND(E43*F43*G43*H43,2) -> 4249.4
C44: Alquiler de casa almacén (incluye agua y luz) | D44: Glb/mes | E44: 0 | F44: 1 | G44: 5 | H44: 450 | I44: =ROUND(E44*F44*G44*H44,2) -> 0
C45: Comunicaciones: telefono, fax, internet, radio, etc. | D45: Glb/mes | E45: 1 | F45: 1 | G45: 5 | H45: 550 | I45: =ROUND(E45*F45*G45*H45,2) -> 2750
C46: Alimentación | D46: Glb/mes | E46: 1 | F46: 1 | G46: 5 | H46: 2000 | I46: =ROUND(E46*F46*G46*H46,2) -> 10000
C47: Pasajes | D47: Glb/mes | E47: 1 | F47: 1 | G47: 5 | H47: 650 | I47: =ROUND(E47*F47*G47*H47,2) -> 3250
C49: PARCIAL 1,3 | I49: =SUM(I42:I48) -> 27749.4
...

Sheet RES-LP
B2: RESUMEN PRESUPUESTO DE OBRA
B4: AMPLIACIÓN DEL SERVICIO DE ENERGÍA ELÉCTRICA EN LA PROVINCIA DEL SANTA Y EN EL DISTRITO DE PAMPAROMAS – DEPARTAMENTO DE ANCASH
B6: UBICACIÓN | C6: : | D6: ANCASH
B7: SECCIÓN I | C7: : | D7: LINEAS PRIMARIAS | H7: Fecha: 30-May-2022
H8: T.C. (S/ /US$): 3,683
B9: ITEM | C9: DESCRIPCION | G9: PRESUPUESTO CONTRATO | H9: PRESUPUESTO ESTUDIO DEFINIVO | I9: ADICIONALES | K9: DEDUCTIVOS
I10: MAYORES METRADOS | J10: PARTIDAS NUEVAS | K10: MENOR METRADO | L10: DEDUCTIVO VINCULANTE
B12: A | D12: SUMINISTRO DE MATERIALES | G12: =+'Mtdo-Ppto LP'!K154 -> 628325.26 | H12: =+'Mtdo-Ppto LP'!M154 -> 683730.19 | I12: =+'Mtdo-Ppto LP'!O154 -> 91503.47 | J12: =+'Mtdo-Ppto LP'!Q154 -> 85371.61 | K12: =+'Mtdo-Ppto LP'!S154 -> 121470.16 | L12: =+'Mtdo-Ppto LP'!U154 -> 94577.96
B13: B | D13: MONTAJE ELECTROMECANICO | G13: =+'Mtdo-Ppto LP'!K307 -> 461491.17 | H13: =+'Mtdo-Ppto LP'!M307 -> 552762.73 | I13: =+'Mtdo-Ppto LP'!O307 -> 54136.69 | J13: =+'Mtdo-Ppto LP'!Q307 -> 91265.2 | K13: =+'Mtdo-Ppto LP'!S307 -> 54130.28 | L13: =+'Mtdo-Ppto LP'!U307 -> 47888.05
B14: C | D14: TRANSPORTE DE MATERIALES | G14: =+'Mtdo-Ppto LP'!K446 -> 60052.8 | H14: =+'Mtdo-Ppto LP'!M446 -> 59272.43 | I14: =+'Mtdo-Ppto LP'!O446 -> 9755.13 | J14: =+'Mtdo-Ppto LP'!Q446 -> 6567.64 | K14: =+'Mtdo-Ppto LP'!S446 -> 17103.14 | L14: =+'Mtdo-Ppto LP'!U446 -> 11389.32
B15: D | D15: TOTAL COSTO DIRECTO | G15: =+SUM(G12:G14) -> 1149869.2 | H15: =+SUM(H12:H14) -> 1295765.3 | I15: =+SUM(I12:I14) -> 155395.29 | J15: =+SUM(J12:J14) -> 183204.45 | K15: =+SUM(K12:K14) -> 192703.58 | L15: =+SUM(L12:L14) -> 153855.33
B16: E | D16: GASTOS GENERALES (10.12%) | G16: =ROUND(G15*10.12%,2) -> 116366.77 | H16: =ROUND(H15*10.12%,2) -> 131131.45 | I16: =ROUND(I15*10.12%,2) -> 15726 | J16: =ROUND(J15*10.12%,2) -> 18540.29 | K16: =ROUND(K15*10.12%,2) -> 19501.6 | L16: =ROUND(L15*10.12%,2) -> 15570.16
B17: F | D17: UTILIDADES (3%) | G17: =ROUND(G15*3%,2) -> 34496.08 | H17: =ROUND(H15*3%,2) -> 38872.96 | I17: =ROUND(I15*3%,2) -> 4661.86 | J17: =ROUND(J15*3%,2) -> 5496.13 | K17: =ROUND(K15*3%,2) -> 5781.11 | L17: =ROUND(L15*3%,2) -> 4615.66
B18: G | D18: COSTO TOTAL S/. (No incluye I.G.V.) | G18: =G17+G16+G15 -> 1300732.1 | H18: =H17+H16+H15 -> 1465769.8 | I18: =I17+I16+I15 -> 175783.15 | J18: =J17+J16+J15 -> 207240.87 | K18: =K17+K16+K15 -> 217986.29 | L18: =L17+L16+L15 -> 174041.15 | M18: =+H18-G18 -> 165037.68
D20: INCIDENCIA % | G20: =+G18/G18 -> 1 | H20: =+H18/$G$18 -> 1.1268806 | I20: =+I18/$G$18 -> 0.1351417 | J20: =+J18/$G$18 -> 0.15932633 | K20: =+K18/$G$18 -> 0.16758739 | L20: =+L18/$G$18 -> 0.13380246
H22: =+H18-I18+K18-J18 -> 1300732 | K22: =+G12-H12+I12+J12-K12 -> -0.01
H23: =+G18-H22 -> 0.050000001 | K23: =+G13-H13+I13+J13-K13 -> 0.05
K24: =+G14-H14+I14+J14-K14 -> 0
K25: =+G15-H15+I15+J15-K15 -> 0.04

Sheet Mtdo-Ppto LP
B6: PRESUPUESTO DE OBRA
B8: OBRA | E8: : | F8: AMPLIACIÓN DEL SERVICIO DE ENERGÍA ELÉCTRICA EN LA PROVINCIA DEL SANTA Y EN EL DISTRITO DE PAMPAROMAS – DEPARTAMENTO DE ANCASH
B9: DEPARTAMENTO | E9: : | F9: ANCASH
B10: SECCIÓN I | E10: : | F10: LINEAS PRIMARIAS
B12: ITEM | C12: DESCRIPCIÓN DE PARTIDAS | G12: UNID. | H12: Precio de Contrato | I12: Precio Pactado | J12: CONTRACTUAL | L12: ESTUDIO DEFINITIVO | N12: ADICIONALES | R12: DEDUCTIVOS | V12: OBSERVACIÓN
J13: Metrado | K13: TOTAL | L13: Metrado | M13: TOTAL | N13: MAYORES METRADOS | P13: PARTIDAS NUEVAS | R13: MENORES METRADOS | T13: DEDUCTIVO VINCULANTE
N14: Metrado | O14: TOTAL | P14: Metrado | Q14: TOTAL | R14: Metrado | S14: TOTAL | T14: Metrado | U14: TOTAL
H15: Unitario | I15: Unitario | J15: Cantidad | K15: S/. | L15: Cantidad | M15: S/. | N15: Cantidad | O15: S/. | P15: Cantidad | Q15: S/. | R15: Cantidad | S15: S/. | T15: Cantidad | U15: S/.
B16: A | D16: SUMINISTRO DE MATERIALES
B17: 1 | C17: 3 | D17: CRUCETAS DE MADERA DE PROCEDENCIA NACIONAL | Y17: 1
B18: 1.01 | C18: =+C17+1 -> 4 | D18: Cruceta de madera tratada de 90 mm x 115 mm x 1,20 m | G18: u | H18: 105 | J18: 11 | K18: =+ROUND($H18*J18,2) -> 1155 | L18: =+[191]Metrados!E19 -> 7 | M18: =+ROUND($H18*L18,2) -> 735 | N18: =+IF($L18-$J18>=0,$L18-$J18,0) -> 0 | O18: =+ROUND($H18*N18,2) -> 0 | Q18: =+ROUND($H18*P18,2) -> 0 | R18: =+IF($L18-$J18<=0,-$L18+$J18,0) -> 4 | S18: =+ROUND($H18*R18,2) -> 420 | T18: =+R18 -> 4 | U18: =+ROUND($H18*T18,2) -> 420 | V18: Se vincula con el mayor metrado de la partida 4.01 | Z18: 0
B19: 1.02 | C19: =+C18+1 -> 5 | D19: Cruceta de madera tratada de 90 mm x 115 mm x 2,00 m | G19: u | H19: 178 | J19: 2 | K19: =+ROUND($H19*J19,2) -> 356 | L19: =+[191]Metrados!E20 -> 1 | M19: =+ROUND($H19*L19,2) -> 178 | N19: =+IF($L19-$J19>=0,$L19-$J19,0) -> 0 | O19: =+ROUND($H19*N19,2) -> 0 | Q19: =+ROUND($H19*P19,2) -> 0 | R19: =+IF($L19-$J19<=0,-$L19+$J19,0) -> 1 | S19: =+ROUND($H19*R19,2) -> 178 | T19: =+R19 -> 1 | U19: =+ROUND($H19*T19,2) -> 178 | V19: Se vincula con el mayor metrado de la partida 4.01 | Z19: 0
B20: 1.03 | C20: =+C19+1 -> 6 | D20: Cruceta de madera tratada de 90 mm x 115 mm x 2,40 m | G20: u | H20: 205 | J20: 1 | K20: =+ROUND($H20*J20,2) -> 205 | L20: =+[191]Metrados!E21 -> 13 | M20: =+ROUND($H20*L20,2) -> 2665 | N20: =+IF($L20-$J20>=0,$L20-$J20,0) -> 12 | O20: =+ROUND($H20*N20,2) -> 2460 | Q20: =+ROUND($H20*P20,2) -> 0 | R20: =+IF($L20-$J20<=0,-$L20+$J20,0) -> 0 | S20: =+ROUND($H20*R20,2) -> 0 | T20: =+R20 -> 0 | U20: =+ROUND($H20*T20,2) -> 0 | V20: Se vincula con el mayor metrado de la partida 4.01 | Z20: 13
B21: 1.04 | C21: =+C20+1 -> 7 | D21: Listón de madera tratada 50 x 19 mm sección, 2,7 m longitud (incluye clavos de fijación) | G21: u | H21: 27.35 | J21: 9 | K21: =+ROUND($H21*J21,2) -> 246.15 | L21: =+[191]Metrados!E22 -> 0 | M21: =+ROUND($H21*L21,2) -> 0 | N21: =+IF($L21-$J21>=0,$L21-$J21,0) -> 0 | O21: =+ROUND($H21*N21,2) -> 0 | Q21: =+ROUND($H21*P21,2) -> 0 | R21: =+IF($L21-$J21<=0,-$L21+$J21,0) -> 9 | S21: =+ROUND($H21*R21,2) -> 246.15 | U21: =+ROUND($H21*T21,2) -> 0 | Z21: 0
C22: =+#REF!+1 -> #REF! | F22: =+"SUB-TOTAL "&B17&": " -> SUB-TOTAL 1: | K22: =+SUM(K18:K21) -> 1962.15 | M22: =+SUM(M18:M21) -> 3578 | O22: =+SUM(O18:O21) -> 2460 | Q22: =+SUM(Q18:Q21) -> 0 | S22: =+SUM(S18:S21) -> 844.15 | U22: =+SUM(U18:U21) -> 598 | W22: =+K22-M22+O22+Q22-S22 -> 0 | Z22: 0
B23: 2 | C23: =+C22+1 -> #REF! | D23: POSTES DE CONCRETO ARMADO CENTRIFUGADO | Z23: 0
B24: 2.01 | C24: =+C21+1 -> 8 | D24: Poste de C.A.C. de 12 m/200 daN (Incluye perilla) | G24: u | H24: 837.45 | J24: 15 | K24: =+ROUND($H24*J24,2) -> 12561.75 | L24: =+[191]Metrados!E25 -> 3 | M24: =+ROUND($H24*L24,2) -> 2512.35 | N24: =+IF($L24-$J24>=0,$L24-$J24,0) -> 0 | O24: =+ROUND($H24*N24,2) -> 0 | Q24: =+ROUND($H24*P24,2) -> 0 | R24: =+IF($L24-$J24<=0,-$L24+$J24,0) -> 12 | S24: =+ROUND($H24*R24,2) -> 10049.4 | T24: =+R24 -> 12 | U24: =+ROUND($H24*T24,2) -> 10049.4 | V24: Se vincula con la partida nueva 3.02 y 3.03 | Z24: 0
B25: 2.02 | C25: =+#REF!+1 -> #REF! | D25: Poste de C.A.C. de 12 m/300 daN (Incluye perilla) | G25: u | H25: 923.47 | J25: 6 | K25: =+ROUND($H25*J25,2) -> 5540.82 | L25: =+[191]Metrados!E26 -> 6 | M25: =+ROUND($H25*L25,2) -> 5540.82 | N25: =+IF($L25-$J25>=0,$L25-$J25,0) -> 0 | O25: =+ROUND($H25*N25,2) -> 0 | Q25: =+ROUND($H25*P25,2) -> 0 | R25: =+IF($L25-$J25<=0,-$L25+$J25,0) -> 0 | S25: =+ROUND($H25*R25,2) -> 0 | U25: =+ROUND($H25*T25,2) -> 0 | Z25: 0
B26: 2.03 | C26: =+#REF!+1 -> #REF! | D26: Poste de C.A.C. de 13 m/300 daN (Incluye perilla) | G26: u | H26: 1085.14 | J26: 118 | K26: =+ROUND($H26*J26,2) -> 128046.52 | L26: =+[191]Metrados!E27 -> 96 | M26: =+ROUND($H26*L26,2) -> 104173.44 | N26: =+IF($L26-$J26>=0,$L26-$J26,0) -> 0 | O26: =+ROUND($H26*N26,2) -> 0 | Q26: =+ROUND($H26*P26,2) -> 0 | R26: =+IF($L26-$J26<=0,-$L26+$J26,0) -> 22 | S26: =+ROUND($H26*R26,2) -> 23873.08 | T26: =+R26 -> 22 | U26: =+ROUND($H26*T26,2) -> 23873.08 | V26: Se vincula con el mayor metrado de la partida 2.04 | Z26: 0
B27: 2.04 | C27: =+C22+1 -> #REF! | D27: Poste de C.A.C. de 13 m/400 daN (Incluye perilla) | G27: u | H27: 1207.94 | J27: 32 | K27: =+ROUND($H27*J27,2) -> 38654.08 | L27: =+[191]Metrados!E28 -> 60 | M27: =+ROUND($H27*L27,2) -> 72476.4 | N27: =+IF($L27-$J27>=0,$L27-$J27,0) -> 28 | O27: =+ROUND($H27*N27,2) -> 33822.32 | Q27: =+ROUND($H27*P27,2) -> 0 | R27: =+IF($L27-$J27<=0,-$L27+$J27,0) -> 0 | S27: =+ROUND($H27*R27,2) -> 0 | U27: =+ROUND($H27*T27,2) -> 0 | Z27: 0
B28: =+B27+0.01 -> 2.05 | C28: =+C27+1 -> #REF! | D28: Poste de C.A.C. de 15 m/400 daN (Incluye perilla) | G28: u | I28: 0 | K28: =+ROUND($H28*J28,2) -> 0 | L28: =+[191]Metrados!E29 -> 0 | M28: =+ROUND($I28*L28,2) -> 0 | O28: =+ROUND($H28*N28,2) -> 0 | P28: =+L28 -> 0 | Q28: =+ROUND($I28*P28,2) -> 0 | S28: =+ROUND($H28*R28,2) -> 0 | U28: =+ROUND($H28*T28,2) -> 0 | Z28: 0
C29: =+#REF!+1 -> #REF! | F29: =+"SUB-TOTAL "&B23&": " -> SUB-TOTAL 2: | K29: =+SUM(K24:K28) -> 184803.17 | M29: =+SUM(M24:M28) -> 184703.01 | O29: =+SUM(O24:O28) -> 33822.32 | Q29: =+SUM(Q24:Q28) -> 0 | S29: =+SUM(S24:S28) -> 33922.48 | U29: =+SUM(U24:U28) -> 33922.48 | W29: =+K29-M29+O29+Q29-S29 -> 0 | Z29: 0
B30: 3 | C30: =+#REF!+1 -> #REF! | D30: POSTES DE MADERA IMPORTADA | Z30: 0
B31: 3.01 | C31: =+C30+1 -> #REF! | D31: Poste de madera importada (Pino Amarillo del Sur) de 12 m, Clase 6 | G31: u | H31: 1703.39 | J31: 9 | K31: =+ROUND($H31*J31,2) -> 15330.51 | L31: =+[191]Metrados!E32 -> 0 | M31: =+ROUND($H31*L31,2) -> 0 | N31: =+IF($L31-$J31>=0,$L31-$J31,0) -> 0 | O31: =+ROUND($H31*N31,2) -> 0 | Q31: =+ROUND($H31*P31,2) -> 0 | R31: =+IF($L31-$J31<=0,-$L31+$J31,0) -> 9 | S31: =+ROUND($H31*R31,2) -> 15330.51 | T31: =+R31 -> 9 | U31: =+ROUND($H31*T31,2) -> 15330.51 | V31: Se vincula con la partida nueva 3.02 y 3.03 | Z31: 0
C32: =+#REF!+1 -> #REF! | F32: =+"SUB-TOTAL "&B30&": " -> SUB-TOTAL 3: | K32: =+SUM(K31:K31) -> 15330.51 | M32: =+SUM(M31:M31) -> 0 | O32: =+SUM(O31:O31) -> 0 | Q32: =+SUM(Q31:Q31) -> 0 | S32: =+SUM(S31:S31) -> 15330.51 | U32: =+SUM(U31:U31) -> 15330.51 | W32: =+K32-M32+O32+Q32-S32 -> 0 | Z32: 0
B33: 3.00A | C33: =+C32+1 -> #REF! | D33: POSTES DE FIBRA DE VIDRIO | Z33: 0
B34: 3.01A | C34: =+#REF!+1 -> #REF! | D34: Poste de PRFV de 12 m/200 daN | G34: u | I34: 1958.01 | K34: =+ROUND($H34*J34,2) -> 0 | L34: =+[191]Metrados!E35 -> 4 | M34: =+ROUND($I34*L34,2) -> 7832.04 | O34: =+ROUND($H34*N34,2) -> 0 | P34: =+L34 -> 4 | Q34: =+ROUND($I34*P34,2) -> 7832.04 | R34: =+IF($L34-$J34<=0,-$L34+$J34,0) -> 0 | S34: =+ROUND($H34*R34,2) -> 0 | U34: =+ROUND($H34*T34,2) -> 0 | Z34: 0
B35: 3.02A | C35: =+C34+1 -> #REF! | D35: Poste de PRFV de 12 m/300 daN | G35: u | I35: 2336.29 | K35: =+ROUND($H35*J35,2) -> 0 | L35: =+[191]Metrados!E36 -> 11 | M35: =+ROUND($I35*L35,2) -> 25699.19 | O35: =+ROUND($H35*N35,2) -> 0 | P35: =+L35 -> 11 | Q35: =+ROUND($I35*P35,2) -> 25699.19 | R35: =+IF($L35-$J35<=0,-$L35+$J35,0) -> 0 | S35: =+ROUND($H35*R35,2) -> 0 | U35: =+ROUND($H35*T35,2) -> 0 | Z35: 0
C36: =+#REF!+1 -> #REF! | F36: =+"SUB-TOTAL "&B33&": " -> SUB-TOTAL 3.00A: | M36: =+SUM(M34:M35) -> 33531.23 | O36: =+SUM(O34:O35) -> 0 | Q36: =+SUM(Q34:Q35) -> 33531.23 | S36: =+SUM(S34:S35) -> 0 | U36: =+SUM(U34:U35) -> 0 | W36: =+K36-M36+O36+Q36-S36 -> 0 | Z36: 0
B37: 4 | C37: =+C32+1 -> #REF! | D37: OTROS MATERIALES DE CONCRETO ARMADO | Z37: 0
B38: 4.01 | C38: =+C37+1 -> #REF! | D38: Cruceta Asimétrica de C.A.V. Za / 1,5 / 0,9 / 250 / 200 / 100 daN (Za / L / L1/ T / F / V) | G38: u | H38: 120.3 | J38: 2 | K38: =+ROUND($H38*J38,2) -> 240.6 | L38: =+[191]Metrados!E39 -> 0 | M38: =+ROUND($H38*L38,2) -> 0 | N38: =+IF($L38-$J38>=0,$L38-$J38,0) -> 0 | O38: =+ROUND($H38*N38,2) -> 0 | Q38: =+ROUND($H38*P38,2) -> 0 | R38: =+IF($L38-$J38<=0,-$L38+$J38,0) -> 2 | S38: =+ROUND($H38*R38,2) -> 240.6 | U38: =+ROUND($H38*T38,2) -> 0 | Z38: -12
B39: 4.02 | C39: =+C38+1 -> #REF! | D39: Ménsula de C.A.V. M / 1,2 / 250 / 150 / 150 daN (M / L / T / F / V) | G39: u | H39: 88.8 | J39: 393 | K39: =+ROUND($H39*J39,2) -> 34898.4 | L39: =+[191]Metrados!E40 -> 84 | M39: =+ROUND($H39*L39,2) -> 7459.2 | N39: =+IF($L39-$J39>=0,$L39-$J39,0) -> 0 | O39: =+ROUND($H39*N39,2) -> 0 | Q39: =+ROUND($H39*P39,2) -> 0 | R39: =+IF($L39-$J39<=0,-$L39+$J39,0) -> 309 | S39: =+ROUND($H39*R39,2) -> 27439.2 | T39: =+N38+P41 -> 122 | U39: =+ROUND($H39*T39,2) -> 10833.6 | V39: Se vincula con el mayor metrado de la partida 4.01 y la partida nueva 4.05 | Z39: 0
B40: 4.03 | C40: =+C39+1 -> #REF! | D40: Ménsula de C.A.V. M / 0,8 / 250 / 150 / 150 daN (M / L / T / F / V) | G40: u | H40: 92.26 | J40: 1 | K40: =+ROUND($H40*J40,2) -> 92.26 | L40: =+[191]Metrados!E41 -> 0 | M40: =+ROUND($H40*L40,2) -> 0 | N40: =+IF($L40-$J40>=0,$L40-$J40,0) -> 0 | O40: =+ROUND($H40*N40,2) -> 0 | Q40: =+ROUND($H40*P40,2) -> 0 | R40: =+IF($L40-$J40<=0,-$L40+$J40,0) -> 1 | S40: =+ROUND($H40*R40,2) -> 92.26 | U40: =+ROUND($H40*T40,2) -> 0 | Z40: 0
B41: 4.05 | C41: =+C40+1 -> #REF! | D41: Cruceta Simétrica de C.A.V. Z / 2,4 / 300 / 300 / 150 daN (Z/ L / T / F / V) | G41: u | I41: 230 | K41: =+ROUND($H41*J41,2) -> 0 | L41: =+[191]Metrados!E42 -> 122 | M41: =+ROUND($I41*L41,2) -> 28060 | O41: =+ROUND($H41*N41,2) -> 0 | P41: =+L41 -> 122 | Q41: =+ROUND($I41*P41,2) -> 28060 | R41: =+IF($L41-$J41<=0,-$L41+$J41,0) -> 0 | S41: =+ROUND($H41*R41,2) -> 0 | U41: =+ROUND($H41*T41,2) -> 0 | Z41: -1
C42: =+#REF!+1 -> #REF! | F42: =+"SUB-TOTAL "&B37&": " -> SUB-TOTAL 4: | K42: =+SUM(K38:K41) -> 35231.26 | M42: =+SUM(M38:M41) -> 35519.2 | O42: =+SUM(O38:O41) -> 0 | Q42: =+SUM(Q38:Q41) -> 28060 | S42: =+SUM(S38:S41) -> 27772.06 | U42: =+SUM(U38:U40) -> 10833.6 | Z42: 0
B43: 5 | C43: =+C42+1 -> #REF! | D43: AISLADORES Y ACCESORIOS | Z43: 0
B44: 5.01 | C44: =+C43+1 -> #REF! | D44: Aislador de Porcelana Tipo Pin, Clase ANSI 56-3 | G44: u | H44: 76.45 | J44: 29 | K44: =+ROUND($H44*J44,2) -> 2217.05 | L44: =+[191]Metrados!E45 -> 24 | M44: =+ROUND($H44*L44,2) -> 1834.8 | N44: =+IF($L44-$J44>=0,$L44-$J44,0) -> 0 | O44: =+ROUND($H44*N44,2) -> 0 | Q44: =+ROUND($H44*P44,2) -> 0 | R44: =+IF($L44-$J44<=0,-$L44+$J44,0) -> 5 | S44: =+ROUND($H44*R44,2) -> 382.25 | T44: =+R44 -> 5 | U44: =+ROUND($H44*T44,2) -> 382.25 | V44: Se vincula con el mayor metrado de la partida 6.01 y 6.02 | Z44: 0
B45: 5.02 | C45: =+C44+1 -> #REF! | D45: Espiga de AºGº de 609 mm longitud, para Cabeza de Poste y Aislador ANSI 56-3 | G45: u | H45: 35.96 | J45: 29 | K45: =+ROUND($H45*J45,2) -> 1042.84 | L45: =+[191]Metrados!E46 -> 24 | M45: =+ROUND($H45*L45,2) -> 863.04 | N45: =+IF($L45-$J45>=0,$L45-$J45,0) -> 0 | O45: =+ROUND($H45*N45,2) -> 0 | Q45: =+ROUND($H45*P45,2) -> 0 | R45: =+IF($L45-$J45<=0,-$L45+$J45,0) -> 5 | S45: =+ROUND($H45*R45,2) -> 179.8 | T45: =+R45 -> 5 | U45: =+ROUND($H45*T45,2) -> 179.8 | V45: Se vincula con el mayor metrado de la partida 6.01 y 6.02 | Z45: 0
B46: 5.03 | C46: =+C44+1 -> #REF! | D46: Conjunto Aislador Line Post Polimérico en Mesula y Cruceta: | G46: u | H46: 209.65 | J46: 369 | K46: =+ROUND($H46*J46,2) -> 77360.85 | L46: =+[191]Metrados!E48 -> 307 | M46: =+ROUND($H46*L46,2) -> 64362.55 | Z46: 0
C47: =+C45+1 -> #REF! | D47: .- Aislador Polimérico de 36 kV, Tipo Line Post con Espárrago de 19 mm Ø, 200 mm longitud (Alternativa a Conjunto Aislador-Espiga en Cruceta) | N47: =+IF($L46-$J46>=0,$L46-$J46,0) -> 0 | O47: =+ROUND($H46*N47,2) -> 0 | Q47: =+ROUND($H46*P47,2) -> 0 | R47: =+IF($L46-$J46<=0,-$L46+$J46,0) -> 62 | S47: =+ROUND($H46*R47,2) -> 12998.3 | T47: =+R47 -> 62 | U47: =+ROUND($H46*T47,2) -> 12998.3 | V47: Se vincula con el mayor metrado de la partida 6.01 y 6.02 | Z47: 0
...

Sheet FP LP
B3: FORMULA POLINÓMICA
C6: PROYECTO :
C7: AMPLIACIÓN DEL SERVICIO DE ENERGÍA ELÉCTRICA EN LA PROVINCIA DEL SANTA Y EN EL DISTRITO DE PAMPAROMAS – DEPARTAMENTO DE ANCASH”
C9: LINEAS PRIMARIAS
C10: PRESUPUESTO BASE S/ | D10: =+'RES-LP'!H18 -> 1465769.8 | K10: =D10=SUM(G13:G27) -> TRUE
B12: Nº | C12: ELEMENTO REPRESENTATIVO | D12: INDICE | E12: SIMBOLO | F12: SIMBOLO MONOMIO | G12: MONTO | H12: INCIDENCIA | I12: % PARCIAL | J12: COEFICIENTE
B13: 1 | C13: POSTES DE MADERA IMPORTADA | D13: 042 | E13: PM | F13: PC | G13: =+'Mtdo-Ppto LP'!M32 -> 0 | H13: =ROUND(G13/$D$10,3) -> 0 | I13: =ROUND(G13/SUM($G$13:$G$16),4) -> 0 | J13: =ROUND(SUM(H13:H16),3) -> 0.176
C14: CRUCETAS DE MADERA | D14: 043 | E14: CM | G14: =+'Mtdo-Ppto LP'!M22 -> 3578 | H14: =ROUND(G14/$D$10,3) -> 0.002 | I14: =ROUND(G14/SUM($G$13:$G$16),4) -> 0.0139
C15: POSTES DE CONCRETO | D15: 062 | E15: PC | G15: =+'Mtdo-Ppto LP'!M29+'Mtdo-Ppto LP'!M36 -> 218234.24 | H15: =ROUND(G15/$D$10,3-0.1) -> 0.15 | I15: =ROUND(G15/SUM($G$13:$G$16),4) -> 0.8481
C16: OTROS MATERIALES DE CONCRETO ARMADO | D16: 062 | E16: CC | G16: =+'Mtdo-Ppto LP'!M42 -> 35519.2 | H16: =ROUND(G16/$D$10,3) -> 0.024 | I16: =ROUND(G16/SUM($G$13:$G$16),4) -> 0.138
B17: 2 | C17: CONDUCTORES DE AAAC Y ACCESORIOS | D17: 030 | E17: DI | F17: DI | G17: =+'Mtdo-Ppto LP'!M56+'Mtdo-Ppto LP'!M73 -> 133692.72 | H17: =ROUND(G17/$D$10,3) -> 0.091 | I17: =ROUND(G17/SUM($G$17:$G$18),4) -> 0.9068 | J17: =ROUND(SUM(H17:H18),3) -> 0.1
C18: EQUIPOS DE PROTECCIÓN | D18: 011 | E18: AE1 | G18: =+'Mtdo-Ppto LP'!M136 -> 13745.66 | H18: =ROUND(G18/$D$10,3) -> 0.009 | I18: =ROUND(G18/SUM($G$17:$G$18),4) -> 0.0932
B19: 3 | C19: AISLADORES Y ACCESORIOS | D19: 011 | E19: AE2 | F19: AE2 | G19: =+'Mtdo-Ppto LP'!M48+'Mtdo-Ppto LP'!M52 -> 93781.25 | H19: =ROUND(G19/$D$10,3) -> 0.064 | I19: =ROUND(G19/SUM($G$19:$G$24),4) -> 0.3362 | J19: =ROUND(SUM(H19:H24),3) -> 0.191
C20: RETENIDAS Y ANCLAJES | D20: 002 | E20: FE | G20: =+'Mtdo-Ppto LP'!M117 -> 31585.24 | H20: =ROUND(G20/$D$10,3) -> 0.022 | I20: =ROUND(G20/SUM($G$19:$G$24),4) -> 0.1132
C21: FERRETERIA PARA POSTES Y CRUCETAS | D21: 002 | E21: FP | G21: =+'Mtdo-Ppto LP'!M101 -> 15148.54 | H21: =ROUND(G21/$D$10,3) -> 0.01 | I21: =ROUND(G21/SUM($G$19:$G$24),4) -> 0.0543
C22: CONDUCTOR DE COBRE | D22: 006 | E22: CU | G22: =+'Mtdo-Ppto LP'!M76 -> 40485.12 | H22: =ROUND(G22/$D$10,3) -> 0.028 | I22: =ROUND(G22/SUM($G$19:$G$24),4) -> 0.1451
C23: MATERIAL PARA PUESTA A TIERRA | D23: 006 | E23: PT | G23: =+'Mtdo-Ppto LP'!M129 -> 11437.24 | H23: =ROUND(G23/$D$10,3) -> 0.008 | I23: =ROUND(G23/SUM($G$19:$G$24),4) -> 0.041
C24: TRAMO SUBTERRANEO | D24: 006 | E24: TS | G24: =+'Mtdo-Ppto LP'!M153 -> 86522.98 | H24: =ROUND(G24/$D$10,3) -> 0.059 | I24: =ROUND(G24/SUM($G$19:$G$24),4) -> 0.3102
B25: 4 | C25: MONTAJE ELECTROMECANICO | D25: 047 | E25: J | F25: J | G25: =+'Mtdo-Ppto LP'!M307 -> 552762.73 | H25: =ROUND(G25/$D$10,3) -> 0.377 | I25: =ROUND(G25/($G$25+$G$26),4) -> 0.9032 | J25: =ROUND(SUM(H25:H26),3) -> 0.417
C26: TRANSPORTE | D26: 032 | E26: FT | G26: =+'Mtdo-Ppto LP'!M446 -> 59272.43 | H26: =ROUND(G26/$D$10,3) -> 0.04 | I26: =ROUND(G26/($G$25+$G$26),4) -> 0.0968
B27: 5 | C27: GASTOS GENERALES Y UTILIDADES | D27: 039 | E27: GG | F27: GU | G27: =+'RES-LP'!H16+'RES-LP'!H17 -> 170004.41 | H27: =ROUND(G27/$D$10,3) -> 0.116 | I27: =+G27/G27 -> 1 | J27: =ROUND(SUM(H27),3) -> 0.116
B29: K= | C29: =J13&" PCr/PCo + "&J17&" DIr/DIo + "&J19&" AE2r/AE2o+ "&J25&" Jr/Jo + "&J27&" GUr/GUo" -> 0.176 PCr/PCo + 0.1 DIr/DIo + 0.191 AE2r/AE2o+ 0.417 Jr/Jo + 0.116 GUr/GUo
B32: NOTAS:
B34: 1.- | C34: En la fórmula los sub-indices "o" de cada símbolo corresponden al indice de precios según (CREPCO) a la
C35: fecha de Elaboración del Presupuesto (Presupuesto Base) y los sub-indices "r" al indice de precios al
C36: momento de reajuste o fecha de valorización
B37: 2.- | C37: En el caso de los monomios compuestos por varios indices se ha considerado para efecto de denominación
C38: el símbolo que tiene mayor porcentaje de incidencia
B39: 3.- | C39: En caso de cambios en el suministro se deberá actualizar la formula polinómica.
H46: =+IF(SUM(H13:H27)=1,"OK","X") -> OK | I46: =+IF(SUM(I13:I27)=5,"OK","X") -> OK | J46: =+IF(SUM(J13:J27)=1,"OK","X") -> OK

Sheet RES-RP
B2: RESUMEN PRESUPUESTO DE OBRA
B4: AMPLIACIÓN DEL SERVICIO DE ENERGÍA ELÉCTRICA EN LA PROVINCIA DEL SANTA Y EN EL DISTRITO DE PAMPAROMAS – DEPARTAMENTO DE ANCASH
B6: UBICACIÓN | C6: : | D6: ANCASH
B7: SECCIÓN II | C7: : | D7: REDES PRIMARIAS | H7: Fecha: 30-May-2022
H8: T.C. (S/./US$): 3,642
B9: ITEM | C9: DESCRIPCION | G9: PRESUPUESTO CONTRATO | H9: PRESUPUESTO ESTUDIO DEFINIVO | I9: ADICIONALES | K9: DEDUCTIVOS
I10: MAYORES METRADOS | J10: PARTIDAS NUEVAS | K10: MENOR METRADO | L10: DEDUCTIVO VINCULANTE
B12: A | D12: SUMINISTRO DE MATERIALES | G12: =+'Mtdo-Ppto RP'!K136 -> 202256.75 | H12: =+'Mtdo-Ppto RP'!M136 -> 223205.59 | I12: =+'Mtdo-Ppto RP'!O136 -> 17268.84 | J12: =+'Mtdo-Ppto RP'!Q136 -> 55879.66 | K12: =+'Mtdo-Ppto RP'!S136 -> 52199.66 | L12: =+'Mtdo-Ppto RP'!U136 -> 29858.15
B13: B | D13: MONTAJE ELECTROMECANICO | G13: =+'Mtdo-Ppto RP'!K235 -> 85459.52 | H13: =+'Mtdo-Ppto RP'!M235 -> 84855.49 | I13: =+'Mtdo-Ppto RP'!O235 -> 13835.11 | J13: =+'Mtdo-Ppto RP'!Q235 -> 4104.22 | K13: =+'Mtdo-Ppto RP'!S235 -> 18543.39 | L13: =+'Mtdo-Ppto RP'!U235 -> 8920.98
B14: C | D14: TRANSPORTE DE MATERIALES | G14: =+'Mtdo-Ppto RP'!K356 -> 16212.19 | H14: =+'Mtdo-Ppto RP'!M356 -> 19115.26 | I14: =+'Mtdo-Ppto RP'!O356 -> 2169.3 | J14: =+'Mtdo-Ppto RP'!Q356 -> 4146.01 | K14: =+'Mtdo-Ppto RP'!S356 -> 3412.24 | L14: =+'Mtdo-Ppto RP'!U356 -> 2082.23
B15: D | D15: TOTAL COSTO DIRECTO | G15: =+SUM(G12:G14) -> 303928.46 | H15: =+SUM(H12:H14) -> 327176.34 | I15: =+SUM(I12:I14) -> 33273.25 | J15: =+SUM(J12:J14) -> 64129.89 | K15: =+SUM(K12:K14) -> 74155.29 | L15: =+SUM(L12:L14) -> 40861.36
B16: E | D16: GASTOS GENERALES (10.12%) | G16: =ROUND(G15*10.12%,2) -> 30757.56 | H16: =ROUND(H15*10.12%,2) -> 33110.25 | I16: =ROUND(I15*10.12%,2) -> 3367.25 | J16: =ROUND(J15*10.12%,2) -> 6489.94 | K16: =ROUND(K15*10.12%,2) -> 7504.52 | L16: =ROUND(L15*10.12%,2) -> 4135.17
B17: F | D17: UTILIDADES (3%) | G17: =ROUND(G15*3%,2) -> 9117.85 | H17: =ROUND(H15*3%,2) -> 9815.29 | I17: =ROUND(I15*3%,2) -> 998.2 | J17: =ROUND(J15*3%,2) -> 1923.9 | K17: =ROUND(K15*3%,2) -> 2224.66 | L17: =ROUND(L15*3%,2) -> 1225.84
B18: G | D18: COSTO TOTAL S/. (No incluye I.G.V.) | G18: =G17+G16+G15 -> 343803.87 | H18: =H17+H16+H15 -> 370101.88 | I18: =I17+I16+I15 -> 37638.7 | J18: =J17+J16+J15 -> 72543.73 | K18: =K17+K16+K15 -> 83884.47 | L18: =L17+L16+L15 -> 46222.37 | M18: =+H18-G18 -> 26298.01
D20: INCIDENCIA % | G20: =+G18/G18 -> 1 | H20: =+H18/$G$18 -> 1.0764913 | I20: =+I18/$G$18 -> 0.10947724 | J20: =+J18/$G$18 -> 0.21100324 | K20: =+K18/$G$18 -> 0.24398931 | L20: =+L18/$G$18 -> 0.13444401
H22: =+H18-I18+K18-J18 -> 343803.92 | K22: =+G12-H12+I12+J12-K12 -> 0
H23: =+G18-H22 -> -0.05 | K23: =+G13-H13+I13+J13-K13 -> -0.03
K24: =+G14-H14+I14+J14-K14 -> 0
K25: =+G15-H15+I15+J15-K15 -> -0.03

Sheet Mtdo-Ppto RP
B6: PRESUPUESTO DE OBRA
B8: OBRA | E8: : | F8: AMPLIACIÓN DEL SERVICIO DE ENERGÍA ELÉCTRICA EN LA PROVINCIA DEL SANTA Y EN EL DISTRITO DE PAMPAROMAS – DEPARTAMENTO DE ANCASH
B9: DEPARTAMENTO | E9: : | F9: ANCASH
B10: SECCIÓN II | E10: : | F10: REDES PRIMARIAS
B12: ITEM | C12: DESCRIPCIÓN DE PARTIDAS | G12: UNID. | H12: Precio de Contrato | I12: Precio Pactado | J12: CONTRACTUAL | L12: ESTUDIO DEFINITIVO | N12: ADICIONALES | R12: DEDUCTIVOS | V12: OBSERVACIÓN
J13: Metrado | K13: TOTAL | L13: Metrado | M13: TOTAL | N13: MAYORES METRADOS | P13: PARTIDAS NUEVAS | R13: MENORES METRADOS | T13: DEDUCTIVO VINCULANTE
N14: Metrado | O14: TOTAL | P14: Metrado | Q14: TOTAL | R14: Metrado | S14: TOTAL | T14: Metrado | U14: TOTAL
H15: Unitario | I15: Unitario | J15: Cantidad | K15: S/. | L15: Cantidad | M15: S/. | N15: Cantidad | O15: S/. | P15: Cantidad | Q15: S/. | R15: Cantidad | S15: S/. | T15: Cantidad | U15: S/.
B16: A | D16: SUMINISTRO DE MATERIALES
B17: 1 | C17: 3 | D17: CRUCETAS DE MADERA DE PROCEDENCIA NACIONAL
B18: =+B17+0.01 -> 1.01 | C18: =+C17+1 -> 4 | D18: Cruceta de madera tratada de 90 mm x 115 mm x 1,20 m | G18: u | H18: 105 | J18: 13 | K18: =+ROUND($H18*J18,2) -> 1365 | L18: =+[192]Metrado!E13 -> 10 | M18: =+ROUND($H18*L18,2) -> 1050 | N18: =+IF($L18-$J18>=0,$L18-$J18,0) -> 0 | O18: =+ROUND($H18*N18,2) -> 0 | Q18: =+ROUND($H18*P18,2) -> 0 | R18: =+IF($L18-$J18<=0,-$L18+$J18,0) -> 3 | S18: =+ROUND($H18*R18,2) -> 315 | T18: =+R18 -> 3 | U18: =+ROUND($H18*T18,2) -> 315 | V18: Se vincula con la partida nueva 1.03 | Y18: 0
B19: =+B18+0.01 -> 1.02 | C19: =+C18+1 -> 5 | D19: Listón de madera tratada 50 x 19 mm sección, 2,7 m longitud (incluye clavos de fijación) | G19: u | H19: 27.35 | J19: 2 | K19: =+ROUND($H19*J19,2) -> 54.7 | L19: =+[192]Metrado!E14 -> 0 | M19: =+ROUND($H19*L19,2) -> 0 | N19: =+IF($L19-$J19>=0,$L19-$J19,0) -> 0 | O19: =+ROUND($H19*N19,2) -> 0 | Q19: =+ROUND($H19*P19,2) -> 0 | R19: =+IF($L19-$J19<=0,-$L19+$J19,0) -> 2 | S19: =+ROUND($H19*R19,2) -> 54.7 | U19: =+ROUND($H19*T19,2) -> 0 | Y19: 0
B20: 1.03 | C20: =+C19+1 -> 6 | D20: Cruceta de madera tratada de 90 mm x 115 mm x 2,00 m | G20: u | I20: =+'Mtdo-Ppto LP'!H19 -> 178 | K20: =+ROUND($H20*J20,2) -> 0 | L20: =+[192]Metrado!E15 -> 2 | M20: =+ROUND($I20*L20,2) -> 356 | O20: =+ROUND($H20*N20,2) -> 0 | P20: =+L20 -> 2 | Q20: =+ROUND($I20*P20,2) -> 356 | S20: =+ROUND($H20*R20,2) -> 0 | U20: =+ROUND($H20*T20,2) -> 0 | Y20: 0
B21: 1.04 | C21: =+C20+1 -> 7 | D21: Cruceta de madera tratada de 90 mm x 115 mm x 2,40 m | G21: u | I21: =+'Mtdo-Ppto LP'!H20 -> 205 | K21: =+ROUND($H21*J21,2) -> 0 | L21: =+[192]Metrado!E16 -> 3 | M21: =+ROUND($I21*L21,2) -> 615 | O21: =+ROUND($H21*N21,2) -> 0 | P21: =+L21 -> 3 | Q21: =+ROUND($I21*P21,2) -> 615 | S21: =+ROUND($H21*R21,2) -> 0 | U21: =+ROUND($H21*T21,2) -> 0 | Y21: 0
C22: =+C19+1 -> 6 | F22: =+"SUB-TOTAL "&B17&": " -> SUB-TOTAL 1: | K22: =+SUM(K18:K21) -> 1419.7 | M22: =+SUM(M18:M21) -> 2021 | O22: =+SUM(O18:O21) -> 0 | Q22: =+SUM(Q18:Q21) -> 971 | S22: =+SUM(S18:S21) -> 369.7 | U22: =+SUM(U18:U21) -> 315 | W22: =+K22-M22+O22+Q22-S22 -> 0 | Y22: 0
B23: =1+B17 -> 2 | C23: =+C22+1 -> 7 | D23: POSTES DE CONCRETO ARMADO CENTRIFUGADO | Y23: 0
B24: 2.01 | C24: =+C20+1 -> 7 | D24: Poste de C.A.C. de 12 m/200 daN (Incluye perilla) | G24: u | H24: 837.45 | J24: 3 | K24: =+ROUND($H24*J24,2) -> 2512.35 | L24: =+[192]Metrado!E19 -> 1 | M24: =+ROUND($H24*L24,2) -> 837.45 | N24: =+IF($L24-$J24>=0,$L24-$J24,0) -> 0 | O24: =+ROUND($H24*N24,2) -> 0 | Q24: =+ROUND($H24*P24,2) -> 0 | R24: =+IF($L24-$J24<=0,-$L24+$J24,0) -> 2 | S24: =+ROUND($H24*R24,2) -> 1674.9 | T24: =+R24 -> 2 | U24: =+ROUND($H24*T24,2) -> 1674.9 | V24: Se vincula con la partida nueva 3.02 | Y24: 0
B25: 2.02 | C25: =+C21+1 -> 8 | D25: Poste de C.A.C. de 12 m/300 daN (Incluye perilla) | G25: u | H25: 923.47 | J25: 11 | K25: =+ROUND($H25*J25,2) -> 10158.17 | L25: =+[192]Metrado!E20 -> 13 | M25: =+ROUND($H25*L25,2) -> 12005.11 | N25: =+IF($L25-$J25>=0,$L25-$J25,0) -> 2 | O25: =+ROUND($H25*N25,2) -> 1846.94 | Q25: =+ROUND($H25*P25,2) -> 0 | R25: =+IF($L25-$J25<=0,-$L25+$J25,0) -> 0 | S25: =+ROUND($H25*R25,2) -> 0 | U25: =+ROUND($H25*T25,2) -> 0 | Y25: 0
B26: 2.03 | C26: =+C22+1 -> 7 | D26: Poste de C.A.C. de 13 m/300 daN (Incluye perilla) | G26: u | H26: 1085.14 | J26: 10 | K26: =+ROUND($H26*J26,2) -> 10851.4 | L26: =+[192]Metrado!E21 -> 11 | M26: =+ROUND($H26*L26,2) -> 11936.54 | N26: =+IF($L26-$J26>=0,$L26-$J26,0) -> 1 | O26: =+ROUND($H26*N26,2) -> 1085.14 | Q26: =+ROUND($H26*P26,2) -> 0 | R26: =+IF($L26-$J26<=0,-$L26+$J26,0) -> 0 | S26: =+ROUND($H26*R26,2) -> 0 | U26: =+ROUND($H26*T26,2) -> 0 | Y26: 0
B27: 2.04 | C27: =+C23+1 -> 8 | D27: Poste de C.A.C. de 13 m/400 daN (Incluye perilla) | G27: u | H27: 1207.94 | J27: 10 | K27: =+ROUND($H27*J27,2) -> 12079.4 | L27: =+[192]Metrado!E22 -> 14 | M27: =+ROUND($H27*L27,2) -> 16911.16 | N27: =+IF($L27-$J27>=0,$L27-$J27,0) -> 4 | O27: =+ROUND($H27*N27,2) -> 4831.76 | Q27: =+ROUND($H27*P27,2) -> 0 | R27: =+IF($L27-$J27<=0,-$L27+$J27,0) -> 0 | S27: =+ROUND($H27*R27,2) -> 0 | U27: =+ROUND($H27*T27,2) -> 0 | Y27: 0
C28: =+C27+1 -> 9 | F28: =+"SUB-TOTAL "&B23&": " -> SUB-TOTAL 2: | K28: =+SUM(K24:K27) -> 35601.32 | M28: =+SUM(M24:M27) -> 41690.26 | O28: =+SUM(O24:O27) -> 7763.84 | Q28: =+SUM(Q24:Q27) -> 0 | S28: =+SUM(S24:S27) -> 1674.9 | U28: =+SUM(U24:U27) -> 1674.9 | W28: =+K28-M28+O28+Q28-S28 -> -2.2737368e-12 | Y28: 0
B29: 3 | C29: =+C28+1 -> 10 | D29: POSTES DE MADERA IMPORTADA | Y29: 0
B30: 3.01 | C30: =+#REF!+1 -> #REF! | D30: Poste de madera importada (Pino Amarillo del Sur) de 12 m, Clase 5 | G30: u | H30: 1864.52 | J30: 2 | K30: =+ROUND($H30*J30,2) -> 3729.04 | L30: =+[192]Metrado!E25 -> 0 | M30: =+ROUND($H30*L30,2) -> 0 | N30: =+IF($L30-$J30>=0,$L30-$J30,0) -> 0 | O30: =+ROUND($H30*N30,2) -> 0 | Q30: =+ROUND($H30*P30,2) -> 0 | R30: =+IF($L30-$J30<=0,-$L30+$J30,0) -> 2 | S30: =+ROUND($H30*R30,2) -> 3729.04 | T30: =+R30 -> 2 | U30: =+ROUND($H30*T30,2) -> 3729.04 | V30: Se vincula con la partida nueva 3.02 | Y30: 0
C31: =+#REF!+1 -> #REF! | F31: =+"SUB-TOTAL "&B29&": " -> SUB-TOTAL 3: | K31: =+SUM(K30:K30) -> 3729.04 | M31: =+SUM(M30:M30) -> 0 | O31: =+SUM(O30:O30) -> 0 | Q31: =+SUM(Q30:Q30) -> 0 | S31: =+SUM(S30:S30) -> 3729.04 | U31: =+SUM(U30:U30) -> 3729.04 | Y31: 0
B32: 3.00A | C32: =+C31+1 -> #REF! | D32: POSTES DE FIBRA DE VIDRIO | Y32: 0
B33: 3.01A | C33: =+C32+1 -> #REF! | D33: Poste de PRFV de 12 m/200 daN | I33: 1958.01 | K33: =+ROUND($H33*J33,2) -> 0 | L33: =+[192]Metrado!E28 -> 0 | M33: =+ROUND($I33*L33,2) -> 0 | O33: =+ROUND($H33*N33,2) -> 0 | P33: =+L33 -> 0 | Q33: =+ROUND($I33*P33,2) -> 0 | S33: =+ROUND($H33*R33,2) -> 0 | U33: =+ROUND($H33*T33,2) -> 0 | Y33: 0
B34: 3.02A | C34: =+C33+1 -> #REF! | D34: Poste de PRFV de 12 m/300 daN | I34: 2336.29 | K34: =+ROUND($H34*J34,2) -> 0 | L34: =+[192]Metrado!E29 -> 5 | M34: =+ROUND($I34*L34,2) -> 11681.45 | O34: =+ROUND($H34*N34,2) -> 0 | P34: =+L34 -> 5 | Q34: =+ROUND($I34*P34,2) -> 11681.45 | S34: =+ROUND($H34*R34,2) -> 0 | U34: =+ROUND($H34*T34,2) -> 0 | Y34: 0
C35: =+C34+1 -> #REF! | F35: =+"SUB-TOTAL "&B32&": " -> SUB-TOTAL 3.00A: | M35: =+SUM(M33:M34) -> 11681.45 | O35: =+SUM(O33:O34) -> 0 | Q35: =+SUM(Q33:Q34) -> 11681.45 | S35: =+SUM(S33:S34) -> 0 | U35: =+SUM(U33:U34) -> 0 | Y35: 0
B36: =+B29+1 -> 4 | C36: =+C31+1 -> #REF! | D36: OTROS MATERIALES DE CONCRETO ARMADO | Y36: 0
B37: 4.01 | C37: =+C36+1 -> #REF! | D37: Cruceta Asimétrica de C.A.V. Za / 1,5 / 0,9 / 250 / 200 / 100 daN (Za / L / L1/ T / F / V) | G37: u | H37: 120.3 | J37: 5 | K37: =+ROUND($H37*J37,2) -> 601.5 | L37: =+[192]Metrado!E32 -> 5 | M37: =+ROUND($H37*L37,2) -> 601.5 | N37: =+IF($L37-$J37>=0,$L37-$J37,0) -> 0 | O37: =+ROUND($H37*N37,2) -> 0 | Q37: =+ROUND($H37*P37,2) -> 0 | R37: =+IF($L37-$J37<=0,-$L37+$J37,0) -> 0 | S37: =+ROUND($H37*R37,2) -> 0 | U37: =+ROUND($H37*T37,2) -> 0 | Y37: 0
B38: 4.02 | C38: =+C37+1 -> #REF! | D38: Ménsula de C.A.V. M / 1,2 / 250 / 150 / 150 daN (M / L / T / F / V) | G38: u | H38: 88.8 | J38: 40 | K38: =+ROUND($H38*J38,2) -> 3552 | L38: =+[192]Metrado!E33 -> 60 | M38: =+ROUND($H38*L38,2) -> 5328 | N38: =+IF($L38-$J38>=0,$L38-$J38,0) -> 20 | O38: =+ROUND($H38*N38,2) -> 1776 | Q38: =+ROUND($H38*P38,2) -> 0 | R38: =+IF($L38-$J38<=0,-$L38+$J38,0) -> 0 | S38: =+ROUND($H38*R38,2) -> 0 | U38: =+ROUND($H38*T38,2) -> 0 | Y38: 0
B39: 4.03 | C39: =+C38+1 -> #REF! | D39: Plataforma de Concreto Soporte de Transformador de 2,20 m, carga de trabajo de 500 daN | G39: u | H39: 620 | J39: 5 | K39: =+ROUND($H39*J39,2) -> 3100 | L39: =+[192]Metrado!E34 -> 5 | M39: =+ROUND($H39*L39,2) -> 3100 | N39: =+IF($L39-$J39>=0,$L39-$J39,0) -> 0 | O39: =+ROUND($H39*N39,2) -> 0 | Q39: =+ROUND($H39*P39,2) -> 0 | R39: =+IF($L39-$J39<=0,-$L39+$J39,0) -> 0 | S39: =+ROUND($H39*R39,2) -> 0 | U39: =+ROUND($H39*T39,2) -> 0 | Y39: 0
C40: =+#REF!+1 -> #REF! | F40: =+"SUB-TOTAL "&B36&": " -> SUB-TOTAL 4: | K40: =+SUM(K37:K39) -> 7253.5 | M40: =+SUM(M37:M39) -> 9029.5 | O40: =+SUM(O37:O39) -> 1776 | Q40: =+SUM(Q37:Q39) -> 0 | S40: =+SUM(S37:S39) -> 0 | U40: =+SUM(U37:U39) -> 0 | Y40: 0
B41: =+B36+1 -> 5 | C41: =+C40+1 -> #REF! | D41: AISLADORES Y ACCESORIOS | Y41: 0
B42: 5.01 | C42: =+C41+1 -> #REF! | D42: Aislador de Porcelana Tipo Pin, Clase ANSI 56-3 | G42: u | H42: 76.45 | J42: 16 | K42: =+ROUND($H42*J42,2) -> 1223.2 | L42: =+[192]Metrado!E37 -> 25 | M42: =+ROUND($H42*L42,2) -> 1911.25 | N42: =+IF($L42-$J42>=0,$L42-$J42,0) -> 9 | O42: =+ROUND($H42*N42,2) -> 688.05 | Q42: =+ROUND($H42*P42,2) -> 0 | R42: =+IF($L42-$J42<=0,-$L42+$J42,0) -> 0 | S42: =+ROUND($H42*R42,2) -> 0 | U42: =+ROUND($H42*T42,2) -> 0 | Y42: 0
B43: 5.02 | C43: =+C42+1 -> #REF! | D43: Espiga de AºGº de 609 mm longitud, para Cabeza de Poste y Aislador ANSI 56-3 | G43: u | H43: 35.96 | J43: 16 | K43: =+ROUND($H43*J43,2) -> 575.36 | L43: =+[192]Metrado!E38 -> 17 | M43: =+ROUND($H43*L43,2) -> 611.32 | N43: =+IF($L43-$J43>=0,$L43-$J43,0) -> 1 | O43: =+ROUND($H43*N43,2) -> 35.96 | Q43: =+ROUND($H43*P43,2) -> 0 | R43: =+IF($L43-$J43<=0,-$L43+$J43,0) -> 0 | S43: =+ROUND($H43*R43,2) -> 0 | U43: =+ROUND($H43*T43,2) -> 0 | Y43: 0
B44: 5.03 | C44: =+C43+1 -> #REF! | D44: Conjunto Aislador Line Post Polimérico en Cruceta: | G44: u | H44: 209.65 | J44: 40 | K44: =+ROUND($H44*J44,2) -> 8386 | L44: =+[192]Metrado!E40 -> 50 | M44: =+ROUND($H44*L44,2) -> 10482.5 | N44: =+IF($L44-$J44>=0,$L44-$J44,0) -> 10 | O44: =+ROUND($H44*N44,2) -> 2096.5 | Q44: =+ROUND($H44*P45,2) -> 0 | R44: =+IF($L44-$J44<=0,-$L44+$J44,0) -> 0 | S44: =+ROUND($H44*R44,2) -> 0 | U44: =+ROUND($H44*T45,2) -> 0 | Y44: 0
C45: =+C44+1 -> #REF! | D45: - Aislador Polimérico de 36 kV, Tipo Line Post con Espárrago de 19 mm Ø, 200 mm longitud (Alternativa a Conjunto Aislador-Espiga en Cruceta) | Y45: 0
B46: 5.04 | C46: =+#REF!+1 -> #REF! | D46: Espiga para cruceta, forjada de 381mm LONG. Para aislador Tipo Pin, Clase ANSI 56-3 | G46: u | I46: 49.41 | K46: =+ROUND($H46*J46,2) -> 0 | L46: =+[192]Metrado!E41 -> 8 | M46: =+ROUND($I46*L46,2) -> 395.28 | O46: =+ROUND($H46*N46,2) -> 0 | P46: =+L46 -> 8 | Q46: =+ROUND($I46*P46,2) -> 395.28 | S46: =+ROUND($H46*R46,2) -> 0 | U46: =+ROUND($H46*T46,2) -> 0 | Y46: 0
C47: =+#REF!+1 -> #REF! | F47: =+"SUB-TOTAL "&B41&": " -> SUB-TOTAL 5: | K47: =+SUM(K42:K46) -> 10184.56 | M47: =+SUM(M42:M46) -> 13400.35 | O47: =+SUM(O42:O46) -> 2820.51 | Q47: =+SUM(Q42:Q46) -> 395.28 | S47: =+SUM(S42:S46) -> 0 | U47: =+SUM(U42:U46) -> 0 | Y47: 0
...

Sheet FP RP
B3: FORMULA POLINÓMICA
C6: PROYECTO :
C7: AMPLIACIÓN DEL SERVICIO DE ENERGÍA ELÉCTRICA EN LA PROVINCIA DEL SANTA Y EN EL DISTRITO DE PAMPAROMAS – DEPARTAMENTO DE ANCASH”
C9: REDES PRIMARIAS
C10: PRESUPUESTO BASE S/ | D10: =+'RES-RP'!H18 -> 370101.88 | L10: =D10=SUM(G13:G28) -> TRUE
B12: Nº | C12: ELEMENTO REPRESENTATIVO | D12: INDICE | E12: SIMBOLO | F12: SIMBOLO MONOMIO | G12: MONTO | H12: INCIDENCIA | I12: % PARCIAL | J12: COEFICIENTE
B13: 1 | C13: POSTES DE MADERA IMPORTADA | D13: 042 | E13: PM | F13: PC | G13: =+'Mtdo-Ppto RP'!M31 -> 0 | H13: =ROUND(G13/$D$10,3) -> 0 | I13: =ROUND(G13/SUM($G$13:$G$20),4) -> 0 | J13: =ROUND(SUM(H13:H20),3) -> 0.247
C14: CRUCETAS DE MADERA | D14: 043 | E14: CM | G14: =+'Mtdo-Ppto RP'!M22 -> 2021 | H14: =ROUND(G14/$D$10,3) -> 0.005 | I14: =ROUND(G14/SUM($G$13:$G$20),4) -> 0.022
C15: POSTES DE CONCRETO | D15: 062 | E15: PC | G15: =+'Mtdo-Ppto RP'!M28+'Mtdo-Ppto RP'!M35 -> 53371.71 | H15: =ROUND(G15/$D$10,3) -> 0.144 | I15: =ROUND(G15/SUM($G$13:$G$20),4)+0.0001 -> 0.5812
C16: OTROS MATERIALES DE CONCRETO ARMADO | D16: 062 | E16: CC | G16: =+'Mtdo-Ppto RP'!M40 -> 9029.5 | H16: =ROUND(G16/$D$10,3) -> 0.024 | I16: =ROUND(G16/SUM($G$13:$G$20),4) -> 0.0983
C17: FERRETERIA PARA POSTES Y CRUCETAS | D17: 002 | E17: FP | G17: =+'Mtdo-Ppto RP'!M85 -> 3735.48 | H17: =ROUND(G17/$D$10,3) -> 0.01 | I17: =ROUND(G17/SUM($G$13:$G$20),4) -> 0.0407
C18: RETENIDAS Y ANCLAJES | D18: 002 | E18: FE | G18: =+'Mtdo-Ppto RP'!M99 -> 6000.31 | H18: =ROUND(G18/$D$10,3) -> 0.016 | I18: =ROUND(G18/SUM($G$13:$G$20),4) -> 0.0653
C19: CONDUCTOR DE COBRE Y ACCESORIOS | D19: 006 | E19: CU | G19: =+'Mtdo-Ppto RP'!M65 -> 5523.2 | H19: =ROUND(G19/$D$10,3) -> 0.015 | I19: =ROUND(G19/SUM($G$13:$G$20),4) -> 0.0601
C20: MATERIAL PARA PUESTA A TIERRA | D20: 006 | E20: PT | G20: =+'Mtdo-Ppto RP'!M111 -> 12159.04 | H20: =ROUND(G20/$D$10,3+0.1) -> 0.033 | I20: =ROUND(G20/SUM($G$13:$G$20),4) -> 0.1324
B21: 2 | C21: EQUIPOS DE PROTECCIÓN | D21: 011 | E21: AE1 | F21: AE1 | G21: =+'Mtdo-Ppto RP'!M117 -> 14296.26 | H21: =ROUND(G21/$D$10,3) -> 0.039 | I21: =ROUND(G21/SUM($G$21:$G$24),4) -> 0.3262 | J21: =ROUND(SUM(H21:H24),3) -> 0.119
C22: AISLADORES Y ACCESORIOS | D22: 011 | E22: AE2 | G22: =+'Mtdo-Ppto RP'!M47+'Mtdo-Ppto RP'!M51 -> 15572.01 | H22: =ROUND(G22/$D$10,3) -> 0.042 | I22: =ROUND(G22/SUM($G$21:$G$24),4)+0.0001 -> 0.3554
C23: CABLES DE ENERGÍA | D23: 019 | E23: NY | G23: =+'Mtdo-Ppto RP'!M135 -> 3267.22 | H23: =ROUND(G23/$D$10,3) -> 0.009 | I23: =ROUND(G23/SUM($G$21:$G$24),4) -> 0.0745
C24: CONDUCTORES DE AAAC Y ACCESORIOS | D24: 030 | E24: DI | G24: =+'Mtdo-Ppto RP'!M54+'Mtdo-Ppto RP'!M62 -> 10691.09 | H24: =ROUND(G24/$D$10,3) -> 0.029 | I24: =ROUND(G24/SUM($G$21:$G$24),4) -> 0.2439
B25: 3 | C25: TRANSFORMADORES DE DISTRIBUCIÓN Y TABLEROS | D25: 048 | E25: EN | F25: EN | G25: =+'Mtdo-Ppto RP'!M124+'Mtdo-Ppto RP'!M130 -> 87538.77 | H25: =ROUND(G25/$D$10,3) -> 0.237 | I25: =ROUND(G25/SUM($G$25:$G$25),4) -> 1 | J25: =ROUND(SUM(H25),3) -> 0.237
B26: 4 | C26: MONTAJE ELECTROMECANICO | D26: 047 | E26: J | F26: J | G26: =+'Mtdo-Ppto RP'!M235 -> 84855.49 | H26: =ROUND(G26/$D$10,3) -> 0.229 | I26: =ROUND(G26/($G$26+$G$27),4) -> 0.8161 | J26: =ROUND(SUM(H26:H27),3) -> 0.281
C27: TRANSPORTE | D27: 032 | E27: FT | G27: =+'Mtdo-Ppto RP'!M356 -> 19115.26 | H27: =ROUND(G27/$D$10,3) -> 0.052 | I27: =ROUND(G27/($G$26+$G$27),4) -> 0.1839
B28: 5 | C28: GASTOS GENERALES Y UTILIDADES | D28: 039 | E28: GG | F28: GG | G28: =+'RES-RP'!H16+'RES-RP'!H17 -> 42925.54 | H28: =ROUND(G28/$D$10,3) -> 0.116 | I28: =+G28/G28 -> 1 | J28: =ROUND(SUM(H28),3) -> 0.116
B30: K= | C30: =J13&" PCr/PCo + "&J21&" AE1r/AE1o + "&J25&" ENr/ENo+ "&J26&" Jr/Jo + "&J28&" GGr/GGo" -> 0.247 PCr/PCo + 0.119 AE1r/AE1o + 0.237 ENr/ENo+ 0.281 Jr/Jo + 0.116 GGr/GGo
B33: NOTAS:
B35: 1.- | C35: En la fórmula los sub-indices "o" de cada símbolo corresponden al indice de precios según (CREPCO) a la
C36: fecha de Elaboración del Presupuesto (Presupuesto Base) y los sub-indices "r" al indice de precios al
C37: momento de reajuste o fecha de valorización
B38: 2.- | C38: En el caso de los monomios compuestos por varios indices se ha considerado para efecto de denominación
C39: el símbolo que tiene mayor porcentaje de incidencia
B40: 3.- | C40: En caso de cambios en el suministro se deberá actualizar la formula polinómica.
H42: =+IF(SUM(H13:H28)=1,"OK","X") -> OK | I42: =+IF(SUM(I13:I28)=5,"OK","X") -> OK | J42: =+IF(SUM(J13:J28)=1,"OK","X") -> OK

Sheet RES-RS
B2: RESUMEN PRESUPUESTO DE OBRA
B4: AMPLIACIÓN DEL SERVICIO DE ENERGÍA ELÉCTRICA EN LA PROVINCIA DEL SANTA Y EN EL DISTRITO DE PAMPAROMAS – DEPARTAMENTO DE ANCASH
B6: UBICACIÓN | C6: : | D6: ANCASH
B7: SECCIÓN III | C7: : | D7: REDES SECUNDARIAS | H7: Fecha: 30-May-2022
H8: T.C. (S/ /US$): 3,683
B9: ITEM | C9: DESCRIPCION | G9: PRESUPUESTO CONTRATO | H9: PRESUPUESTO ESTUDIO DEFINIVO | I9: ADICIONALES | K9: DEDUCTIVOS
I10: MAYORES METRADOS | J10: PARTIDAS NUEVAS | K10: MENOR METRADO | L10: DEDUCTIVO VINCULANTE
B12: A | D12: SUMINISTRO DE MATERIALES | G12: =+'Mtdo-Ppto RS'!K127 -> 301377.1 | H12: =+'Mtdo-Ppto RS'!M127 -> 420410.61 | I12: =+'Mtdo-Ppto RS'!O127 -> 56280.94 | J12: =+'Mtdo-Ppto RS'!Q127 -> 142438.64 | K12: =+'Mtdo-Ppto RS'!S127 -> 79686.08 | L12: =+'Mtdo-Ppto RS'!U127 -> 71672.95
B13: B | D13: MONTAJE ELECTROMECANICO | G13: =+'Mtdo-Ppto RS'!K240 -> 273560.14 | H13: =+'Mtdo-Ppto RS'!M240 -> 323016.92 | I13: =+'Mtdo-Ppto RS'!O240 -> 56606.16 | J13: =+'Mtdo-Ppto RS'!Q240 -> 20757.42 | K13: =+'Mtdo-Ppto RS'!S240 -> 27906.79 | L13: =+'Mtdo-Ppto RS'!U240 -> 25189.23
B14: C | D14: TRANSPORTE DE MATERIALES | G14: =+'Mtdo-Ppto RS'!K352 -> 39859.51 | H14: =+'Mtdo-Ppto RS'!M352 -> 46723.13 | I14: =+'Mtdo-Ppto RS'!O352 -> 4340.58 | J14: =+'Mtdo-Ppto RS'!Q352 -> 6469.06 | K14: =+'Mtdo-Ppto RS'!S352 -> 3946.02 | L14: =+'Mtdo-Ppto RS'!U352 -> 3211.37
B15: D | D15: TOTAL COSTO DIRECTO | G15: =+SUM(G12:G14) -> 614796.75 | H15: =+SUM(H12:H14) -> 790150.66 | I15: =+SUM(I12:I14) -> 117227.68 | J15: =+SUM(J12:J14) -> 169665.12 | K15: =+SUM(K12:K14) -> 111538.89 | L15: =+SUM(L12:L14) -> 100073.55
B16: E | D16: GASTOS GENERALES (10.12%) | G16: =ROUND(G15*10.12%,2) -> 62217.43 | H16: =ROUND(H15*10.12%,2) -> 79963.25 | I16: =ROUND(I15*10.12%,2) -> 11863.44 | J16: =ROUND(J15*10.12%,2) -> 17170.11 | K16: =ROUND(K15*10.12%,2) -> 11287.74 | L16: =ROUND(L15*10.12%,2) -> 10127.44
B17: F | D17: UTILIDADES (3%) | G17: =ROUND(G15*3%,2) -> 18443.9 | H17: =ROUND(H15*3%,2) -> 23704.52 | I17: =ROUND(I15*3%,2) -> 3516.83 | J17: =ROUND(J15*3%,2) -> 5089.95 | K17: =ROUND(K15*3%,2) -> 3346.17 | L17: =ROUND(L15*3%,2) -> 3002.21
B18: G | D18: COSTO TOTAL S/. (No incluye I.G.V.) | G18: =G17+G16+G15 -> 695458.08 | H18: =H17+H16+H15 -> 893818.43 | I18: =I17+I16+I15 -> 132607.95 | J18: =J17+J16+J15 -> 191925.18 | K18: =K17+K16+K15 -> 126172.8 | L18: =L17+L16+L15 -> 113203.2 | M18: =+H18-G18 -> 198360.35
D20: INCIDENCIA % | G20: =+G18/G18 -> 1 | H20: =+H18/$G$18 -> 1.2852226 | I20: =+I18/$G$18 -> 0.19067713 | J20: =+J18/$G$18 -> 0.27596944 | K20: =+K18/$G$18 -> 0.18142402 | L20: =+L18/$G$18 -> 0.16277502
H22: =+H18-I18+K18-J18 -> 695458.1 | K22: =+G12-H12+I12+J12-K12 -> -0.01
H23: =+G18-H22 -> -0.02 | K23: =+G13-H13+I13+J13-K13 -> 0.01
K24: =+G14-H14+I14+J14-K14 -> -1.0004442e-11
K25: =+G15-H15+I15+J15-K15 -> 0

Sheet Mtdo-Ppto RS
B6: PRESUPUESTO DE OBRA
B8: OBRA | E8: : | F8: =+'RES-GRAL OBRA'!F4:L4 -> AMPLIACIÓN DEL SERVICIO DE ENERGÍA ELÉCTRICA EN LA PROVINCIA DEL SANTA Y EN EL DISTRITO DE PAMPAROMAS – DEPARTAMENTO DE ANCASH
B9: DEPARTAMENTO | E9: : | F9: =+'RES-GRAL OBRA'!F5 -> ANCASH
B10: SECCIÓN III | E10: : | F10: REDES SECUNDARIAS
B12: ITEM | C12: DESCRIPCIÓN DE PARTIDAS | G12: UNID. | H12: Precio de Contrato | I12: Precio Pactado | J12: CONTRACTUAL | L12: ESTUDIO DEFINITIVO | N12: ADICIONALES | R12: DEDUCTIVOS | V12: OBSERVACIÓN
J13: Metrado | K13: TOTAL | L13: Metrado | M13: TOTAL | N13: MAYORES METRADOS | P13: PARTIDAS NUEVAS | R13: MENORES METRADOS | T13: DEDUCTIVO VINCULANTE
N14: Metrado | O14: TOTAL | P14: Metrado | Q14: TOTAL | R14: Metrado | S14: TOTAL | T14: Metrado | U14: TOTAL
H15: Unitario | I15: Unitario | J15: Cantidad | K15: S/. | L15: Cantidad | M15: S/. | N15: Cantidad | O15: S/. | P15: Cantidad | Q15: S/. | R15: Cantidad | S15: S/. | T15: Cantidad | U15: S/.
B16: A | D16: SUMINISTRO DE MATERIALES
B17: 1 | C17: 3 | D17: POSTES DE CONCRETO ARMADO Y MADERA IMPORTADA
B18: =+B17+0.01 -> 1.01 | C18: =+C17+1 -> 4 | D18: Poste de C.A.C. de 8 m/200 daN (Incluye perilla) | G18: u | H18: 372.21 | J18: 153 | K18: =+ROUND($H18*J18,2) -> 56948.13 | L18: =+[193]Metrado!F12 -> 141 | M18: =+ROUND($H18*L18,2) -> 52481.61 | N18: =+IF($L18-$J18>=0,$L18-$J18,0) -> 0 | O18: =+ROUND($H18*N18,2) -> 0 | Q18: =+ROUND($H18*P18,2) -> 0 | R18: =+IF($L18-$J18<=0,-$L18+$J18,0) -> 12 | S18: =+ROUND($H18*R18,2) -> 4466.52 | T18: =+R18 -> 12 | U18: =+ROUND($H18*T18,2) -> 4466.52 | V18: Se vincula con el mayor metrado de la partida 1.02 | Y18: 0
B19: =+B18+0.01 -> 1.02 | C19: =+C18+1 -> 5 | D19: Poste de C.A.C. de 8 m/300 daN (Incluye perilla) | G19: u | H19: 402.99 | J19: 79 | K19: =+ROUND($H19*J19,2) -> 31836.21 | L19: =+[193]Metrado!F13 -> 100 | M19: =+ROUND($H19*L19,2) -> 40299 | N19: =+IF($L19-$J19>=0,$L19-$J19,0) -> 21 | O19: =+ROUND($H19*N19,2) -> 8462.79 | Q19: =+ROUND($H19*P19,2) -> 0 | R19: =+IF($L19-$J19<=0,-$L19+$J19,0) -> 0 | S19: =+ROUND($H19*R19,2) -> 0 | U19: =+ROUND($H19*T19,2) -> 0 | Y19: 0
C20: =+C19+1 -> 6 | F20: =+"SUB-TOTAL "&B17&": " -> SUB-TOTAL 1: | K20: =+SUM(K18:K19) -> 88784.34 | M20: =+SUM(M18:M19) -> 92780.61 | O20: =+SUM(O18:O19) -> 8462.79 | Q20: =+SUM(Q18:Q19) -> 0 | S20: =+SUM(S18:S19) -> 4466.52 | U20: =+SUM(U18:U19) -> 4466.52 | W20: =+K20-M20+O20+Q20-S20 -> 0 | Y20: 0
B21: =1+B17 -> 2 | C21: =+C20+1 -> 7 | D21: POSTES DE MADERA IMPORTADA | Y21: 0
B22: =+B21+0.01 -> 2.01 | C22: =+C21+1 -> 8 | D22: Poste de madera importada (Pino Amarillo del Sur) de 8 m, Clase 7 | G22: u | H22: 805.66 | J22: 9 | K22: =+ROUND($H22*J22,2) -> 7250.94 | L22: =+[193]Metrado!F16 -> 0 | M22: =+ROUND($H22*L22,2) -> 0 | N22: =+IF($L22-$J22>=0,$L22-$J22,0) -> 0 | O22: =+ROUND($H22*N22,2) -> 0 | Q22: =+ROUND($H22*P22,2) -> 0 | R22: =+IF($L22-$J22<=0,-$L22+$J22,0) -> 9 | S22: =+ROUND($H22*R22,2) -> 7250.94 | T22: =+R22 -> 9 | U22: =+ROUND($H22*T22,2) -> 7250.94 | V22: Se vincula con la partida nueva 2.01A | Y22: 0
C23: =+C22+1 -> 9 | F23: =+"SUB-TOTAL "&B21&": " -> SUB-TOTAL 2: | K23: =+SUM(K22) -> 7250.94 | M23: =+SUM(M22) -> 0 | O23: =+SUM(O22) -> 0 | Q23: =+SUM(Q22) -> 0 | S23: =+SUM(S22) -> 7250.94 | U23: =+SUM(U22) -> 7250.94 | W23: =+K23-M23+O23+Q23-S23 -> 0 | Y23: 0
B24: 2.00A | C24: =+C23+1 -> 10 | D24: POSTES DE FIBRA DE VIDRIO | Y24: 0
