Workbook
Name ARMADO_RP: BD!$E$2:$AT$223
Name DatosXLoc: [1]DATOS_xLOC!$A$3:$K$176
Name f_cond: BD!$BM$45
Name LOCALIDAD: REDCAD!$BV$2:$CA$22
Name Num_Dec: BD!$BM$46
Name PLANILLA: REDCAD!$A$2:$BI$1005
Name PLANILLA1: REDCAD!$C$2:$CQ$1048576
Name POSTES: REDCAD!$BK$3:$BO$15
Name TRAFOS: REDCAD!$BQ$4:$BT$20
Name Vol_PAT: BD!$BH$36:$BV$43
Name Vol_Poste: BD!$BH$3:$BY$26
Name Vol_Retenida: BD!$BH$28:$BV$34

Sheet BD
A2: Item | B2: 1 | C2: Descripción de Partidas | D2: Unid. | E2: DS-0 | F2: DS-0A | G2: DT-0 | H2: EC | I2: PS1-0 | J2: PA1-0 | K2: PTV-0 | L2: TS-0 | M2: DS-2 | N2: PS1-2 | O2: PSVE-2 | P2: TSVE-2 | Q2: SMM-1P | R2: SMM-2P | S2: SBM-2P | T2: SBM-2V | U2: 5kVA-1ø-13,2kV | V2: 5kVA-2ø-13,8kV | W2: 10kVA-2ø-13,8kV | X2: 25kVA-2ø-13,8kV | Y2: 37.5kVA-2ø-13,8kV | Z2: 5kVA-2ø-22,9kV | AA2: 35 mm² AAAC | AB2: CAC 12/200 | AC2: CAC 12/300 | AD2: CAC 13/300 | AE2: CAC 13/400 | AF2: PRFV 12/200 | AG2: PRFV 12/300 | AH2: RI | AI2: RIY | AJ2: RV | AK2: RVY | AL2: PAT-1C | AM2: PAT-1 | AN2: PAT-2 | AO2: PAT-3 | AP2: - | AQ2: -- | AR2: - -- | AS2: - - | AT2: 0 | BH2: 1 | BI2: 2 | BJ2: 3 | BK2: 4 | BL2: 5 | BM2: 6 | BN2: 7 | BO2: 8 | BP2: 9 | BQ2: 10 | BR2: 11 | BS2: 12 | BT2: 13 | BU2: 14 | BV2: 15 | BW2: 16 | BX2: 17 | BY2: 17
B3: =+B2+1 -> 2 | W3: 37.5kVA-2ø-13,8kV | BH3: POSTE_CIM | BI3: Tipo de Poste | BJ3: Tipo de Cimentacion | BK3: Excavación (m3) | BL3: Relleno (m3) | BM3: % Relleno Directo | BN3: Longitud del Poste (m) | BO3: Diametro en la Punta (m) | BP3: Diametro en la Base (m) | BQ3: Circunferencia mínima en la cabeza (m) | BR3: Circunferencia mínima en la linea de tierra (m) | BS3: Altura de Empotramiento de Poste (m) | BT3: Diametro del Poste a la altura de empotramiento(m) | BU3: Diametro del hoyo del Poste (m) | BV3: Profundidad del hoyo del Poste (m) | BW3: Altura de Solado (m) | BX3: Volumen parte del Poste enterrado (m3) | BY3: Volumen solado
A4: 1 | B4: =+B3+1 -> 3 | C4: CRUCETAS DE MADERA DE PROCEDENCIA NACIONAL | W4: 5kVA-1ø-13,2kV
A5: =+A4+0.01 -> 1.01 | B5: =+B4+1 -> 4 | C5: Cruceta de madera tratada de 90 mm x 115 mm x 1,20 m | D5: u | F5: 1 | Q5: 1 | R5: 1 | W5: 5kVA-2ø-13,8kV | BH5: CAC 12/200CI-C | BI5: 12/200 | BJ5: CI-C | BK5: =ROUND(PI()*($BU5^2)*$BV5/4,Num_Dec) -> 0.905 | BL5: =ROUND(PI()*($BU5^2)*$BV5/4-$BX5-BY5,Num_Dec) -> 0.745 | BM5: =+BL5/BK5 -> 0.82320442 | BN5: 12 | BO5: 0.16 | BP5: 0.35 | BS5: 1.8 | BT5: =+($BN5*$BP5-$BS5*$BP5+$BS5*$BO5)/$BN5 -> 0.3215 | BU5: 0.8 | BV5: 1.8 | BX5: =$BS5*PI()*($BP5^2+$BT5^2+$BP5*$BT5)/12 -> 0.15946123 | BY5: =+PI()*POWER(BU5,2)*BW5/4 -> 0
A6: =+A5+0.01 -> 1.02 | B6: =+B5+1 -> 5 | C6: Listón de madera tratada 50 x 19 mm sección, 2,7 m longitud (incluye clavos de fijación) | D6: u | W6: 5kVA-2ø-22,9kV | BH6: CAC 12/300CI-C | BI6: 12/300 | BJ6: CI-C | BK6: =ROUND(PI()*($BU6^2)*$BV6/4,Num_Dec) -> 0.905 | BL6: =ROUND(PI()*($BU6^2)*$BV6/4-$BX6-BY6,Num_Dec) -> 0.745 | BM6: =+BL6/BK6 -> 0.82320442 | BN6: 12 | BO6: 0.16 | BP6: 0.35 | BS6: 1.8 | BT6: =+($BN6*$BP6-$BS6*$BP6+$BS6*$BO6)/$BN6 -> 0.3215 | BU6: 0.8 | BV6: 1.8 | BX6: =$BS6*PI()*($BP6^2+$BT6^2+$BP6*$BT6)/12 -> 0.15946123 | BY6: =+PI()*POWER(BU6,2)*BW6/4 -> 0
A7: =+A6+0.01 -> 1.03 | B7: =+B6+1 -> 6 | C7: Cruceta de madera tratada de 90 mm x 115 mm x 2,00 m | D7: u | S7: 1 | BH7: CAC 13/300CI-A | BI7: 13/300 | BJ7: CI-A | BK7: =ROUND(PI()*($BU7^2)*$BV7/4,Num_Dec) -> 1.081 | BL7: =ROUND(PI()*($BU7^2)*$BV7/4-$BX7-BY7,Num_Dec) -> 0.848 | BM7: =+BL7/BK7 -> 0.78445883 | BN7: 13 | BO7: 0.18 | BP7: 0.38 | BS7: 1.6 | BT7: =+($BN7*$BP7-$BS7*$BP7+$BS7*$BO7)/$BN7 -> 0.35538462 | BU7: 0.9 | BV7: 1.7 | BW7: 0.1 | BX7: =$BS7*PI()*($BP7^2+$BT7^2+$BP7*$BT7)/12 -> 0.16995781 | BY7: =+PI()*POWER(BU7,2)*BW7/4 -> 0.063617251
A8: =+A7+0.01 -> 1.04 | B8: =+B7+1 -> 7 | C8: Cruceta de madera tratada de 90 mm x 115 mm x 2,40 m | D8: u | N8: 1 | BH8: CAC 13/400CI-A | BI8: 13/400 | BJ8: CI-A | BK8: =ROUND(PI()*($BU8^2)*$BV8/4,Num_Dec) -> 1.081 | BL8: =ROUND(PI()*($BU8^2)*$BV8/4-$BX8-BY8,Num_Dec) -> 0.848 | BM8: =+BL8/BK8 -> 0.78445883 | BN8: 13 | BO8: 0.18 | BP8: 0.38 | BS8: 1.6 | BT8: =+($BN8*$BP8-$BS8*$BP8+$BS8*$BO8)/$BN8 -> 0.35538462 | BU8: 0.9 | BV8: 1.7 | BW8: 0.1 | BX8: =$BS8*PI()*($BP8^2+$BT8^2+$BP8*$BT8)/12 -> 0.16995781 | BY8: =+PI()*POWER(BU8,2)*BW8/4 -> 0.063617251
B9: =+B8+1 -> 8 | BH9: PRFV 12/200CI-C | BI9: 12/200 | BJ9: CI-C | BK9: =ROUND(PI()*($BU9^2)*$BV9/4,Num_Dec) -> 0.905 | BL9: =ROUND(PI()*($BU9^2)*$BV9/4-$BX9-BY9,Num_Dec) -> 0.745 | BM9: =+BL9/BK9 -> 0.82320442 | BN9: 12 | BO9: 0.16 | BP9: 0.35 | BS9: 1.8 | BT9: =+($BN9*$BP9-$BS9*$BP9+$BS9*$BO9)/$BN9 -> 0.3215 | BU9: 0.8 | BV9: 1.8 | BX9: =$BS9*PI()*($BP9^2+$BT9^2+$BP9*$BT9)/12 -> 0.15946123 | BY9: =+PI()*POWER(BU9,2)*BW9/4 -> 0
A10: =1+A4 -> 2 | B10: =+B9+1 -> 9 | C10: POSTES DE CONCRETO ARMADO CENTRIFUGADO | BH10: PRFV 12/300CI-C | BI10: 12/300 | BJ10: CI-C | BK10: =ROUND(PI()*($BU10^2)*$BV10/4,Num_Dec) -> 0.905 | BL10: =ROUND(PI()*($BU10^2)*$BV10/4-$BX10-BY10,Num_Dec) -> 0.745 | BM10: =+BL10/BK10 -> 0.82320442 | BN10: 12 | BO10: 0.16 | BP10: 0.35 | BS10: 1.8 | BT10: =+($BN10*$BP10-$BS10*$BP10+$BS10*$BO10)/$BN10 -> 0.3215 | BU10: 0.8 | BV10: 1.8 | BX10: =$BS10*PI()*($BP10^2+$BT10^2+$BP10*$BT10)/12 -> 0.15946123 | BY10: =+PI()*POWER(BU10,2)*BW10/4 -> 0
A11: =+A10+0.01 -> 2.01 | B11: =+B10+1 -> 10 | C11: Poste de C.A.C. de 12 m/200 daN (Incluye perilla) | D11: u | AB11: 1 | BH11: CAC 12/200CII-C | BI11: 12/200 | BJ11: CII-C | BK11: =ROUND(PI()*($BU11^2)*$BV11/4,Num_Dec) -> 0.754 | BL11: =ROUND(PI()*($BU11^2)*$BV11/4-$BX11-BY11,Num_Dec) -> 0.619 | BM11: =+BL11/BK11 -> 0.82095491 | BN11: 12 | BO11: 0.16 | BP11: 0.35 | BS11: 1.5 | BT11: =+($BN11*$BP11-$BS11*$BP11+$BS11*$BO11)/$BN11 -> 0.32625 | BU11: 0.8 | BV11: 1.5 | BX11: =$BS11*PI()*($BP11^2+$BT11^2+$BP11*$BT11)/12 -> 0.13474549 | BY11: =+PI()*POWER(BU11,2)*BW11/4 -> 0
A12: =+A11+0.01 -> 2.02 | B12: =+B11+1 -> 11 | C12: Poste de C.A.C. de 12 m/300 daN (Incluye perilla) | D12: u | AC12: 1 | BH12: CAC 12/300CII-C | BI12: 12/300 | BJ12: CII-C | BK12: =ROUND(PI()*($BU12^2)*$BV12/4,Num_Dec) -> 0.754 | BL12: =ROUND(PI()*($BU12^2)*$BV12/4-$BX12-BY12,Num_Dec) -> 0.619 | BM12: =+BL12/BK12 -> 0.82095491 | BN12: 12 | BO12: 0.16 | BP12: 0.35 | BS12: 1.5 | BT12: =+($BN12*$BP12-$BS12*$BP12+$BS12*$BO12)/$BN12 -> 0.32625 | BU12: 0.8 | BV12: 1.5 | BX12: =$BS12*PI()*($BP12^2+$BT12^2+$BP12*$BT12)/12 -> 0.13474549 | BY12: =+PI()*POWER(BU12,2)*BW12/4 -> 0
A13: =+A12+0.01 -> 2.03 | B13: =+B12+1 -> 12 | C13: Poste de C.A.C. de 13 m/300 daN (Incluye perilla) | D13: u | AD13: 1 | BH13: CAC 13/300CII-A | BI13: 13/300 | BJ13: CII-A | BK13: =ROUND(PI()*($BU13^2)*$BV13/4,Num_Dec) -> 1.018 | BL13: =ROUND(PI()*($BU13^2)*$BV13/4-$BX13-BY13,Num_Dec) -> 0.794 | BM13: =+BL13/BK13 -> 0.77996071 | BN13: 13 | BO13: 0.18 | BP13: 0.38 | BS13: 1.5 | BT13: =+($BN13*$BP13-$BS13*$BP13+$BS13*$BO13)/$BN13 -> 0.35692308 | BU13: 0.9 | BV13: 1.6 | BW13: 0.1 | BX13: =$BS13*PI()*($BP13^2+$BT13^2+$BP13*$BT13)/12 -> 0.15999537 | BY13: =+PI()*POWER(BU13,2)*BW13/4 -> 0.063617251
A14: =+A13+0.01 -> 2.04 | B14: =+B13+1 -> 13 | C14: Poste de C.A.C. de 13 m/400 daN (Incluye perilla) | D14: u | AE14: 1 | BH14: CAC 13/400CII-A | BI14: 13/400 | BJ14: CII-A | BK14: =ROUND(PI()*($BU14^2)*$BV14/4,Num_Dec) -> 1.018 | BL14: =ROUND(PI()*($BU14^2)*$BV14/4-$BX14-BY14,Num_Dec) -> 0.794 | BM14: =+BL14/BK14 -> 0.77996071 | BN14: 13 | BO14: 0.18 | BP14: 0.38 | BS14: 1.5 | BT14: =+($BN14*$BP14-$BS14*$BP14+$BS14*$BO14)/$BN14 -> 0.35692308 | BU14: 0.9 | BV14: 1.6 | BW14: 0.1 | BX14: =$BS14*PI()*($BP14^2+$BT14^2+$BP14*$BT14)/12 -> 0.15999537 | BY14: =+PI()*POWER(BU14,2)*BW14/4 -> 0.063617251
B15: =+B14+1 -> 14 | BH15: PRFV 12/200CII-C | BI15: 12/200 | BJ15: CII-C | BK15: =ROUND(PI()*($BU15^2)*$BV15/4,Num_Dec) -> 0.754 | BL15: =ROUND(PI()*($BU15^2)*$BV15/4-$BX15-BY15,Num_Dec) -> 0.619 | BM15: =+BL15/BK15 -> 0.82095491 | BN15: 12 | BO15: 0.16 | BP15: 0.35 | BS15: 1.5 | BT15: =+($BN15*$BP15-$BS15*$BP15+$BS15*$BO15)/$BN15 -> 0.32625 | BU15: 0.8 | BV15: 1.5 | BX15: =$BS15*PI()*($BP15^2+$BT15^2+$BP15*$BT15)/12 -> 0.13474549 | BY15: =+PI()*POWER(BU15,2)*BW15/4 -> 0
A16: 3 | B16: =+B15+1 -> 15 | C16: POSTES DE MADERA IMPORTADA | BH16: PRFV 12/300CII-C | BI16: 12/300 | BJ16: CII-C | BK16: =ROUND(PI()*($BU16^2)*$BV16/4,Num_Dec) -> 0.754 | BL16: =ROUND(PI()*($BU16^2)*$BV16/4-$BX16-BY16,Num_Dec) -> 0.619 | BM16: =+BL16/BK16 -> 0.82095491 | BN16: 12 | BO16: 0.16 | BP16: 0.35 | BS16: 1.5 | BT16: =+($BN16*$BP16-$BS16*$BP16+$BS16*$BO16)/$BN16 -> 0.32625 | BU16: 0.8 | BV16: 1.5 | BX16: =$BS16*PI()*($BP16^2+$BT16^2+$BP16*$BT16)/12 -> 0.13474549 | BY16: =+PI()*POWER(BU16,2)*BW16/4 -> 0
A17: =+A16+0.01 -> 3.01 | B17: =+B16+1 -> 16 | C17: Poste de madera importada (Pino Amarillo del Sur) de 12 m, Clase 5 | D17: u | BH17: CAC 15/400CI-A | BI17: 15/400 | BJ17: CII-C | BK17: =ROUND(PI()*($BU17^2)*$BV17/4,Num_Dec) -> 1.106 | BL17: =ROUND(PI()*($BU17^2)*$BV17/4-$BX17-BY17,Num_Dec) -> 0.766 | BM17: =+BL17/BK17 -> 0.6925859 | BN17: 15 | BO17: 0.21 | BP17: 0.435 | BS17: =+BN17/10+0.6 -> 2.1 | BT17: =+($BN17*$BP17-$BS17*$BP17+$BS17*$BO17)/$BN17 -> 0.4035 | BU17: 0.8 | BV17: 2.2 | BW17: 0.1 | BX17: =$BS17*PI()*($BP17^2+$BT17^2+$BP17*$BT17)/12 -> 0.29004112 | BY17: =+PI()*POWER(BU17,2)*BW17/4 -> 0.050265482
B18: =+B17+1 -> 17
A19: 3.00A | B19: =+B18+1 -> 18 | C19: POSTES DE FIBRA DE VIDRIO
A20: 3.01A | B20: =+B19+1 -> 19 | C20: Poste de PRFV de 12 m/200 daN | D20: u | AF20: 1 | BH20: =+BI20&BJ20 -> -- | BI20: - | BJ20: -
A21: 3.02A | B21: =+B20+1 -> 20 | C21: Poste de PRFV de 12 m/300 daN | D21: u | AG21: 1 | BH21: =+BI21&BJ21 -> 11/EXIST- | BI21: 11/EXIST | BJ21: -
B22: =+B21+1 -> 21 | BH22: =+BI22&BJ22 -> 12/EXIST- | BI22: 12/EXIST | BJ22: -
A23: =1+A16 -> 4 | B23: =+B22+1 -> 22 | C23: OTROS MATERIALES DE CONCRETO ARMADO | BH23: CAC 13/EXIST- | BI23: 13/EXIST | BJ23: -
A24: =+A23+0.01 -> 4.01 | B24: =+B23+1 -> 23 | C24: Cruceta Asimétrica de C.A.V. Za / 1,5 / 0,9 / 250 / 200 / 100 daN (Za / L / L1/ T / F / V) | D24: u | T24: 1 | BH24: =+BI24&BJ24 -> 12/C5- | BI24: 12/C5 | BJ24: -
A25: =+A24+0.01 -> 4.02 | B25: =+B24+1 -> 24 | C25: Ménsula de C.A.V. M / 1,2 / 250 / 150 / 150 daN (M / L / T / F / V) | D25: u | O25: 2 | P25: 2 | T25: 2 | BH25: - -- | BI25: - | BJ25: -
A26: =+A25+0.01 -> 4.03 | B26: =+B25+1 -> 25 | C26: Plataforma de Concreto Soporte de Transformador de 2,20 m, carga de trabajo de 500 daN | D26: u | T26: 1 | BH26: 0 00
B27: =+B26+1 -> 26
A28: =1+A23 -> 5 | B28: =+B27+1 -> 27 | C28: AISLADORES Y ACCESORIOS | BH28: Retenida | BK28: Excavación (m3) | BL28: Relleno (m3) | BM28: % Relleno | BN28: Volumen de hoyo de retenida(m3) | BO28: Volumen de Chaflán (m3) | BP28: Profundidad de hoyo de retenida (m) | BQ28: Ancho de hoyo de retenida (m) | BR28: Largo de hoyo de retenida (m) | BS28: Profundidad de Chaflan (m) | BT28: Ancho de Zanja de Chaflan (m) | BU28: Largo de Zanja de Chaflan (m) | BV28: Volumen de Bloque de Concreto(m3)
A29: =+A28+0.01 -> 5.01 | B29: =+B28+1 -> 28 | C29: Aislador de Porcelana Tipo Pin, Clase ANSI 56-3 | D29: u | F29: 1 | I29: 1 | J29: 2 | L29: 1 | N29: 2
A30: =+A29+0.01 -> 5.02 | B30: =+B29+1 -> 29 | C30: Espiga de AºGº de 609 mm longitud, para Cabeza de Poste y Aislador ANSI 56-3 | D30: u | I30: 1 | J30: 2 | L30: 1
A31: =+A30+0.01 -> 5.03 | B31: =+B30+1 -> 30 | C31: Conjunto Aislador Line Post Polimérico en Cruceta: | BH31: RI | BK31: =ROUND(BN31+BO31,$BM$46) -> 1.118 | BL31: =ROUND($BK31-$BV31,Num_Dec) -> 1.094 | BM31: =BL31/BK31 -> 0.97853309 | BN31: =+BP31*BQ31*BR31 -> 0.98 | BO31: =BS31*BT31*BU31/2 -> 0.138 | BP31: 2 | BQ31: 0.7 | BR31: 0.7 | BS31: 1.15 | BT31: 0.3 | BU31: 0.8 | BV31: =0.4*0.4*0.15 -> 0.024
B32: =+B31+1 -> 31 | C32: - Aislador Polimérico de 36 kV, Tipo Line Post con Espárrago de 19 mm Ø, 200 mm longitud (Alternativa a Conjunto Aislador-Espiga en Cruceta) | D32: u | O32: 2 | P32: 2 | BH32: RV | BK32: =ROUND(BN32+BO32,$BM$46) -> 1.078 | BL32: =ROUND($BK32-$BV32,Num_Dec) -> 1.054 | BM32: =BL32/BK32 -> 0.97773655 | BN32: =+BP32*BQ32*BR32 -> 1.078 | BO32: 0 | BP32: 2.2 | BQ32: 0.7 | BR32: 0.7 | BS32: 0 | BT32: 0 | BU32: 0 | BV32: =0.4*0.4*0.15 -> 0.024
A33: 5.04 | B33: =+B32+1 -> 32 | C33: Espiga para cruceta, forjada de 381mm LONG. Para aislador Tipo Pin, Clase ANSI 56-3 | D33: u | F33: 1 | N33: 2 | BH33: RIY | BK33: =ROUND(BN33+BO33,$BM$46) -> 1.118 | BL33: =ROUND($BK33-$BV33,Num_Dec) -> 1.094 | BM33: =BL33/BK33 -> 0.97853309 | BN33: =+BP33*BQ33*BR33 -> 0.98 | BO33: =BS33*BT33*BU33/2 -> 0.138 | BP33: 2 | BQ33: 0.7 | BR33: 0.7 | BS33: 1.15 | BT33: 0.3 | BU33: 0.8 | BV33: =0.4*0.4*0.15 -> 0.024
B34: =+B33+1 -> 33 | BH34: RVY | BK34: =ROUND(BN34+BO34,$BM$46) -> 1.408 | BL34: =ROUND($BK34-$BV34,Num_Dec) -> 1.384 | BM34: =BL34/BK34 -> 0.98295455 | BN34: =+BP34*BQ34*BR34 -> 1.408 | BO34: 0 | BP34: 2.2 | BQ34: 0.8 | BR34: 0.8 | BS34: 0 | BT34: 0 | BU34: 0 | BV34: =0.4*0.4*0.15 -> 0.024
A35: =1+A28 -> 6 | B35: =+B34+1 -> 34 | C35: AISLADORES DE SUSPENSIÓN Y ACCESORIOS
A36: =+A35+0.01 -> 6.01 | B36: =+B35+1 -> 35 | C36: Grillete Recto | D36: u | G36: 1 | K36: 1 | L36: 1 | P36: 2 | BH36: Puesta a Tierra | BK36: Excavación (m3) | BL36: Relleno (m3) | BM36: % Relleno | BN36: Volumen de hoyo de P. Tierra (m3) | BO36: Volumen de Zanja (m3) | BP36: Diametro de hoyo de P. Tierra (m) | BQ36: Profundidad de hoyo de P. Tierra (m) | BR36: Ancho de Zanja de P. Tierra (m) | BS36: Profundidad de zanja de Puesta a Tierra (m) | BT36: Distancia del eje del Poste a la Varilla de P.T. (m) | BU36: Longitud de Zanja (m) | BV36: Volumen de Caja de Registro (m3)
A37: =+A36+0.01 -> 6.02 | B37: =+B36+1 -> 36 | C37: Aislador Polimerico con Conexión Horquilla (Estructura) y Lengüeta (Linea) de 36 kV, según Especificacion Técnica. | D37: u | G37: 1 | K37: 1 | L37: 1 | P37: 2
B38: =+B37+1 -> 37
A39: =1+A35 -> 7 | B39: =+B38+1 -> 38 | C39: CONDUCTOR DE ALEACIÓN DE ALUMINIO | BH39: PAT-1 | BK39: =ROUND(BN39+BO39,Num_Dec) -> 1.573 | BL39: =ROUND(BK39-BV39*1,Num_Dec) -> 1.485 | BM39: =BL39/BK39 -> 0.94405594 | BN39: =PI()*($BP39^2)*BQ39/4 -> 1.357168 | BO39: =+$BR39*$BS39*$BU39 -> 0.21618 | BP39: 0.8 | BQ39: 2.7 | BR39: 0.3 | BS39: 0.6 | BT39: 2 | BU39: 1.201 | BV39: =+ROUND(PI()*POWER(0.5,2)*0.45/4,Num_Dec) -> 0.088
A40: =+A39+0.01 -> 7.01 | B40: =+B39+1 -> 39 | C40: Conductor de Aleacion de Aluminio de 35 mm² | D40: km | AA40: 1.035 | BH40: PAT-2 | BK40: =ROUND(BN40+BO40,Num_Dec) -> 3.147 | BL40: =ROUND(BK40-BV40*1,Num_Dec) -> 2.971 | BM40: =BL40/BK40 -> 0.94407372 | BN40: =PI()*($BP40^2)*BQ40/4*2 -> 2.7143361 | BO40: =+$BR40*$BS40*$BU40*2 -> 0.43236 | BP40: 0.8 | BQ40: 2.7 | BR40: 0.3 | BS40: 0.6 | BT40: 2 | BU40: 1.201 | BV40: =+ROUND(PI()*POWER(0.5,2)*0.45/4,Num_Dec)*2 -> 0.176
B41: =+B40+1 -> 40 | BH41: PAT-3 | BK41: =ROUND(BN41+BO41,Num_Dec) -> 5.089 | BL41: =ROUND(BK41-BV41*1,Num_Dec) -> 4.825 | BM41: =BL41/BK41 -> 0.9481234 | BN41: =PI()*($BP41^2)*BQ41/4*3 -> 4.0715041 | BO41: =+$BR41*$BS41*$BU41*2+3.251*0.3*0.6 -> 1.01754 | BP41: 0.8 | BQ41: 2.7 | BR41: 0.3 | BS41: 0.6 | BT41: 2 | BU41: 1.201 | BV41: =+ROUND(PI()*POWER(0.5,2)*0.45/4,Num_Dec)*3 -> 0.264
...

Sheet REDCAD
A1: 1 | B1: =+A1+1 -> 2 | C1: =+B1+1 -> 3 | D1: =+C1+1 -> 4 | E1: =+D1+1 -> 5 | F1: =+E1+1 -> 6 | G1: =+F1+1 -> 7 | H1: =+G1+1 -> 8 | I1: =+H1+1 -> 9 | ... BI1: =+BH1+1 -> 61
A2: ID | B2: N° | C2: Localidad | D2: N° SED | E2: N° Estructura | F2: Arm. Primario | G2: Arm. Secundario | H2: RI | I2: RV | J2: PAT | K2: Conductor | L2: Vano-m | M2: Num. Fases | N2: Soporte | O2: Cantidad de Soportes | P2: Subestación | Q2: Seccionadores | R2: Pararrayos | S2: Coordenada X | T2: Coordenada Y | U2: Conexiones I | V2: Conexiones L | W2: Conexiones T | X2: Conexiones + | Y2: Retenida Inclinada de RS | Z2: Retenida Vertical de RS | AA2: Retenida Inclinada de RP | AB2: Retenida Vertical de RP | AC2: Retenida Inclinada de LP | AD2: Retenida Vertical de LP | AE2: Retenida Inclinada Existente de RS | AF2: Retenida Vertical Existente de RS | AG2: Retenida Inclinada Existente de RP | AH2: Retenida Vertical Existente de RP | AI2: Retenida Inclinada en Y de RS | AJ2: Retenida Vertical en Y de RS | AK2: Retenida Inclinada en Y de RP | AL2: Retenida Vertical en Y de RP | AM2: Terreno_I Poste % | AN2: Terreno_II Poste % | AO2: Cimentacion | AP2: Terreno_I Retenida % | AQ2: Terreno_II Retenida % | AR2: Terreno_I PAT % | AS2: Terreno_II PAT % | AT2: Cemento Conductivo | AU2: Accesibilidad | AV2: Fusibles | AW2: AMORTIGUADOR | AX2: Area | AY2: SISTEMA | AZ2: VEREDA | BA2: TIPO MATERIAL | BB2: POSTE | BC2: LONGITUD | BD2: DESPEJE DE ARBOLES | BE2: CODIGO NTCSE | BF2: CODIGO INVENTARIO | BG2: CODIGOD NTCSE SED | BH2: CODIGO NTCSE SECCIONADOR | BI2: ID | BK2: SOPORTE | BL2: USO | BM2: MATERIAL | BN2: ALTURA/CARGA DE TRABJO | BO2: LONGITUD | BV2: N° | BW2: LOCALIDAD | BX2: DEPARTAMENTO | BY2: PROVINCIA | BZ2: DISTRITO | CA2: SISTEMA
A3: 1 | B3: 1 | C3: CONCHIPAMPA | D3: - | E3: 0 | F3: - | G3: DS-0 | H3: 0 | I3: 0 | J3: - | K3: 35 mm² AAAC | L3: 0 | M3: 1 | N3: - | O3: 0 | P3: - | Q3: 0 | R3: 0 | S3: 174368.64 | T3: 8980122.95 | U3: 0 | V3: 0 | W3: 0 | X3: 0 | Y3: 0 | Z3: 0 | AA3: 0 | AB3: 0 | AC3: 0 | AD3: 0 | AE3: 0 | AF3: 0 | AG3: 0 | AH3: 0 | AM3: 0 | AN3: 0 | AO3: - | AT3: 0 | AU3: SI | AV3: =+IF(M3<>0,VLOOKUP($P3,TRAFOS,4,0),"-") -> - | AW3: =IF($L3<250,0,IF($L3<400,$M3*2,IF($L3<600,$M3*4,$M3*6))) -> 0 | AX3: 2 | AY3: =+IF(P3<>0,VLOOKUP($P3,TRAFOS,3,0),"-") -> - | AZ3: =+IF(B3<>0,"NO","-") -> NO | BA3: =+IF($N3<>0,VLOOKUP($N3,POSTES,3,0),"-") -> - | BB3: =+IF($N3<>0,VLOOKUP($N3,POSTES,4,0),"-") -> - | BC3: =+IF($N3<>0,VLOOKUP($N3,POSTES,5,0),0) -> - | BI3: 1 | BK3: CAC RS Existente | BL3: BT | BM3: CAC | BN3: 8/200-E | BO3: 8 | BV3: 1 | BW3: CONCHIPAMPA | BX3: ANCASH | BY3: HUAYLAS | BZ3: PAMPAROMÁS | CA3: 1Ø | CD3: =+SUM(AM3:AN3) -> 0 | CE3: =+SUM(AP3:AQ3) -> 0 | CF3: =+SUM(AR3:AS3) -> 0
A4: =+A3+1 -> 2 | B4: 1 | C4: CONCHIPAMPA | D4: - | E4: 1 | F4: TS-0 | G4: - | H4: 1 | I4: 0 | J4: PAT-1C | K4: 35 mm² AAAC | L4: 22.2 | M4: 1 | N4: CAC 12/300 | O4: 1 | P4: - | Q4: 0 | R4: 0 | S4: 174390.7176 | T4: 8980123.4154 | U4: 0 | V4: 0 | W4: 0 | X4: 0 | Y4: 0 | Z4: 0 | AA4: 1 | AB4: 0 | AC4: 0 | AD4: 0 | AE4: 0 | AF4: 0 | AG4: 0 | AH4: 0 | AK4: 0 | AL4: 0 | AM4: 1 | AN4: 0 | AO4: CI-C | AP4: 1 | AQ4: 0 | AR4: 1 | AS4: 0 | AT4: 0 | AU4: SI | AV4: =+IF(M4<>0,VLOOKUP($P4,TRAFOS,4,0),"-") -> - | AW4: =IF($L4<250,0,IF($L4<400,$M4*2,IF($L4<600,$M4*4,$M4*6))) -> 0 | AX4: 2 | AY4: =+IF(P4<>0,VLOOKUP($P4,TRAFOS,3,0),"-") -> - | AZ4: =+IF(B4<>0,"NO","-") -> NO | BA4: =+IF($N4<>0,VLOOKUP($N4,POSTES,3,0),"-") -> CAC | BB4: =+IF($N4<>0,VLOOKUP($N4,POSTES,4,0),"-") -> 12/300 | BC4: =+IF($N4<>0,VLOOKUP($N4,POSTES,5,0),0) -> 12 | BI4: =+BI3+1 -> 2 | BK4: CAC 11/200-E | BL4: MT | BM4: CAC | BN4: 11/200 | BO4: 11 | BQ4: TRAFO | BR4: POTENCIA | BS4: SISTEMA | BT4: FUSIBLE | BV4: 2 | BW4: PUEBLO NUEVO HUASCAR | BX4: ANCASH | BY4: HUAYLAS | BZ4: PAMPAROMÁS | CA4: 1Ø | CD4: =+SUM(AM4:AN4) -> 1 | CE4: =+SUM(AP4:AQ4) -> 1 | CF4: =+SUM(AR4:AS4) -> 1
A5: =+A4+1 -> 3 | B5: 1 | C5: CONCHIPAMPA | D5: - | E5: 2 | F5: TS-0 | G5: - | H5: 1 | I5: 0 | J5: PAT-1C | K5: 35 mm² AAAC | L5: 45.3 | M5: 1 | N5: CAC 12/300 | O5: 1 | P5: - | Q5: 0 | R5: 0 | S5: 174434.0564 | T5: 8980110.6284 | U5: 0 | V5: 0 | W5: 0 | X5: 0 | Y5: 0 | Z5: 0 | AA5: 1 | AB5: 0 | AC5: 0 | AD5: 0 | AE5: 0 | AF5: 0 | AG5: 0 | AH5: 0 | AK5: 0 | AL5: 0 | AM5: 1 | AN5: 0 | AO5: CI-C | AP5: 1 | AQ5: 0 | AR5: 1 | AS5: 0 | AT5: 0 | AU5: SI | AV5: =+IF(M5<>0,VLOOKUP($P5,TRAFOS,4,0),"-") -> - | AW5: =IF($L5<250,0,IF($L5<400,$M5*2,IF($L5<600,$M5*4,$M5*6))) -> 0 | AX5: 2 | AY5: =+IF(P5<>0,VLOOKUP($P5,TRAFOS,3,0),"-") -> - | AZ5: =+IF(B5<>0,"NO","-") -> NO | BA5: =+IF($N5<>0,VLOOKUP($N5,POSTES,3,0),"-") -> CAC | BB5: =+IF($N5<>0,VLOOKUP($N5,POSTES,4,0),"-") -> 12/300 | BC5: =+IF($N5<>0,VLOOKUP($N5,POSTES,5,0),0) -> 12 | BI5: =+BI4+1 -> 3 | BK5: CAC 12/300-E | BL5: MT | BM5: CAC | BN5: 12/300 | BO5: 12 | BQ5: 5kVA-1ø-13,2kV | BR5: 5 | BS5: 13,2kV | BT5: 2A-K | BV5: 3 | BW5: HUANCA | BX5: ANCASH | BY5: HUAYLAS | BZ5: PAMPAROMÁS | CA5: 1Ø | CD5: =+SUM(AM5:AN5) -> 1 | CE5: =+SUM(AP5:AQ5) -> 1 | CF5: =+SUM(AR5:AS5) -> 1
A6: =+A5+1 -> 4 | B6: 1 | C6: CONCHIPAMPA | D6: 01 | E6: 3 | F6: PS1-0 | G6: SMM-2P | H6: 0 | I6: 0 | J6: PAT-3 | K6: 35 mm² AAAC | L6: 29.8 | M6: 1 | N6: CAC 12/300 | O6: 1 | P6: 5kVA-1ø-13,2kV | Q6: 1 | R6: 1 | S6: 174461.1523 | T6: 8980123.1393 | U6: 0 | V6: 0 | W6: 0 | X6: 0 | Y6: 0 | Z6: 0 | AA6: 0 | AB6: 0 | AC6: 0 | AD6: 0 | AE6: 0 | AF6: 0 | AG6: 0 | AH6: 0 | AM6: 1 | AN6: 0 | AO6: CI-C | AR6: 1 | AS6: 0 | AT6: 0 | AU6: SI | AV6: =+IF(M6<>0,VLOOKUP($P6,TRAFOS,4,0),"-") -> 2A-K | AW6: =IF($L6<250,0,IF($L6<400,$M6*2,IF($L6<600,$M6*4,$M6*6))) -> 0 | AX6: 2 | AY6: =+IF(P6<>0,VLOOKUP($P6,TRAFOS,3,0),"-") -> 13,2kV | AZ6: =+IF(B6<>0,"NO","-") -> NO | BA6: =+IF($N6<>0,VLOOKUP($N6,POSTES,3,0),"-") -> CAC | BB6: =+IF($N6<>0,VLOOKUP($N6,POSTES,4,0),"-") -> 12/300 | BC6: =+IF($N6<>0,VLOOKUP($N6,POSTES,5,0),0) -> 12 | BI6: =+BI5+1 -> 4 | BK6: CAC 12/200 | BL6: MT | BM6: CAC | BN6: 12/200 | BO6: 12 | BQ6: 10kVA-1ø-13,2kV | BR6: 10 | BS6: 13,2kV | BT6: 2A-K | BV6: 4 | BW6: ALIZO | BX6: ANCASH | BY6: SANTA | BZ6: CACERES DEL PERU | CA6: 1Ø | CD6: =+SUM(AM6:AN6) -> 1 | CE6: =+SUM(AP6:AQ6) -> 0 | CF6: =+SUM(AR6:AS6) -> 1
A7: =+A6+1 -> 5 | B7: 2 | C7: PUEBLO NUEVO HUASCAR | D7: - | E7: 0 | F7: - | G7: DS-0 | H7: 0 | I7: 0 | J7: - | K7: 35 mm² AAAC | L7: 0 | M7: 1 | N7: - | O7: 0 | P7: - | Q7: 0 | R7: 0 | S7: 172081.9996 | T7: 8982503.9895 | U7: 0 | V7: 0 | W7: 0 | X7: 0 | Y7: 0 | Z7: 0 | AA7: 0 | AB7: 0 | AC7: 0 | AD7: 0 | AE7: 0 | AF7: 0 | AG7: 0 | AH7: 0 | AM7: 0 | AN7: 0 | AO7: - | AT7: 0 | AU7: SI | AV7: =+IF(M7<>0,VLOOKUP($P7,TRAFOS,4,0),"-") -> - | AW7: =IF($L7<250,0,IF($L7<400,$M7*2,IF($L7<600,$M7*4,$M7*6))) -> 0 | AX7: 2 | AY7: =+IF(P7<>0,VLOOKUP($P7,TRAFOS,3,0),"-") -> - | AZ7: =+IF(B7<>0,"NO","-") -> NO | BA7: =+IF($N7<>0,VLOOKUP($N7,POSTES,3,0),"-") -> - | BB7: =+IF($N7<>0,VLOOKUP($N7,POSTES,4,0),"-") -> - | BC7: =+IF($N7<>0,VLOOKUP($N7,POSTES,5,0),0) -> - | BI7: =+BI6+1 -> 5 | BK7: CAC 12/300 | BL7: MT | BM7: CAC | BN7: 12/300 | BO7: 12 | BQ7: 15kVA-1ø-13,2kV | BR7: 15 | BS7: 13,2kV | BT7: 3A-K | BV7: 5 | BW7: COTOHUAIN | BX7: ANCASH | BY7: SANTA | BZ7: CACERES DEL PERU | CA7: 1Ø | CD7: =+SUM(AM7:AN7) -> 0 | CE7: =+SUM(AP7:AQ7) -> 0 | CF7: =+SUM(AR7:AS7) -> 0
A8: =+A7+1 -> 6 | B8: 2 | C8: PUEBLO NUEVO HUASCAR | D8: - | E8: 1 | F8: TS-0 | G8: - | H8: 1 | I8: 0 | J8: PAT-1C | K8: 35 mm² AAAC | L8: 29 | M8: 1 | N8: CAC 12/300 | O8: 1 | P8: - | Q8: 0 | R8: 0 | S8: 172058.9236 | T8: 8982521.5358 | U8: 0 | V8: 0 | W8: 0 | X8: 0 | Y8: 0 | Z8: 0 | AA8: 1 | AB8: 0 | AC8: 0 | AD8: 0 | AE8: 0 | AF8: 0 | AG8: 0 | AH8: 0 | AK8: 0 | AL8: 0 | AM8: 1 | AN8: 0 | AO8: CI-C | AP8: 1 | AQ8: 0 | AR8: 1 | AS8: 0 | AT8: 4 | AU8: SI | AV8: =+IF(M8<>0,VLOOKUP($P8,TRAFOS,4,0),"-") -> - | AW8: =IF($L8<250,0,IF($L8<400,$M8*2,IF($L8<600,$M8*4,$M8*6))) -> 0 | AX8: 2 | AY8: =+IF(P8<>0,VLOOKUP($P8,TRAFOS,3,0),"-") -> - | AZ8: =+IF(B8<>0,"NO","-") -> NO | BA8: =+IF($N8<>0,VLOOKUP($N8,POSTES,3,0),"-") -> CAC | BB8: =+IF($N8<>0,VLOOKUP($N8,POSTES,4,0),"-") -> 12/300 | BC8: =+IF($N8<>0,VLOOKUP($N8,POSTES,5,0),0) -> 12 | BI8: =+BI7+1 -> 6 | BK8: CAC 13/300 | BL8: MT | BM8: CAC | BN8: 13/300 | BO8: 13 | BQ8: 25kVA-1ø-13,2kV | BR8: 25 | BS8: 13,2kV | BT8: 3A-K | BV8: 6 | BW8: CUTICALLA | BX8: ANCASH | BY8: SANTA | BZ8: CACERES DEL PERU | CA8: 1Ø | CD8: =+SUM(AM8:AN8) -> 1 | CE8: =+SUM(AP8:AQ8) -> 1 | CF8: =+SUM(AR8:AS8) -> 1
A9: =+A8+1 -> 7 | B9: 2 | C9: PUEBLO NUEVO HUASCAR | D9: - | E9: 2 | F9: PA1-0 | G9: - | H9: 1 | I9: 0 | J9: PAT-1C | K9: 35 mm² AAAC | L9: 115.4 | M9: 1 | N9: CAC 12/300 | O9: 1 | P9: - | Q9: 0 | R9: 0 | S9: 172038.253 | T9: 8982634.9787 | U9: 0 | V9: 0 | W9: 0 | X9: 0 | Y9: 0 | Z9: 0 | AA9: 1 | AB9: 0 | AC9: 0 | AD9: 0 | AE9: 0 | AF9: 0 | AG9: 0 | AH9: 0 | AK9: 0 | AL9: 0 | AM9: 1 | AN9: 0 | AO9: CI-C | AP9: 1 | AQ9: 0 | AR9: 1 | AS9: 0 | AT9: 0 | AU9: SI | AV9: =+IF(M9<>0,VLOOKUP($P9,TRAFOS,4,0),"-") -> - | AW9: =IF($L9<250,0,IF($L9<400,$M9*2,IF($L9<600,$M9*4,$M9*6))) -> 0 | AX9: 2 | AY9: =+IF(P9<>0,VLOOKUP($P9,TRAFOS,3,0),"-") -> - | AZ9: =+IF(B9<>0,"NO","-") -> NO | BA9: =+IF($N9<>0,VLOOKUP($N9,POSTES,3,0),"-") -> CAC | BB9: =+IF($N9<>0,VLOOKUP($N9,POSTES,4,0),"-") -> 12/300 | BC9: =+IF($N9<>0,VLOOKUP($N9,POSTES,5,0),0) -> 12 | BI9: =+BI8+1 -> 7 | BK9: CAC 13/400 | BL9: MT | BM9: CAC | BN9: 13/400 | BO9: 13 | BQ9: - | BR9: - | BS9: - | BT9: - | BV9: 7 | BW9: HICHIK YACU | BX9: ANCASH | BY9: SANTA | BZ9: CACERES DEL PERU | CA9: 1Ø | CD9: =+SUM(AM9:AN9) -> 1 | CE9: =+SUM(AP9:AQ9) -> 1 | CF9: =+SUM(AR9:AS9) -> 1
A10: =+A9+1 -> 8 | B10: 2 | C10: PUEBLO NUEVO HUASCAR | D10: - | E10: 3 | F10: TS-0 | G10: - | H10: 1 | I10: 0 | J10: PAT-1C | K10: 35 mm² AAAC | L10: 63.1 | M10: 1 | N10: CAC 12/300 | O10: 1 | P10: - | Q10: 0 | R10: 0 | S10: 172036.9713 | T10: 8982697.9748 | U10: 0 | V10: 0 | W10: 0 | X10: 0 | Y10: 0 | Z10: 0 | AA10: 1 | AB10: 0 | AC10: 0 | AD10: 0 | AE10: 0 | AF10: 0 | AG10: 0 | AH10: 0 | AK10: 0 | AL10: 0 | AM10: 1 | AN10: 0 | AO10: CI-C | AP10: 1 | AQ10: 0 | AR10: 1 | AS10: 0 | AT10: 2 | AU10: SI | AV10: =+IF(M10<>0,VLOOKUP($P10,TRAFOS,4,0),"-") -> - | AW10: =IF($L10<250,0,IF($L10<400,$M10*2,IF($L10<600,$M10*4,$M10*6))) -> 0 | AX10: 2 | AY10: =+IF(P10<>0,VLOOKUP($P10,TRAFOS,3,0),"-") -> - | AZ10: =+IF(B10<>0,"NO","-") -> NO | BA10: =+IF($N10<>0,VLOOKUP($N10,POSTES,3,0),"-") -> CAC | BB10: =+IF($N10<>0,VLOOKUP($N10,POSTES,4,0),"-") -> 12/300 | BC10: =+IF($N10<>0,VLOOKUP($N10,POSTES,5,0),0) -> 12 | BI10: =+BI9+1 -> 8 | BK10: MAD 12/C5 | BL10: MT | BM10: MAD | BN10: 12/C5 | BO10: 12 | BQ10: 5kVA-2ø-22,9kV | BR10: 5 | BS10: 22,9kV | BT10: 2A-K | BV10: 8 | BW10: MAL PASO | BX10: ANCASH | BY10: SANTA | BZ10: CACERES DEL PERU | CA10: 1Ø | CD10: =+SUM(AM10:AN10) -> 1 | CE10: =+SUM(AP10:AQ10) -> 1 | CF10: =+SUM(AR10:AS10) -> 1
A11: =+A10+1 -> 9 | B11: 2 | C11: PUEBLO NUEVO HUASCAR | D11: - | E11: 4 | F11: PA1-0 | G11: - | H11: 0 | I11: 0 | J11: PAT-1C | K11: 35 mm² AAAC | L11: 36.4 | M11: 1 | N11: CAC 12/300 | O11: 1 | P11: - | Q11: 0 | R11: 0 | S11: 172070.8955 | T11: 8982711.1068 | U11: 0 | V11: 0 | W11: 0 | X11: 0 | Y11: 0 | Z11: 0 | AA11: 0 | AB11: 0 | AC11: 0 | AD11: 0 | AE11: 0 | AF11: 0 | AG11: 0 | AH11: 0 | AM11: 1 | AN11: 0 | AO11: CI-C | AR11: 1 | AS11: 0 | AT11: 0 | AU11: SI | AV11: =+IF(M11<>0,VLOOKUP($P11,TRAFOS,4,0),"-") -> - | AW11: =IF($L11<250,0,IF($L11<400,$M11*2,IF($L11<600,$M11*4,$M11*6))) -> 0 | AX11: 2 | AY11: =+IF(P11<>0,VLOOKUP($P11,TRAFOS,3,0),"-") -> - | AZ11: =+IF(B11<>0,"NO","-") -> NO | BA11: =+IF($N11<>0,VLOOKUP($N11,POSTES,3,0),"-") -> CAC | BB11: =+IF($N11<>0,VLOOKUP($N11,POSTES,4,0),"-") -> 12/300 | BC11: =+IF($N11<>0,VLOOKUP($N11,POSTES,5,0),0) -> 12 | BI11: =+BI10+1 -> 9 | BK11: - | BL11: - | BM11: - | BN11: - | BO11: - | BQ11: 10kVA-2ø-13,8kV | BR11: 10 | BS11: 13,8kV | BT11: 2A-K | BV11: 9 | BW11: QUESHQUE | BX11: ANCASH | BY11: SANTA | BZ11: CACERES DEL PERU | CA11: 1Ø | CD11: =+SUM(AM11:AN11) -> 1 | CE11: =+SUM(AP11:AQ11) -> 0 | CF11: =+SUM(AR11:AS11) -> 1
A12: =+A11+1 -> 10 | B12: 2 | C12: PUEBLO NUEVO HUASCAR | D12: - | E12: 5 | F12: PA1-0 | G12: - | H12: 0 | I12: 0 | J12: PAT-1C | K12: 35 mm² AAAC | L12: 37.9 | M12: 1 | N12: CAC 12/300 | O12: 1 | P12: - | Q12: 0 | R12: 0 | S12: 172079.0269 | T12: 8982674.0201 | U12: 0 | V12: 0 | W12: 0 | X12: 0 | Y12: 0 | Z12: 0 | AA12: 0 | AB12: 0 | AC12: 0 | AD12: 0 | AE12: 0 | AF12: 0 | AG12: 0 | AH12: 0 | AM12: 1 | AN12: 0 | AO12: CI-C | AR12: 1 | AS12: 0 | AT12: 0 | AU12: SI | AV12: =+IF(M12<>0,VLOOKUP($P12,TRAFOS,4,0),"-") -> - | AW12: =IF($L12<250,0,IF($L12<400,$M12*2,IF($L12<600,$M12*4,$M12*6))) -> 0 | AX12: 2 | AY12: =+IF(P12<>0,VLOOKUP($P12,TRAFOS,3,0),"-") -> - | AZ12: =+IF(B12<>0,"NO","-") -> NO | BA12: =+IF($N12<>0,VLOOKUP($N12,POSTES,3,0),"-") -> CAC | BB12: =+IF($N12<>0,VLOOKUP($N12,POSTES,4,0),"-") -> 12/300 | BC12: =+IF($N12<>0,VLOOKUP($N12,POSTES,5,0),0) -> 12 | BI12: =+BI11+1 -> 10 | BK12: PRFV 12/200 | BL12: MT | BM12: PRFV | BN12: 12/200 | BO12: 12 | BQ12: 5kVA-2ø-13,8kV | BR12: 5 | BS12: 13,8kV | BT12: 2A-K | BV12: 10 | BW12: QUITA COLCAP | BX12: ANCASH | BY12: SANTA | BZ12: CACERES DEL PERU | CA12: 1Ø | CD12: =+SUM(AM12:AN12) -> 1 | CE12: =+SUM(AP12:AQ12) -> 0 | CF12: =+SUM(AR12:AS12) -> 1
A13: =+A12+1 -> 11 | B13: 2 | C13: PUEBLO NUEVO HUASCAR | D13: 01 | E13: 6 | F13: PS1-0 | G13: SMM-2P | H13: 0 | I13: 0 | J13: PAT-3 | K13: 35 mm² AAAC | L13: 38 | M13: 1 | N13: CAC 12/300 | O13: 1 | P13: 5kVA-1ø-13,2kV | Q13: 1 | R13: 1 | S13: 172115.8626 | T13: 8982666.8032 | U13: 0 | V13: 0 | W13: 0 | X13: 0 | Y13: 0 | Z13: 0 | AA13: 0 | AB13: 0 | AC13: 0 | AD13: 0 | AE13: 0 | AF13: 0 | AG13: 0 | AH13: 0 | AM13: 1 | AN13: 0 | AO13: CI-C | AR13: 1 | AS13: 0 | AT13: 0 | AU13: SI | AV13: =+IF(M13<>0,VLOOKUP($P13,TRAFOS,4,0),"-") -> 2A-K | AW13: =IF($L13<250,0,IF($L13<400,$M13*2,IF($L13<600,$M13*4,$M13*6))) -> 0 | AX13: 2 | AY13: =+IF(P13<>0,VLOOKUP($P13,TRAFOS,3,0),"-") -> 13,2kV | AZ13: =+IF(B13<>0,"NO","-") -> NO | BA13: =+IF($N13<>0,VLOOKUP($N13,POSTES,3,0),"-") -> CAC | BB13: =+IF($N13<>0,VLOOKUP($N13,POSTES,4,0),"-") -> 12/300 | BC13: =+IF($N13<>0,VLOOKUP($N13,POSTES,5,0),0) -> 12 | BI13: =+BI12+1 -> 11 | BK13: PRFV 12/300 | BL13: MT | BM13: PRFV | BN13: 12/300 | BO13: 12 | BQ13: 25kVA-2ø-13,8kV | BR13: 25 | BS13: 13,8kV | BT13: 3A-K | BV13: 11 | BW13: SHUCUQUI | BX13: ANCASH | BY13: SANTA | BZ13: CACERES DEL PERU | CA13: 1Ø | CD13: =+SUM(AM13:AN13) -> 1 | CE13: =+SUM(AP13:AQ13) -> 0 | CF13: =+SUM(AR13:AS13) -> 1
A14: =+A13+1 -> 12 | B14: 3 | C14: HUANCA | D14: - | E14: 0 | F14: - | G14: DS-0 | H14: 0 | I14: 0 | J14: - | K14: 35 mm² AAAC | L14: 0 | M14: 1 | N14: - | O14: 0 | P14: - | Q14: 0 | R14: 0 | S14: 173294.2221 | T14: 8978052.0843 | U14: 0 | V14: 0 | W14: 0 | X14: 0 | Y14: 0 | Z14: 0 | AA14: 0 | AB14: 0 | AC14: 0 | AD14: 0 | AE14: 0 | AF14: 0 | AG14: 0 | AH14: 0 | AM14: 0 | AN14: 0 | AO14: - | AU14: NO | AV14: =+IF(M14<>0,VLOOKUP($P14,TRAFOS,4,0),"-") -> - | AW14: =IF($L14<250,0,IF($L14<400,$M14*2,IF($L14<600,$M14*4,$M14*6))) -> 0 | AX14: 2 | AY14: =+IF(P14<>0,VLOOKUP($P14,TRAFOS,3,0),"-") -> - | AZ14: =+IF(B14<>0,"NO","-") -> NO | BA14: =+IF($N14<>0,VLOOKUP($N14,POSTES,3,0),"-") -> - | BB14: =+IF($N14<>0,VLOOKUP($N14,POSTES,4,0),"-") -> - | BC14: =+IF($N14<>0,VLOOKUP($N14,POSTES,5,0),0) -> - | BI14: =+BI13+1 -> 12 | BK14: MAD MT Existente | BL14: MT | BM14: MAD | BN14: 12/C5-E | BO14: 12 | BQ14: 37.5kVA-2ø-13,8kV | BR14: 37.5 | BS14: 13,8kV | BT14: 3A-K | BV14: 12 | BW14: MIRAFLORES LOS ALAMOS | BX14: ANCASH | BY14: SANTA | BZ14: CACERES DEL PERU | CA14: 1Ø | CD14: =+SUM(AM14:AN14) -> 0 | CE14: =+SUM(AP14:AQ14) -> 0 | CF14: =+SUM(AR14:AS14) -> 0
A15: =+A14+1 -> 13 | B15: 3 | C15: HUANCA | D15: 01 | E15: 1 | F15: PS1-0 | G15: SMM-2P | H15: 0 | I15: 0 | J15: PAT-3 | K15: 35 mm² AAAC | L15: 24.2 | M15: 1 | N15: PRFV 12/300 | O15: 1 | P15: 5kVA-1ø-13,2kV | Q15: 1 | R15: 1 | S15: 173284.3471 | T15: 8978074.0845 | U15: 0 | V15: 0 | W15: 0 | X15: 0 | Y15: 0 | Z15: 0 | AA15: 0 | AB15: 0 | AC15: 0 | AD15: 0 | AE15: 0 | AF15: 0 | AG15: 0 | AH15: 0 | AM15: 1 | AN15: 0 | AO15: CI-C | AR15: 1 | AS15: 0 | AU15: NO | AV15: =+IF(M15<>0,VLOOKUP($P15,TRAFOS,4,0),"-") -> 2A-K | AW15: =IF($L15<250,0,IF($L15<400,$M15*2,IF($L15<600,$M15*4,$M15*6))) -> 0 | AX15: 2 | AY15: =+IF(P15<>0,VLOOKUP($P15,TRAFOS,3,0),"-") -> 13,2kV | AZ15: =+IF(B15<>0,"NO","-") -> NO | BA15: =+IF($N15<>0,VLOOKUP($N15,POSTES,3,0),"-") -> PRFV | BB15: =+IF($N15<>0,VLOOKUP($N15,POSTES,4,0),"-") -> 12/300 | BC15: =+IF($N15<>0,VLOOKUP($N15,POSTES,5,0),0) -> 12 | BI15: =+BI14+1 -> 13 | BK15: CAC MT Existente | BL15: MT | BM15: CAC | BN15: 12/200-E | BO15: 12 | BQ15: 25kVA-3øE-22,9kV-Existente | BR15: 25 | BS15: 22,9kV | BV15: 13 | BW15: SHIJISPAMPA | BX15: ANCASH | BY15: SANTA | BZ15: CACERES DEL PERU | CA15: 1Ø | CD15: =+SUM(AM15:AN15) -> 1 | CE15: =+SUM(AP15:AQ15) -> 0 | CF15: =+SUM(AR15:AS15) -> 1
A16: =+A15+1 -> 14 | B16: 6 | C16: CUTICALLA | D16: - | E16: 0 | F16: - | G16: DS-0 | H16: 0 | I16: 0 | J16: - | K16: 35 mm² AAAC | L16: 0 | M16: 1 | N16: - | O16: 0 | P16: - | Q16: 0 | R16: 0 | S16: 827655.2368 | T16: 9006937.0561 | U16: 0 | V16: 0 | W16: 0 | X16: 0 | Y16: 0 | Z16: 0 | AA16: 0 | AB16: 0 | AC16: 0 | AD16: 0 | AE16: 0 | AF16: 0 | AG16: 0 | AH16: 0 | AM16: 0 | AN16: 0 | AO16: - | AU16: NO | AV16: =+IF(M16<>0,VLOOKUP($P16,TRAFOS,4,0),"-") -> - | AW16: =IF($L16<250,0,IF($L16<400,$M16*2,IF($L16<600,$M16*4,$M16*6))) -> 0 | AX16: 2 | AY16: =+IF(P16<>0,VLOOKUP($P16,TRAFOS,3,0),"-") -> - | AZ16: =+IF(B16<>0,"NO","-") -> NO | BA16: =+IF($N16<>0,VLOOKUP($N16,POSTES,3,0),"-") -> - | BB16: =+IF($N16<>0,VLOOKUP($N16,POSTES,4,0),"-") -> - | BC16: =+IF($N16<>0,VLOOKUP($N16,POSTES,5,0),0) -> - | BI16: =+BI15+1 -> 14 | BQ16: 40kVA-3øE-22,9kV-Existente | BR16: 40 | BS16: 22,9kV | BV16: 14 | BW16: ANCHACANCHA-JACANAN | BX16: ANCASH | BY16: SANTA | BZ16: CACERES DEL PERU | CA16: 1Ø | CD16: =+SUM(AM16:AN16) -> 0 | CE16: =+SUM(AP16:AQ16) -> 0 | CF16: =+SUM(AR16:AS16) -> 0
A17: =+A16+1 -> 15 | B17: 6 | C17: CUTICALLA | D17: 01 | E17: 1 | F17: PS1-0 | G17: SMM-2P | H17: 0 | I17: 0 | J17: PAT-3 | K17: 35 mm² AAAC | L17: 30.6 | M17: 1 | N17: PRFV 12/300 | O17: 1 | P17: 5kVA-1ø-13,2kV | Q17: 1 | R17: 1 | S17: 827664.3627 | T17: 9006966.2543 | U17: 0 | V17: 0 | W17: 0 | X17: 0 | Y17: 0 | Z17: 0 | AA17: 0 | AB17: 0 | AC17: 0 | AD17: 0 | AE17: 0 | AF17: 0 | AG17: 0 | AH17: 0 | AM17: 1 | AN17: 0 | AO17: CI-C | AR17: 1 | AS17: 0 | AU17: NO | AV17: =+IF(M17<>0,VLOOKUP($P17,TRAFOS,4,0),"-") -> 2A-K | AW17: =IF($L17<250,0,IF($L17<400,$M17*2,IF($L17<600,$M17*4,$M17*6))) -> 0 | AX17: 2 | AY17: =+IF(P17<>0,VLOOKUP($P17,TRAFOS,3,0),"-") -> 13,2kV | AZ17: =+IF(B17<>0,"NO","-") -> NO | BA17: =+IF($N17<>0,VLOOKUP($N17,POSTES,3,0),"-") -> PRFV | BB17: =+IF($N17<>0,VLOOKUP($N17,POSTES,4,0),"-") -> 12/300 | BC17: =+IF($N17<>0,VLOOKUP($N17,POSTES,5,0),0) -> 12 | BI17: =+BI16+1 -> 15 | BQ17: 50kVA-3øE-22,9kV-Existente | BR17: 50 | BS17: 22,9kV | BV17: 15 | BW17: AGUA QUITA ALIZO | BX17: ANCASH | BY17: SANTA | BZ17: MACATE | CA17: 1Ø | CD17: =+SUM(AM17:AN17) -> 1 | CE17: =+SUM(AP17:AQ17) -> 0 | CF17: =+SUM(AR17:AS17) -> 1
A18: =+A17+1 -> 16 | B18: 7 | C18: HICHIK YACU | D18: - | E18: 0 | F18: DS-0 | G18: DS-0A | H18: 0 | I18: 0 | J18: - | K18: 35 mm² AAAC | L18: 0 | M18: 2 | N18: - | O18: 0 | P18: - | Q18: 0 | R18: 0 | S18: 820915.9873 | T18: 9007045.0102 | U18: 0 | V18: 0 | W18: 0 | X18: 0 | Y18: 0 | Z18: 0 | AA18: 0 | AB18: 0 | AC18: 0 | AD18: 0 | AE18: 0 | AF18: 0 | AG18: 0 | AH18: 0 | AM18: 0 | AN18: 0 | AO18: - | AT18: 0 | AU18: SI | AV18: =+IF(M18<>0,VLOOKUP($P18,TRAFOS,4,0),"-") -> - | AW18: =IF($L18<250,0,IF($L18<400,$M18*2,IF($L18<600,$M18*4,$M18*6))) -> 0 | AX18: 2 | AY18: =+IF(P18<>0,VLOOKUP($P18,TRAFOS,3,0),"-") -> - | AZ18: =+IF(B18<>0,"NO","-") -> NO | BA18: =+IF($N18<>0,VLOOKUP($N18,POSTES,3,0),"-") -> - | BB18: =+IF($N18<>0,VLOOKUP($N18,POSTES,4,0),"-") -> - | BC18: =+IF($N18<>0,VLOOKUP($N18,POSTES,5,0),0) -> - | BI18: =+BI17+1 -> 16 | BQ18: 15kVA-2ø-22,9kV-Existente | BR18: 15 | BS18: 22,9kV | BV18: 16 | BW18: NUEVO VALLE LA CARBONERA | BX18: ANCASH | BY18: SANTA | BZ18: NUEVO CHIMBOTE | CA18: 1Ø | CD18: =+SUM(AM18:AN18) -> 0 | CE18: =+SUM(AP18:AQ18) -> 0 | CF18: =+SUM(AR18:AS18) -> 0
A19: =+A18+1 -> 17 | B19: 7 | C19: HICHIK YACU | D19: - | E19: 1 | F19: PS1-2 | G19: - | H19: 0 | I19: 0 | J19: PAT-1C | K19: 35 mm² AAAC | L19: 25 | M19: 2 | N19: CAC 12/200 | O19: 1 | P19: - | Q19: 0 | R19: 0 | S19: 820892.3973 | T19: 9007053.00 | U19: 0 | V19: 0 | W19: 0 | X19: 0 | Y19: 0 | Z19: 0 | AA19: 0 | AB19: 0 | AC19: 0 | AD19: 0 | AE19: 0 | AF19: 0 | AG19: 0 | AH19: 0 | AM19: 1 | AN19: 0 | AO19: CI-C | AR19: 1 | AS19: 0 | AT19: 0 | AU19: SI | AV19: =+IF(M19<>0,VLOOKUP($P19,TRAFOS,4,0),"-") -> - | AW19: =IF($L19<250,0,IF($L19<400,$M19*2,IF($L19<600,$M19*4,$M19*6))) -> 0 | AX19: 2 | AY19: =+IF(P19<>0,VLOOKUP($P19,TRAFOS,3,0),"-") -> - | AZ19: =+IF(B19<>0,"NO","-") -> NO | BA19: =+IF($N19<>0,VLOOKUP($N19,POSTES,3,0),"-") -> CAC | BB19: =+IF($N19<>0,VLOOKUP($N19,POSTES,4,0),"-") -> 12/200 | BC19: =+IF($N19<>0,VLOOKUP($N19,POSTES,5,0),0) -> 12 | BI19: =+BI18+1 -> 17 | BQ19: 40kVA-3øE-22,9kV | BR19: 40 | BS19: 22,9kV | BV19: 17 | BW19: C.P. CESAR VALLEJO | BX19: ANCASH | BY19: SANTA | BZ19: NUEVO CHIMBOTE | CA19: 1Ø | CD19: =+SUM(AM19:AN19) -> 1 | CE19: =+SUM(AP19:AQ19) -> 0 | CF19: =+SUM(AR19:AS19) -> 1
A20: =+A19+1 -> 18 | B20: 7 | C20: HICHIK YACU | D20: 01 | E20: 2 | F20: PS1-2 | G20: SBM-2P | H20: 0 | I20: 0 | J20: PAT-3 | K20: 35 mm² AAAC | L20: 15.5 | M20: 2 | N20: CAC 12/300 | O20: 1 | P20: 5kVA-2ø-22,9kV | Q20: 2 | R20: 2 | S20: 820877.7455 | T20: 9007057.9625 | U20: 0 | V20: 0 | W20: 0 | X20: 0 | Y20: 0 | Z20: 0 | AA20: 0 | AB20: 0 | AC20: 0 | AD20: 0 | AE20: 0 | AF20: 0 | AG20: 0 | AH20: 0 | AM20: 1 | AN20: 0 | AO20: CI-C | AR20: 1 | AS20: 0 | AT20: 0 | AU20: SI | AV20: =+IF(M20<>0,VLOOKUP($P20,TRAFOS,4,0),"-") -> 2A-K | AW20: =IF($L20<250,0,IF($L20<400,$M20*2,IF($L20<600,$M20*4,$M20*6))) -> 0 | AX20: 2 | AY20: =+IF(P20<>0,VLOOKUP($P20,TRAFOS,3,0),"-") -> 22,9kV | AZ20: =+IF(B20<>0,"NO","-") -> NO | BA20: =+IF($N20<>0,VLOOKUP($N20,POSTES,3,0),"-") -> CAC | BB20: =+IF($N20<>0,VLOOKUP($N20,POSTES,4,0),"-") -> 12/300 | BC20: =+IF($N20<>0,VLOOKUP($N20,POSTES,5,0),0) -> 12 | BI20: =+BI19+1 -> 18 | BQ20: 37,5kVA-1ø-13,2kV-Existente | BR20: 37.5 | BS20: 13,2kV | BV20: 18 | BW20: MEDANO NEGRO | BX20: ANCASH | BY20: SANTA | BZ20: NUEVO CHIMBOTE | CA20: 1Ø | CD20: =+SUM(AM20:AN20) -> 1 | CE20: =+SUM(AP20:AQ20) -> 0 | CF20: =+SUM(AR20:AS20) -> 1
A21: =+A20+1 -> 19 | B21: 8 | C21: MAL PASO | D21: - | E21: 0 | F21: DS-0 | G21: DS-0A | H21: 0 | I21: 0 | J21: - | K21: 35 mm² AAAC | L21: 0 | M21: 2 | N21: - | O21: 0 | P21: - | Q21: 0 | R21: 0 | S21: 821816.32 | T21: 9005158.4 | U21: 0 | V21: 0 | W21: 0 | X21: 0 | Y21: 0 | Z21: 0 | AA21: 0 | AB21: 0 | AC21: 0 | AD21: 0 | AE21: 0 | AF21: 0 | AG21: 0 | AH21: 0 | AM21: 0 | AN21: 0 | AO21: - | AT21: 0 | AU21: SI | AV21: =+IF(M21<>0,VLOOKUP($P21,TRAFOS,4,0),"-") -> - | AW21: =IF($L21<250,0,IF($L21<400,$M21*2,IF($L21<600,$M21*4,$M21*6))) -> 0 | AX21: 2 | AY21: =+IF(P21<>0,VLOOKUP($P21,TRAFOS,3,0),"-") -> - | AZ21: NO | BA21: =+IF($N21<>0,VLOOKUP($N21,POSTES,3,0),"-") -> - | BB21: =+IF($N21<>0,VLOOKUP($N21,POSTES,4,0),"-") -> - | BC21: =+IF($N21<>0,VLOOKUP($N21,POSTES,5,0),0) -> - | BI21: =+BI20+1 -> 19 | BV21: 19 | BW21: PAMPA HERMOSA | BX21: ANCASH | BY21: SANTA | BZ21: NUEVO CHIMBOTE | CA21: 1Ø | CD21: =+SUM(AM21:AN21) -> 0 | CE21: =+SUM(AP21:AQ21) -> 0 | CF21: =+SUM(AR21:AS21) -> 0
A22: =+A21+1 -> 20 | B22: 8 | C22: MAL PASO | D22: 01 | E22: 1 | F22: PS1-2 | G22: SBM-2P | H22: 0 | I22: 0 | J22: PAT-3 | K22: 35 mm² AAAC | L22: 42.7 | M22: 2 | N22: CAC 12/300 | O22: 1 | P22: 5kVA-2ø-22,9kV | Q22: 2 | R22: 2 | S22: 821777.92 | T22: 9005137.92 | U22: 0 | V22: 0 | W22: 0 | X22: 0 | Y22: 0 | Z22: 0 | AA22: 0 | AB22: 0 | AC22: 0 | AD22: 0 | AE22: 0 | AF22: 0 | AG22: 0 | AH22: 0 | AM22: 1 | AN22: 0 | AO22: CI-C | AR22: 1 | AS22: 0 | AT22: 0 | AU22: SI | AV22: =+IF(M22<>0,VLOOKUP($P22,TRAFOS,4,0),"-") -> 2A-K | AW22: =IF($L22<250,0,IF($L22<400,$M22*2,IF($L22<600,$M22*4,$M22*6))) -> 0 | AX22: 2 | AY22: =+IF(P22<>0,VLOOKUP($P22,TRAFOS,3,0),"-") -> 22,9kV | AZ22: =+IF(B22<>0,"NO","-") -> NO | BA22: =+IF($N22<>0,VLOOKUP($N22,POSTES,3,0),"-") -> CAC | BB22: =+IF($N22<>0,VLOOKUP($N22,POSTES,4,0),"-") -> 12/300 | BC22: =+IF($N22<>0,VLOOKUP($N22,POSTES,5,0),0) -> 12 | BI22: =+BI21+1 -> 20 | BV22: 20 | BW22: EL PARAISO NUEVO VALLE LA CARBONERA | BX22: ANCASH | BY22: SANTA | BZ22: NUEVO CHIMBOTE | CA22: 1Ø | CD22: =+SUM(AM22:AN22) -> 1 | CE22: =+SUM(AP22:AQ22) -> 0 | CF22: =+SUM(AR22:AS22) -> 1
A23: =+A22+1 -> 21 | B23: 9 | C23: QUESHQUE | D23: - | H23: 0 | I23: 0 | J23: - | K23: 35 mm² AAAC | M23: 1 | N23: - | P23: - | S23: 821672.9083 | T23: 9009910.98 | U23: 0 | V23: 0 | W23: 0 | X23: 0 | Y23: 0 | Z23: 0 | AA23: 0 | AB23: 0 | AC23: 0 | AD23: 0 | AE23: 0 | AF23: 0 | AG23: 0 | AH23: 0 | AM23: 0 | AN23: 0 | AO23: - | AT23: 2 | AU23: SI | AV23: =+IF(M23<>0,VLOOKUP($P23,TRAFOS,4,0),"-") -> - | AW23: =IF($L23<250,0,IF($L23<400,$M23*2,IF($L23<600,$M23*4,$M23*6))) -> 0 | AX23: 2 | AY23: =+IF(P23<>0,VLOOKUP($P23,TRAFOS,3,0),"-") -> - | AZ23: =+IF(B23<>0,"NO","-") -> NO | BA23: =+IF($N23<>0,VLOOKUP($N23,POSTES,3,0),"-") -> - | BB23: =+IF($N23<>0,VLOOKUP($N23,POSTES,4,0),"-") -> - | BC23: =+IF($N23<>0,VLOOKUP($N23,POSTES,5,0),0) -> - | BI23: =+BI22+1 -> 21 | CD23: =+SUM(AM23:AN23) -> 0 | CE23: =+SUM(AP23:AQ23) -> 0 | CF23: =+SUM(AR23:AS23) -> 0
A24: =+A23+1 -> 22 | B24: 9 | C24: QUESHQUE | D24: 01 | H24: 0 | I24: 0 | J24: - | K24: 35 mm² AAAC | M24: 1 | N24: CAC 12/300 | O24: 0 | P24: - | S24: 821657.538 | T24: 9009913.86 | U24: 0 | V24: 0 | W24: 0 | X24: 0 | Y24: 0 | Z24: 0 | AA24: 0 | AB24: 0 | AC24: 0 | AD24: 0 | AE24: 0 | AF24: 0 | AG24: 0 | AH24: 0 | AM24: 1 | AN24: 0 | AO24: CI-C | AT24: 0 | AU24: SI | AV24: =+IF(M24<>0,VLOOKUP($P24,TRAFOS,4,0),"-") -> - | AW24: =IF($L24<250,0,IF($L24<400,$M24*2,IF($L24<600,$M24*4,$M24*6))) -> 0 | AX24: 2 | AY24: =+IF(P24<>0,VLOOKUP($P24,TRAFOS,3,0),"-") -> - | AZ24: =+IF(B24<>0,"NO","-") -> NO | BA24: =+IF($N24<>0,VLOOKUP($N24,POSTES,3,0),"-") -> CAC | BB24: =+IF($N24<>0,VLOOKUP($N24,POSTES,4,0),"-") -> 12/300 | BC24: =+IF($N24<>0,VLOOKUP($N24,POSTES,5,0),0) -> 12 | BI24: =+BI23+1 -> 22 | CD24: =+SUM(AM24:AN24) -> 1 | CE24: =+SUM(AP24:AQ24) -> 0 | CF24: =+SUM(AR24:AS24) -> 0
A25: =+A24+1 -> 23 | B25: 10 | C25: QUITA COLCAP | D25: - | E25: 1 | F25: - | G25: DS-0 | H25: 0 | I25: 0 | J25: - | K25: 35 mm² AAAC | L25: 0 | M25: 1 | N25: - | O25: 0 | P25: - | Q25: 0 | R25: 0 | S25: 824014.03 | T25: 9005995.55 | U25: 0 | V25: 0 | W25: 0 | X25: 0 | Y25: 0 | Z25: 0 | AA25: 0 | AB25: 0 | AC25: 0 | AD25: 0 | AE25: 0 | AF25: 0 | AG25: 0 | AH25: 0 | AM25: 0 | AN25: 0 | AO25: - | AT25: 0 | AU25: NO | AV25: =+IF(M25<>0,VLOOKUP($P25,TRAFOS,4,0),"-") -> - | AW25: =IF($L25<250,0,IF($L25<400,$M25*2,IF($L25<600,$M25*4,$M25*6))) -> 0 | AX25: 2 | AY25: =+IF(P25<>0,VLOOKUP($P25,TRAFOS,3,0),"-") -> - | AZ25: =+IF(B25<>0,"NO","-") -> NO | BA25: =+IF($N25<>0,VLOOKUP($N25,POSTES,3,0),"-") -> - | BB25: =+IF($N25<>0,VLOOKUP($N25,POSTES,4,0),"-") -> - | BC25: =+IF($N25<>0,VLOOKUP($N25,POSTES,5,0),0) -> - | BI25: =+BI24+1 -> 23 | CD25: =+SUM(AM25:AN25) -> 0 | CE25: =+SUM(AP25:AQ25) -> 0 | CF25: =+SUM(AR25:AS25) -> 0
A26: =+A25+1 -> 24 | B26: 10 | C26: QUITA COLCAP | D26: 01 | E26: 2 | F26: PS1-0 | G26: SMM-2P | H26: 0 | I26: 0 | J26: PAT-3 | K26: 35 mm² AAAC | L26: 34.42 | M26: 1 | N26: PRFV 12/300 | O26: 1 | P26: 5kVA-1ø-13,2kV | Q26: 1 | R26: 1 | S26: 824037.11 | T26: 9005969.88 | U26: 0 | V26: 0 | W26: 0 | X26: 0 | Y26: 0 | Z26: 0 | AA26: 0 | AB26: 0 | AC26: 0 | AD26: 0 | AE26: 0 | AF26: 0 | AG26: 0 | AH26: 0 | AM26: 1 | AN26: 0 | AO26: CI-C | AR26: 1 | AS26: 0 | AT26: 0 | AU26: NO | AV26: =+IF(M26<>0,VLOOKUP($P26,TRAFOS,4,0),"-") -> 2A-K | AW26: =IF($L26<250,0,IF($L26<400,$M26*2,IF($L26<600,$M26*4,$M26*6))) -> 0 | AX26: 2 | AY26: =+IF(P26<>0,VLOOKUP($P26,TRAFOS,3,0),"-") -> 13,2kV | AZ26: =+IF(B26<>0,"NO","-") -> NO | BA26: =+IF($N26<>0,VLOOKUP($N26,POSTES,3,0),"-") -> PRFV | BB26: =+IF($N26<>0,VLOOKUP($N26,POSTES,4,0),"-") -> 12/300 | BC26: =+IF($N26<>0,VLOOKUP($N26,POSTES,5,0),0) -> 12 | BI26: =+BI25+1 -> 24 | CD26: =+SUM(AM26:AN26) -> 1 | CE26: =+SUM(AP26:AQ26) -> 0 | CF26: =+SUM(AR26:AS26) -> 1
A27: =+A26+1 -> 25 | B27: 11 | C27: SHUCUQUI | D27: - | E27: 1 | F27: - | G27: - | H27: 0 | I27: 0 | J27: - | K27: 35 mm² AAAC | L27: 0 | M27: 1 | N27: - | O27: 0 | P27: - | Q27: 0 | R27: 0 | S27: 823595.72 | T27: 9008347.95 | U27: 0 | V27: 0 | W27: 0 | X27: 0 | Y27: 0 | Z27: 0 | AA27: 0 | AB27: 0 | AC27: 0 | AD27: 0 | AE27: 0 | AF27: 0 | AG27: 0 | AH27: 0 | AM27: 0 | AN27: 0 | AO27: - | AT27: 2 | AU27: NO | AV27: =+IF(M27<>0,VLOOKUP($P27,TRAFOS,4,0),"-") -> - | AW27: =IF($L27<250,0,IF($L27<400,$M27*2,IF($L27<600,$M27*4,$M27*6))) -> 0 | AX27: 2 | AY27: =+IF(P27<>0,VLOOKUP($P27,TRAFOS,3,0),"-") -> - | AZ27: =+IF(B27<>0,"NO","-") -> NO | BA27: =+IF($N27<>0,VLOOKUP($N27,POSTES,3,0),"-") -> - | BB27: =+IF($N27<>0,VLOOKUP($N27,POSTES,4,0),"-") -> - | BC27: =+IF($N27<>0,VLOOKUP($N27,POSTES,5,0),0) -> - | BI27: =+BI26+1 -> 25 | CD27: =+SUM(AM27:AN27) -> 0 | CE27: =+SUM(AP27:AQ27) -> 0 | CF27: =+SUM(AR27:AS27) -> 0
A28: =+A27+1 -> 26 | B28: 11 | C28: SHUCUQUI | D28: 01 | E28: 2 | F28: PTV-0 | G28: SMM-1P | H28: 0 | I28: 0 | J28: PAT-3 | K28: 35 mm² AAAC | L28: 41.94 | M28: 1 | N28: PRFV 12/300 | O28: 1 | P28: 5kVA-1ø-13,2kV | Q28: 1 | R28: 1 | S28: 823634.01 | T28: 9008331.00 | U28: 0 | V28: 0 | W28: 0 | X28: 0 | Y28: 0 | Z28: 0 | AA28: 0 | AB28: 0 | AC28: 0 | AD28: 0 | AE28: 0 | AF28: 0 | AG28: 0 | AH28: 0 | AM28: 1 | AN28: 0 | AO28: CI-C | AR28: 1 | AS28: 0 | AT28: 0 | AU28: NO | AV28: =+IF(M28<>0,VLOOKUP($P28,TRAFOS,4,0),"-") -> 2A-K | AW28: =IF($L28<250,0,IF($L28<400,$M28*2,IF($L28<600,$M28*4,$M28*6))) -> 0 | AX28: 2 | AY28: =+IF(P28<>0,VLOOKUP($P28,TRAFOS,3,0),"-") -> 13,2kV | AZ28: =+IF(B28<>0,"NO","-") -> NO | BA28: =+IF($N28<>0,VLOOKUP($N28,POSTES,3,0),"-") -> PRFV | BB28: =+IF($N28<>0,VLOOKUP($N28,POSTES,4,0),"-") -> 12/300 | BC28: =+IF($N28<>0,VLOOKUP($N28,POSTES,5,0),0) -> 12 | BI28: =+BI27+1 -> 26 | CD28: =+SUM(AM28:AN28) -> 1 | CE28: =+SUM(AP28:AQ28) -> 0 | CF28: =+SUM(AR28:AS28) -> 1
A29: =+A28+1 -> 27 | B29: 13 | C29: SHIJISPAMPA | D29: - | E29: 1 | F29: DT-0 | H29: 0 | I29: 0 | J29: - | K29: 35 mm² AAAC | L29: 0 | M29: 1 | N29: - | O29: 0 | P29: - | Q29: 0 | R29: 0 | S29: 821469.2362 | T29: 9002799.9433 | U29: 0 | V29: 0 | W29: 0 | X29: 0 | Y29: 0 | Z29: 0 | AA29: 0 | AB29: 0 | AC29: 0 | AD29: 0 | AE29: 0 | AF29: 0 | AG29: 0 | AH29: 0 | AM29: 0 | AN29: 0 | AO29: - | AT29: 0 | AU29: SI | AV29: =+IF(M29<>0,VLOOKUP($P29,TRAFOS,4,0),"-") -> - | AW29: =IF($L29<250,0,IF($L29<400,$M29*2,IF($L29<600,$M29*4,$M29*6))) -> 0 | AX29: 2 | AY29: =+IF(P29<>0,VLOOKUP($P29,TRAFOS,3,0),"-") -> - | AZ29: =+IF(B29<>0,"NO","-") -> NO | BA29: =+IF($N29<>0,VLOOKUP($N29,POSTES,3,0),"-") -> - | BB29: =+IF($N29<>0,VLOOKUP($N29,POSTES,4,0),"-") -> - | BC29: =+IF($N29<>0,VLOOKUP($N29,POSTES,5,0),0) -> - | BI29: =+BI28+1 -> 27 | CD29: =+SUM(AM29:AN29) -> 0 | CE29: =+SUM(AP29:AQ29) -> 0 | CF29: =+SUM(AR29:AS29) -> 0
A30: =+A29+1 -> 28 | B30: 13 | C30: SHIJISPAMPA | D30: - | E30: 2 | F30: PS1-0 | G30: - | H30: 0 | I30: 0 | J30: PAT-1C | K30: 35 mm² AAAC | L30: 16 | M30: 1 | N30: CAC 12/300 | O30: 1 | P30: - | Q30: 0 | R30: 0 | S30: 821480.25 | T30: 9002788.8 | U30: 0 | V30: 0 | W30: 0 | X30: 0 | Y30: 0 | Z30: 0 | AA30: 0 | AB30: 0 | AC30: 0 | AD30: 0 | AE30: 0 | AF30: 0 | AG30: 0 | AH30: 0 | AM30: 1 | AN30: 0 | AO30: CI-C | AR30: 1 | AS30: 0 | AT30: 0 | AU30: SI | AV30: =+IF(M30<>0,VLOOKUP($P30,TRAFOS,4,0),"-") -> - | AW30: =IF($L30<250,0,IF($L30<400,$M30*2,IF($L30<600,$M30*4,$M30*6))) -> 0 | AX30: 2 | AY30: =+IF(P30<>0,VLOOKUP($P30,TRAFOS,3,0),"-") -> - | AZ30: =+IF(B30<>0,"NO","-") -> NO | BA30: =+IF($N30<>0,VLOOKUP($N30,POSTES,3,0),"-") -> CAC | BB30: =+IF($N30<>0,VLOOKUP($N30,POSTES,4,0),"-") -> 12/300 | BC30: =+IF($N30<>0,VLOOKUP($N30,POSTES,5,0),0) -> 12 | BI30: =+BI29+1 -> 28 | CD30: =+SUM(AM30:AN30) -> 1
A31: =+A30+1 -> 29 | B31: 13 | C31: SHIJISPAMPA | D31: 01 | E31: 3 | F31: PTV-0 | G31: SMM-1P | H31: 0 | I31: 0 | J31: PAT-3 | K31: 35 mm² AAAC | L31: 25 | M31: 1 | N31: CAC 12/300 | O31: 1 | P31: 5kVA-1ø-13,2kV | Q31: 1 | R31: 1 | S31: 821497.8347 | T31: 9002771.0121 | U31: 0 | V31: 0 | W31: 0 | X31: 0 | Y31: 0 | Z31: 0 | AA31: 0 | AB31: 0 | AC31: 0 | AD31: 0 | AE31: 0 | AF31: 0 | AG31: 0 | AH31: 0 | AM31: 1 | AN31: 0 | AO31: CI-C | AR31: 1 | AS31: 0 | AT31: 4 | AU31: SI | AV31: =+IF(M31<>0,VLOOKUP($P31,TRAFOS,4,0),"-") -> 2A-K | AW31: =IF($L31<250,0,IF($L31<400,$M31*2,IF($L31<600,$M31*4,$M31*6))) -> 0 | AX31: 2 | AY31: =+IF(P31<>0,VLOOKUP($P31,TRAFOS,3,0),"-") -> 13,2kV | AZ31: =+IF(B31<>0,"NO","-") -> NO | BA31: =+IF($N31<>0,VLOOKUP($N31,POSTES,3,0),"-") -> CAC | BB31: =+IF($N31<>0,VLOOKUP($N31,POSTES,4,0),"-") -> 12/300 | BC31: =+IF($N31<>0,VLOOKUP($N31,POSTES,5,0),0) -> 12 | BI31: =+BI30+1 -> 29 | CD31: =+SUM(AM31:AN31) -> 1 | CE31: =+SUM(AP31:AQ31) -> 0 | CF31: =+SUM(AR31:AS31) -> 1
A32: =+A31+1 -> 30 | B32: 15 | C32: AGUA QUITA ALIZO | D32: - | E32: 1 | F32: - | G32: DS-0 | H32: 0 | I32: 0 | J32: - | K32: 35 mm² AAAC | L32: 0 | M32: 1 | N32: - | O32: 0 | P32: - | Q32: 0 | R32: 0 | S32: 812082.87 | T32: 9015811.14 | U32: 0 | V32: 0 | W32: 0 | X32: 0 | Y32: 0 | Z32: 0 | AA32: 0 | AB32: 0 | AC32: 0 | AD32: 0 | AE32: 0 | AF32: 0 | AG32: 0 | AH32: 0 | AM32: 0 | AN32: 0 | AO32: - | AT32: 4 | AU32: NO | AV32: =+IF(M32<>0,VLOOKUP($P32,TRAFOS,4,0),"-") -> - | AW32: =IF($L32<250,0,IF($L32<400,$M32*2,IF($L32<600,$M32*4,$M32*6))) -> 0 | AX32: 2 | AY32: =+IF(P32<>0,VLOOKUP($P32,TRAFOS,3,0),"-") -> - | AZ32: =+IF(B32<>0,"NO","-") -> NO | BA32: =+IF($N32<>0,VLOOKUP($N32,POSTES,3,0),"-") -> - | BB32: =+IF($N32<>0,VLOOKUP($N32,POSTES,4,0),"-") -> - | BC32: =+IF($N32<>0,VLOOKUP($N32,POSTES,5,0),0) -> - | BI32: =+BI31+1 -> 30 | CD32: =+SUM(AM32:AN32) -> 0 | CE32: =+SUM(AP32:AQ32) -> 0 | CF32: =+SUM(AR32:AS32) -> 0
A33: =+A32+1 -> 31 | B33: 15 | C33: AGUA QUITA ALIZO | D33: 02 | E33: 2 | F33: PS1-0 | G33: SMM-2P | H33: 0 | I33: 0 | J33: PAT-3 | K33: 35 mm² AAAC | L33: 23.62 | M33: 1 | N33: PRFV 12/300 | O33: 1 | P33: 5kVA-1ø-13,2kV | Q33: 1 | R33: 1 | S33: 812060.08 | T33: 9015805.44 | U33: 0 | V33: 0 | W33: 0 | X33: 0 | Y33: 0 | Z33: 0 | AA33: 0 | AB33: 0 | AC33: 0 | AD33: 0 | AE33: 0 | AF33: 0 | AG33: 0 | AH33: 0 | AM33: 1 | AN33: 0 | AO33: CI-C | AR33: 1 | AS33: 0 | AT33: 0 | AU33: NO | AV33: =+IF(M33<>0,VLOOKUP($P33,TRAFOS,4,0),"-") -> 2A-K | AW33: =IF($L33<250,0,IF($L33<400,$M33*2,IF($L33<600,$M33*4,$M33*6))) -> 0 | AX33: 2 | AY33: =+IF(P33<>0,VLOOKUP($P33,TRAFOS,3,0),"-") -> 13,2kV | AZ33: =+IF(B33<>0,"NO","-") -> NO | BA33: =+IF($N33<>0,VLOOKUP($N33,POSTES,3,0),"-") -> PRFV | BB33: =+IF($N33<>0,VLOOKUP($N33,POSTES,4,0),"-") -> 12/300 | BC33: =+IF($N33<>0,VLOOKUP($N33,POSTES,5,0),0) -> 12 | BI33: =+BI32+1 -> 31 | CD33: =+SUM(AM33:AN33) -> 1 | CE33: =+SUM(AP33:AQ33) -> 0 | CF33: =+SUM(AR33:AS33) -> 1
A34: =+A33+1 -> 32 | B34: 16 | C34: NUEVO VALLE LA CARBONERA | D34: - | E34: 0 | F34: EC | G34: - | H34: 0 | I34: 0 | J34: - | K34: 35 mm² AAAC | L34: 0 | M34: 2 | N34: - | O34: 0 | P34: - | Q34: 0 | R34: 0 | S34: - | T34: - | U34: 0 | V34: 0 | W34: 0 | X34: 0 | Y34: 0 | Z34: 0 | AA34: 0 | AB34: 0 | AC34: 0 | AD34: 0 | AE34: 0 | AF34: 0 | AG34: 0 | AH34: 0 | AM34: 0 | AN34: 0 | AO34: - | AU34: SI | AV34: =+IF(M34<>0,VLOOKUP($P34,TRAFOS,4,0),"-") -> - | AW34: =IF($L34<250,0,IF($L34<400,$M34*2,IF($L34<600,$M34*4,$M34*6))) -> 0 | AX34: 2 | AY34: =+IF(P34<>0,VLOOKUP($P34,TRAFOS,3,0),"-") -> - | AZ34: =+IF(B34<>0,"NO","-") -> NO | BA34: =+IF($N34<>0,VLOOKUP($N34,POSTES,3,0),"-") -> - | BB34: =+IF($N34<>0,VLOOKUP($N34,POSTES,4,0),"-") -> - | BC34: =+IF($N34<>0,VLOOKUP($N34,POSTES,5,0),0) -> - | BI34: =+BI33+1 -> 32 | CD34: =+SUM(AM34:AN34) -> 0 | CE34: =+SUM(AP34:AQ34) -> 0 | CF34: =+SUM(AR34:AS34) -> 0
A35: =+A34+1 -> 33 | B35: 16 | C35: NUEVO VALLE LA CARBONERA | D35: - | E35: 1 | F35: TSVE-2 | G35: - | H35: 1 | I35: 0 | J35: PAT-1C | K35: 35 mm² AAAC | L35: 10 | M35: 2 | N35: CAC 13/400 | O35: 1 | P35: - | Q35: 0 | R35: 0 | S35: 783434.99 | T35: 8992271.00 | U35: 0 | V35: 0 | W35: 0 | X35: 0 | Y35: 0 | Z35: 0 | AA35: 0 | AB35: 0 | AC35: 0 | AD35: 0 | AE35: 0 | AF35: 0 | AG35: 0 | AH35: 0 | AK35: 1 | AL35: 0 | AM35: 1 | AN35: 0 | AO35: CI-A | AP35: 1 | AQ35: 0 | AR35: 1 | AS35: 0 | AU35: SI | AV35: =+IF(M35<>0,VLOOKUP($P35,TRAFOS,4,0),"-") -> - | AW35: =IF($L35<250,0,IF($L35<400,$M35*2,IF($L35<600,$M35*4,$M35*6))) -> 0 | AX35: 2 | AY35: =+IF(P35<>0,VLOOKUP($P35,TRAFOS,3,0),"-") -> - | AZ35: =+IF(B35<>0,"NO","-") -> NO | BA35: =+IF($N35<>0,VLOOKUP($N35,POSTES,3,0),"-") -> CAC | BB35: =+IF($N35<>0,VLOOKUP($N35,POSTES,4,0),"-") -> 13/400 | BC35: =+IF($N35<>0,VLOOKUP($N35,POSTES,5,0),0) -> 13 | BI35: =+BI34+1 -> 33 | CD35: =+SUM(AM35:AN35) -> 1 | CE35: =+SUM(AP35:AQ35) -> 1 | CF35: =+SUM(AR35:AS35) -> 1
A36: =+A35+1 -> 34 | B36: 16 | C36: NUEVO VALLE LA CARBONERA | D36: - | E36: 2 | F36: TSVE-2 | G36: - | H36: 1 | I36: 0 | J36: PAT-1C | K36: 35 mm² AAAC | L36: 88 | M36: 2 | N36: CAC 13/400 | O36: 1 | P36: - | Q36: 0 | R36: 0 | S36: 783378.85 | T36: 8992337.92 | U36: 0 | V36: 0 | W36: 0 | X36: 0 | Y36: 0 | Z36: 0 | AA36: 0 | AB36: 0 | AC36: 0 | AD36: 0 | AE36: 0 | AF36: 0 | AG36: 0 | AH36: 0 | AK36: 1 | AL36: 0 | AM36: 1 | AN36: 0 | AO36: CI-A | AP36: 1 | AQ36: 0 | AR36: 1 | AS36: 0 | AT36: 0 | AU36: SI | AV36: =+IF(M36<>0,VLOOKUP($P36,TRAFOS,4,0),"-") -> - | AW36: =IF($L36<250,0,IF($L36<400,$M36*2,IF($L36<600,$M36*4,$M36*6))) -> 0 | AX36: 2 | AY36: =+IF(P36<>0,VLOOKUP($P36,TRAFOS,3,0),"-") -> - | AZ36: =+IF(B36<>0,"NO","-") -> NO | BA36: =+IF($N36<>0,VLOOKUP($N36,POSTES,3,0),"-") -> CAC | BB36: =+IF($N36<>0,VLOOKUP($N36,POSTES,4,0),"-") -> 13/400 | BC36: =+IF($N36<>0,VLOOKUP($N36,POSTES,5,0),0) -> 13 | BI36: =+BI35+1 -> 34 | CD36: =+SUM(AM36:AN36) -> 1 | CE36: =+SUM(AP36:AQ36) -> 1 | CF36: =+SUM(AR36:AS36) -> 1
A37: =+A36+1 -> 35 | B37: 16 | C37: NUEVO VALLE LA CARBONERA | D37: 01 | E37: 3 | F37: PSVE-2 | G37: SBM-2V | H37: 0 | I37: 0 | J37: PAT-3 | K37: 35 mm² AAAC | L37: 26.8 | M37: 2 | N37: CAC 13/400 | O37: 1 | P37: 37.5kVA-2ø-13,8kV | Q37: 2 | R37: 2 | S37: 783361.96 | T37: 8992338.69 | U37: 0 | V37: 0 | W37: 0 | X37: 0 | Y37: 0 | Z37: 0 | AA37: 0 | AB37: 0 | AC37: 0 | AD37: 0 | AE37: 0 | AF37: 0 | AG37: 0 | AH37: 0 | AM37: 1 | AN37: 0 | AO37: CI-A | AR37: 1 | AS37: 0 | AT37: 0 | AU37: SI | AV37: =+IF(M37<>0,VLOOKUP($P37,TRAFOS,4,0),"-") -> 3A-K | AW37: =IF($L37<250,0,IF($L37<400,$M37*2,IF($L37<600,$M37*4,$M37*6))) -> 0 | AX37: 2 | AY37: =+IF(P37<>0,VLOOKUP($P37,TRAFOS,3,0),"-") -> 13,8kV | AZ37: =+IF(B37<>0,"NO","-") -> NO | BA37: =+IF($N37<>0,VLOOKUP($N37,POSTES,3,0),"-") -> CAC | BB37: =+IF($N37<>0,VLOOKUP($N37,POSTES,4,0),"-") -> 13/400 | BC37: =+IF($N37<>0,VLOOKUP($N37,POSTES,5,0),0) -> 13 | BI37: =+BI36+1 -> 35 | CD37: =+SUM(AM37:AN37) -> 1 | CE37: =+SUM(AP37:AQ37) -> 0 | CF37: =+SUM(AR37:AS37) -> 1
A38: =+A37+1 -> 36 | B38: 17 | C38: C.P. CESAR VALLEJO | D38: - | E38: 0 | F38: - | G38: DS-2 | H38: 0 | I38: 0 | J38: - | K38: 35 mm² AAAC | L38: 0 | M38: 2 | N38: - | O38: 0 | P38: - | Q38: 0 | R38: 0 | S38: 783661.69 | T38: 8995683.85 | U38: 0 | V38: 0 | W38: 0 | X38: 0 | Y38: 0 | Z38: 0 | AA38: 0 | AB38: 0 | AC38: 0 | AD38: 0 | AE38: 0 | AF38: 0 | AG38: 0 | AH38: 0 | AM38: 0 | AN38: 0 | AO38: - | AT38: 0 | AU38: SI | AV38: =+IF(M38<>0,VLOOKUP($P38,TRAFOS,4,0),"-") -> - | AW38: =IF($L38<250,0,IF($L38<400,$M38*2,IF($L38<600,$M38*4,$M38*6))) -> 0 | AX38: 2 | AY38: =+IF(P38<>0,VLOOKUP($P38,TRAFOS,3,0),"-") -> - | AZ38: =+IF(B38<>0,"NO","-") -> NO | BA38: =+IF($N38<>0,VLOOKUP($N38,POSTES,3,0),"-") -> - | BB38: =+IF($N38<>0,VLOOKUP($N38,POSTES,4,0),"-") -> - | BC38: =+IF($N38<>0,VLOOKUP($N38,POSTES,5,0),0) -> - | BI38: =+BI37+1 -> 36 | CD38: =+SUM(AM38:AN38) -> 0 | CE38: =+SUM(AP38:AQ38) -> 0 | CF38: =+SUM(AR38:AS38) -> 0
A39: =+A38+1 -> 37 | B39: 17 | C39: C.P. CESAR VALLEJO | D39: - | E39: 1 | F39: PSVE-2 | G39: - | H39: 0 | I39: 0 | J39: PAT-1C | K39: 35 mm² AAAC | L39: 24.7 | M39: 2 | N39: CAC 13/400 | O39: 1 | P39: - | Q39: 0 | R39: 0 | S39: 783685.86 | T39: 8995687.97 | U39: 0 | V39: 0 | W39: 0 | X39: 0 | Y39: 0 | Z39: 0 | AA39: 1 | AB39: 0 | AC39: 0 | AD39: 0 | AE39: 0 | AF39: 0 | AG39: 0 | AH39: 0 | AM39: 1 | AN39: 0 | AO39: CI-A | AP39: 0 | AQ39: 1 | AR39: 1 | AS39: 0 | AT39: 0 | AU39: SI | AV39: =+IF(M39<>0,VLOOKUP($P39,TRAFOS,4,0),"-") -> - | AW39: =IF($L39<250,0,IF($L39<400,$M39*2,IF($L39<600,$M39*4,$M39*6))) -> 0 | AX39: 2 | AY39: =+IF(P39<>0,VLOOKUP($P39,TRAFOS,3,0),"-") -> - | AZ39: =+IF(B39<>0,"NO","-") -> NO | BA39: =+IF($N39<>0,VLOOKUP($N39,POSTES,3,0),"-") -> CAC | BB39: =+IF($N39<>0,VLOOKUP($N39,POSTES,4,0),"-") -> 13/400 | BC39: =+IF($N39<>0,VLOOKUP($N39,POSTES,5,0),0) -> 13 | BI39: =+BI38+1 -> 37 | CD39: =+SUM(AM39:AN39) -> 1 | CE39: =+SUM(AP39:AQ39) -> 1 | CF39: =+SUM(AR39:AS39) -> 1
A40: =+A39+1 -> 38 | B40: 17 | C40: C.P. CESAR VALLEJO | D40: 01 | E40: 2 | F40: PSVE-2 | G40: SBM-2V | H40: 0 | I40: 0 | J40: PAT-3 | K40: 35 mm² AAAC | L40: 37.3 | M40: 2 | N40: CAC 13/400 | O40: 1 | P40: 37.5kVA-2ø-13,8kV | Q40: 2 | R40: 2 | S40: 783714.59 | T40: 8995711.597 | U40: 0 | V40: 0 | W40: 0 | X40: 0 | Y40: 0 | Z40: 0 | AA40: 0 | AB40: 0 | AC40: 0 | AD40: 0 | AE40: 0 | AF40: 0 | AG40: 0 | AH40: 0 | AM40: 1 | AN40: 0 | AO40: CI-A | AR40: 1 | AS40: 0 | AT40: 0 | AU40: SI | AV40: =+IF(M40<>0,VLOOKUP($P40,TRAFOS,4,0),"-") -> 3A-K | AW40: =IF($L40<250,0,IF($L40<400,$M40*2,IF($L40<600,$M40*4,$M40*6))) -> 0 | AX40: 2 | AY40: =+IF(P40<>0,VLOOKUP($P40,TRAFOS,3,0),"-") -> 13,8kV | AZ40: =+IF(B40<>0,"NO","-") -> NO | BA40: =+IF($N40<>0,VLOOKUP($N40,POSTES,3,0),"-") -> CAC | BB40: =+IF($N40<>0,VLOOKUP($N40,POSTES,4,0),"-") -> 13/400 | BC40: =+IF($N40<>0,VLOOKUP($N40,POSTES,5,0),0) -> 13 | BI40: =+BI39+1 -> 38 | CD40: =+SUM(AM40:AN40) -> 1 | CE40: =+SUM(AP40:AQ40) -> 0 | CF40: =+SUM(AR40:AS40) -> 1
...

Sheet Hoja7
A3: Etiquetas de fila | B3: Suma de Vano-m | D3: Etiquetas de fila | E3: Suma de Vano-m | G3: Etiquetas de fila | J3: Etiquetas de fila
A4: - | B4: 0 | D4: - | E4: 1764.3 | G4: - | J4: -
A5: DS-0 | B5: 0 | D5: DS-0 | E5: 0 | G5: 35 mm² AAAC | J5: 10kVA-2ø-13,8kV
A6: EC | B6: 0 | D6: DS-0A | E6: 0 | G6: Total general | J6: 37.5kVA-2ø-13,8kV
A7: PA1-0 | B7: 189.7 | D7: DS-2 | E7: 0 | J7: 5kVA-1ø-13,2kV
A8: PS1-0 | B8: 196.44 | D8: PTV-0 | E8: 0 | J8: 5kVA-2ø-13,8kV
A9: PS1-2 | B9: 83.2 | D9: SBM-2P | E9: 88 | J9: 5kVA-2ø-22,9kV
A10: PSVE-2 | B10: 1116.4 | D10: SBM-2V | E10: 117.7 | J10: Total general
A11: PTV-0 | B11: 82.94 | D11: SMM-1P | E11: 82.94
A12: TS-0 | B12: 159.6 | D12: SMM-2P | E12: 196.44
A13: TSVE-2 | B13: 421.1 | D13: Total general | E13: 2249.38 | J13: Etiquetas de fila | K13: Suma de Cantidad de Soportes
A14: Total general | B14: 2249.38 | J14: - | K14: 0
J15: CAC 12/200 | K15: 0
J16: CAC 12/300 | K16: 0
J17: CAC 13/300 | K17: 0
J18: CAC 13/400 | K18: 0
J19: PRFV 12/300 | K19: 0
J20: Total general | K20: 0
D22: DS-0 | E22: 0
D23: EC | E23: 0
D24: PA1-0 | E24: 189.7
D25: PS1-0 | E25: 196.44
D26: PS1-2 | E26: 83.2
D27: PSVE-2 | E27: 1116.4
D28: PTV-0 | E28: 82.94
D29: TS-0 | E29: 159.6
D30: TSVE-2 | E30: 421.1
D31: - | E31: 1764.3
D32: DS-0A | E32: 0
D33: DS-2 | E33: 0
... D37: SMM-2P | E37: 196.44

Sheet Hoja6
A1: ID | B1: N° | C1: Localidad | D1: N° SED | E1: N° Estructura | F1: Arm. Primario | G1: Arm. Secundario | H1: RI | I1: RV | J1: PAT | K1: Conductor | L1: Vano-m | M1: Num. Fases | N1: Soporte | O1: Cantidad de Soportes | P1: Subestación | Q1: Seccionadores | R1: Pararrayos | S1: Coordenada X | T1: Coordenada Y | U1: Conexiones I | V1: Conexiones L | W1: Conexiones T | X1: Conexiones + | Y1: Retenida Inclinada de RS | Z1: Retenida Vertical de RS | AA1: Retenida Inclinada de RP | AB1: Retenida Vertical de RP | AC1: Retenida Inclinada de LP | AD1: Retenida Vertical de LP | AE1: Retenida Inclinada Existente de RS | AF1: Retenida Vertical Existente de RS | AG1: Retenida Inclinada Existente de RP | AH1: Retenida Vertical Existente de RP
A2: 1 | B2: 1 | C2: CONCHIPAMPA | D2: - | E2: 0 | F2: - | G2: DS-0 | H2: 0 | I2: 0 | J2: - | K2: - | L2: 0 | M2: 0 | N2: - | O2: 0 | P2: - | Q2: 0 | R2: 0 | S2: 174368.64 | T2: 8980122.95 | U2: 0 | V2: 0 | W2: 0 | X2: 0 | Y2: 0 | Z2: 0 | AA2: 0 | AB2: 0 | AC2: 0 | AD2: 0 | AE2: 0 | AF2: 0 | AG2: 0 | AH2: 0
A3: =+A2+1 -> 2 | B3: 1 | C3: CONCHIPAMPA | D3: - | E3: 1 | F3: TS-0 | G3: - | H3: 1 | I3: 0 | J3: PAT-1C | K3: 35 mm² AAAC | L3: 22.2 | M3: 1 | N3: CAC 12/300 | O3: 1 | P3: - | Q3: 0 | R3: 0 | S3: 174390.7176 | T3: 8980123.4154 | U3: 0 | V3: 0 | W3: 0 | X3: 0 | Y3: 0 | Z3: 0 | AA3: 1 | AB3: 0 | AC3: 0 | AD3: 0 | AE3: 0 | AF3: 0 | AG3: 0 | AH3: 0
A4: =+A3+1 -> 3 | B4: 1 | C4: CONCHIPAMPA | D4: - | E4: 2 | F4: TS-0 | G4: - | H4: 1 | I4: 0 | J4: PAT-1C | K4: 35 mm² AAAC | L4: 45.3 | M4: 1 | N4: CAC 12/300 | O4: 1 | P4: - | Q4: 0 | R4: 0 | S4: 174434.0564 | T4: 8980110.6284 | U4: 0 | V4: 0 | W4: 0 | X4: 0 | Y4: 0 | Z4: 0 | AA4: 1 | AB4: 0 | AC4: 0 | AD4: 0 | AE4: 0 | AF4: 0 | AG4: 0 | AH4: 0
