Workbook

Sheet Resumen Total
B2: Resumen General del Valor Referencial (Obra y Estudio)
B3: Proyecto | D3: : | E3: “AMPLIACIÓN DEL SERVICIO DE ENERGÍA ELÉCTRICA EN LA PROVINCIA DEL SANTA Y EN EL DISTRITO DE PAMPAROMAS – DEPARTAMENTO DE ANCASH”
B4: Departamento | D4: : | E4: ANCASH | H4: Fecha: | I4: 44711
B5: Ítem | C5: Descripción | G5: Total Sin I.G.V. (S/) | H5: I.G.V. | I5: Total S/
B6: A | D6: COSTO DE OBRA | G6: =+#REF! -> #REF! | H6: =ROUND(+G6*0.18,2) -> #REF! | I6: =SUM(G6:H6) -> #REF! | L6: =+I11-L11 -> 3137339.3 | N6: =+L6/I6 -> #REF!
B7: B | D7: COSTO DE EXPEDIENTE TÉCNICO | G7: =+'EXPED-TECNICO'!K193 -> 200121.88 | H7: =ROUND(+G7*0.18,2) -> 36021.94 | I7: =SUM(G7:H7) -> 236143.82
D8: TOTAL | G8: =SUM(G6:G7) -> #REF! | H8: =SUM(H6:H7) -> #REF! | I8: =+ROUND(SUM(I6:I7),2) -> #REF!
H11: 3748314.6 | I11: 3373483.1 | L11: =+ROUND(I11*7%,2) -> 236143.82
H12: =+I11-I8 -> #REF! | I12: =+I11/I8 -> #REF!
F14: Inversiones
F15: Componentes | G15: US$ sin IGV) | H15: Cantidad
F16: US$ / km Línea Primaria | G16: =+#REF! -> #REF! | H16: US$ / km
F17: US$ / Conexión Línea Primaria | G17: =+#REF! -> #REF! | H17: US$ / Conexión
F18: US$ / Conexión Red Primaria (1/) | G18: =+#REF! -> #REF! | H18: US$ / Conexión
F19: US$ / Conexión Red Secundaria y Conexiones Domiciliarias | G19: =+#REF! -> #REF! | H19: US$ / Conexión
F20: US$ Conexión Total (incluye IGV) | G20: =+#REF! -> #REF! | H20: US$ / Conexión

Sheet G. GENERALES
A1: “AMPLIACIÓN DEL SERVICIO DE ENERGÍA ELÉCTRICA EN LA PROVINCIA DEL SANTA Y EN EL DISTRITO DE PAMPAROMAS – DEPARTAMENTO DE ANCASH”
A3: CALCULO DE LOS GASTOS GENERALES DIRECTOS E INDIRECTOS
B5: Sección : | C5: LINEAS PRIMARIAS, REDES PRIMARIAS Y REDES SECUNDARIAS
B6: Departamento : | C6: ANCASH
B7: Plazo de Obra + Expediente Técnico: | C7: =+F9+F10 -> 10 | D7: meses
A9: 1.0 | B9: GASTOS GENERALES VARIABLES-GG DIRECTOS | E9: Estudio Definitivo : | F9: 4 | G9: meses
E10: Obra : | F10: 6 | G10: meses
A11: 1.1 | B11: Personal Profesional Principal
B12: Descripción | C12: Unidad | D12: Cant. | E12: Particip. | F12: Tiempo | G12: Sueldo | H12: Parcial
E13: % | F13: (meses) | G13: (S/) | H13: (S/)
B14: Ingeniero Residente de la Obra | C14: Und. | D14: 1 | E14: 1 | F14: 10 | G14: 7500 | H14: =+ROUND(+G14*F14*D14*E14,2) -> 75000
B15: Ing. de Seguridad e Higiene Ocupacional | C15: Und. | D15: 1 | E15: 1 | F15: 6 | G15: 5500 | H15: =+ROUND(+G15*F15*D15*E15,2) -> 33000
B16: Ing. Especialista en Sistemas Fotovoltaicos | C16: Und. | D16: 1 | E16: 0.4 | F16: 6 | G16: 5500 | H16: =+ROUND(+G16*F16*D16*E16,2) -> 13200
B17: Ing. Especialista en Redes de Distribución | C17: Und. | D17: 1 | E17: 0.5 | F17: 6 | G17: 5500 | H17: =+ROUND(+G17*F17*D17*E17,2) -> 16500
B19: PARCIAL 1,1 | H19: =SUM(H14:H18) -> 137700
A22: 1.2 | B22: Personal de Auxiliar y Apoyo
B23: Descripción | C23: Und. | D23: Cant. | E23: Particip. | F23: Tiempo | G23: Sueldo | H23: Parcial
E24: % | F24: (meses) | G24: (S/) | H24: (S/)
B25: Administrador | C25: Und. | D25: 1 | E25: 0.8 | F25: 6 | G25: 3000 | H25: =+ROUND(+G25*F25*D25*E25,2) -> 14400
B26: Dibujante en Autocad y otros programas | C26: Und. | D26: 1 | E26: 0.5 | F26: 6 | G26: 1800 | H26: =+ROUND(+G26*F26*D26*E26,2) -> 5400
B27: Almacenero | C27: Und. | D27: 1 | E27: 0.8 | F27: 6 | G27: 1800 | H27: =+ROUND(+G27*F27*D27*E27,2) -> 8640
B28: Técnico mecánico | C28: Und. | D28: 1 | E28: 0.3 | F28: 6 | G28: 1800 | H28: =+ROUND(+G28*F28*D28*E28,2) -> 3240
B29: Chofer | C29: Und. | D29: 1 | E29: 1 | F29: 6 | G29: 1700 | H29: =+ROUND(+G29*F29*D29*E29,2) -> 10200
B30: Seguridad en obra (Guardian) | C30: Und. | D30: 1 | E30: 0.7 | F30: 6 | G30: 1500 | H30: =+ROUND(+G30*F30*D30*E30,2) -> 6300
B32: PARCIAL 1,2 | H32: =SUM(H25:H31) -> 48180
A35: 1.3 | B35: Hospedajes, Oficina, Campamentos, alimentación y movilidad del personal principal, auxiliar y apoyo
B36: Descripción | C36: Und. | D36: Cant. | E36: Particip. | F36: Tiempo | G36: Gasto/ Und. | H36: Parcial
E37: % | F37: (meses) | G37: (S/) | H37: (S/)
B38: Hospedajes | C38: Glb/mes | D38: 1 | E38: 1 | F38: 6 | G38: 1200 | H38: =+ROUND(+G38*F38*D38*E38,2) -> 7200
B39: Alquiler de Oficina en Obra (Incluye agua y luz) | C39: Glb/mes | D39: 1 | E39: 1 | F39: 6 | G39: 350 | H39: =+ROUND(+G39*F39*D39*E39,2) -> 2100
B40: Alquiler de casa almacén (incluye agua y luz) | C40: Glb/mes | D40: 1 | E40: 1 | F40: 6 | G40: 450 | H40: =+ROUND(+G40*F40*D40*E40,2) -> 2700
B41: Comunicaciones: telefono, fax, internet, radio, etc. | C41: Glb/mes | D41: 1 | E41: 1 | F41: 6 | G41: 550 | H41: =+ROUND(+G41*F41*D41*E41,2) -> 3300
B42: Alimentación | C42: Glb/mes | D42: 1 | E42: 1 | F42: 6 | G42: 1200 | H42: =+ROUND(+G42*F42*D42*E42,2) -> 7200
B43: Pasajes | C43: Glb/mes | D43: 1 | E43: 1 | F43: 6 | G43: 650 | H43: =+ROUND(+G43*F43*D43*E43,2) -> 3900
B45: PARCIAL 1,3 | H45: =SUM(H38:H44) -> 26400
A47: 1.4 | B47: Mobiliario, equipo, material de oficina y otros
B48: Descripción | C48: Und. | D48: Cant. | E48: Desgaste | F48: Tiempo | G48: Gasto/ Und.xmes | H48: Parcial
E49: % | F49: (meses) | G49: (S/) | H49: (S/)
B50: Mobiliario de oficina | C50: Glb/mes | D50: 1 | E50: 0.05 | F50: 6 | G50: 900 | H50: =+ROUND(G50*F50*E50*D50,2) -> 270
B51: Computadora | C51: Glb/mes | D51: 1 | E51: 0.05 | F51: 6 | G51: 900 | H51: =+ROUND(G51*F51*E51*D51,2) -> 270
...

Sheet CRONOG_VALORIZ
B1: CRONOGRAMA DE DESEMBOLSOS MENSUALES DE OBRA
B3: PROYECTO | E3: : | F3: “AMPLIACIÓN DEL SERVICIO DE ENERGÍA ELÉCTRICA EN LA PROVINCIA DEL SANTA Y EN EL DISTRITO DE PAMPAROMAS – DEPARTAMENTO DE ANCASH”
B4: SECCION I, II y III | E4: : | F4: LINEAS PRIMARIAS, REDES PRIMARIAS Y REDES SECUNDARIAS
B5: DEPARTAMENTO | E5: : | F5: ANCASH
B6: PROVINCIA | E6: : | F6: HUAYLAS Y SANTA
B7: DISTRITO | E7: : | F7: VARIOS | Q7: Fecha: 30-Mayo-2022
H8: PERIODO DE ESTUDIO DEFINITIVO | L8: PERIODO DE OBRA
B9: ITEM | C9: DESCRIPCION | G9: TOTAL S/ | H9: MES 1 | I9: MES 2 | J9: MES 3 | K9: MES 4 | L9: MES 5 | M9: MES 6 | N9: MES 7 | O9: MES 8 | P9: MES 9 | Q9: MES 10
B11: A | D11: SUMINISTROS DE MATERIALES | G11: =+#REF! -> #REF! | L11: =+ROUND($G$11*L25,2) -> #REF! | M11: =+ROUND($G$11*M25,2) -> #REF! | N11: =+ROUND($G$11*N25,2) -> #REF! | O11: =+ROUND($G$11*O25,2) -> #REF! | P11: =+G11-L11-M11-N11-O11-Q11 -> #REF! | Q11: =+ROUND($G$11*Q25,2) -> #REF!
B12: B | D12: MONTAJE ELECTROMECANICO | G12: =+#REF! -> #REF! | L12: =+ROUND($G$12*L26,2) -> #REF! | M12: =+ROUND($G$12*M26,2) -> #REF! | N12: =+ROUND($G$12*N26,2) -> #REF! | O12: =+ROUND($G$12*O26,2) -> #REF! | P12: =+ROUND($G$12*P26,2) -> #REF! | Q12: =+G12-O12-N12-M12-L12-P12 -> #REF!
B13: C | D13: TRANSPORTE DE MATERIALES | G13: =+#REF! -> #REF! | L13: =+ROUND($G$13*L27,2) -> #REF! | M13: =+ROUND($G$13*M27,2) -> #REF! | N13: =+ROUND($G$13*N27,2) -> #REF! | O13: =+ROUND($G$13*O27,2) -> #REF! | P13: =+G13-L13-M13-N13-O13-Q13 -> #REF! | Q13: =+ROUND($G$13*Q27,2) -> #REF!
B15: D | D15: COSTO DIRECTO ( C.D. ) | G15: =+#REF! -> #REF! | L15: =SUM(L11:L13) -> #REF! | M15: =SUM(M11:M13) -> #REF! | N15: =SUM(N11:N13) -> #REF! | O15: =SUM(O11:O13) -> #REF! | P15: =SUM(P11:P13) -> #REF! | Q15: =SUM(Q11:Q13) -> #REF!
B17: E | F17: GASTOS GENERALES | G17: =+#REF! -> #REF! | L17: =+ROUND(L15*($G$17/$G$15),2) -> #REF! | M17: =+ROUND(M15*($G$17/$G$15),2) -> #REF! | N17: =+ROUND(N15*($G$17/$G$15),2) -> #REF! | O17: =+ROUND(O15*($G$17/$G$15),2) -> #REF! | P17: =+ROUND(P15*($G$17/$G$15),2) -> #REF! | Q17: =+G17-O17-N17-M17-L17-P17 -> #REF!
B18: F | F18: UTILIDADES | G18: =+#REF! -> #REF! | L18: =+ROUND(L15*0.08,2) -> #REF! | M18: =+ROUND(M15*0.08,2) -> #REF! | N18: =+ROUND(N15*0.08,2) -> #REF! | O18: =+ROUND(O15*0.08,2) -> #REF! | P18: =+ROUND(P15*0.08,2) -> #REF! | Q18: =+G18-O18-N18-M18-L18-P18 -> #REF!
D21: =+"SUB-TOTAL SIN I.G.V. (S/)" -> SUB-TOTAL SIN I.G.V. (S/) | G21: =+#REF! -> #REF! | L21: =SUM(L15:L18) -> #REF! | M21: =SUM(M15:M18) -> #REF! | N21: =SUM(N15:N18) -> #REF! | O21: =SUM(O15:O18) -> #REF! | P21: =SUM(P15:P18) -> #REF! | Q21: =SUM(Q15:Q18) -> #REF!
D23: IMPUESTO GENERAL A LAS VENTAS IGV (18%) | G23: =+#REF! -> #REF! | L23: =+ROUND(L21*0.18,2) -> #REF! | M23: =+ROUND(M21*0.18,2) -> #REF! | N23: =+ROUND(N21*0.18,2) -> #REF! | O23: =+ROUND(O21*0.18,2) -> #REF! | P23: =+ROUND(P21*0.18,2) -> #REF! | Q23: =+G23-L23-M23-N23-O23-P23 -> #REF!
D24: COSTO TOTAL OBRA (Incluye I.G.V.) | G24: =+#REF! -> #REF! | L24: =SUM(L21:L23) -> #REF! | M24: =SUM(M21:M23) -> #REF! | N24: =SUM(N21:N23) -> #REF! | O24: =SUM(O21:O23) -> #REF! | P24: =SUM(P21:P23) -> #REF! | Q24: =SUM(Q21:Q23) -> #REF!
G25: SUMINISTROS | L25: 0 | M25: 0.255 | N25: 0.36 | O25: 0.335 | P25: 0.05
G26: MONTAJE | L26: 0.15 | M26: 0.2 | N26: 0.25 | O26: 0.15 | P26: 0.15 | Q26: 0.1
G27: TRANSPORTE | L27: 0 | M27: =+M25 -> 0.255 | N27: =+N25 -> 0.36 | O27: =+O25 -> 0.335 | P27: =+P25 -> 0.05

Sheet EXPED-TECNICO
D4: ANALISIS DE COSTOS PARA CONTRATACION DE LA ELABORACION DEL
D5: ESTUDIO DEFINITIVO DEL PROYECTO
D6: “AMPLIACION DEL SISTEMA ELECTRICO RURAL EN LA PROVINCIA DEL SANTA Y EN EL DISTRITO DE PAMPAROMAS - DEPARTAMENTO DE ANCASH”
D9: A. | E9: COSTO DE PERSONAL
D12: A1 | E12: COSTO DE PERSONAL PROFESIONAL
I13: PLAZO : | J13: 4 | K13: MESES
G14: PROFES. | H14: INCIDENCIA | I14: REMUNERACIÓN | J14: TIEMPO | K14: TOTAL
E15: CATEGORIA | G15: ASIGNADO | H15: (c) | I15: Total/mes (7) | J15: EFECTIVO | K15: HONORARIOS
G16: (b) | H16: % | I16: S/ (d) | J16: (Meses) (e)=(a)*(c) | K16: S/ (f)=(b)*(d)*(e)
E18: ESTUDIOS ELECTROMECANICOS
D19: A | E19: Jefe de Estudios | G19: 1 | H19: 1 | I19: 7000 | J19: =+ROUND(+H19*$J$13,2) -> 4 | K19: =+ROUND(I19*J19*G19,2) -> 28000 | M19: =+N199 -> 0
D20: B | E20: Epecialista en Análisis y Diseños de Líneas y Redes Primarias | G20: 1 | H20: 0.5 | I20: 6000 | J20: =+ROUND(+H20*$J$13,1) -> 2 | K20: =+ROUND(I20*J20*G20,2) -> 12000
D21: C | E21: Especialista en Analisis de Sistemas Electricos y Estudio de Coordinación de la Protección | G21: 1 | H21: 0.25 | I21: 6000 | J21: =+ROUND(+H21*$J$13,1) -> 1 | K21: =+ROUND(I21*J21*G21,2) -> 6000
D22: D | E22: Especialista en Analisis y Diseños de Redes Secundarias | G22: 1 | H22: 0.5 | I22: 6000 | J22: =+ROUND(+H22*$J$13,1) -> 2 | K22: =+ROUND(I22*J22*G22,2) -> 12000
D23: E | E23: Especialista en Energias Renovables - Sistemas Fotovoltaicos | G23: 1 | H23: 0.25 | I23: 5000 | J23: =+ROUND(+H23*$J$13,1) -> 1 | K23: =+ROUND(I23*J23*G23,2) -> 5000
D24: F | E24: Especialista en Trabajos Geológicos, Geotécnicos y Diseño de Cimentaciones | G24: 1 | H24: 0.25 | I24: 5000 | J24: =+ROUND(+H24*$J$13,1) -> 1 | K24: =+ROUND(I24*J24*G24,2) -> 5000
D25: G | E25: Especialista en Estudios de Impacto Ambiental | G25: 1 | H25: 0.3753 | I25: 5000 | J25: =+ROUND(+H25*$J$13,1) -> 1.5 | K25: =+ROUND(I25*J25*G25,2) -> 7500
D26: H | E26: Arqueologo, Especialista en Proyectos de Electrificacion | G26: 1 | H26: 0.25 | I26: 5000 | J26: =+ROUND(+H26*$J$13,1) -> 1 | K26: =+ROUND(I26*J26*G26,2) -> 5000
D27: I | E27: Especialista en Gestion de Riesgos | G27: 1 | H27: 0.25 | I27: 5000 | J27: =+ROUND(+H27*$J$13,1) -> 1 | K27: =+ROUND(I27*J27*G27,2) -> 5000
G29: =SUM(G19:G28) -> 9 | I29: COSTO DE PERSONAL | K29: =SUM(K19:K28) -> 85500
D32: A2 | E32: COSTO DE PERSONAL AUXILIAR
G34: PERSONAL | I34: SUELDO | J34: TIEMPO | K34: TOTAL
E35: DESCRIPCION | G35: ASIGNADO | H35: INCIDENCIA | I35: Total/mes | J35: EFECTIVO | K35: HONORARIOS
I36: S/ | J36: (Meses) | K36: S/
E37: Ingenieros Asistentes para labores de Gabinete | G37: =G20 -> 1 | H37: 0.5 | I37: 3500 | J37: =+ROUND(+H37*$J$13,1) -> 2 | K37: =+ROUND(I37*J37*G37,2) -> 7000
E38: Secretaria | G38: 1 | H38: 0.35 | I38: 2000 | J38: =+ROUND(+H38*$J$13,1) -> 1.4 | K38: =+ROUND(I38*J38*G38,2) -> 2800
E39: Dibujantes en Autocad | G39: 1 | H39: 0.5 | I39: 2500 | J39: =+ROUND(+H39*$J$13,2) -> 2 | K39: =+ROUND(I39*J39*G39,2) -> 5000
E40: Personal de campo no calificado | G40: 5 % de A1 | K40: =+ROUND(K29*0.05,2) -> 4275
I42: COSTO PERS. AUXILIAR | K42: =SUM(K37:K40) -> 19075
D43: NOTA | E43: LA REMUNERACIÓN INCLUYE LEYES SOCIALES.
F46: COSTO TOTAL DE PERSONAL (A1 + A2) | J46: S/ | K46: =+K42+K29 -> 104575
D50: ANALISIS DE COSTOS PARA CONTRATACION DE LA ELABORACION DEL
D51: ESTUDIO DEFINITIVO DEL PROYECTO
D52: =+D6 -> “AMPLIACION DEL SISTEMA ELECTRICO RURAL EN LA PROVINCIA DEL SANTA Y EN EL DISTRITO DE PAMPAROMAS - DEPARTAMENTO DE ANCASH”
D56: B | E56: TRABAJOS TOPOGRAFICOS PARA EL DISEÑO TÉCNICO DEL PROYECTO Y REPLANTEO DE OBRA
D59: B1 | E59: LEVANTAMIENTO TOPOGRAFIO DE LINEAS DE MEDIA TENSION (INCLUYE TRABAJOS DE GABINETE)
H61: COSTO POR km DE LINEA DE M.T. | K61: 450
E63: LONGITUD DE LINEA DE MEDIA TENSIÓN | I63: 22.95 | J63: km
H64: SUB TOTAL B1 | J64: S/ | K64: =ROUND(+I63*K61,2) -> 10327.5
D67: B2 | E67: LEVANTAMIENTO TOPOGRAFICO PARA ELABORACION DE PLANOS CATASTRALES (INCLUYE TRABAJOS DE GABINETE)
...

Sheet RESUMEN LP
B2: VALOR REFERENCIAL
B3: LINEAS PRIMARIAS
B4: “AMPLIACIÓN DEL SERVICIO DE ENERGÍA ELÉCTRICA EN LA PROVINCIA DEL SANTA Y EN EL DISTRITO DE PAMPAROMAS – DEPARTAMENTO DE ANCASH”
B6: UBICACIÓN | D6: : | E6: ANCASH
B7: SECCIÓN I | D7: : | E7: LINEAS PRIMARIAS
F8: =+#REF! -> #REF!
F9: =+#REF! -> #REF!
B10: ITEM | C10: DESCRIPCION | F10: TOTAL S/
B12: A | D12: SUMINISTRO DE MATERIALES | F12: =+'SUMINISTRO LP'!J129 -> 628325.26
B13: B | D13: MONTAJE ELECTROMECANICO | F13: =+'MONTAJE LP'!J130 -> 461491.17
B14: C | D14: TRANSPORTE DE MATERIALES | F14: =+TRANS_LP!J130 -> 60052.8 | G14: =+F14/F12 -> 0.095575976
B15: D | D15: TOTAL COSTO DIRECTO | F15: =SUM(F12:F14) -> 1149869.2
B17: E | E17: GASTOS GENERALES | F17: =+ROUND(F15*H17,2) -> #REF! | H17: =+#REF! -> #REF!
B18: F | E18: UTILIDADES | F18: =+ROUND(F15*H18,2) -> #REF! | H18: =+#REF! -> #REF!
D20: COSTO TOTAL S/ (No incluye I.G.V.) | F20: =SUM(F15:F18) -> #REF! | H20: =F20=#REF! -> #REF!

Sheet Alternativa-LP
B3: ="RESUMEN DEL VALOR REFERENCIAL " -> RESUMEN DEL VALOR REFERENCIAL
B5: UBICACIÓN | D5: :
B6: SECCIÓN I | D6: :
B9: ITEM | C9: DESCRIPCION | F9: TOTAL (S/.)
I10: =F11*0.07 -> 43982.768
B11: A | D11: SUMINISTROS DE MATERIALES | F11: =+'RESUMEN LP'!F12 -> 628325.26 | I11: =F11*0.1 -> 62832.526
D12: Origen Nacional | F12: =+F11-F13 -> 315414.07
D13: Origen Importado | F13: =+'SUMINISTRO LP'!J25+'SUMINISTRO LP'!J36+'SUMINISTRO LP'!J40+'SUMINISTRO LP'!J44+'SUMINISTRO LP'!J62+'SUMINISTRO LP'!J116+'SUMINISTRO LP'!J120 -> 312911.19
B15: B | D15: MONTAJE ELECTROMECANICO | F15: =+'RESUMEN LP'!F13 -> 461491.17 | H15: =+F15/$F$11 -> 0.73447814
D16: M.O. Calificada | F16: =ROUND(N16*F15,2) -> 290739.44 | N16: 0.63
D17: M.O. No Calificada | F17: =ROUND(N17*F15,2) -> 170751.73 | N17: =1-N16 -> 0.37
B19: B.1 | D19: ACTIVIDADES COMPLEMENTARIAS DE MONTAJE | F19: 0
B21: C | D21: TRANSPORTE DE MATERIALES | F21: =+'RESUMEN LP'!F14 -> 60052.8 | H21: 0.1
B24: D | D24: TOTAL COSTO DIRECTO (C.D.) | F24: =+F21+F15+F11+F19 -> 1149869.2

Sheet SUMINISTRO LP
B1: VALOR REFERENCIAL
B2: SUMINISTRO DE MATERIALES LÍNEAS PRIMARIAS
B3: UBICACIÓN | E3: : | F3: ANCASH
B4: SECCIÓN I | E4: : | F4: LÍNEAS PRIMARIAS
B5: A: SUMINISTRO DE MATERIALES
B7: Item | C7: Descripción de Partidas | G7: Unid. | H7: Metrado Cant. | I7: Costo Unitario | J7: SubTotal S/
D9: LINEAS PRIMARIAS
B11: 1 | D11: CRUCETAS DE MADERA DE PROCEDENCIA NACIONAL
B12: =+B11+0.01 -> 1.01 | D12: Cruceta de madera tratada de 90 mm x 115 mm x 1,20 m | G12: u | H12: 11 | I12: 105 | J12: =+ROUND(I12*H12,2) -> 1155 | L12: =IFERROR(VLOOKUP(D12,#REF!,2,FALSE),"")
B13: =+B12+0.01 -> 1.02 | D13: Cruceta de madera tratada de 90 mm x 115 mm x 2,00 m | G13: u | H13: 2 | I13: 178 | J13: =+ROUND(I13*H13,2) -> 356 | L13: =IFERROR(VLOOKUP(D13,#REF!,2,FALSE),"")
B14: =+B13+0.01 -> 1.03 | D14: Cruceta de madera tratada de 90 mm x 115 mm x 2,40 m | G14: u | H14: 1 | I14: 205 | J14: =+ROUND(I14*H14,2) -> 205 | L14: =IFERROR(VLOOKUP(D14,#REF!,2,FALSE),"")
B15: =+B14+0.01 -> 1.04 | D15: Listón de madera tratada 50 x 19 mm sección, 2,7 m longitud (incluye clavos de fijación) | G15: u | H15: 9 | I15: 27.35 | J15: =+ROUND(I15*H15,2) -> 246.15 | L15: =IFERROR(VLOOKUP(D15,#REF!,2,FALSE),"")
F16: =+"SUB-TOTAL "&B11&": " -> SUB-TOTAL 1: | J16: =SUM(J12:J15) -> 1962.15 | L16: =IFERROR(VLOOKUP(D16,#REF!,2,FALSE),"")
B17: 2 | D17: POSTES DE CONCRETO ARMADO CENTRIFUGADO | L17: =IFERROR(VLOOKUP(D17,#REF!,2,FALSE),"")
B18: =+B17+0.01 -> 2.01 | D18: Poste de C.A.C. de 12 m/200 daN (Incluye perilla) | G18: u | H18: 15 | I18: 837.45 | J18: =+ROUND(I18*H18,2) -> 12561.75 | L18: =IFERROR(VLOOKUP(D18,#REF!,2,FALSE),"")
B19: =+B18+0.01 -> 2.02 | D19: Poste de C.A.C. de 12 m/300 daN (Incluye perilla) | G19: u | H19: 6 | I19: 923.47 | J19: =+ROUND(I19*H19,2) -> 5540.82 | L19: =IFERROR(VLOOKUP(D19,#REF!,2,FALSE),"")
B20: =+B19+0.01 -> 2.03 | D20: Poste de C.A.C. de 13 m/300 daN (Incluye perilla) | G20: u | H20: 118 | I20: 1085.14 | J20: =+ROUND(I20*H20,2) -> 128046.52 | L20: =IFERROR(VLOOKUP(D20,#REF!,2,FALSE),"")
B21: =+B20+0.01 -> 2.04 | D21: Poste de C.A.C. de 13 m/400 daN (Incluye perilla) | G21: u | H21: 32 | I21: 1207.94 | J21: =+ROUND(I21*H21,2) -> 38654.08 | L21: =IFERROR(VLOOKUP(D21,#REF!,2,FALSE),"")
F22: =+"SUB-TOTAL "&B17&": " -> SUB-TOTAL 2: | J22: =SUM(J18:J21) -> 184803.17 | L22: =IFERROR(VLOOKUP(D22,#REF!,2,FALSE),"")
B23: 3 | D23: POSTES DE MADERA IMPORTADA | L23: =IFERROR(VLOOKUP(D23,#REF!,2,FALSE),"")
B24: =+B23+0.01 -> 3.01 | D24: Poste de madera importada (Pino Amarillo del Sur) de 12 m, Clase 6 | G24: u | H24: 9 | I24: 1703.39 | J24: =+ROUND(I24*H24,2) -> 15330.51 | L24: =IFERROR(VLOOKUP(D24,#REF!,2,FALSE),"")
F25: =+"SUB-TOTAL "&B23&": " -> SUB-TOTAL 3: | J25: =+SUM(J24) -> 15330.51 | L25: =IFERROR(VLOOKUP(D25,#REF!,2,FALSE),"")
B26: 4 | D26: OTROS MATERIALES DE CONCRETO ARMADO | L26: =IFERROR(VLOOKUP(D26,#REF!,2,FALSE),"")
B27: =+B26+0.01 -> 4.01 | D27: Cruceta Asimétrica de C.A.V. Za / 1,5 / 0,9 / 250 / 200 / 100 daN (Za / L / L1/ T / F / V) | G27: u | H27: 2 | I27: 120.3 | J27: =+ROUND(I27*H27,2) -> 240.6 | L27: =IFERROR(VLOOKUP(D27,#REF!,2,FALSE),"")
B28: =+B27+0.01 -> 4.02 | D28: Ménsula de C.A.V. M / 1,2 / 250 / 150 / 150 daN (M / L / T / F / V) | G28: u | H28: 393 | I28: 88.8 | J28: =+ROUND(I28*H28,2) -> 34898.4 | L28: =IFERROR(VLOOKUP(D28,#REF!,2,FALSE),"")
B29: =+B28+0.01 -> 4.03 | D29: Ménsula de C.A.V. M / 0,8 / 250 / 150 / 150 daN (M / L / T / F / V) | G29: u | H29: 1 | I29: 92.26 | J29: =+ROUND(I29*H29,2) -> 92.26 | L29: =IFERROR(VLOOKUP(D29,#REF!,2,FALSE),"")
F30: =+"SUB-TOTAL "&B26&": " -> SUB-TOTAL 4: | J30: =SUM(J27:J29) -> 35231.26 | L30: =IFERROR(VLOOKUP(D30,#REF!,2,FALSE),"")
B31: =1+B26 -> 5 | D31: AISLADORES Y ACCESORIOS | L31: =IFERROR(VLOOKUP(D31,#REF!,2,FALSE),"")
B32: =+B31+0.01 -> 5.01 | D32: Aislador de Porcelana Tipo Pin, Clase ANSI 56-3 | G32: u | H32: 29 | I32: 76.45 | J32: =+ROUND(I32*H32,2) -> 2217.05 | L32: =IFERROR(VLOOKUP(D32,#REF!,2,FALSE),"")
B33: =+B32+0.01 -> 5.02 | D33: Espiga de AºGº de 609 mm longitud, para Cabeza de Poste y Aislador ANSI 56-3 | G33: u | H33: 29 | I33: 35.96 | J33: =+ROUND(I33*H33,2) -> 1042.84 | L33: =IFERROR(VLOOKUP(D33,#REF!,2,FALSE),"")
B34: =+B33+0.01 -> 5.03 | D34: Conjunto Aislador Line Post Polimérico en Mesula y Cruceta: | L34: =IFERROR(VLOOKUP(D34,#REF!,2,FALSE),"")
D35: - Aislador Polimérico de 36 kV, Tipo Line Post con Espárrago de 19 mm Ø, 200 mm longitud (Alternativa a Conjunto Aislador-Espiga en Cruceta) | G35: u | H35: 369 | I35: 209.65 | J35: =+ROUND(I35*H35,2) -> 77360.85 | L35: =IFERROR(VLOOKUP(D35,#REF!,2,FALSE),"")
F36: =+"SUB-TOTAL "&B31&": " -> SUB-TOTAL 5: | J36: =+SUM(J31:J35) -> 80620.74 | L36: =IFERROR(VLOOKUP(D36,#REF!,2,FALSE),"")
B37: =1+B31 -> 6 | D37: AISLADORES DE SUSPENSION Y ACCESORIOS | L37: =IFERROR(VLOOKUP(D37,#REF!,2,FALSE),"")
B38: =0.01+B37 -> 6.01 | D38: Grillete Recto | G38: u | H38: 155 | I38: 17.76 | J38: =+ROUND(I38*H38,2) -> 2752.8 | L38: =IFERROR(VLOOKUP(D38,#REF!,2,FALSE),"")
B39: =0.01+B38 -> 6.02 | D39: Aislador Polimerico con Conexión Horquilla (Estructura) y Lengüeta (Linea) de 36 kV, según Especificacion Técnica. | G39: u | H39: 155 | I39: 76.66 | J39: =+ROUND(I39*H39,2) -> 11882.3 | L39: =IFERROR(VLOOKUP(D39,#REF!,2,FALSE),"")
F40: =+"SUB-TOTAL "&B37&": " -> SUB-TOTAL 6: | J40: =SUM(J38:J39) -> 14635.1 | L40: =IFERROR(VLOOKUP(D40,#REF!,2,FALSE),"")
B41: =1+B37 -> 7 | D41: CONDUCTOR DE ALEACIÓN DE ALUMINIO | L41: =IFERROR(VLOOKUP(D41,#REF!,2,FALSE),"")
B42: =+B41+0.01 -> 7.01 | D42: Conductor de Aleacion de Aluminio de 35 mm² | G42: km | H42: 53.4 | I42: 2249.62 | J42: =+ROUND(I42*H42,2) -> 120129.71 | L42: =IFERROR(VLOOKUP(D42,#REF!,2,FALSE),"")
B43: =+B42+0.01 -> 7.02 | D43: Conductor de Aleacion de Aluminio de 70 mm² | G43: km | H43: 1.91 | I43: 4157 | J43: =+ROUND(I43*H43,2) -> 7939.87 | L43: =IFERROR(VLOOKUP(D43,#REF!,2,FALSE),"")
...

Sheet MONTAJE LP
B1: VALOR REFERENCIAL
B2: MONTAJE ELECTROMECÁNICO DE LÍNEAS PRIMARIAS
B3: UBICACIÓN | E3: : | F3: ANCASH
B4: SECCIÓN I | E4: : | F4: LÍNEAS PRIMARIAS
B5: B: MONTAJE ELECTROMECÁNICO
B7: Item | C7: Descripción de Partidas | G7: Unid. | H7: Metrado Cant. | I7: Costo Unitario | J7: SubTotal S/ | L7: Costo Unitario | M7: 0.9
B9: 1 | D9: OBRAS PRELIMINARES
B10: =B9+0.01 -> 1.01 | D10: Estudio de Coordinación de la Protección y Balance de Cargas | G10: Global | H10: 1 | I10: 5182.52 | J10: =+ROUND(I10*H10,2) -> 5182.52 | L10: 5758.36 | M10: =+ROUND(L10*$M$7,2) -> 5182.52
B11: =B10+0.01 -> 1.02 | D11: Monitoreo e Inspección del Ministerio de Cultura ( Incluye Líneas Primarias, Redes Primarias, Redes Secundarias y SFV ) | G11: Global | H11: 1 | I11: 7070.38 | J11: =+ROUND(I11*H11,2) -> 7070.38 | L11: 7855.98 | M11: =+ROUND(L11*$M$7,2) -> 7070.38
B12: =B11+0.01 -> 1.03 | D12: Programa de Monitoreo Ambiental (Incluye Línea Primarias, Red Primaria, Red Secundaria y SFV) | G12: Global | H12: 1 | I12: 4953.82 | J12: =+ROUND(I12*H12,2) -> 4953.82 | K12: =+#REF! -> #REF! | L12: 5735.13 | M12: =+ROUND(L12*$M$7,2) -> 5161.62
B13: =B12+0.01 -> 1.04 | D13: Programa de Manejo de Residuos | G13: Global | H13: 1 | I13: 5429.3 | J13: =+ROUND(I13*H13,2) -> 5429.3 | K13: =+#REF! -> #REF! | L13: 6280 | M13: =+ROUND(L13*$M$7,2) -> 5652
B14: =B13+0.01 -> 1.05 | D14: Programa de Talleres de Información y de Medidas Preventivas y/o Correctivas | G14: Global | H14: 1 | I14: 1947.8 | J14: =+ROUND(I14*H14,2) -> 1947.8 | L14: 2151.58 | M14: =+ROUND(L14*$M$7,2) -> 1936.42
B15: =B14+0.01 -> 1.06 | D15: Cartel para Obra | G15: u | H15: 1 | I15: 1703.1 | J15: =+ROUND(I15*H15,2) -> 1703.1 | L15: 1892.33 | M15: =+ROUND(L15*$M$7,2) -> 1703.1
B16: =B15+0.01 -> 1.07 | D16: Despeje de Árboles Dentro de la Franja de Servidumbre | G16: Ha | H16: 0.68 | I16: 2340.59 | J16: =+ROUND(I16*H16,2) -> 1591.6 | L16: 2600.66 | M16: =+ROUND(L16*$M$7,2) -> 2340.59
B17: =B16+0.01 -> 1.08 | D17: Elaboración del Expediente Técnico Sustentatorio de Gestión de Servidumbre (1original + 3copias). Incluye Levantamiento Topografico, y presentacion digitalizada del Expediente | G17: km | H17: 22.95 | I17: 585.06 | J17: =+ROUND(I17*H17,2) -> 13427.13 | L17: 716.73 | M17: =+ROUND(L17*$M$7,2) -> 645.06
F18: =+"SUB-TOTAL "&B9&": " -> SUB-TOTAL 1: | J18: =+SUM(J8:J17) -> 41305.65
B19: 2 | D19: TRANSPORTE DE MATERIALES DE ALMACEN EN OBRA A PUNTO DE INSTALACIÒN
B20: =+B19+0.01 -> 2.01 | D20: Transporte de Poste de 12 m/200 daN de Almacen a Punto de Izaje, en Terreno con Acceso Carrozable | G20: u | H20: 14 | I20: 247.05 | J20: =+ROUND(I20*H20,2) -> 3458.7 | L20: 274.5 | M20: =+ROUND(L20*$M$7,2) -> 247.05
B21: =+B20+0.01 -> 2.02 | D21: Transporte de Poste de 12 m/200 daN de Almacen a Punto de Izaje, en Terreno sin Acceso Carrozable (< 1000 m) | G21: u | H21: 1 | I21: 375.26 | J21: =+ROUND(I21*H21,2) -> 375.26 | L21: 416.95 | M21: =+ROUND(L21*$M$7,2) -> 375.26
B22: =+B21+0.01 -> 2.03 | D22: Transporte de Poste de 12 m/300 daN de Almacen a Punto de Izaje, en Terreno con Acceso Carrozable | G22: u | H22: 5 | I22: 270.59 | J22: =+ROUND(I22*H22,2) -> 1352.95 | L22: 300.66 | M22: =+ROUND(L22*$M$7,2) -> 270.59
B23: =+B22+0.01 -> 2.04 | D23: Transporte de Poste de 12 m/300 daN de Almacen a Punto de Izaje, en Terreno sin Acceso Carrozable (< 1000 m) | G23: u | H23: 1 | I23: 416.46 | J23: =+ROUND(I23*H23,2) -> 416.46 | L23: 462.73 | M23: =+ROUND(L23*$M$7,2) -> 416.46
B24: =+B23+0.01 -> 2.05 | D24: Transporte de Poste de 13 m/300 daN de Almacen a Punto de Izaje, en Terreno con Acceso Carrozable | G24: u | H24: 118 | I24: 301.46 | J24: =+ROUND(I24*H24,2) -> 35572.28 | L24: 334.95 | M24: =+ROUND(L24*$M$7,2) -> 301.46
B25: =+B24+0.01 -> 2.06 | D25: Transporte de Poste de 13 m/400 daN de Almacen a Punto de Izaje, en Terreno con Acceso Carrozable | G25: u | H25: 32 | I25: 338.24 | J25: =+ROUND(I25*H25,2) -> 10823.68 | L25: 375.82 | M25: =+ROUND(L25*$M$7,2) -> 338.24
B26: =+B25+0.01 -> 2.07 | D26: Transporte de Poste de madera importada (Pino Amarillo del Sur) de 12m, Clase 6 de Almacen a Punto de Izaje, en Terreno con Acceso Carrozable | G26: u | H26: 2 | I26: 176.17 | J26: =+ROUND(I26*H26,2) -> 352.34 | L26: 195.74 | M26: =+ROUND(L26*$M$7,2) -> 176.17
B27: =+B26+0.01 -> 2.08 | D27: Transporte de Poste de madera importada (Pino Amarillo del Sur) de 12m, Clase 6 de Almacen a Punto de Izaje, en Terreno sin Acceso Carrozable (< 1000 m) | G27: u | H27: 7 | I27: 244.71 | J27: =+ROUND(I27*H27,2) -> 1712.97 | L27: 271.9 | M27: =+ROUND(L27*$M$7,2) -> 244.71
B28: =+B27+0.01 -> 2.09 | D28: Transporte de Cruceta de madera tratada de 90 mm x 115 mm x 1,20 m, de Almacen a Punto de Instalaciòn en Terreno con Acceso Carrozable | G28: u | H28: 10 | I28: 5.43 | J28: =+ROUND(I28*H28,2) -> 54.3 | L28: 6.03 | M28: =+ROUND(L28*$M$7,2) -> 5.43
B29: =+B28+0.01 -> 2.1 | D29: Transporte de Cruceta de madera tratada de 90 mm x 115 mm x 1,20 m, de Almacen a Punto de Instalaciòn en Terreno sin Acceso Carrozable (< 1000 m) | G29: u | H29: 1 | I29: 7.06 | J29: =+ROUND(I29*H29,2) -> 7.06 | L29: 7.84 | M29: =+ROUND(L29*$M$7,2) -> 7.06
B30: =+B29+0.01 -> 2.11 | D30: Transporte de Ménsula de C.A.V y Cruceta Asimétrica de C.A.V, de Almacen a Punto de Instalaciòn en Terreno con Acceso Carrozable | G30: u | H30: 396 | I30: 13.3 | J30: =+ROUND(I30*H30,2) -> 5266.8 | L30: 14.78 | M30: =+ROUND(L30*$M$7,2) -> 13.3
B31: =+B30+0.01 -> 2.12 | D31: Transporte de Cruceta de madera tratada de 90 mm x 115 mm x 2,40 m y 2,00 m, de Almacen a Punto de Instalaciòn en Terreno con Acceso Carrozable | G31: u | H31: 3 | I31: 13.1 | J31: =+ROUND(I31*H31,2) -> 39.3 | L31: 14.56 | M31: =+ROUND(L31*$M$7,2) -> 13.1
... B54: =+B53+0.01 -> 2.35 | D54: Transporte de Accesorios de Ferreteria (Para Postes , conductores, Retenidas y PAT) de Almacen a Punto de Instalaciòn sin Acceso Carrozable (< 1000 m) | G54: Global | H54: 1 | I54: 2275.69 | J54: =+ROUND(I54*H54,2) -> 2275.69 | L54: 2528.54 | M54: =+ROUND(L54*$M$7,2) -> 2275.69
F55: =+"SUB-TOTAL "&B19&": " -> SUB-TOTAL 2: | J55: =+SUM(J19:J54) -> 82420.02
B56: 3 | D56: INSTALACION DE POSTES
B57: =+B56+0.01 -> 3.01 | D57: Excavación en Terreno Tipo I (Arcilloso y Conglomerado) | H57: 190.59 | I57: 61.15 | J57: =+ROUND(I57*H57,2) -> 11654.58 | L57: 67.94 | M57: =+ROUND(L57*$M$7,2) -> 61.15
B58: =+B57+0.01 -> 3.02 | D58: Excavación en Terreno Tipo II (Rocoso) | H58: 6.55 | I58: 208.14 | J58: =+ROUND(I58*H58,2) -> 1363.32 | L58: 231.27 | M58: =+ROUND(L58*$M$7,2) -> 208.14
B59: =+B58+0.01 -> 3.03 | D59: Izaje, Identificación y/o codificación, y Señalización de Poste de madera importada de 12 m, Clase 6 (*) | G59: u | H59: 9 | I59: 95.92 | J59: =+ROUND(I59*H59,2) -> 863.28 | L59: 106.58 | M59: =+ROUND(L59*$M$7,2) -> 95.92
B60: =+B59+0.01 -> 3.04 | D60: Izaje, Identificación y/o codificación, y Señalización de Poste de 13 m/300 daN (*) | G60: u | H60: 118 | I60: 154.07 | J60: =+ROUND(I60*H60,2) -> 18180.26 | L60: 171.19 | M60: =+ROUND(L60*$M$7,2) -> 154.07
B61: =+B60+0.01 -> 3.05 | D61: Izaje, Identificación y/o codificación, y Señalización de Poste de 13 m/400 daN (*) | G61: u | H61: 32 | I61: 194.85 | J61: =+ROUND(I61*H61,2) -> 6235.2 | L61: 216.5 | M61: =+ROUND(L61*$M$7,2) -> 194.85
B62: =+B61+0.01 -> 3.06 | D62: Izaje, Identificación y/o codificación, y Señalización de Poste de 12 m/300 daN (*) | G62: u | H62: 6 | I62: 128.47 | J62: =+ROUND(I62*H62,2) -> 770.82 | L62: 142.74 | M62: =+ROUND(L62*$M$7,2) -> 128.47
B63: =+B62+0.01 -> 3.07 | D63: Izaje, Identificación y/o codificación, y Señalización de Poste de 12 m/200 daN (*) | G63: u | H63: 15 | I63: 123.37 | J63: =+ROUND(I63*H63,2) -> 1850.55 | L63: 137.08 | M63: =+ROUND(L63*$M$7,2) -> 123.37
B64: =+B63+0.01 -> 3.08 | D64: Relleno y Compactación para cimentación de Poste 12m, en Terreno Tipo I (Arcilloso y Conglomerado) | H64: 19.7 | I64: 109.4 | J64: =+ROUND(I64*H64,2) -> 2155.18 | L64: 121.56 | M64: =+ROUND(L64*$M$7,2) -> 109.4
...

Sheet TRANS_LP
B1: VALOR REFERENCIAL
B2: TRANSPORTE DE MATERIALES LÍNEAS PRIMARIAS
B3: UBICACIÓN | E3: : | F3: ANCASH
B4: SECCIÓN I | E4: : | F4: LÍNEAS PRIMARIAS
B5: C: TRANSPORTE DE MATERIALES
B7: Item | C7: Descripción de Partidas | G7: Unid. | H7: Metrado Cant. | I7: Costo Unitario | J7: SubTotal S/
D9: LINEAS PRIMARIAS
B11: 1 | D11: CRUCETAS DE MADERA DE PROCEDENCIA NACIONAL | P11: Indice Unificado
B12: =+B11+0.01 -> 1.01 | D12: =+'SUMINISTRO LP'!D12 -> Cruceta de madera tratada de 90 mm x 115 mm x 1,20 m | G12: u | H12: =+'SUMINISTRO LP'!H12 -> 11 | I12: 5.72 | J12: =+ROUND(I12*H12,2) -> 62.92 | O12: IU | P12: 44440 | Q12: 44682 | R12: Incremento
B13: =+B12+0.01 -> 1.02 | D13: =+'SUMINISTRO LP'!D13 -> Cruceta de madera tratada de 90 mm x 115 mm x 2,00 m | G13: u | H13: =+'SUMINISTRO LP'!H13 -> 2 | I13: 9.87 | J13: =+ROUND(I13*H13,2) -> 19.74 | O13: 32 | P13: 507.42 | Q13: 513.36 | R13: =+Q13/P13 -> 1.0117063
B14: =+B13+0.01 -> 1.03 | D14: =+'SUMINISTRO LP'!D14 -> Cruceta de madera tratada de 90 mm x 115 mm x 2,40 m | G14: u | H14: =+'SUMINISTRO LP'!H14 -> 1 | I14: 13.23 | J14: =+ROUND(I14*H14,2) -> 13.23
B15: =+B14+0.01 -> 1.04 | D15: =+'SUMINISTRO LP'!D15 -> Listón de madera tratada 50 x 19 mm sección, 2,7 m longitud (incluye clavos de fijación) | G15: u | H15: =+'SUMINISTRO LP'!H15 -> 9 | I15: 2.86 | J15: =+ROUND(I15*H15,2) -> 25.74
F16: =+"SUB-TOTAL "&B11&": " -> SUB-TOTAL 1: | J16: =+SUM(J11:J15) -> 121.63
B17: 2 | D17: POSTES DE CONCRETO ARMADO CENTRIFUGADO
B18: =+B17+0.01 -> 2.01 | D18: =+'SUMINISTRO LP'!D18 -> Poste de C.A.C. de 12 m/200 daN (Incluye perilla) | G18: u | H18: =+'SUMINISTRO LP'!H18 -> 15 | I18: 149.76 | J18: =+ROUND(I18*H18,2) -> 2246.4
B19: =+B18+0.01 -> 2.02 | D19: =+'SUMINISTRO LP'!D19 -> Poste de C.A.C. de 12 m/300 daN (Incluye perilla) | G19: u | H19: =+'SUMINISTRO LP'!H19 -> 6 | I19: 156.56 | J19: =+ROUND(I19*H19,2) -> 939.36
B20: =+B19+0.01 -> 2.03 | D20: =+'SUMINISTRO LP'!D20 -> Poste de C.A.C. de 13 m/300 daN (Incluye perilla) | G20: u | H20: =+'SUMINISTRO LP'!H20 -> 118 | I20: 178.72 | J20: =+ROUND(I20*H20,2) -> 21088.96
B21: =+B20+0.01 -> 2.04 | D21: =+'SUMINISTRO LP'!D21 -> Poste de C.A.C. de 13 m/400 daN (Incluye perilla) | G21: u | H21: =+'SUMINISTRO LP'!H21 -> 32 | I21: 191.36 | J21: =+ROUND(I21*H21,2) -> 6123.52
F22: =+"SUB-TOTAL "&B17&": " -> SUB-TOTAL 2: | J22: =+SUM(J18:J21) -> 30398.24
B23: 3 | D23: =+'SUMINISTRO LP'!D23 -> POSTES DE MADERA IMPORTADA
B24: =+B23+0.01 -> 3.01 | D24: =+'SUMINISTRO LP'!D24 -> Poste de madera importada (Pino Amarillo del Sur) de 12 m, Clase 6 | G24: =+'SUMINISTRO LP'!G24 -> u | H24: =+'SUMINISTRO LP'!H24 -> 9 | I24: 167.7 | J24: =+ROUND(I24*H24,2) -> 1509.3
F25: =+"SUB-TOTAL "&B23&": " -> SUB-TOTAL 3: | J25: =+SUM(J24) -> 1509.3
B26: 4 | D26: OTROS MATERIALES DE CONCRETO ARMADO
B27: =+B26+0.01 -> 4.01 | D27: =+'SUMINISTRO LP'!D27 -> Cruceta Asimétrica de C.A.V. Za / 1,5 / 0,9 / 250 / 200 / 100 daN (Za / L / L1/ T / F / V) | G27: u | H27: =+'SUMINISTRO LP'!H27 -> 2 | I27: 17.3 | J27: =+ROUND(I27*H27,2) -> 34.6
B28: =+B27+0.01 -> 4.02 | D28: =+'SUMINISTRO LP'!D28 -> Ménsula de C.A.V. M / 1,2 / 250 / 150 / 150 daN (M / L / T / F / V) | G28: u | H28: =+'SUMINISTRO LP'!H28 -> 393 | I28: 25.6 | J28: =+ROUND(I28*H28,2) -> 10060.8
B29: =+B28+0.01 -> 4.03 | D29: =+'SUMINISTRO LP'!D29 -> Ménsula de C.A.V. M / 0,8 / 250 / 150 / 150 daN (M / L / T / F / V) | G29: u | H29: =+'SUMINISTRO LP'!H29 -> 1 | I29: 22.28 | J29: =+ROUND(I29*H29,2) -> 22.28
F30: =+"SUB-TOTAL "&B26&": " -> SUB-TOTAL 4: | J30: =+SUM(J26:J29) -> 10117.68
B31: =1+B26 -> 5 | D31: AISLADORES Y ACCESORIOS
B32: =+B31+0.01 -> 5.01 | D32: Aislador de Porcelana Tipo Pin, Clase ANSI 56-3 | G32: u | H32: =+'SUMINISTRO LP'!H32 -> 29 | I32: 4.43 | J32: =+ROUND(I32*H32,2) -> 128.47
B33: =+B32+0.01 -> 5.02 | D33: Espiga de AºGº de 609 mm longitud, para Cabeza de Poste y Aislador ANSI 56-3 | G33: u | H33: =+'SUMINISTRO LP'!H33 -> 29 | I33: 2.84 | J33: =+ROUND(I33*H33,2) -> 82.36
B34: =+B33+0.01 -> 5.03 | D34: Conjunto Aislador Line Post Polimérico en Cruceta:
D35: - Aislador Polimérico de 36 kV, Tipo Line Post con Espárrago de 19 mm Ø, 200 mm longitud (Alternativa a Conjunto Aislador-Espiga en Cruceta) | G35: u | H35: =+'SUMINISTRO LP'!H35 -> 369 | I35: 1.64 | J35: =+ROUND(I35*H35,2) -> 605.16
F36: =+"SUB-TOTAL "&B31&": " -> SUB-TOTAL 5: | J36: =+SUM(J31:J35) -> 815.99
B37: =1+B31 -> 6 | D37: AISLADORES DE SUSPENSION Y ACCESORIOS
B38: =0.01+B37 -> 6.01 | D38: Grillete Recto | G38: u | H38: =+'SUMINISTRO LP'!H38 -> 155 | I38: 1.69 | J38: =+ROUND(I38*H38,2) -> 261.95
B39: =0.01+B38 -> 6.02 | D39: Aislador Polimerico con Conexión Horquilla (Estructura) y Lengüeta (Linea) de 36 kV, según Especificacion Técnica. | G39: u | H39: =+'SUMINISTRO LP'!H39 -> 155 | I39: 4.13 | J39: =+ROUND(I39*H39,2) -> 640.15
F40: =+"SUB-TOTAL "&B37&": " -> SUB-TOTAL 6: | J40: =+SUM(J37:J39) -> 902.1
B41: =1+B37 -> 7 | D41: CONDUCTOR DE ALEACIÓN DE ALUMINIO
B42: =+B41+0.01 -> 7.01 | D42: Conductor de Aleacion de Aluminio de 35 mm² | G42: km | H42: =+'SUMINISTRO LP'!H42 -> 53.4 | I42: 83.54 | J42: =+ROUND(I42*H42,2) -> 4461.04
B43: =+B42+0.01 -> 7.02 | D43: Conductor de Aleacion de Aluminio de 70 mm² | G43: km | H43: =+'SUMINISTRO LP'!H43 -> 1.91 | I43: 162.78 | J43: =+ROUND(I43*H43,2) -> 310.91
...

Sheet POLINOMICA LP
B3: FORMULA POLINÓMICA
C6: PROYECTO :
C7: AMPLIACIÓN DEL SERVICIO DE ENERGÍA ELÉCTRICA EN LA PROVINCIA DEL SANTA Y EN EL DISTRITO DE PAMPAROMAS – DEPARTAMENTO DE ANCASH”
C9: LINEAS PRIMARIAS
C10: PRESUPUESTO BASE S/ | D10: =+'RESUMEN LP'!F20 -> #REF! | K10: =D10=SUM(G13:G27) -> #REF! | L10: =D10='RESUMEN LP'!F20 -> #REF!
B12: Nº | C12: ELEMENTO REPRESENTATIVO | D12: INDICE | E12: SIMBOLO | F12: SIMBOLO MONOMIO | G12: MONTO | H12: INCIDENCIA | I12: % PARCIAL | J12: COEFICIENTE
B13: 1 | C13: POSTES DE MADERA IMPORTADA | D13: 042 | E13: PM | F13: PC | G13: =+'SUMINISTRO LP'!J25 -> 15330.51 | H13: =ROUND(G13/$D$10,3) -> #REF! | I13: =ROUND(G13/SUM($G$13:$G$16),4) -> 0.0646 | J13: =ROUND(SUM(H13:H16),3) -> #REF!
C14: CRUCETAS DE MADERA | D14: 043 | E14: CM | G14: =+'SUMINISTRO LP'!J16 -> 1962.15 | H14: =ROUND(G14/$D$10,3) -> #REF! | I14: =ROUND(G14/SUM($G$13:$G$16),4) -> 0.0083
C15: POSTES DE CONCRETO | D15: 062 | E15: PC | G15: =+'SUMINISTRO LP'!J22 -> 184803.17 | H15: =ROUND(G15/$D$10,3) -> #REF! | I15: =ROUND(G15/SUM($G$13:$G$16),4) -> 0.7787
C16: OTROS MATERIALES DE CONCRETO ARMADO | D16: 062 | E16: CC | G16: =+'SUMINISTRO LP'!J30 -> 35231.26 | H16: =ROUND(G16/$D$10,3) -> #REF! | I16: =ROUND(G16/SUM($G$13:$G$16),4) -> 0.1485
B17: 2 | C17: CONDUCTORES DE AAAC Y ACCESORIOS | D17: 030 | E17: DI | F17: DI | G17: =+'SUMINISTRO LP'!J44+'SUMINISTRO LP'!J59 -> 138631.38 | H17: =ROUND(G17/$D$10,3) -> #REF! | I17: =ROUND(G17/SUM($G$17:$G$18),4) -> 0.9343 | J17: =ROUND(SUM(H17:H18),3) -> #REF!
C18: EQUIPOS DE PROTECCIÓN | D18: 011 | E18: AE1 | G18: =+'SUMINISTRO LP'!J116 -> 9748.38 | H18: =ROUND(G18/$D$10,3) -> #REF! | I18: =ROUND(G18/SUM($G$17:$G$18),4) -> 0.0657
B19: 3 | C19: AISLADORES Y ACCESORIOS | D19: 011 | E19: AE2 | F19: AE2 | G19: =+'SUMINISTRO LP'!J36+'SUMINISTRO LP'!J40 -> 95255.84 | H19: =ROUND(G19/$D$10,3) -> #REF! | I19: =ROUND(G19/SUM($G$19:$G$24),4) -> 0.3926 | J19: =ROUND(SUM(H19:H24),3) -> #REF!
C20: RETENIDAS Y ANCLAJES | D20: 002 | E20: FE | G20: =+'SUMINISTRO LP'!J99 -> 27911.09 | H20: =ROUND(G20/$D$10,3) -> #REF! | I20: =ROUND(G20/SUM($G$19:$G$24),4) -> 0.115
C21: FERRETERIA PARA POSTES Y CRUCETAS | D21: 002 | E21: FP | G21: =+'SUMINISTRO LP'!J84 -> 13536.76 | H21: =ROUND(G21/$D$10,3) -> #REF! | I21: =ROUND(G21/SUM($G$19:$G$24),4) -> 0.0558
C22: CONDUCTOR DE COBRE | D22: 006 | E22: CU | G22: =+'SUMINISTRO LP'!J62 -> 37582.08 | H22: =ROUND(G22/$D$10,3) -> #REF! | I22: =ROUND(G22/SUM($G$19:$G$24),4) -> 0.1549
C23: MATERIAL PARA PUESTA A TIERRA | D23: 006 | E23: PT | G23: =+'SUMINISTRO LP'!J110 -> 11193.66 | H23: =ROUND(G23/$D$10,3) -> #REF! | I23: =ROUND(G23/SUM($G$19:$G$24),4) -> 0.0461
C24: TRAMO SUBTERRANEO | D24: 006 | E24: TS | G24: =+'SUMINISTRO LP'!J128 -> 57138.98 | H24: =ROUND(G24/$D$10,3) -> #REF! | I24: =ROUND(G24/SUM($G$19:$G$24),4) -> 0.2355
B25: 4 | C25: MONTAJE ELECTROMECANICO | D25: 047 | E25: J | F25: J | G25: =+'MONTAJE LP'!J130 -> 461491.17 | H25: =ROUND(G25/$D$10,3) -> #REF! | I25: =ROUND(G25/($G$25+$G$26),4) -> 0.8849 | J25: =ROUND(SUM(H25:H26),3) -> #REF!
C26: TRANSPORTE | D26: 032 | E26: FT | G26: =+TRANS_LP!J130 -> 60052.8 | H26: =ROUND(G26/$D$10,3) -> #REF! | I26: =ROUND(G26/($G$25+$G$26),4) -> 0.1151
B27: 5 | C27: GASTOS GENERALES Y UTILIDADES | D27: 039 | E27: GG | F27: GU | G27: =+'RESUMEN LP'!F17+'RESUMEN LP'!F18 -> #REF! | H27: =ROUND(G27/$D$10,3) -> #REF! | I27: =+G27/G27 -> #REF! | J27: =ROUND(SUM(H27),3) -> #REF!
B29: K= | C29: =J13&" PCr/PCo + "&J17&" DIr/DIo + "&J19&" AE2r/AE2o+ "&J25&" Jr/Jo + "&J27&" GUr/GUo" -> #REF!
B32: NOTAS:
B34: 1.- | C34: En la fórmula los sub-indices "o" de cada símbolo corresponden al indice de precios según (CREPCO) a la
C35: fecha de Elaboración del Presupuesto (Presupuesto Base) y los sub-indices "r" al indice de precios al
C36: momento de reajuste o fecha de valorización
B37: 2.- | C37: En el caso de los monomios compuestos por varios indices se ha considerado para efecto de denominación
C38: el símbolo que tiene mayor porcentaje de incidencia
B39: 3.- | C39: En caso de cambios en el suministro se deberá actualizar la formula polinómica.
H46: =+IF(SUM(H13:H27)=1,"OK","X") -> #REF! | I46: =+IF(SUM(I13:I27)=5,"OK","X") -> #REF! | J46: =+IF(SUM(J13:J27)=1,"OK","X") -> #REF!

Sheet RESUMEN RP
B2: VALOR REFERENCIAL
B3: REDES PRIMARIAS
B4: “AMPLIACIÓN DEL SERVICIO DE ENERGÍA ELÉCTRICA EN LA PROVINCIA DEL SANTA Y EN EL DISTRITO DE PAMPAROMAS – DEPARTAMENTO DE ANCASH”
B7: UBICACIÓN | D7: : | E7: ANCASH
B8: SECCIÓN II | D8: : | E8: REDES PRIMARIAS
F9: =+#REF! -> #REF!
F10: =+#REF! -> #REF!
B11: ITEM | C11: DESCRIPCION | F11: TOTAL S/
B13: A | D13: SUMINISTRO DE MATERIALES | F13: =+'SUMINISTRO RP'!J108 -> 202256.75
B14: B | D14: MONTAJE ELECTROMECANICO | F14: =+'MONTAJE RP'!J90 -> 85459.52
B15: C | D15: TRANSPORTE DE MATERIALES | F15: =+TRANS._RP!J109 -> 16212.19 | G15: =+F15/F13 -> 0.080156484
B16: D | D16: TOTAL COSTO DIRECTO | F16: =SUM(F13:F15) -> 303928.46
B18: E | E18: GASTOS GENERALES | F18: =+ROUND(F16*H18,2) -> #REF! | H18: =+#REF! -> #REF!
B19: F | E19: UTILIDADES | F19: =+ROUND(F16*H19,2) -> #REF! | H19: =+#REF! -> #REF!
D21: COSTO TOTAL S/ (No incluye I.G.V.) | F21: =SUM(F16:F19) -> #REF! | H21: =F21=#REF! -> #REF!

Sheet Alternativa-RP
B2: “ELABORACIÓN DEL PERFIL DEL PROYECTO “AMPLIACION DEL SERVICIO DE ELECTRIFICACIÓN RURAL EN LAS PROVINCIAS DE LEONCIO PRADO Y MARAÑON DEL DEPARTAMENTO DE HUANUCO Y LA PROVINCIA DE TOCACHE DEL DEPARTAMENTO DE SAN MARTIN”
B3: ="RESUMEN DEL VALOR REFERENCIAL " -> RESUMEN DEL VALOR REFERENCIAL
B5: UBICACIÓN | D5: :
B6: SECCIÓN I | D6: : | E6: RP
B9: ITEM | C9: DESCRIPCION | F9: TOTAL (S/.)
I10: =F11*0.07 -> 14157.973
B11: A | D11: SUMINISTROS DE MATERIALES | F11: =+'RESUMEN RP'!F13 -> 202256.75 | I11: =F11*0.1 -> 20225.675
D12: Origen Nacional | F12: =+F11-F13 -> 164615.74
D13: Origen Importado | F13: =+'SUMINISTRO RP'!J26+'SUMINISTRO RP'!J28+'SUMINISTRO RP'!J36+'SUMINISTRO RP'!J48+'SUMINISTRO RP'!J94+'SUMINISTRO RP'!J107 -> 37641.01
B15: B | D15: MONTAJE ELECTROMECANICO | F15: =+'RESUMEN RP'!F14 -> 85459.52 | H15: =+F15/$F$11 -> 0.42252988
D16: M.O. Calificada | F16: =ROUND(N16*F15,2) -> 53839.5 | N16: 0.63
D17: M.O. No Calificada | F17: =ROUND(N17*F15,2) -> 31620.02 | N17: =1-N16 -> 0.37
B19: B.1 | D19: ACTIVIDADES COMPLEMENTARIAS DE MONTAJE | F19: 0
B21: C | D21: TRANSPORTE DE MATERIALES | F21: =+'RESUMEN RP'!F15 -> 16212.19 | H21: 0.1
B24: D | D24: TOTAL COSTO DIRECTO (C.D.) | F24: =+F21+F15+F11+F19 -> 303928.46

Sheet SUMINISTRO RP
B1: VALOR REFERENCIAL
B2: SUMINISTRO DE MATERIALES REDES PRIMARIAS
B3: UBICACIÓN | E3: : | F3: ANCASH
B4: SECCIÓN II | E4: : | F4: REDES PRIMARIAS
B5: A: SUMINISTRO DE MATERIALES
B7: Item | C7: Descripción de Partidas | G7: Unid. | H7: Metrado Cant. | I7: Costo Unitario | J7: SubTotal S/
B9: 1 | D9: CRUCETAS DE MADERA DE PROCEDENCIA NACIONAL
B10: =+B9+0.01 -> 1.01 | D10: Cruceta de madera tratada de 90 mm x 115 mm x 1,20 m | G10: u | H10: 13 | I10: 105 | J10: =+ROUND(I10*H10,2) -> 1365
B11: =+B10+0.01 -> 1.02 | D11: Listón de madera tratada 50 x 19 mm sección, 2,7 m longitud (incluye clavos de fijación) | G11: u | H11: 2 | I11: 27.35 | J11: =+ROUND(I11*H11,2) -> 54.7
F12: =+"SUB-TOTAL "&B9&": " -> SUB-TOTAL 1: | J12: =SUM(J10:J11) -> 1419.7
B13: =1+B9 -> 2 | D13: POSTES DE CONCRETO ARMADO CENTRIFUGADO
B14: =+B13+0.01 -> 2.01 | D14: Poste de C.A.C. de 12 m/200 daN (Incluye perilla) | G14: u | H14: 3 | I14: 837.45 | J14: =+ROUND(I14*H14,2) -> 2512.35
B15: =+B14+0.01 -> 2.02 | D15: Poste de C.A.C. de 12 m/300 daN (Incluye perilla) | G15: u | H15: 11 | I15: 923.47 | J15: =+ROUND(I15*H15,2) -> 10158.17
B16: =+B15+0.01 -> 2.03 | D16: Poste de C.A.C. de 13 m/300 daN (Incluye perilla) | G16: u | H16: 10 | I16: 1085.14 | J16: =+ROUND(I16*H16,2) -> 10851.4
B17: =+B16+0.01 -> 2.04 | D17: Poste de C.A.C. de 13 m/400 daN (Incluye perilla) | G17: u | H17: 10 | I17: 1207.94 | J17: =+ROUND(I17*H17,2) -> 12079.4
F18: =+"SUB-TOTAL "&B13&": " -> SUB-TOTAL 2: | J18: =SUM(J14:J17) -> 35601.32
B19: 3 | D19: POSTES DE MADERA IMPORTADA
B20: =+B19+0.01 -> 3.01 | D20: Poste de madera importada (Pino Amarillo del Sur) de 12 m, Clase 5 | G20: u | H20: 2 | I20: 1864.52 | J20: =+ROUND(I20*H20,2) -> 3729.04
F21: =+"SUB-TOTAL "&B19&": " -> SUB-TOTAL 3: | J21: =+SUM(J19:J20) -> 3729.04
B22: =1+B19 -> 4 | D22: OTROS MATERIALES DE CONCRETO ARMADO
B23: =+B22+0.01 -> 4.01 | D23: Cruceta Asimétrica de C.A.V. Za / 1,5 / 0,9 / 250 / 200 / 100 daN (Za / L / L1/ T / F / V) | G23: u | H23: 5 | I23: 120.3 | J23: =+ROUND(I23*H23,2) -> 601.5
B24: =+B23+0.01 -> 4.02 | D24: Ménsula de C.A.V. M / 1,2 / 250 / 150 / 150 daN (M / L / T / F / V) | G24: u | H24: 40 | I24: 88.8 | J24: =+ROUND(I24*H24,2) -> 3552
B25: =+B24+0.01 -> 4.03 | D25: Plataforma de Concreto Soporte de Transformador de 2,20 m, carga de trabajo de 500 daN | G25: u | H25: 5 | I25: 620 | J25: =+ROUND(I25*H25,2) -> 3100
F26: =+"SUB-TOTAL "&B22&": " -> SUB-TOTAL 4: | J26: =SUM(J23:J25) -> 7253.5
B27: =1+B22 -> 5 | D27: AISLADORES Y ACCESORIOS
B28: =+B27+0.01 -> 5.01 | D28: Aislador de Porcelana Tipo Pin, Clase ANSI 56-3 | G28: u | H28: 16 | I28: 76.45 | J28: =+ROUND(I28*H28,2) -> 1223.2
B29: =+B28+0.01 -> 5.02 | D29: Espiga de AºGº de 609 mm longitud, para Cabeza de Poste y Aislador ANSI 56-3 | G29: u | H29: 16 | I29: 35.96 | J29: =+ROUND(I29*H29,2) -> 575.36
B30: =+B29+0.01 -> 5.03 | D30: Conjunto Aislador Line Post Polimérico en Cruceta:
D31: - Aislador Polimérico de 36 kV, Tipo Line Post con Espárrago de 19 mm Ø, 200 mm longitud (Alternativa a Conjunto Aislador-Espiga en Cruceta) | G31: u | H31: 40 | I31: 209.65 | J31: =+ROUND(I31*H31,2) -> 8386
F32: =+"SUB-TOTAL "&B27&": " -> SUB-TOTAL 5: | J32: =+SUM(J28:J31) -> 10184.56
B33: =1+B27 -> 6 | D33: AISLADORES DE SUSPENSIÓN Y ACCESORIOS
B34: =+B33+0.01 -> 6.01 | D34: Grillete Recto | G34: u | H34: 16 | I34: 17.76 | J34: =+ROUND(I34*H34,2) -> 284.16
B35: =+B34+0.01 -> 6.02 | D35: Aislador Polimerico con Conexión Horquilla (Estructura) y Lengüeta (Linea) de 36 kV, según Especificacion Técnica. | G35: u | H35: 16 | I35: 76.66 | J35: =+ROUND(I35*H35,2) -> 1226.56
F36: =+"SUB-TOTAL "&B33&": " -> SUB-TOTAL 6: | J36: =+SUM(J33:J35) -> 1510.72
B37: =1+B33 -> 7 | D37: CONDUCTOR DE ALEACIÓN DE ALUMINIO
B38: =+B37+0.01 -> 7.01 | D38: Conductor de Aleacion de Aluminio de 35 mm² | G38: km | H38: 3.51 | I38: 2249.62 | J38: =+ROUND(I38*H38,2) -> 7896.17
F39: =+"SUB-TOTAL "&B37&": " -> SUB-TOTAL 7: | J39: =+SUM(J38:J38) -> 7896.17
B40: =B37+1 -> 8 | D40: ACCESORIOS PARA CONDUCTOR DE ALEACION ALUMINIO
B41: =+B40+0.01 -> 8.01 | D41: Varilla de Armar preformada Simple para Conductor de 35 mm² | G41: u | H41: 41 | I41: 10.19 | J41: =+ROUND(I41*H41,2) -> 417.79
B42: =+B41+0.01 -> 8.02 | D42: Grapa de Doble Via de Aluminio para Conductor de 35 mm² | G42: u | H42: 41 | I42: 7.77 | J42: =+ROUND(I42*H42,2) -> 318.57
...

Sheet MONTAJE RP
B1: VALOR REFERENCIAL
B2: MONTAJE ELECTROMECÁNICO DE REDES PRIMARIAS
B3: UBICACIÓN | E3: : | F3: ANCASH
B4: SECCIÓN II | E4: : | F4: REDES PRIMARIAS
B5: B: MONTAJE ELECTROMECÁNICO
B7: Item | C7: Descripción de Partidas | G7: Unid. | H7: Metrado Cant. | I7: Costo Unitario | J7: SubTotal S/ | L7: Costo Unitario | M7: 0.9
B9: 1 | D9: TRANSPORTE DE MATERIALES DE ALMACEN EN OBRA A PUNTO DE INSTALACIÒN
B10: =+B9+0.01 -> 1.01 | D10: Transporte de Poste de 12 m/200 daN de Almacen a Punto de Izaje, en Terreno con Acceso Carrozable | G10: u | H10: 3 | I10: 247.05 | J10: =+ROUND(I10*H10,2) -> 741.15 | L10: 274.5 | M10: =+ROUND(L10*$M$7,2) -> 247.05
B11: =+B10+0.01 -> 1.02 | D11: Transporte de Poste de 12 m/300 daN de Almacen a Punto de Izaje, en Terreno con Acceso Carrozable | G11: u | H11: 11 | I11: 270.59 | J11: =+ROUND(I11*H11,2) -> 2976.49 | L11: 300.66 | M11: =+ROUND(L11*$M$7,2) -> 270.59
B12: =+B11+0.01 -> 1.03 | D12: Transporte de Poste de 13 m/300 daN de Almacen a Punto de Izaje, en Terreno con Acceso Carrozable | G12: u | H12: 10 | I12: 301.46 | J12: =+ROUND(I12*H12,2) -> 3014.6 | L12: 334.95 | M12: =+ROUND(L12*$M$7,2) -> 301.46
B13: =+B12+0.01 -> 1.04 | D13: Transporte de Poste de 13 m/400 daN de Almacen a Punto de Izaje, en Terreno con Acceso Carrozable | G13: u | H13: 10 | I13: 338.24 | J13: =+ROUND(I13*H13,2) -> 3382.4 | L13: 375.82 | M13: =+ROUND(L13*$M$7,2) -> 338.24
B14: =+B13+0.01 -> 1.05 | D14: Transporte de Poste de madera importado de 12 m, Clase 5 de Almacen a Punto de Izaje, en Terreno sin Acceso Carrozable (< 1000 m) | G14: u | H14: 2 | I14: 272.39 | J14: =+ROUND(I14*H14,2) -> 544.78 | L14: 302.66 | M14: =+ROUND(L14*$M$7,2) -> 272.39
B15: =+B14+0.01 -> 1.06 | D15: Transporte de Cruceta de madera tratada de 90 mm x 115 mm x 1,20 m, de Almacen a Punto de Instalaciòn en Terreno con Acceso Carrozable | G15: u | H15: 11 | I15: 5.43 | J15: =+ROUND(I15*H15,2) -> 59.73 | L15: 6.03 | M15: =+ROUND(L15*$M$7,2) -> 5.43
B16: =+B15+0.01 -> 1.07 | D16: Transporte de Cruceta de madera tratada de 90 mm x 115 mm x 1,20 m, de Almacen a Punto de Instalaciòn en Terreno sin Acceso Carrozable (< 1000 m) | G16: u | H16: 2 | I16: 7.06 | J16: =+ROUND(I16*H16,2) -> 14.12 | L16: 7.84 | M16: =+ROUND(L16*$M$7,2) -> 7.06
B17: =+B16+0.01 -> 1.08 | D17: Transporte de Aislador de Porcelana Tipo Pin, Clase ANSI 56-3 de Almacén a Punto de Instalaciòn en Terreno con Acceso Carrozable | G17: u | H17: 14 | I17: 10.62 | J17: =+ROUND(I17*H17,2) -> 148.68 | L17: 11.8 | M17: =+ROUND(L17*$M$7,2) -> 10.62
B18: =+B17+0.01 -> 1.09 | D18: Transporte de Aislador de Porcelana Tipo Pin, Clase ANSI 56-3 de Almacén a Punto de Instalaciòn en Terreno sin Acceso Carrozable (< 1000 m) | G18: u | H18: 2 | I18: 13.11 | J18: =+ROUND(I18*H18,2) -> 26.22 | L18: 14.57 | M18: =+ROUND(L18*$M$7,2) -> 13.11
B19: =+B18+0.01 -> 1.1 | D19: Transporte de Aislador Line Post Polimérico de Almacén a Punto de Instalaciòn en Terreno con Acceso Carrozable | G19: u | H19: 40 | I19: 13.1 | J19: =+ROUND(I19*H19,2) -> 524 | L19: 14.56 | M19: =+ROUND(L19*$M$7,2) -> 13.1
B20: =+B19+0.01 -> 1.11 | D20: Transporte de Aislador Polimerico con Conexión Horquilla (Estructura) y Lengüeta (Linea), de 36 Kv y según Especificacion Técnica. de Almacen a Punto de Intalaciòn en Terreno con Acceso Carrozable | G20: u | H20: 25 | I20: 5.43 | J20: =+ROUND(I20*H20,2) -> 135.75 | L20: 6.03 | M20: =+ROUND(L20*$M$7,2) -> 5.43
B21: =+B20+0.01 -> 1.12 | D21: Transporte de Conductor de Aleacion de Aluminio de 35 mm² de Almacen a Punto de Intalaciòn en Terreno con Acceso Carrozable | G21: km | H21: 3.46 | I21: 64.56 | J21: =+ROUND(I21*H21,2) -> 223.38 | L21: 71.73 | M21: =+ROUND(L21*$M$7,2) -> 64.56
... B39: =+B38+0.01 -> 1.3 | D39: Transporte de Plataforma de Concreto Soporte de Transformador, de Almacen a Punto de Instalaciòn en Terreno con Acceso Carrozable | G39: u | H39: 5 | I39: 99.31 | J39: =+ROUND(I39*H39,2) -> 496.55 | L39: 110.34 | M39: =+ROUND(L39*$M$7,2) -> 99.31
F40: =+"SUB-TOTAL "&B9&": " -> SUB-TOTAL 1: | J40: =SUM(J10:J39) -> 22429.41
B41: 2 | D41: INSTALACION DE POSTES
B42: =+B41+0.01 -> 2.01 | D42: Excavación en Terreno Tipo I (Arcilloso y Conglomerado) | H42: 29.79 | I42: 61.15 | J42: =+ROUND(I42*H42,2) -> 1821.66 | L42: 67.94 | M42: =+ROUND(L42*$M$7,2) -> 61.15
B43: =+B42+0.01 -> 2.02 | D43: Excavación en Terreno Tipo II (Rocoso) | H43: 7.14 | I43: 208.14 | J43: =+ROUND(I43*H43,2) -> 1486.12 | L43: 231.27 | M43: =+ROUND(L43*$M$7,2) -> 208.14
B44: =+B43+0.01 -> 2.03 | D44: Izaje, Identificación y/o codificación, y Señalización de Poste de 12 m/200 daN (*) | G44: u | H44: 3 | I44: 123.37 | J44: =+ROUND(I44*H44,2) -> 370.11 | L44: 137.08 | M44: =+ROUND(L44*$M$7,2) -> 123.37
B45: =+B44+0.01 -> 2.04 | D45: Izaje, Identificación y/o codificación, y Señalización de Poste de 12 m/300 daN (*) | G45: u | H45: 11 | I45: 128.47 | J45: =+ROUND(I45*H45,2) -> 1413.17 | L45: 142.74 | M45: =+ROUND(L45*$M$7,2) -> 128.47
B46: =+B45+0.01 -> 2.05 | D46: Izaje, Identificación y/o codificación, y Señalización de Poste de 13 m/300 daN (*) | G46: u | H46: 10 | I46: 154.07 | J46: =+ROUND(I46*H46,2) -> 1540.7 | L46: 171.19 | M46: =+ROUND(L46*$M$7,2) -> 154.07
B47: =+B46+0.01 -> 2.06 | D47: Izaje, Identificación y/o codificación, y Señalización de Poste de 13 m/400 daN (*) | G47: u | H47: 10 | I47: 194.85 | J47: =+ROUND(I47*H47,2) -> 1948.5 | L47: 216.5 | M47: =+ROUND(L47*$M$7,2) -> 194.85
B48: =+B47+0.01 -> 2.07 | D48: Izaje, Identificación y/o codificación, y Señalización de Poste de madera importada de 12 m, Clase 5 (*) | G48: u | H48: 2 | I48: 105.19 | J48: =+ROUND(I48*H48,2) -> 210.38 | L48: 116.88 | M48: =+ROUND(L48*$M$7,2) -> 105.19
B49: =+B48+0.01 -> 2.08 | D49: Relleno y Compactación para cimentación de Poste 12m, en Terreno Tipo I (Arcilloso y Conglomerado) | H49: 12.32 | I49: 109.4 | J49: =+ROUND(I49*H49,2) -> 1347.81 | L49: 121.56 | M49: =+ROUND(L49*$M$7,2) -> 109.4
B50: =+B49+0.01 -> 2.09 | D50: Cimentación con Concreto Ciclópeo de Poste de 13m en Terreno Tipo I (Arcilloso y Conglomerado) | G50: u | H50: 13 | I50: 279.45 | J50: =+ROUND(I50*H50,2) -> 3632.85 | L50: 310.5 | M50: =+ROUND(L50*$M$7,2) -> 279.45
B51: =+B50+0.01 -> 2.1 | D51: Cimentación con concreto ciclópeo de Poste de 13m en Terreno Tipo II (Rocoso) | G51: u | H51: 7 | I51: 270.54 | J51: =+ROUND(I51*H51,2) -> 1893.78 | L51: 300.6 | M51: =+ROUND(L51*$M$7,2) -> 270.54
B52: =+B51+0.01 -> 2.11 | D52: Solado para poste de concreto (e=0.10 m. C:H, 1:8) | G52: u | H52: 20 | I52: 25.38 | J52: =+ROUND(I52*H52,2) -> 507.6 | L52: 28.2 | M52: =+ROUND(L52*$M$7,2) -> 25.38
F53: =+"SUB-TOTAL "&B41&": " -> SUB-TOTAL 2: | J53: =+SUM(J42:J52) -> 16172.68
B54: 3 | D54: INSTALACION DE RETENIDAS
B55: =+B54+0.01 -> 3.01 | D55: Excavación en Terreno Tipo I (Arcilloso y Conglomerado) | H55: 7.84 | I55: 61.15 | J55: =+ROUND(I55*H55,2) -> 479.42 | L55: 67.94 | M55: =+ROUND(L55*$M$7,2) -> 61.15
B56: =+B55+0.01 -> 3.02 | D56: Excavación en Terreno Tipo II (Rocoso) | H56: 2.24 | I56: 208.14 | J56: =+ROUND(I56*H56,2) -> 466.23 | L56: 231.27 | M56: =+ROUND(L56*$M$7,2) -> 208.14
B57: =+B56+0.01 -> 3.03 | D57: Instalación de Retenida Inclinada | G57: u | H57: 4 | I57: 87.45 | J57: =+ROUND(I57*H57,2) -> 349.8 | L57: 97.17 | M57: =+ROUND(L57*$M$7,2) -> 87.45
B58: =+B57+0.01 -> 3.04 | D58: Instalación de Retenida Inclinada en Y | G58: u | H58: 5 | I58: 103.71 | J58: =+ROUND(I58*H58,2) -> 518.55 | L58: 115.23 | M58: =+ROUND(L58*$M$7,2) -> 103.71
B59: =+B58+0.01 -> 3.05 | D59: Relleno y Compactación en Terreno Tipo I de Retenida | H59: 7.7 | I59: 90.22 | J59: =+ROUND(I59*H59,2) -> 694.69 | L59: 100.24 | M59: =+ROUND(L59*$M$7,2) -> 90.22
...

Sheet TRANS._RP
B1: VALOR REFERENCIAL
B2: TRANSPORTE DE MATERIALES DE REDES PRIMARIAS
B3: UBICACIÓN | E3: : | F3: ANCASH
B4: SECCIÓN II | E4: : | F4: REDES PRIMARIAS
B5: C: TRANSPORTE DE MATERIALES
B7: Item | C7: Descripción de Partidas | G7: Unid. | H7: Metrado Cant. | I7: Costo Unitario | J7: SubTotal S/
B9: 1 | D9: CRUCETAS DE MADERA DE PROCEDENCIA NACIONAL
B10: =+B9+0.01 -> 1.01 | D10: =+'SUMINISTRO RP'!D10 -> Cruceta de madera tratada de 90 mm x 115 mm x 1,20 m | G10: =+'SUMINISTRO RP'!G10 -> u | H10: =+'SUMINISTRO RP'!H10 -> 13 | I10: 5.72 | J10: =+ROUND(I10*H10,2) -> 74.36 | Q10: Indice Unificado
B11: =+B10+0.01 -> 1.02 | D11: =+'SUMINISTRO RP'!D11 -> Listón de madera tratada 50 x 19 mm sección, 2,7 m longitud (incluye clavos de fijación) | G11: =+'SUMINISTRO RP'!G11 -> u | H11: =+'SUMINISTRO RP'!H11 -> 2 | I11: 2.86 | J11: =+ROUND(I11*H11,2) -> 5.72 | P11: IU | Q11: 44440 | R11: 44682 | S11: Incremento
F12: =+"SUB-TOTAL "&B9&": " -> SUB-TOTAL 1: | J12: =SUM(J10:J11) -> 80.08 | P12: 32 | Q12: 507.42 | R12: 513.36 | S12: =+R12/Q12 -> 1.0117063
B13: =1+B9 -> 2 | D13: POSTES DE CONCRETO ARMADO CENTRIFUGADO
B14: =+B13+0.01 -> 2.01 | D14: =+'SUMINISTRO RP'!D14 -> Poste de C.A.C. de 12 m/200 daN (Incluye perilla) | G14: =+'SUMINISTRO RP'!G14 -> u | H14: =+'SUMINISTRO RP'!H14 -> 3 | I14: 149.76 | J14: =+ROUND(I14*H14,2) -> 449.28
B15: =+B14+0.01 -> 2.02 | D15: =+'SUMINISTRO RP'!D15 -> Poste de C.A.C. de 12 m/300 daN (Incluye perilla) | G15: =+'SUMINISTRO RP'!G15 -> u | H15: =+'SUMINISTRO RP'!H15 -> 11 | I15: 156.56 | J15: =+ROUND(I15*H15,2) -> 1722.16
B16: =+B15+0.01 -> 2.03 | D16: =+'SUMINISTRO RP'!D16 -> Poste de C.A.C. de 13 m/300 daN (Incluye perilla) | G16: =+'SUMINISTRO RP'!G16 -> u | H16: =+'SUMINISTRO RP'!H16 -> 10 | I16: 178.72 | J16: =+ROUND(I16*H16,2) -> 1787.2
B17: =+B16+0.01 -> 2.04 | D17: =+'SUMINISTRO RP'!D17 -> Poste de C.A.C. de 13 m/400 daN (Incluye perilla) | G17: =+'SUMINISTRO RP'!G17 -> u | H17: =+'SUMINISTRO RP'!H17 -> 10 | I17: 191.36 | J17: =+ROUND(I17*H17,2) -> 1913.6
F18: =+"SUB-TOTAL "&B13&": " -> SUB-TOTAL 2: | J18: =+SUM(J14:J17) -> 5872.24
B19: 3 | D19: POSTES DE MADERA IMPORTADA
B20: =+B19+0.01 -> 3.01 | D20: =+'SUMINISTRO RP'!D20 -> Poste de madera importada (Pino Amarillo del Sur) de 12 m, Clase 5 | G20: =+'SUMINISTRO RP'!G20 -> u | H20: =+'SUMINISTRO RP'!H20 -> 2 | I20: 174.7 | J20: =+ROUND(I20*H20,2) -> 349.4
F21: =+"SUB-TOTAL "&B19&": " -> SUB-TOTAL 3: | J21: =+SUM(J19:J20) -> 349.4
B22: 4 | D22: OTROS MATERIALES DE CONCRETO ARMADO
B23: =+B22+0.01 -> 4.01 | D23: =+'SUMINISTRO RP'!D23 -> Cruceta Asimétrica de C.A.V. Za / 1,5 / 0,9 / 250 / 200 / 100 daN (Za / L / L1/ T / F / V) | G23: =+'SUMINISTRO RP'!G23 -> u | H23: =+'SUMINISTRO RP'!H23 -> 5 | I23: 17.3 | J23: =+ROUND(I23*H23,2) -> 86.5
B24: =+B23+0.01 -> 4.02 | D24: =+'SUMINISTRO RP'!D24 -> Ménsula de C.A.V. M / 1,2 / 250 / 150 / 150 daN (M / L / T / F / V) | G24: =+'SUMINISTRO RP'!G24 -> u | H24: =+'SUMINISTRO RP'!H24 -> 40 | I24: 25.6 | J24: =+ROUND(I24*H24,2) -> 1024
B25: =+B24+0.01 -> 4.03 | D25: =+'SUMINISTRO RP'!D25 -> Plataforma de Concreto Soporte de Transformador de 2,20 m, carga de trabajo de 500 daN | G25: =+'SUMINISTRO RP'!G25 -> u | H25: =+'SUMINISTRO RP'!H25 -> 5 | I25: 27.61 | J25: =+ROUND(I25*H25,2) -> 138.05
F26: =+"SUB-TOTAL "&B22&": " -> SUB-TOTAL 4: | J26: =+SUM(J23:J25) -> 1248.55
B27: =1+B22 -> 5 | D27: AISLADORES Y ACCESORIOS
B28: =+B27+0.01 -> 5.01 | D28: =+'SUMINISTRO RP'!D28 -> Aislador de Porcelana Tipo Pin, Clase ANSI 56-3 | G28: =+'SUMINISTRO RP'!G28 -> u | H28: =+'SUMINISTRO RP'!H28 -> 16 | I28: 4.43 | J28: =+ROUND(I28*H28,2) -> 70.88
B29: =+B28+0.01 -> 5.02 | D29: =+'SUMINISTRO RP'!D29 -> Espiga de AºGº de 609 mm longitud, para Cabeza de Poste y Aislador ANSI 56-3 | G29: =+'SUMINISTRO RP'!G29 -> u | H29: =+'SUMINISTRO RP'!H29 -> 16 | I29: 2.84 | J29: =+ROUND(I29*H29,2) -> 45.44
B30: =+B29+0.01 -> 5.03 | D30: =+'SUMINISTRO RP'!D30 -> Conjunto Aislador Line Post Polimérico en Cruceta:
D31: =+'SUMINISTRO RP'!D31 -> - Aislador Polimérico de 36 kV, Tipo Line Post con Espárrago de 19 mm Ø, 200 mm longitud (Alternativa a Conjunto Aislador-Espiga en Cruceta) | G31: =+'SUMINISTRO RP'!G31 -> u | H31: =+'SUMINISTRO RP'!H31 -> 40 | I31: 1.64 | J31: =+ROUND(I31*H31,2) -> 65.6
F32: =+"SUB-TOTAL "&B27&": " -> SUB-TOTAL 5: | J32: =+SUM(J28:J31) -> 181.92
B33: =1+B27 -> 6 | D33: AISLADORES DE SUSPENSIÓN Y ACCESORIOS
B34: =+B33+0.01 -> 6.01 | D34: =+'SUMINISTRO RP'!D34 -> Grillete Recto | G34: =+'SUMINISTRO RP'!G34 -> u | H34: =+'SUMINISTRO RP'!H34 -> 16 | I34: 1.69 | J34: =+ROUND(I34*H34,2) -> 27.04
B35: =+B34+0.01 -> 6.02 | D35: =+'SUMINISTRO RP'!D35 -> Aislador Polimerico con Conexión Horquilla (Estructura) y Lengüeta (Linea) de 36 kV, según Especificacion Técnica. | G35: =+'SUMINISTRO RP'!G35 -> u | H35: =+'SUMINISTRO RP'!H35 -> 16 | I35: 4.13 | J35: =+ROUND(I35*H35,2) -> 66.08
F36: =+"SUB-TOTAL "&B33&": " -> SUB-TOTAL 6: | J36: =+SUM(J33:J35) -> 93.12
B37: =1+B33 -> 7 | D37: CONDUCTOR DE ALEACIÓN DE ALUMINIO
B38: =+B37+0.01 -> 7.01 | D38: =+'SUMINISTRO RP'!D38 -> Conductor de Aleacion de Aluminio de 35 mm² | G38: =+'SUMINISTRO RP'!G38 -> km | H38: =+'SUMINISTRO RP'!H38 -> 3.51 | I38: 83.54 | J38: =+ROUND(I38*H38,2) -> 293.23
F39: =+"SUB-TOTAL "&B37&": " -> SUB-TOTAL 7: | J39: =+SUM(J38:J38) -> 293.23
B40: =B37+1 -> 8 | D40: ACCESORIOS PARA CONDUCTOR DE ALEACION ALUMINIO
B41: =+B40+0.01 -> 8.01 | D41: =+'SUMINISTRO RP'!D41 -> Varilla de Armar preformada Simple para Conductor de 35 mm² | G41: =+'SUMINISTRO RP'!G41 -> u | H41: =+'SUMINISTRO RP'!H41 -> 41 | I41: 0.68 | J41: =+ROUND(I41*H41,2) -> 27.88
B42: =+B41+0.01 -> 8.02 | D42: =+'SUMINISTRO RP'!D42 -> Grapa de Doble Via de Aluminio para Conductor de 35 mm² | G42: =+'SUMINISTRO RP'!G42 -> u | H42: =+'SUMINISTRO RP'!H42 -> 41 | I42: 0.35 | J42: =+ROUND(I42*H42,2) -> 14.35
...

Sheet POLINOMICA RP
B3: FORMULA POLINÓMICA
C6: PROYECTO :
C7: AMPLIACIÓN DEL SERVICIO DE ENERGÍA ELÉCTRICA EN LA PROVINCIA DEL SANTA Y EN EL DISTRITO DE PAMPAROMAS – DEPARTAMENTO DE ANCASH”
C9: REDES PRIMARIAS
C10: PRESUPUESTO BASE S/ | D10: =+'RESUMEN RP'!F21 -> #REF! | L10: =D10=SUM(G13:G28) -> #REF! | M10: =D10='RESUMEN RP'!F21 -> #REF!
B12: Nº | C12: ELEMENTO REPRESENTATIVO | D12: INDICE | E12: SIMBOLO | F12: SIMBOLO MONOMIO | G12: MONTO | H12: INCIDENCIA | I12: % PARCIAL | J12: COEFICIENTE
B13: 1 | C13: POSTES DE MADERA IMPORTADA | D13: 042 | E13: PM | F13: PC | G13: =+'SUMINISTRO RP'!J21 -> 3729.04 | H13: =ROUND(G13/$D$10,3) -> #REF! | I13: =ROUND(G13/SUM($G$13:$G$20),4) -> 0.0497 | J13: =ROUND(SUM(H13:H20),3) -> #REF!
C14: CRUCETAS DE MADERA | D14: 043 | E14: CM | G14: =+'SUMINISTRO RP'!J12 -> 1419.7 | H14: =ROUND(G14/$D$10,3) -> #REF! | I14: =ROUND(G14/SUM($G$13:$G$20),4) -> 0.0189
C15: POSTES DE CONCRETO | D15: 062 | E15: PC | G15: =+'SUMINISTRO RP'!J18 -> 35601.32 | H15: =ROUND(G15/$D$10,3) -> #REF! | I15: =ROUND(G15/SUM($G$13:$G$20),4) -> 0.4748
C16: OTROS MATERIALES DE CONCRETO ARMADO | D16: 062 | E16: CC | G16: =+'SUMINISTRO RP'!J26 -> 7253.5 | H16: =ROUND(G16/$D$10,3) -> #REF! | I16: =ROUND(G16/SUM($G$13:$G$20),4) -> 0.0967
C17: FERRETERIA PARA POSTES Y CRUCETAS | D17: 002 | E17: FP | G17: =+'SUMINISTRO RP'!J65 -> 3611.97 | H17: =ROUND(G17/$D$10,3) -> #REF! | I17: =ROUND(G17/SUM($G$13:$G$20),4) -> 0.0482
C18: RETENIDAS Y ANCLAJES | D18: 002 | E18: FE | G18: =+'SUMINISTRO RP'!J78 -> 3956.28 | H18: =ROUND(G18/$D$10,3) -> #REF! | I18: =ROUND(G18/SUM($G$13:$G$20),4) -> 0.0528
C19: CONDUCTOR DE COBRE Y ACCESORIOS | D19: 006 | E19: CU | G19: =+'SUMINISTRO RP'!J45+'SUMINISTRO RP'!J48 -> 10565.5 | H19: =ROUND(G19/$D$10,3) -> #REF! | I19: =ROUND(G19/SUM($G$13:$G$20),4) -> 0.1409
