Workbook
Name _10ELECSURME: '[35]Unit-op-cartel'!#REF!
Name _13ELECT: '[35]Unit-op-cartel'!#REF!
Name _16ELECTROL: '[35]Unit-op-cartel'!#REF!
Name _19ELEORIE: '[35]Unit-op-cartel'!#REF!
Name _1EL: '[35]Unit-op-cartel'!#REF!
Name _22ELNO: '[35]Unit-op-cartel'!#REF!
Name _25ELSURE: '[35]Unit-op-cartel'!#REF!
Name _28HIDRAND: '[35]Unit-op-cartel'!#REF!
Name _31S: '[35]Unit-op-cartel'!#REF!
Name _4ELCEN: '[35]Unit-op-cartel'!#REF!
Name _7ELECSURE: '[35]Unit-op-cartel'!#REF!
Name _sec01: '[44]Datos'!$D$26
Name _sec02: '[44]Datos'!$D$27
Name _sec03: '[44]Datos'!$D$28
Name _sec04: '[44]Datos'!$D$29
Name _sec05: '[44]Datos'!$D$30
Name A: '[4]REV3'!$A$32
Name AAA: #REF!
Name ABC: '[51]#¡REF'!#REF!
Name ADV: '[58]#¡REF'!#REF!
Name AEFecha: '[44]Datos'!$D$32
Name AMFecha: '[44]Datos'!$D$33
Name BB: #REF!
Name CD: #REF!
Name DDD: [105]CALCULO!#REF!
Name Departamento: '[92]DATOS DE CAMPO LP'!#REF!
Name DESCRIPCION: #REF!
Name DETAILED: '[112]#¡REF'!#REF!
Name DETALLE: '[112]#¡REF'!#REF!
Name dolar: #REF!
Name Fecha: #REF!
Name fr: '[44]Datos'!$D$9
Name ggd: '[44]Datos'!$D$6
Name ggi: '[44]Datos'!$D$7
Name I: '[127]#¡REF'!#REF!
Name INDICE: #REF!
Name INDICEUNIFICADO: #REF!
Name List_Mon_RS: #REF!
Name List_Res_dger: #REF!
Name Lista_Mon_LP: #REF!
Name localidades: '[141]Aux. Disgregados'!$F$46
Name MNP: '[58]#¡REF'!#REF!
Name name_proy: '[151]RES-GRAL'!$F$4
Name ncon: '[44]Datos'!$D$3
Name ncont: '[44]Datos'!$D$4
Name npro: '[44]Datos'!$D$2
Name p: #REF!
Name PARTIDA: #REF!
Name PBCD: '[44]Datos'!$D$16
Name PBLP: '[44]Datos'!$D$12
Name PBRP: '[44]Datos'!$D$13
Name PBRS: '[44]Datos'!$D$15
Name PBSE: '[44]Datos'!$D$14
Name PCCD: '[44]Datos'!$D$23
Name PCLP: '[44]Datos'!$D$19
Name PCRP: '[44]Datos'!$D$20
Name PCRS: '[44]Datos'!$D$22
Name PCSE: '[44]Datos'!$D$21
Name Q: '[58]1'!#REF!
Name QQQ: '[34]#¡REF'!#REF!

Sheet RESUMEN TOTAL
B2: RESUMEN GENERAL DEL PRESUPUESTO (OBRA Y EXPEDIENTE TÉCNICO)
B4: PROYECTO | C4: : | D4: AMPLIACIÓN DEL SERVICIO DE ENERGÍA ELÉCTRICA EN LA PROVINCIA DEL SANTA Y EN EL DISTRITO DE PAMPAROMAS – DEPARTAMENTO DE ANCASH
B5: DEPARTAMENTO | C5: : | D5: ANCASH
J6: Fecha: 30-May-2022
J7: T.C. (S/ /US$): 3,683
E9: CONTRACTUAL | H9: ESTUDIO DEFINITIVO
B10: ITEM | D10: Descripcion | E10: Total Sin I.G.V. (S/.) | F10: I.G.V. | G10: TOTAL S/. | H10: Total Sin I.G.V. (S/.) | I10: I.G.V. | J10: TOTAL S/.
B12: A | D12: COSTO DE OBRA | E12: =+'RES-GRAL OBRA'!G15 -> #REF! | F12: =+'RES-GRAL OBRA'!G16 -> #REF! | G12: =+SUM(E12:F12) -> #REF! | H12: =+'RES-GRAL OBRA'!H15 -> #REF! | I12: =+'RES-GRAL OBRA'!H16 -> #REF! | J12: =+SUM(H12:I12) -> #REF!
B14: B | D14: COSTO DE EXPEDIENTE TÉCNICO | E14: 200121.88 | F14: 36021.94 | G14: =+SUM(E14:F14) -> 236143.82 | H14: =+E14 -> 200121.88 | I14: =+F14 -> 36021.94 | J14: =+SUM(H14:I14) -> 236143.82
G15: =+SUM(E15:F15) -> 0
D16: TOTAL | E16: =E12+E14 -> #REF! | F16: =F12+F14 -> #REF! | G16: =G12+G14 -> #REF! | H16: =H12+H14 -> #REF! | I16: =I12+I14 -> #REF! | J16: =J12+J14 -> #REF!
G18: % DE INCIDENCIA SOBRE EL CONTRACTUAL | J18: =ROUND((J16/G16),4) -> #REF!
J21: =+J12/G12 -> #REF!

Sheet RES-GRAL OBRA
B2: RESUMEN GENERAL PRESUPUESTO DE OBRA
B4: PROYECTO | E4: : | F4: AMPLIACIÓN DEL SERVICIO DE ENERGÍA ELÉCTRICA EN LA PROVINCIA DEL SANTA Y EN EL DISTRITO DE PAMPAROMAS – DEPARTAMENTO DE ANCASH
B5: DEPARTAMENTO | E5: : | F5: ANCASH | H5: Fecha: 30-May-2022
H6: T.C. (S/ /US$): 3,683
B7: ITEM | C7: DESCRIPCION | G7: PRESUPUESTO CONTRATO | H7: PRESUPUESTO ESTUDIO DEFINITIVO | I7: ADICIONALES | K7: DEDUCTIVOS
I8: MAYORES METRADOS | J8: PARTIDAS NUEVAS | K8: MENOR METRADO | L8: DEDUCTIVO VINCULANTE
B9: A | D9: SUMINISTROS DE MATERIALES | G9: =+'RES-LP'!G12+'RES-RP'!G12+'RES-RS'!G12+'RES- SFV'!G12 -> 1356698.6 | H9: =+'RES-LP'!H12+'RES-RP'!H12+'RES-RS'!H12+'RES- SFV'!H12 -> 1559314.8 | I9: =+'RES-LP'!I12+'RES-RP'!I12+'RES-RS'!I12+'RES- SFV'!I12 -> #REF! | J9: =+'RES-LP'!J12+'RES-RP'!J12+'RES-RS'!J12+'RES- SFV'!J12 -> #REF! | K9: =+'RES-LP'!K12+'RES-RP'!K12+'RES-RS'!K12+'RES- SFV'!K12 -> #REF! | L9: =+'RES-LP'!L12+'RES-RP'!L12+'RES-RS'!L12+'RES- SFV'!L12 -> #REF!
B10: B | D10: MONTAJE ELECTROMECANICO | G10: =+'RES-LP'!G13+'RES-RP'!G13+'RES-RS'!G13+'RES- SFV'!G13 -> #REF! | H10: =+'RES-LP'!H13+'RES-RP'!H13+'RES-RS'!H13+'RES- SFV'!H13 -> #REF! | I10: =+'RES-LP'!I13+'RES-RP'!I13+'RES-RS'!I13+'RES- SFV'!I13 -> #REF! | J10: =+'RES-LP'!J13+'RES-RP'!J13+'RES-RS'!J13+'RES- SFV'!J13 -> #REF! | K10: =+'RES-LP'!K13+'RES-RP'!K13+'RES-RS'!K13+'RES- SFV'!K13 -> #REF! | L10: =+'RES-LP'!L13+'RES-RP'!L13+'RES-RS'!L13+'RES- SFV'!L13 -> #REF!
B11: C | D11: TRANSPORTE DE MATERIALES | G11: =+'RES-LP'!G14+'RES-RP'!G14+'RES-RS'!G14+'RES- SFV'!G14 -> #REF! | H11: =+'RES-LP'!H14+'RES-RP'!H14+'RES-RS'!H14+'RES- SFV'!H14 -> #REF! | I11: =+'RES-LP'!I14+'RES-RP'!I14+'RES-RS'!I14+'RES- SFV'!I14 -> #REF! | J11: =+'RES-LP'!J14+'RES-RP'!J14+'RES-RS'!J14+'RES- SFV'!J14 -> #REF! | K11: =+'RES-LP'!K14+'RES-RP'!K14+'RES-RS'!K14+'RES- SFV'!K14 -> #REF! | L11: =+'RES-LP'!L14+'RES-RP'!L14+'RES-RS'!L14+'RES- SFV'!L14 -> #REF!
B12: D | D12: COSTO DIRECTO ( C.D. ) | G12: =ROUND(SUM(G9:G11),2) -> #REF! | H12: =ROUND(SUM(H9:H11),2) -> #REF! | I12: =ROUND(SUM(I9:I11),2) -> #REF! | J12: =ROUND(SUM(J9:J11),2) -> #REF! | K12: =ROUND(SUM(K9:K11),2) -> #REF! | L12: =ROUND(SUM(L9:L11),2) -> #REF!
B13: E | D13: GASTOS GENERALES (10.12%) | G13: =ROUND(G12*10.12%,2) -> #REF! | H13: =ROUND(H12*10.12%,2) -> #REF! | I13: =ROUND(I12*10.12%,2) -> #REF! | J13: =ROUND(J12*10.12%,2) -> #REF! | K13: =ROUND(K12*10.12%,2) -> #REF! | L13: =ROUND(L12*10.12%,2) -> #REF! | M13: =+H13-G13 -> #REF!
B14: F | D14: UTILIDADES (3%) | G14: =ROUND(G12*3%,2) -> #REF! | H14: =ROUND(H12*3%,2) -> #REF! | I14: =ROUND(I12*3%,2) -> #REF! | J14: =ROUND(J12*3%,2) -> #REF! | K14: =ROUND(K12*3%,2) -> #REF! | L14: =ROUND(L12*3%,2) -> #REF! | M14: =+H14-G14 -> #REF!
D15: SUB-TOTAL SIN I.G.V. (S/.) | G15: =G14+G13+G12 -> #REF! | H15: =H14+H13+H12 -> #REF! | I15: =I14+I13+I12 -> #REF! | J15: =J14+J13+J12 -> #REF! | K15: =K14+K13+K12 -> #REF! | L15: =L14+L13+L12 -> #REF! | M15: =+H15-G15 -> #REF!
D16: IMPUESTO GENERAL A LAS VENTAS IGV (18%) | G16: =ROUND(G15*0.18,2) -> #REF! | H16: =ROUND(H15*0.18,2) -> #REF! | I16: =ROUND(I15*0.18,2) -> #REF! | J16: =ROUND(J15*0.18,2) -> #REF! | K16: =ROUND(K15*0.18,2) -> #REF! | L16: =ROUND(L15*0.18,2) -> #REF!
D17: COSTO TOTAL (Incluye I.G.V.) S/. | G17: =G15+G16 -> #REF! | H17: =H15+H16 -> #REF! | I17: =I15+I16 -> #REF! | J17: =J15+J16 -> #REF! | K17: =K15+K16 -> #REF! | L17: =L15+L16 -> #REF!
D19: INCIDENCIA RESPECTO AL CONTRACTUAL % | H19: =+ROUND(H17/$G$17,4) -> #REF! | I19: =+ROUND(I17/$G$17,4) -> #REF! | J19: =+ROUND(J17/$G$17,4) -> #REF! | K19: =+ROUND(K17/$G$17,4) -> #REF! | L19: =+ROUND(L17/$G$17,4) -> #REF!
H23: =+G17+I17+J17-K17 -> #REF! | I23: =+H17-G17 -> #REF! | J23: =+I17+J17-K17 -> #REF!
H24: =+H17-H23 -> #REF! | J24: =+I23-J23 -> #REF!

Sheet RG
B2: RESUMEN DE PRESUPUESTO CONTRATCUAL REPLANTEO
B4: PROYECTO | E4: : | F4: CREACIÓN INSTALACIÓN DEL SUBSISTEMA DE DISTRIBUCIÓN PRIMARIA 10-22,9 KV Y SUBSISTEMA DE DISTRIBUCIÓN SECUNDARIA 380/220 V E INSTALACIÓN DE ALUMBRADO PÚBLICO LUCAS CUTIVALU DEL DISTRITO DE MIGUEL CHECA - PROVINCIA DE SULLANA - DEPARTAMENTO DE PIURA
B5: DEPARTAMENTOS | E5: : | F5: PIURA
B6: ITEM | C6: DESCRIPCION | G6: LINEAS PRIMARIAS | I6: REDES PRIMARIAS | K6: REDES SECUNDARIAS | M6: TOTAL
G7: PRESUPUESTO CONTRATO | H7: PRESUPUESTO REPLANTEO | I7: PRESUPUESTO CONTRATO | J7: PRESUPUESTO REPLANTEO | K7: PRESUPUESTO CONTRATO | L7: PRESUPUESTO REPLANTEO | M7: PRESUPUESTO CONTRATO | N7: PRESUPUESTO REPLANTEO
B9: A | D9: SUMINISTROS DE MATERIALES | G9: =+#REF! -> #REF! | H9: =+#REF! -> #REF! | I9: =+#REF! -> #REF! | J9: =+#REF! -> #REF! | K9: =+'RES-RS'!G12 -> 301377.1 | L9: =+'RES-RS'!H12 -> 420410.61 | M9: =+G9+I9+K9 -> #REF! | N9: =+H9+J9+L9 -> #REF!
B10: B | D10: MONTAJE ELECTROMECANICO | G10: =+#REF! -> #REF! | H10: =+#REF! -> #REF! | I10: =+#REF! -> #REF! | J10: =+#REF! -> #REF! | K10: =+'RES-RS'!G13 -> #REF! | L10: =+'RES-RS'!H13 -> #REF! | M10: =+G10+I10+K10 -> #REF! | N10: =+H10+J10+L10 -> #REF!
B11: C | D11: TRANSPORTE DE MATERIALES | G11: =+#REF! -> #REF! | H11: =+#REF! -> #REF! | I11: =+#REF! -> #REF! | J11: =+#REF! -> #REF! | K11: =+'RES-RS'!G14 -> #REF! | L11: =+'RES-RS'!H14 -> #REF! | M11: =+G11+I11+K11 -> #REF! | N11: =+H11+J11+L11 -> #REF!
B13: D | D13: COSTO DIRECTO ( C.D. ) | G13: =SUM(G9:G12) -> #REF! | H13: =SUM(H9:H12) -> #REF! | I13: =SUM(I9:I12) -> #REF! | J13: =SUM(J9:J12) -> #REF! | K13: =SUM(K9:K12) -> #REF! | L13: =SUM(L9:L12) -> #REF! | M13: =SUM(M9:M12) -> #REF! | N13: =SUM(N9:N12) -> #REF!
B15: E | D15: GASTOS GENERALES (30.52%) | G15: =ROUND(G13*30.52%,2) -> #REF! | H15: =ROUND(H13*30.52%,2) -> #REF! | I15: =ROUND(I13*30.52%,2) -> #REF! | J15: =ROUND(J13*30.52%,2) -> #REF! | K15: =ROUND(K13*30.52%,2) -> #REF! | L15: =ROUND(L13*30.52%,2) -> #REF! | M15: =ROUND(M13*30.52%,2) -> #REF! | N15: =ROUND(N13*30.52%,2) -> #REF!
B16: F | D16: UTILIDADES (4.01%) | G16: =ROUND(G13*4.01%,2) -> #REF! | H16: =ROUND(H13*4.01%,2) -> #REF! | I16: =ROUND(I13*4.01%,2) -> #REF! | J16: =ROUND(J13*4.01%,2) -> #REF! | K16: =ROUND(K13*4.01%,2) -> #REF! | L16: =ROUND(L13*4.01%,2) -> #REF! | M16: =ROUND(M13*4.01%,2) -> #REF! | N16: =ROUND(N13*4.01%,2) -> #REF!
D19: SUB-TOTAL SIN I.G.V. (S/.) | G19: =G16+G15+G13 -> #REF! | H19: =H16+H15+H13 -> #REF! | I19: =I16+I15+I13 -> #REF! | J19: =J16+J15+J13 -> #REF! | K19: =K16+K15+K13 -> #REF! | L19: =L16+L15+L13 -> #REF! | M19: =M16+M15+M13 -> #REF! | N19: =N16+N15+N13 -> #REF!
D21: IMPUESTO GENERAL A LAS VENTAS IGV (18%) | G21: =ROUND(G19*0.18,2) -> #REF! | H21: =ROUND(H19*0.18,2) -> #REF! | I21: =ROUND(I19*0.18,2) -> #REF! | J21: =ROUND(J19*0.18,2) -> #REF! | K21: =ROUND(K19*0.18,2) -> #REF! | L21: =ROUND(L19*0.18,2) -> #REF! | M21: =ROUND(M19*0.18,2) -> #REF! | N21: =ROUND(N19*0.18,2) -> #REF!
D22: COSTO TOTAL (Incluye I.G.V.) S/. | G22: =G19+G21 -> #REF! | H22: =H19+H21 -> #REF! | I22: =I19+I21 -> #REF! | J22: =J19+J21 -> #REF! | K22: =K19+K21 -> #REF! | L22: =L19+L21 -> #REF! | M22: =M19+M21 -> #REF! | N22: =N19+N21 -> #REF!
D23: INCIDENCIA RESPECTO AL CONTRACTUAL % | H23: =+H22/$G$22 -> #REF! | J23: =+J22/$I$22 -> #REF! | L23: =+L22/$L$22 -> #REF! | N23: =+N22/$M$22 -> #REF!
D24: INCIDENCIA DEL ADICIONAL % | G24: =+(I22+J22-L22)/G22 -> #REF!
D25: INCIDENCIA DEL MAYOR METRADO % | G25: =+K22/G22 -> #REF!
D26: INCIDENCIA DEL ADICONAL + MAYOR METRADO % | G26: =+(I22+J22+K22-L22)/G22 -> #REF!
H29: =+H22-K22+M22 -> #REF! | M29: 1495463.1 | N29: 1557304.6
H30: =+H29-G22 -> #REF!

Sheet GG Contr.
B1: CREACIÓN INSTALACIÓN DEL SUBSISTEMA DE DISTRIBUCIÓN PRIMARIA 10-22,9 KV Y SUBSISTEMA DE DISTRIBUCIÓN SECUNDARIA 380/220 V E INSTALACIÓN DE ALUMBRADO PÚBLICO LUCAS CUTIVALU DEL DISTRITO DE MIGUEL CHECA - PROVINCIA DE SULLANA - DEPARTAMENTO DE PIURA
B3: CALCULO DE LOS GASTOS GENERALES DIRECTOS E INDIRECTOS
C5: Sección : | D5: LINEAS PRIMARIAS, REDES PRIMARIAS Y REDES SECUNDARIAS
C6: Departamento : | D6: PIURA | K6: =I190/E69 -> 0.30530483
C7: Plazo de Obra : | D7: 5 | E7: meses
B9: 1.0 | C9: GASTOS GENERALES VARIABLES-GG DIRECTOS | I9: 942051.3
B11: 1.1 | C11: Personal Profesional Principal
C12: Descripción | D12: Unidad | E12: Cant. | F12: Particip. | G12: Tiempo | H12: Sueldo | I12: Parcial
F13: % | G13: (meses) | H13: (S/.) | I13: (S/.)
C14: Gerente de Obra | D14: Und. | E14: 0 | F14: 0.5 | G14: 2.5 | H14: 10000 | I14: 0
C15: Ingeniero Residente de la Obra | D15: Und. | E15: 1 | F15: 1 | G15: 5 | H15: 6000 | I15: =ROUND(E15*F15*G15*H15,2) -> 30000
C16: Ingeniero Asistente de Obra | D16: Und. | E16: 0 | F16: 0.82 | G16: 4.1 | H16: 6500 | I16: 0
C17: Gestor de Servidumbre | D17: Und. | E17: 0 | F17: 0.5 | G17: 2.5 | H17: 4500 | I17: 0
C18: Ingeniero de Seguridad e Higiene Ocupacional | D18: Und. | E18: 1 | F18: 1 | G18: 5 | H18: 4500 | I18: =ROUND(E18*F18*G18*H18,2) -> 22500
C19: Ingeniero Asistente de Residente de Obra | D19: Und. | E19: 1 | F19: 1 | G19: 5 | H19: 4000 | I19: =ROUND(E19*F19*G19*H19,2) -> 20000
C21: PARCIAL 1,1 | I21: =SUM(I14:I20) -> 72500
C22: Nota: El sueldo considerado por cada profesional incluye impuestos y leyes sociales
B24: 1.2 | C24: Personal de Auxiliar y Apoyo
C25: Descripción | D25: Und. | E25: Cant. | F25: Particip. | G25: Tiempo | H25: Sueldo | I25: Parcial
F26: % | G26: (meses) | H26: (S/.) | I26: (S/.)
C27: Administrador | D27: Und. | E27: 1 | F27: 1 | G27: 5 | H27: 3500 | I27: =ROUND(E27*F27*G27*H27,2) -> 17500
C28: Asistente de administrador | D28: Und. | E28: 0 | F28: 0.8 | G28: 4 | H28: 1500 | I28: =ROUND(E28*F28*G28*H28,2) -> 0
C29: Dibujante en Autocad y otros programas | D29: Und. | E29: 1 | F29: 1 | G29: 5 | H29: 1500 | I29: =ROUND(E29*F29*G29*H29,2) -> 7500
C30: Almacenero | D30: Und. | E30: 1 | F30: 1 | G30: 5 | H30: 1800 | I30: =ROUND(E30*F30*G30*H30,2) -> 9000
C31: Asistente de almacen | D31: Und. | E31: 0 | F31: 1 | G31: 5 | H31: 1050 | I31: =ROUND(E31*F31*G31*H31,2) -> 0
C32: Técnico mecánico | D32: Und. | E32: 0 | F32: 1 | G32: 5 | H32: 1200 | I32: =ROUND(E32*F32*G32*H32,2) -> 0
C33: Chofer | D33: Und. | E33: 1 | F33: 1 | G33: 5 | H33: 1500 | I33: =ROUND(E33*F33*G33*H33,2) -> 7500
C34: Seguridad en obra (Guardian) | D34: Und. | E34: 1 | F34: 1 | G34: 5 | H34: 1047 | I34: =ROUND(E34*F34*G34*H34,2) -> 5235
C36: PARCIAL 1,2 | I36: =SUM(I27:I35) -> 46735 | K36: 46735
C37: Nota: El sueldo considerado por trabajador incluye impuestos y leyes sociales
B39: 1.3 | C39: Hospedajes, Oficina, Campamentos, alimentación y movilidad del personal principal, auxiliar y apoyo
C40: Descripción | D40: Und. | E40: Cant. | F40: Particip. | G40: Tiempo | H40: Gasto/ Und. | I40: Parcial
F41: % | G41: (meses) | H41: (S/.) | I41: (S/.)
C42: Hospedajes | D42: Glb/mes | E42: 1 | F42: 1 | G42: 5 | H42: 1500 | I42: =ROUND(E42*F42*G42*H42,2) -> 7500
C43: Alquiler de Oficina - Almacen en Obra (Incluye agua y luz) | D43: Glb/mes | E43: 1 | F43: 1 | G43: 5 | H43: 849.88 | I43: =ROUND(E43*F43*G43*H43,2) -> 4249.4
C44: Alquiler de casa almacén (incluye agua y luz) | D44: Glb/mes | E44: 0 | F44: 1 | G44: 5 | H44: 450 | I44: =ROUND(E44*F44*G44*H44,2) -> 0
C45: Comunicaciones: telefono, fax, internet, radio, etc. | D45: Glb/mes | E45: 1 | F45: 1 | G45: 5 | H45: 550 | I45: =ROUND(E45*F45*G45*H45,2) -> 2750
C46: Alimentación | D46: Glb/mes | E46: 1 | F46: 1 | G46: 5 | H46: 2000 | I46: =ROUND(E46*F46*G46*H46,2) -> 10000
C47: Pasajes | D47: Glb/mes | E47: 1 | F47: 1 | G47: 5 | H47: 650 | I47: =ROUND(E47*F47*G47*H47,2) -> 3250
C49: PARCIAL 1,3 | I49: =SUM(I42:I48) -> 27749.4
...

Sheet RES-LP
B2: RESUMEN PRESUPUESTO DE OBRA
B4: AMPLIACIÓN DEL SERVICIO DE ENERGÍA ELÉCTRICA EN LA PROVINCIA DEL SANTA Y EN EL DISTRITO DE PAMPAROMAS – DEPARTAMENTO DE ANCASH
B6: UBICACIÓN | C6: : | D6: ANCASH
B7: SECCIÓN I | C7: : | D7: LINEAS PRIMARIAS | H7: Fecha: 30-May-2022
H8: T.C. (S/ /US$): 3,683
B9: ITEM | C9: DESCRIPCION | G9: PRESUPUESTO CONTRATO | H9: PRESUPUESTO ESTUDIO DEFINIVO | I9: ADICIONALES | K9: DEDUCTIVOS
I10: MAYORES METRADOS | J10: PARTIDAS NUEVAS | K10: MENOR METRADO | L10: DEDUCTIVO VINCULANTE
B12: A | D12: SUMINISTRO DE MATERIALES | G12: =+LP!J154 -> 628325.26 | H12: =+LP!L154 -> 683730.19 | I12: =+LP!#REF! -> #REF! | J12: =+LP!#REF! -> #REF! | K12: =+LP!#REF! -> #REF! | L12: =+LP!#REF! -> #REF!
B13: B | D13: MONTAJE ELECTROMECANICO | G13: =+LP!#REF! -> #REF! | H13: =+LP!#REF! -> #REF! | I13: =+LP!#REF! -> #REF! | J13: =+LP!#REF! -> #REF! | K13: =+LP!#REF! -> #REF! | L13: =+LP!#REF! -> #REF!
B14: C | D14: TRANSPORTE DE MATERIALES | G14: =+LP!#REF! -> #REF! | H14: =+LP!#REF! -> #REF! | I14: =+LP!#REF! -> #REF! | J14: =+LP!#REF! -> #REF! | K14: =+LP!#REF! -> #REF! | L14: =+LP!#REF! -> #REF!
B15: D | D15: TOTAL COSTO DIRECTO | G15: =+SUM(G12:G14) -> #REF! | H15: =+SUM(H12:H14) -> #REF! | I15: =+SUM(I12:I14) -> #REF! | J15: =+SUM(J12:J14) -> #REF! | K15: =+SUM(K12:K14) -> #REF! | L15: =+SUM(L12:L14) -> #REF!
B16: E | D16: GASTOS GENERALES (10.12%) | G16: =ROUND(G15*10.12%,2) -> #REF! | H16: =ROUND(H15*10.12%,2) -> #REF! | I16: =ROUND(I15*10.12%,2) -> #REF! | J16: =ROUND(J15*10.12%,2) -> #REF! | K16: =ROUND(K15*10.12%,2) -> #REF! | L16: =ROUND(L15*10.12%,2) -> #REF!
B17: F | D17: UTILIDADES (3%) | G17: =ROUND(G15*3%,2) -> #REF! | H17: =ROUND(H15*3%,2) -> #REF! | I17: =ROUND(I15*3%,2) -> #REF! | J17: =ROUND(J15*3%,2) -> #REF! | K17: =ROUND(K15*3%,2) -> #REF! | L17: =ROUND(L15*3%,2) -> #REF!
B18: G | D18: COSTO TOTAL S/. (No incluye I.G.V.) | G18: =G17+G16+G15 -> #REF! | H18: =H17+H16+H15 -> #REF! | I18: =I17+I16+I15 -> #REF! | J18: =J17+J16+J15 -> #REF! | K18: =K17+K16+K15 -> #REF! | L18: =L17+L16+L15 -> #REF! | M18: =+H18-G18 -> #REF!
D20: INCIDENCIA % | G20: =+G18/G18 -> #REF! | H20: =+H18/$G$18 -> #REF! | I20: =+I18/$G$18 -> #REF! | J20: =+J18/$G$18 -> #REF! | K20: =+K18/$G$18 -> #REF! | L20: =+L18/$G$18 -> #REF!
H22: =+H18-I18+K18-J18 -> #REF! | K22: =+G12-H12+I12+J12-K12 -> #REF!
H23: =+G18-H22 -> #REF! | K23: =+G13-H13+I13+J13-K13 -> #REF!
K24: =+G14-H14+I14+J14-K14 -> #REF!
K25: =+G15-H15+I15+J15-K15 -> #REF!

Sheet LP
J1: VARI | K1: VARI
A6: COMPARATIVO DE PRECIOS
A8: OBRA | D8: : | E8: AMPLIACIÓN DEL SERVICIO DE ENERGÍA ELÉCTRICA EN LA PROVINCIA DEL SANTA Y EN EL DISTRITO DE PAMPAROMAS – DEPARTAMENTO DE ANCASH
A9: DEPARTAMENTO | D9: : | E9: ANCASH
A10: SECCIÓN I | D10: : | E10: LINEAS PRIMARIAS
A12: ITEM | B12: DESCRIPCIÓN DE PARTIDAS | F12: UNID. | G12: Precio de Contrato | H12: Precio Pactado | I12: CONTRACTUAL | K12: ESTUDIO DEFINITIVO | M12: PRECIO DE VENTA | N12: MENDOZA | Q12: DIFERENCIA DE PRECIOS | T12: PRECIO DE VENTA | U12: GELCO/Group Electric JYM Sac PU | X12: PRECIO DE VENTA | Y12: EL DETALLE | AB12: PRECIO DE VENTA | AC12: CIE
I13: Metrado | J13: TOTAL | K13: Metrado | L13: TOTAL | N13: Metrado | O13: TOTAL | P13: % | U13: Metrado | V13: TOTAL | W13: % | Y13: Metrado | Z13: TOTAL | AA13: % | AC13: Metrado | AD13: TOTAL | AE13: %
G15: Unitario | H15: Unitario | I15: Cantidad | J15: S/. | K15: Cantidad | L15: S/. | M15: S/. | N15: Cantidad | O15: S/. | Q15: S/. | R15: TDT | S15: PROYECTO | T15: S/. | U15: Cantidad | V15: S/. | X15: S/. | Y15: Cantidad | Z15: S/. | AB15: S/. | AC15: Cantidad | AD15: S/.
A16: A | C16: SUMINISTRO DE MATERIALES
A17: 1 | B17: 3 | C17: CRUCETAS DE MADERA DE PROCEDENCIA NACIONAL
A18: 1.01 | B18: =+B17+1 -> 4 | C18: Cruceta de madera tratada de 90 mm x 115 mm x 1,20 m | F18: u | G18: 105 | I18: 11 | J18: =+ROUND($G18*I18,2) -> 1155 | K18: =+[191]Metrados!E19 -> 7 | L18: =+ROUND($G18*K18,2) -> 735 | M18: 0 | N18: =K18 -> 7 | O18: =+ROUND($M18*N18,2) -> 0 | P18: =+M18/($G18+$H18) -> 0 | Q18: =+G18-M18 -> 105 | T18: 0 | U18: =$K18 -> 7 | V18: =+ROUND($T18*U18,2) -> 0 | W18: =+T18/($G18+$H18) -> 0 | X18: 0 | Y18: =$K18 -> 7 | Z18: =+ROUND($X18*Y18,2) -> 0 | AA18: =+X18/($G18+$H18) -> 0 | AB18: 0 | AC18: =$K18 -> 7 | AD18: =+ROUND($AB18*AC18,2) -> 0 | AE18: =+AB18/($G18+$H18) -> 0 | AF18: =+M18+O18+X18 -> 0
A19: 1.02 | B19: =+B18+1 -> 5 | C19: Cruceta de madera tratada de 90 mm x 115 mm x 2,00 m | F19: u | G19: 178 | I19: 2 | J19: =+ROUND($G19*I19,2) -> 356 | K19: =+'[191]Metrados'!E20 -> 1 | L19: =+ROUND($G19*K19,2) -> 178 | M19: 0 | N19: =K19 -> 1 | O19: =+ROUND($M19*N19,2) -> 0 | P19: =+M19/($G19+$H19) -> 0 | Q19: =+G19-M19 -> 178 | T19: 0 | U19: =$K19 -> 1 | V19: =+ROUND($T19*U19,2) -> 0 | W19: =+T19/($G19+$H19) -> 0 | X19: 0 | Y19: =$K19 -> 1 | Z19: =+ROUND($X19*Y19,2) -> 0 | AA19: =+X19/($G19+$H19) -> 0 | AB19: 0 | AC19: =$K19 -> 1 | AD19: =+ROUND($AB19*AC19,2) -> 0 | AE19: =+AB19/($G19+$H19) -> 0 | AF19: =+M19+O19+X19 -> 0
A20: 1.03 | B20: =+B19+1 -> 6 | C20: Cruceta de madera tratada de 90 mm x 115 mm x 2,40 m | F20: u | G20: 205 | I20: 1 | J20: =+ROUND($G20*I20,2) -> 205 | K20: =+'[191]Metrados'!E21 -> 13 | L20: =+ROUND($G20*K20,2) -> 2665 | M20: 0 | N20: =K20 -> 13 | O20: =+ROUND($M20*N20,2) -> 0 | P20: =+M20/($G20+$H20) -> 0 | Q20: =+G20-M20 -> 205 | T20: 0 | U20: =$K20 -> 13 | V20: =+ROUND($T20*U20,2) -> 0 | W20: =+T20/($G20+$H20) -> 0 | X20: 0 | Y20: =$K20 -> 13 | Z20: =+ROUND($X20*Y20,2) -> 0 | AA20: =+X20/($G20+$H20) -> 0 | AB20: 0 | AC20: =$K20 -> 13 | AD20: =+ROUND($AB20*AC20,2) -> 0 | AE20: =+AB20/($G20+$H20) -> 0 | AF20: =+M20+O20+X20 -> 0
A21: 1.04 | B21: =+B20+1 -> 7 | C21: Listón de madera tratada 50 x 19 mm sección, 2,7 m longitud (incluye clavos de fijación) | F21: u | G21: 27.35 | I21: 9 | J21: =+ROUND($G21*I21,2) -> 246.15 | K21: =+'[191]Metrados'!E22 -> 0 | L21: =+ROUND($G21*K21,2) -> 0 | M21: 0 | N21: =K21 -> 0 | O21: =+ROUND($M21*N21,2) -> 0 | P21: =+M21/($G21+$H21) -> 0 | Q21: =+G21-M21 -> 27.35 | T21: 0 | U21: =$K21 -> 0 | V21: =+ROUND($T21*U21,2) -> 0 | W21: =+T21/($G21+$H21) -> 0 | X21: 0 | Y21: =$K21 -> 0 | Z21: =+ROUND($X21*Y21,2) -> 0 | AA21: =+X21/($G21+$H21) -> 0 | AB21: 0 | AC21: =$K21 -> 0 | AD21: =+ROUND($AB21*AC21,2) -> 0 | AE21: =+AB21/($G21+$H21) -> 0 | AF21: =+M21+O21+X21 -> 0
B22: =B21+1 -> 8 | E22: =+"SUB-TOTAL "&A17&": " -> SUB-TOTAL 1: | J22: =+SUM(J18:J21) -> 1962.15 | L22: =+SUM(L18:L21) -> 3578 | M22: 0 | N22: =K22 -> 0 | O22: =+SUM(O18:O21) -> 0 | Q22: =+G22-M22 -> 0 | T22: 0 | U22: =$K22 -> 0 | V22: =+SUM(V18:V21) -> 0 | X22: 0 | Y22: =$K22 -> 0 | Z22: =+SUM(Z18:Z21) -> 0 | AB22: 0 | AC22: =$K22 -> 0 | AD22: =+SUM(AD18:AD21) -> 0 | AF22: =+M22+O22+X22 -> 0
A23: 2 | B23: =+B22+1 -> 9 | C23: POSTES DE CONCRETO ARMADO CENTRIFUGADO | M23: 0 | N23: =K23 -> 0 | Q23: =+G23-M23 -> 0 | T23: 0 | U23: =$K23 -> 0 | X23: 0 | Y23: =$K23 -> 0 | AB23: 0 | AC23: =$K23 -> 0 | AF23: =+M23+O23+X23 -> 0
A24: 2.01 | B24: =+B23+1 -> 10 | C24: Poste de C.A.C. de 12 m/200 daN (Incluye perilla) | F24: u | G24: 837.45 | I24: 15 | J24: =+ROUND($G24*I24,2) -> 12561.75 | K24: =+'[191]Metrados'!E25 -> 3 | L24: =+ROUND($G24*K24,2) -> 2512.35 | M24: 0 | N24: =K24 -> 3 | O24: =+ROUND($M24*N24,2) -> 0 | P24: =+M24/($G24+$H24) -> 0 | Q24: =+G24-M24 -> 837.45 | T24: 0 | U24: =$K24 -> 3 | V24: =+ROUND($T24*U24,2) -> 0 | W24: =+T24/($G24+$H24) -> 0 | X24: 0 | Y24: =$K24 -> 3 | Z24: =+ROUND($X24*Y24,2) -> 0 | AA24: =+X24/($G24+$H24) -> 0 | AB24: 0 | AC24: =$K24 -> 3 | AD24: =+ROUND($AB24*AC24,2) -> 0 | AE24: =+AB24/($G24+$H24) -> 0 | AF24: =+M24+O24+X24 -> 0
A25: 2.02 | B25: =+B24+1 -> 11 | C25: Poste de C.A.C. de 12 m/300 daN (Incluye perilla) | F25: u | G25: 923.47 | I25: 6 | J25: =+ROUND($G25*I25,2) -> 5540.82 | K25: =+'[191]Metrados'!E26 -> 6 | L25: =+ROUND($G25*K25,2) -> 5540.82 | M25: 0 | N25: =K25 -> 6 | O25: =+ROUND($M25*N25,2) -> 0 | P25: =+M25/($G25+$H25) -> 0 | Q25: =+G25-M25 -> 923.47 | T25: 0 | U25: =$K25 -> 6 | V25: =+ROUND($T25*U25,2) -> 0 | W25: =+T25/($G25+$H25) -> 0 | X25: 0 | Y25: =$K25 -> 6 | Z25: =+ROUND($X25*Y25,2) -> 0 | AA25: =+X25/($G25+$H25) -> 0 | AB25: 0 | AC25: =$K25 -> 6 | AD25: =+ROUND($AB25*AC25,2) -> 0 | AE25: =+AB25/($G25+$H25) -> 0 | AF25: =+M25+O25+X25 -> 0
A26: 2.03 | B26: =+B25+1 -> 12 | C26: Poste de C.A.C. de 13 m/300 daN (Incluye perilla) | F26: u | G26: 1085.14 | I26: 118 | J26: =+ROUND($G26*I26,2) -> 128046.52 | K26: =+'[191]Metrados'!E27 -> 96 | L26: =+ROUND($G26*K26,2) -> 104173.44 | M26: 0 | N26: =K26 -> 96 | O26: =+ROUND($M26*N26,2) -> 0 | P26: =+M26/($G26+$H26) -> 0 | Q26: =+G26-M26 -> 1085.14 | T26: 0 | U26: =$K26 -> 96 | V26: =+ROUND($T26*U26,2) -> 0 | W26: =+T26/($G26+$H26) -> 0 | X26: 0 | Y26: =$K26 -> 96 | Z26: =+ROUND($X26*Y26,2) -> 0 | AA26: =+X26/($G26+$H26) -> 0 | AB26: 0 | AC26: =$K26 -> 96 | AD26: =+ROUND($AB26*AC26,2) -> 0 | AE26: =+AB26/($G26+$H26) -> 0 | AF26: =+M26+O26+X26 -> 0
A27: 2.04 | B27: =+B26+1 -> 13 | C27: Poste de C.A.C. de 13 m/400 daN (Incluye perilla) | F27: u | G27: 1207.94 | I27: 32 | J27: =+ROUND($G27*I27,2) -> 38654.08 | K27: =+'[191]Metrados'!E28 -> 60 | L27: =+ROUND($G27*K27,2) -> 72476.4 | M27: 0 | N27: =K27 -> 60 | O27: =+ROUND($M27*N27,2) -> 0 | P27: =+M27/($G27+$H27) -> 0 | Q27: =+G27-M27 -> 1207.94 | T27: 0 | U27: =$K27 -> 60 | V27: =+ROUND($T27*U27,2) -> 0 | W27: =+T27/($G27+$H27) -> 0 | X27: 0 | Y27: =$K27 -> 60 | Z27: =+ROUND($X27*Y27,2) -> 0 | AA27: =+X27/($G27+$H27) -> 0 | AB27: 0 | AC27: =$K27 -> 60 | AD27: =+ROUND($AB27*AC27,2) -> 0 | AE27: =+AB27/($G27+$H27) -> 0 | AF27: =+M27+O27+X27 -> 0
A28: =+A27+0.01 -> 2.05 | B28: =+B27+1 -> 14 | C28: Poste de C.A.C. de 15 m/400 daN (Incluye perilla) | F28: u | H28: 0 | J28: =+ROUND($G28*I28,2) -> 0 | K28: =+'[191]Metrados'!E29 -> 0 | L28: =+ROUND($H28*K28,2) -> 0 | M28: 0 | N28: =K28 -> 0 | O28: =+ROUND($M28*N28,2) -> 0 | Q28: =+G28-M28 -> 0 | T28: 0 | U28: =$K28 -> 0 | V28: =+ROUND($T28*U28,2) -> 0 | X28: 0 | Y28: =$K28 -> 0 | Z28: =+ROUND($X28*Y28,2) -> 0 | AB28: 0 | AC28: =$K28 -> 0 | AD28: =+ROUND($AB28*AC28,2) -> 0 | AF28: =+M28+O28+X28 -> 0
B29: =+B28+1 -> 15 | E29: =+"SUB-TOTAL "&A23&": " -> SUB-TOTAL 2: | J29: =+SUM(J24:J28) -> 184803.17 | L29: =+SUM(L24:L28) -> 184703.01 | M29: 0 | N29: =K29 -> 0 | O29: =+SUM(O24:O28) -> 0 | Q29: =+G29-M29 -> 0 | T29: 0 | U29: =$K29 -> 0 | V29: =+SUM(V24:V28) -> 0 | X29: 0 | Y29: =$K29 -> 0 | Z29: =+SUM(Z24:Z28) -> 0 | AB29: 0 | AC29: =$K29 -> 0 | AD29: =+SUM(AD24:AD28) -> 0 | AF29: =+M29+O29+X29 -> 0
A30: 3 | B30: =+B29+1 -> 16 | C30: POSTES DE MADERA IMPORTADA | M30: 0 | N30: =K30 -> 0 | Q30: =+G30-M30 -> 0 | T30: 0 | U30: =$K30 -> 0 | X30: 0 | Y30: =$K30 -> 0 | AB30: 0 | AC30: =$K30 -> 0 | AF30: =+M30+O30+X30 -> 0
A31: 3.01 | B31: =+B30+1 -> 17 | C31: Poste de madera importada (Pino Amarillo del Sur) de 12 m, Clase 6 | F31: u | G31: 1703.39 | I31: 9 | J31: =+ROUND($G31*I31,2) -> 15330.51 | K31: =+'[191]Metrados'!E32 -> 0 | L31: =+ROUND($G31*K31,2) -> 0 | M31: 0 | N31: =K31 -> 0 | O31: =+ROUND($M31*N31,2) -> 0 | P31: =+M31/($G31+$H31) -> 0 | Q31: =+G31-M31 -> 1703.39 | T31: 0 | U31: =$K31 -> 0 | V31: =+ROUND($T31*U31,2) -> 0 | W31: =+T31/($G31+$H31) -> 0 | X31: 0 | Y31: =$K31 -> 0 | Z31: =+ROUND($X31*Y31,2) -> 0 | AA31: =+X31/($G31+$H31) -> 0 | AB31: 0 | AC31: =$K31 -> 0 | AD31: =+ROUND($AB31*AC31,2) -> 0 | AE31: =+AB31/($G31+$H31) -> 0 | AF31: =+M31+O31+X31 -> 0
B32: =+B31+1 -> 18 | E32: =+"SUB-TOTAL "&A30&": " -> SUB-TOTAL 3: | J32: =+SUM(J31:J31) -> 15330.51 | L32: =+SUM(L31:L31) -> 0 | M32: 0 | N32: =K32 -> 0 | O32: =+SUM(O31:O31) -> 0 | Q32: =+G32-M32 -> 0 | T32: 0 | U32: =$K32 -> 0 | V32: =+SUM(V31:V31) -> 0 | X32: 0 | Y32: =$K32 -> 0 | Z32: =+SUM(Z31:Z31) -> 0 | AB32: 0 | AC32: =$K32 -> 0 | AD32: =+SUM(AD31:AD31) -> 0 | AF32: =+M32+O32+X32 -> 0
A33: 3.00A | B33: =+B32+1 -> 19 | C33: POSTES DE FIBRA DE VIDRIO | M33: 0 | N33: =K33 -> 0 | Q33: =+G33-M33 -> 0 | T33: 0 | U33: =$K33 -> 0 | X33: 0 | Y33: =$K33 -> 0 | AB33: 0 | AC33: =$K33 -> 0 | AF33: =+M33+O33+X33 -> 0
A34: 3.01A | B34: =+B33+1 -> 20 | C34: Poste de PRFV de 12 m/200 daN | F34: u | G34: 1958.01 | H34: 1958.01 | J34: =+ROUND($G34*I34,2) -> 0 | K34: =+'[191]Metrados'!E35 -> 4 | L34: =+ROUND($H34*K34,2) -> 7832.04 | M34: 0 | N34: =K34 -> 4 | O34: =+ROUND($M34*N34,2) -> 0 | P34: =+M34/($G34+$H34) -> 0 | Q34: =+G34-M34 -> 1958.01 | T34: 1480.75 | U34: =$K34 -> 4 | V34: =+ROUND($T34*U34,2) -> 5923 | W34: =+T34/($G34+$H34) -> 0.37812626 | X34: 0 | Y34: =$K34 -> 4 | Z34: =+ROUND($X34*Y34,2) -> 0 | AA34: =+X34/($G34+$H34) -> 0 | AB34: 0 | AC34: =$K34 -> 4 | AD34: =+ROUND($AB34*AC34,2) -> 0 | AE34: =+AB34/($G34+$H34) -> 0 | AF34: =+M34+O34+X34 -> 0
A35: 3.02A | B35: =+B34+1 -> 21 | C35: Poste de PRFV de 12 m/300 daN | F35: u | G35: 2336.29 | H35: 2336.29 | J35: =+ROUND($G35*I35,2) -> 0 | K35: =+'[191]Metrados'!E36 -> 11 | L35: =+ROUND($H35*K35,2) -> 25699.19 | M35: 0 | N35: =K35 -> 11 | O35: =+ROUND($M35*N35,2) -> 0 | P35: =+M35/($G35+$H35) -> 0 | Q35: =+G35-M35 -> 2336.29 | T35: 1573.3 | U35: =$K35 -> 11 | V35: =+ROUND($T35*U35,2) -> 17306.3 | W35: =+T35/($G35+$H35) -> 0.33670906 | X35: 0 | Y35: =$K35 -> 11 | Z35: =+ROUND($X35*Y35,2) -> 0 | AA35: =+X35/($G35+$H35) -> 0 | AB35: 0 | AC35: =$K35 -> 11 | AD35: =+ROUND($AB35*AC35,2) -> 0 | AE35: =+AB35/($G35+$H35) -> 0 | AF35: =+M35+O35+X35 -> 0
B36: =+B35+1 -> 22 | E36: =+"SUB-TOTAL "&A33&": " -> SUB-TOTAL 3.00A: | L36: =+L34+L35 -> 33531.23 | M36: 0 | N36: =K36 -> 0 | O36: =+O34+O35 -> 0 | Q36: =+G36-M36 -> 0 | T36: 0 | U36: =$K36 -> 0 | V36: =+V34+V35 -> 23229.3 | X36: 0 | Y36: =$K36 -> 0 | AB36: 0 | AC36: =$K36 -> 0 | AF36: =+M36+O36+X36 -> 0
A37: 4 | B37: =+B36+1 -> 23 | C37: OTROS MATERIALES DE CONCRETO ARMADO | M37: 0 | N37: =K37 -> 0 | Q37: =+G37-M37 -> 0 | T37: 0 | U37: =$K37 -> 0 | X37: 0 | Y37: =$K37 -> 0 | AB37: 0 | AC37: =$K37 -> 0 | AF37: =+M37+O37+X37 -> 0
A38: 4.01 | B38: =+B37+1 -> 24 | C38: Cruceta Asimétrica de C.A.V. Za / 1,5 / 0,9 / 250 / 200 / 100 daN (Za / L / L1/ T / F / V) | F38: u | G38: 120.3 | I38: 2 | J38: =+ROUND($G38*I38,2) -> 240.6 | K38: =+'[191]Metrados'!E39 -> 0 | L38: =+ROUND($G38*K38,2) -> 0 | M38: 0 | N38: =K38 -> 0 | O38: =+ROUND($M38*N38,2) -> 0 | P38: =+M38/($G38+$H38) -> 0 | Q38: =+G38-M38 -> 120.3 | T38: 0 | U38: =$K38 -> 0 | V38: =+ROUND($T38*U38,2) -> 0 | W38: =+T38/($G38+$H38) -> 0 | X38: 0 | Y38: =$K38 -> 0 | Z38: =+ROUND($X38*Y38,2) -> 0 | AA38: =+X38/($G38+$H38) -> 0 | AB38: 0 | AC38: =$K38 -> 0 | AD38: =+ROUND($AB38*AC38,2) -> 0 | AE38: =+AB38/($G38+$H38) -> 0 | AF38: =+M38+O38+X38 -> 0
A39: 4.02 | B39: =+B38+1 -> 25 | C39: Ménsula de C.A.V. M / 1,2 / 250 / 150 / 150 daN (M / L / T / F / V) | F39: u | G39: 88.8 | I39: 393 | J39: =+ROUND($G39*I39,2) -> 34898.4 | K39: =+'[191]Metrados'!E40 -> 84 | L39: =+ROUND($G39*K39,2) -> 7459.2 | M39: 0 | N39: =K39 -> 84 | O39: =+ROUND($M39*N39,2) -> 0 | P39: =+M39/($G39+$H39) -> 0 | Q39: =+G39-M39 -> 88.8 | T39: 0 | U39: =$K39 -> 84 | V39: =+ROUND($T39*U39,2) -> 0 | W39: =+T39/($G39+$H39) -> 0 | X39: 0 | Y39: =$K39 -> 84 | Z39: =+ROUND($X39*Y39,2) -> 0 | AA39: =+X39/($G39+$H39) -> 0 | AB39: 0 | AC39: =$K39 -> 84 | AD39: =+ROUND($AB39*AC39,2) -> 0 | AE39: =+AB39/($G39+$H39) -> 0 | AF39: =+M39+O39+X39 -> 0
A40: 4.03 | B40: =+B39+1 -> 26 | C40: Ménsula de C.A.V. M / 0,8 / 250 / 150 / 150 daN (M / L / T / F / V) | F40: u | G40: 92.26 | I40: 1 | J40: =+ROUND($G40*I40,2) -> 92.26 | K40: =+'[191]Metrados'!E41 -> 0 | L40: =+ROUND($G40*K40,2) -> 0 | M40: 0 | N40: =K40 -> 0 | O40: =+ROUND($M40*N40,2) -> 0 | P40: =+M40/($G40+$H40) -> 0 | Q40: =+G40-M40 -> 92.26 | T40: 0 | U40: =$K40 -> 0 | V40: =+ROUND($T40*U40,2) -> 0 | W40: =+T40/($G40+$H40) -> 0 | X40: 0 | Y40: =$K40 -> 0 | Z40: =+ROUND($X40*Y40,2) -> 0 | AA40: =+X40/($G40+$H40) -> 0 | AB40: 0 | AC40: =$K40 -> 0 | AD40: =+ROUND($AB40*AC40,2) -> 0 | AE40: =+AB40/($G40+$H40) -> 0 | AF40: =+M40+O40+X40 -> 0
A41: 4.05 | B41: =+B40+1 -> 27 | C41: Cruceta Simétrica de C.A.V. Z / 2,4 / 300 / 300 / 150 daN (Z/ L / T / F / V) | F41: u | G41: 230 | H41: 230 | J41: =+ROUND($G41*I41,2) -> 0 | K41: =+'[191]Metrados'!E42 -> 122 | L41: =+ROUND($H41*K41,2) -> 28060 | M41: 0 | N41: =K41 -> 122 | O41: =+ROUND($M41*N41,2) -> 0 | P41: =+M41/($G41+$H41) -> 0 | Q41: =+G41-M41 -> 230 | T41: 0 | U41: =$K41 -> 122 | V41: =+ROUND($T41*U41,2) -> 0 | W41: =+T41/($G41+$H41) -> 0 | X41: 0 | Y41: =$K41 -> 122 | Z41: =+ROUND($X41*Y41,2) -> 0 | AA41: =+X41/($G41+$H41) -> 0 | AB41: 0 | AC41: =$K41 -> 122 | AD41: =+ROUND($AB41*AC41,2) -> 0 | AE41: =+AB41/($G41+$H41) -> 0 | AF41: =+M41+O41+X41 -> 0
B42: =+B41+1 -> 28 | E42: =+"SUB-TOTAL "&A37&": " -> SUB-TOTAL 4: | J42: =+SUM(J38:J41) -> 35231.26 | L42: =+SUM(L38:L41) -> 35519.2 | M42: 0 | N42: =K42 -> 0 | O42: =+SUM(O38:O41) -> 0 | Q42: =+G42-M42 -> 0 | T42: 0 | U42: =$K42 -> 0 | V42: =+SUM(V38:V41) -> 0 | X42: 0 | Y42: =$K42 -> 0 | Z42: =+SUM(Z38:Z41) -> 0 | AB42: 0 | AC42: =$K42 -> 0 | AD42: =+SUM(AD38:AD41) -> 0 | AF42: =+M42+O42+X42 -> 0
A43: 5 | B43: =+B42+1 -> 29 | C43: AISLADORES Y ACCESORIOS | M43: 0 | N43: =K43 -> 0 | Q43: =+G43-M43 -> 0 | T43: 0 | U43: =$K43 -> 0 | X43: 0 | Y43: =$K43 -> 0 | AB43: 0 | AC43: =$K43 -> 0 | AF43: =+M43+O43+X43 -> 0
A44: 5.01 | B44: =+B43+1 -> 30 | C44: Aislador de Porcelana Tipo Pin, Clase ANSI 56-3 | F44: u | G44: 76.45 | I44: 29 | J44: =+ROUND($G44*I44,2) -> 2217.05 | K44: =+'[191]Metrados'!E45 -> 24 | L44: =+ROUND($G44*K44,2) -> 1834.8 | M44: 0 | N44: =K44 -> 24 | O44: =+ROUND($M44*N44,2) -> 0 | P44: =+M44/($G44+$H44) -> 0 | Q44: =+G44-M44 -> 76.45 | T44: 0 | U44: =$K44 -> 24 | V44: =+ROUND($T44*U44,2) -> 0 | W44: =+T44/($G44+$H44) -> 0 | X44: 0 | Y44: =$K44 -> 24 | Z44: =+ROUND($X44*Y44,2) -> 0 | AA44: =+X44/($G44+$H44) -> 0 | AB44: 0 | AC44: =$K44 -> 24 | AD44: =+ROUND($AB44*AC44,2) -> 0 | AE44: =+AB44/($G44+$H44) -> 0 | AF44: =+M44+O44+X44 -> 0
A45: 5.02 | B45: =+B44+1 -> 31 | C45: Espiga de AºGº de 609 mm longitud, para Cabeza de Poste y Aislador ANSI 56-3 | F45: u | G45: 35.96 | I45: 29 | J45: =+ROUND($G45*I45,2) -> 1042.84 | K45: =+'[191]Metrados'!E46 -> 24 | L45: =+ROUND($G45*K45,2) -> 863.04 | M45: 29.85 | N45: =K45 -> 24 | O45: =+ROUND($M45*N45,2) -> 716.4 | P45: =+M45/($G45+$H45) -> 0.83008899 | Q45: =+(G45+H45)-M45 -> 6.11 | R45: SI | T45: 0 | U45: =$K45 -> 24 | V45: =+ROUND($T45*U45,2) -> 0 | W45: =+T45/($G45+$H45) -> 0 | X45: 22.8823 | Y45: =$K45 -> 24 | Z45: =+ROUND($X45*Y45,2) -> 549.18 | AA45: =+X45/($G45+$H45) -> 0.63632647 | AB45: 0 | AC45: =$K45 -> 24 | AD45: =+ROUND($AB45*AC45,2) -> 0 | AE45: =+AB45/($G45+$H45) -> 0 | AF45: =+M45+O45+X45 -> 769.1323
A46: 5.03 | B46: =+B45+1 -> 32 | C46: Conjunto Aislador Line Post Polimérico en Mesula y Cruceta: | F46: u | G46: 209.65 | I46: 369 | J46: =+ROUND($G46*I46,2) -> 77360.85 | K46: =+[191]Metrados!E48 -> 307 | L46: =+ROUND($G46*K46,2) -> 64362.55 | M46: 0 | N46: =K46 -> 307 | O46: =+ROUND($M46*N46,2) -> 0 | P46: =+M46/($G46+$H46) -> 0 | Q46: =+G46-M46 -> 209.65 | T46: 0 | U46: =$K46 -> 307 | V46: =+ROUND($T46*U46,2) -> 0 | W46: =+T46/($G46+$H46) -> 0 | X46: 0 | Y46: =$K46 -> 307 | Z46: =+ROUND($X46*Y46,2) -> 0 | AA46: =+X46/($G46+$H46) -> 0 | AB46: 0 | AC46: =$K46 -> 307 | AD46: =+ROUND($AB46*AC46,2) -> 0 | AE46: =+AB46/($G46+$H46) -> 0 | AF46: =+M46+O46+X46 -> 0
B47: =+B46+1 -> 33 | C47: .- Aislador Polimérico de 36 kV, Tipo Line Post con Espárrago de 19 mm Ø, 200 mm longitud (Alternativa a Conjunto Aislador-Espiga en Cruceta) | M47: 0 | Q47: =+G47-M47 -> 0 | T47: 0 | U47: =$K47 -> 0 | X47: 0 | Y47: =$K47 -> 0 | AB47: 0 | AC47: =$K47 -> 0 | AF47: =+M47+O47+X47 -> 0
...

Sheet FP LP
B3: FORMULA POLINÓMICA
C6: PROYECTO :
C7: AMPLIACIÓN DEL SERVICIO DE ENERGÍA ELÉCTRICA EN LA PROVINCIA DEL SANTA Y EN EL DISTRITO DE PAMPAROMAS – DEPARTAMENTO DE ANCASH”
C9: LINEAS PRIMARIAS
C10: PRESUPUESTO BASE S/ | D10: =+'RES-LP'!H18 -> #REF! | K10: =D10=SUM(G13:G27) -> #REF!
B12: Nº | C12: ELEMENTO REPRESENTATIVO | D12: INDICE | E12: SIMBOLO | F12: SIMBOLO MONOMIO | G12: MONTO | H12: INCIDENCIA | I12: % PARCIAL | J12: COEFICIENTE
B13: 1 | C13: POSTES DE MADERA IMPORTADA | D13: 042 | E13: PM | F13: PC | G13: =+LP!L32 -> 0 | H13: =ROUND(G13/$D$10,3) -> #REF! | I13: =ROUND(G13/SUM($G$13:$G$16),4) -> 0 | J13: =ROUND(SUM(H13:H16),3) -> #REF!
C14: CRUCETAS DE MADERA | D14: 043 | E14: CM | G14: =+LP!L22 -> 3578 | H14: =ROUND(G14/$D$10,3) -> #REF! | I14: =ROUND(G14/SUM($G$13:$G$16),4) -> 0.0139
C15: POSTES DE CONCRETO | D15: 062 | E15: PC | G15: =+LP!L29+LP!L36 -> 218234.24 | H15: =ROUND(G15/$D$10,3-0.1) -> #REF! | I15: =ROUND(G15/SUM($G$13:$G$16),4) -> 0.8481
C16: OTROS MATERIALES DE CONCRETO ARMADO | D16: 062 | E16: CC | G16: =+LP!L42 -> 35519.2 | H16: =ROUND(G16/$D$10,3) -> #REF! | I16: =ROUND(G16/SUM($G$13:$G$16),4) -> 0.138
B17: 2 | C17: CONDUCTORES DE AAAC Y ACCESORIOS | D17: 030 | E17: DI | F17: DI | G17: =+LP!L56+LP!L73 -> 133692.72 | H17: =ROUND(G17/$D$10,3) -> #REF! | I17: =ROUND(G17/SUM($G$17:$G$18),4) -> 0.9068 | J17: =ROUND(SUM(H17:H18),3) -> #REF!
C18: EQUIPOS DE PROTECCIÓN | D18: 011 | E18: AE1 | G18: =+LP!L136 -> 13745.66 | H18: =ROUND(G18/$D$10,3) -> #REF! | I18: =ROUND(G18/SUM($G$17:$G$18),4) -> 0.0932
B19: 3 | C19: AISLADORES Y ACCESORIOS | D19: 011 | E19: AE2 | F19: AE2 | G19: =+LP!L48+LP!L52 -> 93781.25 | H19: =ROUND(G19/$D$10,3) -> #REF! | I19: =ROUND(G19/SUM($G$19:$G$24),4) -> 0.3362 | J19: =ROUND(SUM(H19:H24),3) -> #REF!
C20: RETENIDAS Y ANCLAJES | D20: 002 | E20: FE | G20: =+LP!L117 -> 31585.24 | H20: =ROUND(G20/$D$10,3) -> #REF! | I20: =ROUND(G20/SUM($G$19:$G$24),4) -> 0.1132
C21: FERRETERIA PARA POSTES Y CRUCETAS | D21: 002 | E21: FP | G21: =+LP!L101 -> 15148.54 | H21: =ROUND(G21/$D$10,3) -> #REF! | I21: =ROUND(G21/SUM($G$19:$G$24),4) -> 0.0543
C22: CONDUCTOR DE COBRE | D22: 006 | E22: CU | G22: =+LP!L76 -> 40485.12 | H22: =ROUND(G22/$D$10,3) -> #REF! | I22: =ROUND(G22/SUM($G$19:$G$24),4) -> 0.1451
C23: MATERIAL PARA PUESTA A TIERRA | D23: 006 | E23: PT | G23: =+LP!L129 -> 11437.24 | H23: =ROUND(G23/$D$10,3) -> #REF! | I23: =ROUND(G23/SUM($G$19:$G$24),4) -> 0.041
C24: TRAMO SUBTERRANEO | D24: 006 | E24: TS | G24: =+LP!L153 -> 86522.98 | H24: =ROUND(G24/$D$10,3) -> #REF! | I24: =ROUND(G24/SUM($G$19:$G$24),4) -> 0.3102
B25: 4 | C25: MONTAJE ELECTROMECANICO | D25: 047 | E25: J | F25: J | G25: =+LP!#REF! -> #REF! | H25: =ROUND(G25/$D$10,3) -> #REF! | I25: =ROUND(G25/($G$25+$G$26),4) -> #REF! | J25: =ROUND(SUM(H25:H26),3) -> #REF!
C26: TRANSPORTE | D26: 032 | E26: FT | G26: =+LP!#REF! -> #REF! | H26: =ROUND(G26/$D$10,3) -> #REF! | I26: =ROUND(G26/($G$25+$G$26),4) -> #REF!
B27: 5 | C27: GASTOS GENERALES Y UTILIDADES | D27: 039 | E27: GG | F27: GU | G27: =+'RES-LP'!H16+'RES-LP'!H17 -> #REF! | H27: =ROUND(G27/$D$10,3) -> #REF! | I27: =+G27/G27 -> #REF! | J27: =ROUND(SUM(H27),3) -> #REF!
B29: K= | C29: =J13&" PCr/PCo + "&J17&" DIr/DIo + "&J19&" AE2r/AE2o+ "&J25&" Jr/Jo + "&J27&" GUr/GUo" -> #REF!
B32: NOTAS:
B34: 1.- | C34: En la fórmula los sub-indices "o" de cada símbolo corresponden al indice de precios según (CREPCO) a la
C35: fecha de Elaboración del Presupuesto (Presupuesto Base) y los sub-indices "r" al indice de precios al
C36: momento de reajuste o fecha de valorización
B37: 2.- | C37: En el caso de los monomios compuestos por varios indices se ha considerado para efecto de denominación
C38: el símbolo que tiene mayor porcentaje de incidencia
B39: 3.- | C39: En caso de cambios en el suministro se deberá actualizar la formula polinómica.
H46: =+IF(SUM(H13:H27)=1,"OK","X") -> #REF! | I46: =+IF(SUM(I13:I27)=5,"OK","X") -> #REF! | J46: =+IF(SUM(J13:J27)=1,"OK","X") -> #REF!

Sheet RES-RP
B2: RESUMEN PRESUPUESTO DE OBRA
B4: AMPLIACIÓN DEL SERVICIO DE ENERGÍA ELÉCTRICA EN LA PROVINCIA DEL SANTA Y EN EL DISTRITO DE PAMPAROMAS – DEPARTAMENTO DE ANCASH
B6: UBICACIÓN | C6: : | D6: ANCASH
B7: SECCIÓN II | C7: : | D7: REDES PRIMARIAS | H7: Fecha: 30-May-2022
H8: T.C. (S/./US$): 3,642
B9: ITEM | C9: DESCRIPCION | G9: PRESUPUESTO CONTRATO | H9: PRESUPUESTO ESTUDIO DEFINIVO | I9: ADICIONALES | K9: DEDUCTIVOS
I10: MAYORES METRADOS | J10: PARTIDAS NUEVAS | K10: MENOR METRADO | L10: DEDUCTIVO VINCULANTE
B12: A | D12: SUMINISTRO DE MATERIALES | G12: =+RP!K136 -> 202256.75 | H12: =+RP!M136 -> 223205.59 | I12: =+RP!#REF! -> #REF! | J12: =+RP!#REF! -> #REF! | K12: =+RP!#REF! -> #REF! | L12: =+RP!#REF! -> #REF!
B13: B | D13: MONTAJE ELECTROMECANICO | G13: =+RP!#REF! -> #REF! | H13: =+RP!#REF! -> #REF! | I13: =+RP!#REF! -> #REF! | J13: =+RP!#REF! -> #REF! | K13: =+RP!#REF! -> #REF! | L13: =+RP!#REF! -> #REF!
B14: C | D14: TRANSPORTE DE MATERIALES | G14: =+RP!#REF! -> #REF! | H14: =+RP!#REF! -> #REF! | I14: =+RP!#REF! -> #REF! | J14: =+RP!#REF! -> #REF! | K14: =+RP!#REF! -> #REF! | L14: =+RP!#REF! -> #REF!
B15: D | D15: TOTAL COSTO DIRECTO | G15: =+SUM(G12:G14) -> #REF! | H15: =+SUM(H12:H14) -> #REF! | I15: =+SUM(I12:I14) -> #REF! | J15: =+SUM(J12:J14) -> #REF! | K15: =+SUM(K12:K14) -> #REF! | L15: =+SUM(L12:L14) -> #REF!
B16: E | D16: GASTOS GENERALES (10.12%) | G16: =ROUND(G15*10.12%,2) -> #REF! | H16: =ROUND(H15*10.12%,2) -> #REF! | I16: =ROUND(I15*10.12%,2) -> #REF! | J16: =ROUND(J15*10.12%,2) -> #REF! | K16: =ROUND(K15*10.12%,2) -> #REF! | L16: =ROUND(L15*10.12%,2) -> #REF!
B17: F | D17: UTILIDADES (3%) | G17: =ROUND(G15*3%,2) -> #REF! | H17: =ROUND(H15*3%,2) -> #REF! | I17: =ROUND(I15*3%,2) -> #REF! | J17: =ROUND(J15*3%,2) -> #REF! | K17: =ROUND(K15*3%,2) -> #REF! | L17: =ROUND(L15*3%,2) -> #REF!
B18: G | D18: COSTO TOTAL S/. (No incluye I.G.V.) | G18: =G17+G16+G15 -> #REF! | H18: =H17+H16+H15 -> #REF! | I18: =I17+I16+I15 -> #REF! | J18: =J17+J16+J15 -> #REF! | K18: =K17+K16+K15 -> #REF! | L18: =L17+L16+L15 -> #REF! | M18: =+H18-G18 -> #REF!
D20: INCIDENCIA % | G20: =+G18/G18 -> #REF! | H20: =+H18/$G$18 -> #REF! | I20: =+I18/$G$18 -> #REF! | J20: =+J18/$G$18 -> #REF! | K20: =+K18/$G$18 -> #REF! | L20: =+L18/$G$18 -> #REF!
H22: =+H18-I18+K18-J18 -> #REF! | K22: =+G12-H12+I12+J12-K12 -> #REF!
H23: =+G18-H22 -> #REF! | K23: =+G13-H13+I13+J13-K13 -> #REF!
K24: =+G14-H14+I14+J14-K14 -> #REF!
K25: =+G15-H15+I15+J15-K15 -> #REF!

Sheet RP
B6: COMPARATIVO DE PRECIOS
B8: OBRA | E8: : | F8: AMPLIACIÓN DEL SERVICIO DE ENERGÍA ELÉCTRICA EN LA PROVINCIA DEL SANTA Y EN EL DISTRITO DE PAMPAROMAS – DEPARTAMENTO DE ANCASH
B9: DEPARTAMENTO | E9: : | F9: ANCASH
B10: SECCIÓN II | E10: : | F10: REDES PRIMARIAS
B12: ITEM | C12: DESCRIPCIÓN DE PARTIDAS | G12: UNID. | H12: Precio de Contrato | I12: Precio Pactado | J12: CONTRACTUAL | L12: ESTUDIO DEFINITIVO | N12: PRECIO DE VENTA | O12: MENDOZA | R12: DIFERENCIA DE PRECIOS | U12: PRECIO DE VENTA | V12: GELCO/Group Electric JYM Sac PU | Y12: PRECIO DE VENTA | Z12: EL DETALLE | AC12: PRECIO DE VENTA | AD12: CIE
J13: Metrado | K13: TOTAL | L13: Metrado | M13: TOTAL | O13: Metrado | P13: TOTAL | Q13: % | V13: Metrado | W13: TOTAL | X13: % | Z13: Metrado | AA13: TOTAL | AB13: % | AD13: Metrado | AE13: TOTAL | AF13: %
H15: Unitario | I15: Unitario | J15: Cantidad | K15: S/. | L15: Cantidad | M15: S/. | N15: S/. | O15: Cantidad | P15: S/. | R15: S/. | S15: TDT | T15: PROYECTO | U15: S/. | V15: Cantidad | W15: S/. | Y15: S/. | Z15: Cantidad | AA15: S/. | AC15: S/. | AD15: Cantidad | AE15: S/.
B16: A | D16: SUMINISTRO DE MATERIALES
B17: 1 | C17: 3 | D17: CRUCETAS DE MADERA DE PROCEDENCIA NACIONAL
B18: =+B17+0.01 -> 1.01 | C18: =+C17+1 -> 4 | D18: Cruceta de madera tratada de 90 mm x 115 mm x 1,20 m | G18: u | H18: 105 | J18: 13 | K18: =+ROUND($H18*J18,2) -> 1365 | L18: =+[193]Metrado!E13 -> 10 | M18: =+ROUND($H18*L18,2) -> 1050 | N18: 0 | O18: =L18 -> 10 | P18: =+ROUND($N18*O18,2) -> 0 | Q18: =+N18/($H18+$I18) -> 0 | R18: =+(H18+I18)-N18 -> 105 | U18: 0 | V18: =$L18 -> 10 | W18: =+ROUND($U18*V18,2) -> 0 | X18: =+U18/($H18+$I18) -> 0 | Y18: 0 | Z18: =$L18 -> 10 | AA18: =+ROUND($Y18*Z18,2) -> 0 | AB18: =+Y18/($H18+$I18) -> 0 | AC18: 0 | AD18: =$L18 -> 10 | AE18: =+ROUND($AC18*AD18,2) -> 0 | AF18: =+AC18/($H18+$I18) -> 0
B19: =+B18+0.01 -> 1.02 | C19: =+C18+1 -> 5 | D19: Listón de madera tratada 50 x 19 mm sección, 2,7 m longitud (incluye clavos de fijación) | G19: u | H19: 27.35 | J19: 2 | K19: =+ROUND($H19*J19,2) -> 54.7 | L19: =+'[193]Metrado'!E14 -> 0 | M19: =+ROUND($H19*L19,2) -> 0 | N19: 0 | O19: =L19 -> 0 | P19: =+ROUND($N19*O19,2) -> 0 | Q19: =+N19/($H19+$I19) -> 0 | R19: =+(H19+I19)-N19 -> 27.35 | U19: 0 | V19: =$L19 -> 0 | W19: =+ROUND($U19*V19,2) -> 0 | X19: =+U19/($H19+$I19) -> 0 | Y19: 0 | Z19: =$L19 -> 0 | AA19: =+ROUND($Y19*Z19,2) -> 0 | AB19: =+Y19/($H19+$I19) -> 0 | AC19: 0 | AD19: =$L19 -> 0 | AE19: =+ROUND($AC19*AD19,2) -> 0 | AF19: =+AC19/($H19+$I19) -> 0
B20: 1.03 | C20: =+C19+1 -> 6 | D20: Cruceta de madera tratada de 90 mm x 115 mm x 2,00 m | G20: u | I20: =+LP!G19 -> 178 | K20: =+ROUND($H20*J20,2) -> 0 | L20: =+'[193]Metrado'!E15 -> 2 | M20: =+ROUND($I20*L20,2) -> 356 | N20: 0 | O20: =L20 -> 2 | P20: =+ROUND($N20*O20,2) -> 0 | Q20: =+N20/($H20+$I20) -> 0 | R20: =+(H20+I20)-N20 -> 178 | U20: 0 | V20: =$L20 -> 2 | W20: =+ROUND($U20*V20,2) -> 0 | X20: =+U20/($H20+$I20) -> 0 | Y20: 0 | Z20: =$L20 -> 2 | AA20: =+ROUND($Y20*Z20,2) -> 0 | AB20: =+Y20/($H20+$I20) -> 0 | AC20: 0 | AD20: =$L20 -> 2 | AE20: =+ROUND($AC20*AD20,2) -> 0 | AF20: =+AC20/($H20+$I20) -> 0
B21: 1.04 | C21: =+C20+1 -> 7 | D21: Cruceta de madera tratada de 90 mm x 115 mm x 2,40 m | G21: u | I21: =+LP!G20 -> 205 | K21: =+ROUND($H21*J21,2) -> 0 | L21: =+'[193]Metrado'!E16 -> 3 | M21: =+ROUND($I21*L21,2) -> 615 | N21: 0 | O21: =L21 -> 3 | P21: =+ROUND($N21*O21,2) -> 0 | Q21: =+N21/($H21+$I21) -> 0 | R21: =+(H21+I21)-N21 -> 205 | U21: 0 | V21: =$L21 -> 3 | W21: =+ROUND($U21*V21,2) -> 0 | X21: =+U21/($H21+$I21) -> 0 | Y21: 0 | Z21: =$L21 -> 3 | AA21: =+ROUND($Y21*Z21,2) -> 0 | AB21: =+Y21/($H21+$I21) -> 0 | AC21: 0 | AD21: =$L21 -> 3 | AE21: =+ROUND($AC21*AD21,2) -> 0 | AF21: =+AC21/($H21+$I21) -> 0
C22: =+C19+1 -> 6 | F22: =+"SUB-TOTAL "&B17&": " -> SUB-TOTAL 1: | K22: =+SUM(K18:K21) -> 1419.7 | M22: =+SUM(M18:M21) -> 2021 | N22: 0 | O22: =L22 -> 0 | P22: =+SUM(P18:P21) -> 0 | R22: =+(H22+I22)-N22 -> 0 | U22: 0 | V22: =$L22 -> 0 | W22: =+SUM(W18:W21) -> 0 | Y22: 0 | Z22: =$L22 -> 0 | AA22: =+SUM(AA18:AA21) -> 0 | AC22: 0 | AD22: =$L22 -> 0 | AE22: =+SUM(AE18:AE21) -> 0
B23: =1+B17 -> 2 | C23: =+C22+1 -> 7 | D23: POSTES DE CONCRETO ARMADO CENTRIFUGADO | N23: 0 | O23: =L23 -> 0 | R23: =+(H23+I23)-N23 -> 0 | U23: 0 | V23: =$L23 -> 0 | Y23: 0 | Z23: =$L23 -> 0 | AC23: 0 | AD23: =$L23 -> 0
B24: 2.01 | C24: =+C20+1 -> 7 | D24: Poste de C.A.C. de 12 m/200 daN (Incluye perilla) | G24: u | H24: 837.45 | J24: 3 | K24: =+ROUND($H24*J24,2) -> 2512.35 | L24: =+'[193]Metrado'!E19 -> 1 | M24: =+ROUND($H24*L24,2) -> 837.45 | N24: 0 | O24: =L24 -> 1 | P24: =+ROUND($N24*O24,2) -> 0 | Q24: =+N24/($H24+$I24) -> 0 | R24: =+(H24+I24)-N24 -> 837.45 | U24: 0 | V24: =$L24 -> 1 | W24: =+ROUND($U24*V24,2) -> 0 | X24: =+U24/($H24+$I24) -> 0 | Y24: 0 | Z24: =$L24 -> 1 | AA24: =+ROUND($Y24*Z24,2) -> 0 | AB24: =+Y24/($H24+$I24) -> 0 | AC24: 0 | AD24: =$L24 -> 1 | AE24: =+ROUND($AC24*AD24,2) -> 0 | AF24: =+AC24/($H24+$I24) -> 0
B25: 2.02 | C25: =+C21+1 -> 8 | D25: Poste de C.A.C. de 12 m/300 daN (Incluye perilla) | G25: u | H25: 923.47 | J25: 11 | K25: =+ROUND($H25*J25,2) -> 10158.17 | L25: =+'[193]Metrado'!E20 -> 13 | M25: =+ROUND($H25*L25,2) -> 12005.11 | N25: 0 | O25: =L25 -> 13 | P25: =+ROUND($N25*O25,2) -> 0 | Q25: =+N25/($H25+$I25) -> 0 | R25: =+(H25+I25)-N25 -> 923.47 | U25: 0 | V25: =$L25 -> 13 | W25: =+ROUND($U25*V25,2) -> 0 | X25: =+U25/($H25+$I25) -> 0 | Y25: 0 | Z25: =$L25 -> 13 | AA25: =+ROUND($Y25*Z25,2) -> 0 | AB25: =+Y25/($H25+$I25) -> 0 | AC25: 0 | AD25: =$L25 -> 13 | AE25: =+ROUND($AC25*AD25,2) -> 0 | AF25: =+AC25/($H25+$I25) -> 0
B26: 2.03 | C26: =+C22+1 -> 7 | D26: Poste de C.A.C. de 13 m/300 daN (Incluye perilla) | G26: u | H26: 1085.14 | J26: 10 | K26: =+ROUND($H26*J26,2) -> 10851.4 | L26: =+'[193]Metrado'!E21 -> 11 | M26: =+ROUND($H26*L26,2) -> 11936.54 | N26: 0 | O26: =L26 -> 11 | P26: =+ROUND($N26*O26,2) -> 0 | Q26: =+N26/($H26+$I26) -> 0 | R26: =+(H26+I26)-N26 -> 1085.14 | U26: 0 | V26: =$L26 -> 11 | W26: =+ROUND($U26*V26,2) -> 0 | X26: =+U26/($H26+$I26) -> 0 | Y26: 0 | Z26: =$L26 -> 11 | AA26: =+ROUND($Y26*Z26,2) -> 0 | AB26: =+Y26/($H26+$I26) -> 0 | AC26: 0 | AD26: =$L26 -> 11 | AE26: =+ROUND($AC26*AD26,2) -> 0 | AF26: =+AC26/($H26+$I26) -> 0
B27: 2.04 | C27: =+C23+1 -> 8 | D27: Poste de C.A.C. de 13 m/400 daN (Incluye perilla) | G27: u | H27: 1207.94 | J27: 10 | K27: =+ROUND($H27*J27,2) -> 12079.4 | L27: =+'[193]Metrado'!E22 -> 14 | M27: =+ROUND($H27*L27,2) -> 16911.16 | N27: 0 | O27: =L27 -> 14 | P27: =+ROUND($N27*O27,2) -> 0 | Q27: =+N27/($H27+$I27) -> 0 | R27: =+(H27+I27)-N27 -> 1207.94 | U27: 0 | V27: =$L27 -> 14 | W27: =+ROUND($U27*V27,2) -> 0 | X27: =+U27/($H27+$I27) -> 0 | Y27: 0 | Z27: =$L27 -> 14 | AA27: =+ROUND($Y27*Z27,2) -> 0 | AB27: =+Y27/($H27+$I27) -> 0 | AC27: 0 | AD27: =$L27 -> 14 | AE27: =+ROUND($AC27*AD27,2) -> 0 | AF27: =+AC27/($H27+$I27) -> 0
C28: =+C27+1 -> 9 | F28: =+"SUB-TOTAL "&B23&": " -> SUB-TOTAL 2: | K28: =+SUM(K24:K27) -> 35601.32 | M28: =+SUM(M24:M27) -> 41690.26 | N28: 0 | O28: =L28 -> 0 | P28: =+SUM(P24:P27) -> 0 | R28: =+(H28+I28)-N28 -> 0 | U28: 0 | V28: =$L28 -> 0 | W28: =+SUM(W24:W27) -> 0 | Y28: 0 | Z28: =$L28 -> 0 | AA28: =+SUM(AA24:AA27) -> 0 | AC28: 0 | AD28: =$L28 -> 0 | AE28: =+SUM(AE24:AE27) -> 0
B29: 3 | C29: =+C28+1 -> 10 | D29: POSTES DE MADERA IMPORTADA | N29: 0 | O29: =L29 -> 0 | R29: =+(H29+I29)-N29 -> 0 | U29: 0 | V29: =$L29 -> 0 | Y29: 0 | Z29: =$L29 -> 0 | AC29: 0 | AD29: =$L29 -> 0
B30: 3.01 | C30: =+#REF!+1 -> #REF! | D30: Poste de madera importada (Pino Amarillo del Sur) de 12 m, Clase 5 | G30: u | H30: 1864.52 | J30: 2 | K30: =+ROUND($H30*J30,2) -> 3729.04 | L30: =+'[193]Metrado'!E25 -> 0 | M30: =+ROUND($H30*L30,2) -> 0 | N30: 0 | O30: =L30 -> 0 | P30: =+ROUND($N30*O30,2) -> 0 | Q30: =+N30/($H30+$I30) -> 0 | R30: =+(H30+I30)-N30 -> 1864.52 | U30: 0 | V30: =$L30 -> 0 | W30: =+ROUND($U30*V30,2) -> 0 | X30: =+U30/($H30+$I30) -> 0 | Y30: 0 | Z30: =$L30 -> 0 | AA30: =+ROUND($Y30*Z30,2) -> 0 | AB30: =+Y30/($H30+$I30) -> 0 | AC30: 0 | AD30: =$L30 -> 0 | AE30: =+ROUND($AC30*AD30,2) -> 0 | AF30: =+AC30/($H30+$I30) -> 0
C31: =+#REF!+1 -> #REF! | F31: =+"SUB-TOTAL "&B29&": " -> SUB-TOTAL 3: | K31: =+SUM(K30:K30) -> 3729.04 | M31: =+SUM(M30:M30) -> 0 | N31: 0 | O31: =L31 -> 0 | P31: =+SUM(P30:P30) -> 0 | R31: =+(H31+I31)-N31 -> 0 | U31: 0 | V31: =$L31 -> 0 | W31: =+SUM(W30:W30) -> 0 | Y31: 0 | Z31: =$L31 -> 0 | AA31: =+SUM(AA30:AA30) -> 0 | AC31: 0 | AD31: =$L31 -> 0 | AE31: =+SUM(AE30:AE30) -> 0
B32: 3.00A | C32: =+C31+1 -> #REF! | D32: POSTES DE FIBRA DE VIDRIO | N32: 0 | O32: =L32 -> 0 | R32: =+(H32+I32)-N32 -> 0 | U32: 0 | V32: =$L32 -> 0 | Y32: 0 | Z32: =$L32 -> 0 | AC32: 0 | AD32: =$L32 -> 0
B33: 3.01A | C33: =+C32+1 -> #REF! | D33: Poste de PRFV de 12 m/200 daN | I33: 1958.01 | K33: =+ROUND($H33*J33,2) -> 0 | L33: =+'[193]Metrado'!E28 -> 0 | M33: =+ROUND($I33*L33,2) -> 0 | N33: 0 | O33: =L33 -> 0 | P33: =+ROUND($N33*O33,2) -> 0 | Q33: =+N33/($H33+$I33) -> 0 | R33: =+(H33+I33)-N33 -> 1958.01 | U33: 0 | V33: =$L33 -> 0 | W33: =+ROUND($U33*V33,2) -> 0 | X33: =+U33/($H33+$I33) -> 0 | Y33: 0 | Z33: =$L33 -> 0 | AA33: =+ROUND($Y33*Z33,2) -> 0 | AB33: =+Y33/($H33+$I33) -> 0 | AC33: 0 | AD33: =$L33 -> 0 | AE33: =+ROUND($AC33*AD33,2) -> 0 | AF33: =+AC33/($H33+$I33) -> 0
B34: 3.02A | C34: =+C33+1 -> #REF! | D34: Poste de PRFV de 12 m/300 daN | I34: 2336.29 | K34: =+ROUND($H34*J34,2) -> 0 | L34: =+'[193]Metrado'!E29 -> 5 | M34: =+ROUND($I34*L34,2) -> 11681.45 | N34: 0 | O34: =L34 -> 5 | P34: =+ROUND($N34*O34,2) -> 0 | Q34: =+N34/($H34+$I34) -> 0 | R34: =+(H34+I34)-N34 -> 2336.29 | U34: 0 | V34: =$L34 -> 5 | W34: =+ROUND($U34*V34,2) -> 0 | X34: =+U34/($H34+$I34) -> 0 | Y34: 0 | Z34: =$L34 -> 5 | AA34: =+ROUND($Y34*Z34,2) -> 0 | AB34: =+Y34/($H34+$I34) -> 0 | AC34: 0 | AD34: =$L34 -> 5 | AE34: =+ROUND($AC34*AD34,2) -> 0 | AF34: =+AC34/($H34+$I34) -> 0
C35: =+C34+1 -> #REF! | F35: =+"SUB-TOTAL "&B32&": " -> SUB-TOTAL 3.00A: | M35: =+SUM(M33:M34) -> 11681.45 | N35: 0 | O35: =L35 -> 0 | R35: =+(H35+I35)-N35 -> 0 | U35: 0 | V35: =$L35 -> 0 | Y35: 0 | Z35: =$L35 -> 0 | AC35: 0 | AD35: =$L35 -> 0
B36: =+B29+1 -> 4 | C36: =+C31+1 -> #REF! | D36: OTROS MATERIALES DE CONCRETO ARMADO | N36: 0 | O36: =L36 -> 0 | R36: =+(H36+I36)-N36 -> 0 | U36: 0 | V36: =$L36 -> 0 | Y36: 0 | Z36: =$L36 -> 0 | AC36: 0 | AD36: =$L36 -> 0
B37: 4.01 | C37: =+C36+1 -> #REF! | D37: Cruceta Asimétrica de C.A.V. Za / 1,5 / 0,9 / 250 / 200 / 100 daN (Za / L / L1/ T / F / V) | G37: u | H37: 120.3 | J37: 5 | K37: =+ROUND($H37*J37,2) -> 601.5 | L37: =+'[193]Metrado'!E32 -> 5 | M37: =+ROUND($H37*L37,2) -> 601.5 | N37: 0 | O37: =L37 -> 5 | P37: =+ROUND($N37*O37,2) -> 0 | Q37: =+N37/($H37+$I37) -> 0 | R37: =+(H37+I37)-N37 -> 120.3 | U37: 0 | V37: =$L37 -> 5 | W37: =+ROUND($U37*V37,2) -> 0 | X37: =+U37/($H37+$I37) -> 0 | Y37: 0 | Z37: =$L37 -> 5 | AA37: =+ROUND($Y37*Z37,2) -> 0 | AB37: =+Y37/($H37+$I37) -> 0 | AC37: 0 | AD37: =$L37 -> 5 | AE37: =+ROUND($AC37*AD37,2) -> 0 | AF37: =+AC37/($H37+$I37) -> 0
B38: 4.02 | C38: =+C37+1 -> #REF! | D38: Ménsula de C.A.V. M / 1,2 / 250 / 150 / 150 daN (M / L / T / F / V) | G38: u | H38: 88.8 | J38: 40 | K38: =+ROUND($H38*J38,2) -> 3552 | L38: =+'[193]Metrado'!E33 -> 60 | M38: =+ROUND($H38*L38,2) -> 5328 | N38: 0 | O38: =L38 -> 60 | P38: =+ROUND($N38*O38,2) -> 0 | Q38: =+N38/($H38+$I38) -> 0 | R38: =+(H38+I38)-N38 -> 88.8 | U38: 0 | V38: =$L38 -> 60 | W38: =+ROUND($U38*V38,2) -> 0 | X38: =+U38/($H38+$I38) -> 0 | Y38: 0 | Z38: =$L38 -> 60 | AA38: =+ROUND($Y38*Z38,2) -> 0 | AB38: =+Y38/($H38+$I38) -> 0 | AC38: 0 | AD38: =$L38 -> 60 | AE38: =+ROUND($AC38*AD38,2) -> 0 | AF38: =+AC38/($H38+$I38) -> 0
B39: 4.03 | C39: =+C38+1 -> #REF! | D39: Plataforma de Concreto Soporte de Transformador de 2,20 m, carga de trabajo de 500 daN | G39: u | H39: 620 | J39: 5 | K39: =+ROUND($H39*J39,2) -> 3100 | L39: =+'[193]Metrado'!E34 -> 5 | M39: =+ROUND($H39*L39,2) -> 3100 | N39: 0 | O39: =L39 -> 5 | P39: =+ROUND($N39*O39,2) -> 0 | Q39: =+N39/($H39+$I39) -> 0 | R39: =+(H39+I39)-N39 -> 620 | U39: 0 | V39: =$L39 -> 5 | W39: =+ROUND($U39*V39,2) -> 0 | X39: =+U39/($H39+$I39) -> 0 | Y39: 0 | Z39: =$L39 -> 5 | AA39: =+ROUND($Y39*Z39,2) -> 0 | AB39: =+Y39/($H39+$I39) -> 0 | AC39: 0 | AD39: =$L39 -> 5 | AE39: =+ROUND($AC39*AD39,2) -> 0 | AF39: =+AC39/($H39+$I39) -> 0
C40: =+#REF!+1 -> #REF! | F40: =+"SUB-TOTAL "&B36&": " -> SUB-TOTAL 4: | K40: =+SUM(K37:K39) -> 7253.5 | M40: =+SUM(M37:M39) -> 9029.5 | N40: 0 | O40: =L40 -> 0 | P40: =+SUM(P37:P39) -> 0 | R40: =+(H40+I40)-N40 -> 0 | U40: 0 | V40: =$L40 -> 0 | W40: =+SUM(W37:W39) -> 0 | Y40: 0 | Z40: =$L40 -> 0 | AA40: =+SUM(AA37:AA39) -> 0 | AC40: 0 | AD40: =$L40 -> 0 | AE40: =+SUM(AE37:AE39) -> 0
B41: =+B36+1 -> 5 | C41: =+C40+1 -> #REF! | D41: AISLADORES Y ACCESORIOS | N41: 0 | O41: =L41 -> 0 | R41: =+(H41+I41)-N41 -> 0 | U41: 0 | V41: =$L41 -> 0 | Y41: 0 | Z41: =$L41 -> 0 | AC41: 0 | AD41: =$L41 -> 0
B42: 5.01 | C42: =+C41+1 -> #REF! | D42: Aislador de Porcelana Tipo Pin, Clase ANSI 56-3 | G42: u | H42: 76.45 | J42: 16 | K42: =+ROUND($H42*J42,2) -> 1223.2 | L42: =+'[193]Metrado'!E37 -> 25 | M42: =+ROUND($H42*L42,2) -> 1911.25 | N42: 0 | O42: =L42 -> 25 | P42: =+ROUND($N42*O42,2) -> 0 | Q42: =+N42/($H42+$I42) -> 0 | R42: =+(H42+I42)-N42 -> 76.45 | U42: 0 | V42: =$L42 -> 25 | W42: =+ROUND($U42*V42,2) -> 0 | X42: =+U42/($H42+$I42) -> 0 | Y42: 0 | Z42: =$L42 -> 25 | AA42: =+ROUND($Y42*Z42,2) -> 0 | AB42: =+Y42/($H42+$I42) -> 0 | AC42: 0 | AD42: =$L42 -> 25 | AE42: =+ROUND($AC42*AD42,2) -> 0 | AF42: =+AC42/($H42+$I42) -> 0
B43: 5.02 | C43: =+C42+1 -> #REF! | D43: Espiga de AºGº de 609 mm longitud, para Cabeza de Poste y Aislador ANSI 56-3 | G43: u | H43: 35.96 | J43: 16 | K43: =+ROUND($H43*J43,2) -> 575.36 | L43: =+'[193]Metrado'!E38 -> 17 | M43: =+ROUND($H43*L43,2) -> 611.32 | N43: 29.85 | O43: =L43 -> 17 | P43: =+ROUND($N43*O43,2) -> 507.45 | Q43: =+N43/($H43+$I43) -> 0.83008899 | R43: =+(H43+I43)-N43 -> 6.11 | S43: =+IFERROR(VLOOKUP(D43,LP!C45:S128,15,0),0) -> 6.11 | T43: =+IFERROR(VLOOKUP(D43,LP!A45:S128,16,0),0) -> 0 | U43: 0 | V43: =$L43 -> 17 | W43: =+ROUND($U43*V43,2) -> 0 | X43: =+U43/($H43+$I43) -> 0 | Y43: 0 | Z43: =$L43 -> 17 | AA43: =+ROUND($Y43*Z43,2) -> 0 | AB43: =+Y43/($H43+$I43) -> 0 | AC43: 0 | AD43: =$L43 -> 17 | AE43: =+ROUND($AC43*AD43,2) -> 0 | AF43: =+AC43/($H43+$I43) -> 0
B44: 5.03 | C44: =+C43+1 -> #REF! | D44: Conjunto Aislador Line Post Polimérico en Cruceta: | G44: u | H44: 209.65 | J44: 40 | K44: =+ROUND($H44*J44,2) -> 8386 | L44: =+[193]Metrado!E40 -> 50 | M44: =+ROUND($H44*L44,2) -> 10482.5 | N44: 0 | O44: =L44 -> 50 | P44: =+ROUND($N44*O44,2) -> 0 | Q44: =+N44/($H44+$I44) -> 0 | R44: =+(H44+I44)-N44 -> 209.65 | U44: 0 | V44: =$L44 -> 50 | W44: =+ROUND($U44*V44,2) -> 0 | X44: =+U44/($H44+$I44) -> 0 | Y44: 0 | Z44: =$L44 -> 50 | AA44: =+ROUND($Y44*Z44,2) -> 0 | AB44: =+Y44/($H44+$I44) -> 0 | AC44: 0 | AD44: =$L44 -> 50 | AE44: =+ROUND($AC44*AD44,2) -> 0 | AF44: =+AC44/($H44+$I44) -> 0
C45: =+C44+1 -> #REF! | D45: - Aislador Polimérico de 36 kV, Tipo Line Post con Espárrago de 19 mm Ø, 200 mm longitud (Alternativa a Conjunto Aislador-Espiga en Cruceta) | N45: 0 | R45: =+(H45+I45)-N45 -> 0 | U45: 0 | V45: =$L45 -> 0 | Y45: 0 | Z45: =$L45 -> 0 | AC45: 0 | AD45: =$L45 -> 0
B46: 5.04 | C46: =+#REF!+1 -> #REF! | D46: Espiga para cruceta, forjada de 381mm LONG. Para aislador Tipo Pin, Clase ANSI 56-3 | G46: u | I46: 49.41 | K46: =+ROUND($H46*J46,2) -> 0 | L46: =+[193]Metrado!E41 -> 8 | M46: =+ROUND($I46*L46,2) -> 395.28 | N46: 35.87 | O46: =L46 -> 8 | P46: =+ROUND($N46*O46,2) -> 286.96 | Q46: =+N46/($H46+$I46) -> 0.7259664 | R46: =+(H46+I46)-N46 -> 13.54 | S46: =+IFERROR(VLOOKUP(D46,LP!C48:S131,15,0),0) -> 0 | T46: =+IFERROR(VLOOKUP(D46,LP!A48:S131,16,0),0) -> 0 | U46: 0 | V46: =$L46 -> 8 | W46: =+ROUND($U46*V46,2) -> 0 | X46: =+U46/($H46+$I46) -> 0 | Y46: 0 | Z46: =$L46 -> 8 | AA46: =+ROUND($Y46*Z46,2) -> 0 | AB46: =+Y46/($H46+$I46) -> 0 | AC46: 0 | AD46: =$L46 -> 8 | AE46: =+ROUND($AC46*AD46,2) -> 0 | AF46: =+AC46/($H46+$I46) -> 0
C47: =+#REF!+1 -> #REF! | F47: =+"SUB-TOTAL "&B41&": " -> SUB-TOTAL 5: | K47: =+SUM(K42:K46) -> 10184.56 | M47: =+SUM(M42:M46) -> 13400.35 | N47: 0 | O47: =L47 -> 0 | P47: =+SUM(P42:P46) -> 794.41 | R47: =+(H47+I47)-N47 -> 0 | U47: 0 | V47: =$L47 -> 0 | W47: =+SUM(W42:W46) -> 0 | Y47: 0 | Z47: =$L47 -> 0 | AA47: =+SUM(AA42:AA46) -> 0 | AC47: 0 | AD47: =$L47 -> 0 | AE47: =+SUM(AE42:AE46) -> 0
B48: =+B41+1 -> 6 | C48: =+C47+1 -> #REF! | D48: AISLADORES DE SUSPENSIÓN Y ACCESORIOS | N48: 0 | O48: =L48 -> 0 | R48: =+(H48+I48)-N48 -> 0 | U48: 0 | V48: =$L48 -> 0 | Y48: 0 | Z48: =$L48 -> 0 | AC48: 0 | AD48: =$L48 -> 0
...

Sheet FP RP
B3: FORMULA POLINÓMICA
C6: PROYECTO :
C7: AMPLIACIÓN DEL SERVICIO DE ENERGÍA ELÉCTRICA EN LA PROVINCIA DEL SANTA Y EN EL DISTRITO DE PAMPAROMAS – DEPARTAMENTO DE ANCASH”
C9: REDES PRIMARIAS
C10: PRESUPUESTO BASE S/ | D10: =+'RES-RP'!H18 -> #REF! | L10: =D10=SUM(G13:G28) -> #REF!
B12: Nº | C12: ELEMENTO REPRESENTATIVO | D12: INDICE | E12: SIMBOLO | F12: SIMBOLO MONOMIO | G12: MONTO | H12: INCIDENCIA | I12: % PARCIAL | J12: COEFICIENTE
B13: 1 | C13: POSTES DE MADERA IMPORTADA | D13: 042 | E13: PM | F13: PC | G13: =+RP!M31 -> 0 | H13: =ROUND(G13/$D$10,3) -> #REF! | I13: =ROUND(G13/SUM($G$13:$G$20),4) -> 0 | J13: =ROUND(SUM(H13:H20),3) -> #REF!
C14: CRUCETAS DE MADERA | D14: 043 | E14: CM | G14: =+RP!M22 -> 2021 | H14: =ROUND(G14/$D$10,3) -> #REF! | I14: =ROUND(G14/SUM($G$13:$G$20),4) -> 0.022
C15: POSTES DE CONCRETO | D15: 062 | E15: PC | G15: =+RP!M28+RP!M35 -> 53371.71 | H15: =ROUND(G15/$D$10,3) -> #REF! | I15: =ROUND(G15/SUM($G$13:$G$20),4)+0.0001 -> 0.5812
C16: OTROS MATERIALES DE CONCRETO ARMADO | D16: 062 | E16: CC | G16: =+RP!M40 -> 9029.5 | H16: =ROUND(G16/$D$10,3) -> #REF! | I16: =ROUND(G16/SUM($G$13:$G$20),4) -> 0.0983
C17: FERRETERIA PARA POSTES Y CRUCETAS | D17: 002 | E17: FP | G17: =+RP!M85 -> 3735.48 | H17: =ROUND(G17/$D$10,3) -> #REF! | I17: =ROUND(G17/SUM($G$13:$G$20),4) -> 0.0407
C18: RETENIDAS Y ANCLAJES | D18: 002 | E18: FE | G18: =+RP!M99 -> 6000.31 | H18: =ROUND(G18/$D$10,3) -> #REF! | I18: =ROUND(G18/SUM($G$13:$G$20),4) -> 0.0653
C19: CONDUCTOR DE COBRE Y ACCESORIOS | D19: 006 | E19: CU | G19: =+RP!M65 -> 5523.2 | H19: =ROUND(G19/$D$10,3) -> #REF! | I19: =ROUND(G19/SUM($G$13:$G$20),4) -> 0.0601
C20: MATERIAL PARA PUESTA A TIERRA | D20: 006 | E20: PT | G20: =+RP!M111 -> 12159.04 | H20: =ROUND(G20/$D$10,3+0.1) -> #REF! | I20: =ROUND(G20/SUM($G$13:$G$20),4) -> 0.1324
B21: 2 | C21: EQUIPOS DE PROTECCIÓN | D21: 011 | E21: AE1 | F21: AE1 | G21: =+RP!M117 -> 14296.26 | H21: =ROUND(G21/$D$10,3) -> #REF! | I21: =ROUND(G21/SUM($G$21:$G$24),4) -> 0.3262 | J21: =ROUND(SUM(H21:H24),3) -> #REF!
C22: AISLADORES Y ACCESORIOS | D22: 011 | E22: AE2 | G22: =+RP!M47+RP!M51 -> 15572.01 | H22: =ROUND(G22/$D$10,3) -> #REF! | I22: =ROUND(G22/SUM($G$21:$G$24),4)+0.0001 -> 0.3554
C23: CABLES DE ENERGÍA | D23: 019 | E23: NY | G23: =+RP!M135 -> 3267.22 | H23: =ROUND(G23/$D$10,3) -> #REF! | I23: =ROUND(G23/SUM($G$21:$G$24),4) -> 0.0745
C24: CONDUCTORES DE AAAC Y ACCESORIOS | D24: 030 | E24: DI | G24: =+RP!M54+RP!M62 -> 10691.09 | H24: =ROUND(G24/$D$10,3) -> #REF! | I24: =ROUND(G24/SUM($G$21:$G$24),4) -> 0.2439
B25: 3 | C25: TRANSFORMADORES DE DISTRIBUCIÓN Y TABLEROS | D25: 048 | E25: EN | F25: EN | G25: =+RP!M124+RP!M130 -> 87538.77 | H25: =ROUND(G25/$D$10,3) -> #REF! | I25: =ROUND(G25/SUM($G$25:$G$25),4) -> 1 | J25: =ROUND(SUM(H25),3) -> #REF!
